Workbook

Sheet CEO Report
A1: ⚡ MiT Strom Schweiz — CEO Sales Report · Mai 2026
A2: Mobil in Time AG · An Aggreko Company · Burak Ücöz · Neue Einträge in «MiT Strom Pipeline» erscheinen automatisch.
A5: ✅ AUFTRAGSEINGANG (WON) | E5: 📄 OFFERTE — Laufend | I5: 🎯 OPPORTUNITÄT
A6: =SUMIFS('MiT Strom Pipeline'!I$6:I$904,'MiT Strom Pipeline'!R$6:R$904,"WON") -> 333100 | E6: =SUMIFS('MiT Strom Pipeline'!I$6:I$904,'MiT Strom Pipeline'!R$6:R$904,"offered")+SUMIFS('MiT Strom Pipeline'!I$6:I$904,'MiT Strom Pipeline'!R$6:R$904,"to be offered")+SUMIFS('MiT Strom Pipeline'!I$6:I$904,'MiT Strom Pipeline'!R$6:R$904,"on hold") -> 3866028.6 | I6: =SUMIFS('MiT Strom Pipeline'!I$6:I$904,'MiT Strom Pipeline'!R$6:R$904,"follow-up")+SUMIFS('MiT Strom Pipeline'!I$6:I$904,'MiT Strom Pipeline'!R$6:R$904,"Evaluation")+SUMIFS('MiT Strom Pipeline'!I$6:I$904,'MiT Strom Pipeline'!R$6:R$904,"tbd")+SUMIFS('MiT Strom Pipeline'!I$6:I$904,'MiT Strom Pipeline'!R$6:R$904,"In evaluation") -> 672987.69
A7: =COUNTIF('MiT Strom Pipeline'!R$6:R$904,"WON") -> 4 | E7: =COUNTIF('MiT Strom Pipeline'!R$6:R$904,"offered")+COUNTIF('MiT Strom Pipeline'!R$6:R$904,"to be offered")+COUNTIF('MiT Strom Pipeline'!R$6:R$904,"on hold") -> 12 | I7: =COUNTIF('MiT Strom Pipeline'!R$6:R$904,"follow-up")+COUNTIF('MiT Strom Pipeline'!R$6:R$904,"Evaluation")+COUNTIF('MiT Strom Pipeline'!R$6:R$904,"tbd")+COUNTIF('MiT Strom Pipeline'!R$6:R$904,"In evaluation") -> 16
A9: ✅ 1. AUFTRAGSEINGANG (WON) — Bestätigte Aufträge
A10: # | B10: Kunde / Unternehmen | C10: Kt. | D10: Segment | E10: Leistung / Fleet | F10: Volumen CHF | G10: Gew.Wert CHF | H10: Marge CHF | I10: Status | J10: Wahr.% | K10: Nächster Schritt
A11: =IF('MiT Strom Pipeline'!R6="WON",IF(ISNUMBER('MiT Strom Pipeline'!A6),'MiT Strom Pipeline'!A6,""),"") -> 1 | B11: =IF('MiT Strom Pipeline'!R6="WON",'MiT Strom Pipeline'!B6,"") -> Ice Hockey Championship | C11: =IF('MiT Strom Pipeline'!R6="WON",'MiT Strom Pipeline'!C6,"") -> ZH | D11: =IF('MiT Strom Pipeline'!R6="WON",'MiT Strom Pipeline'!D6,"") -> Events & Sport | E11: =IF('MiT Strom Pipeline'!R6="WON",'MiT Strom Pipeline'!E6,"") -> 2×600+2×200 kVA | F11: =IF('MiT Strom Pipeline'!R6="WON",IF(ISNUMBER('MiT Strom Pipeline'!I6),'MiT Strom Pipeline'!I6,0),"") -> 310000 | G11: =IF('MiT Strom Pipeline'!R6="WON",IF(ISNUMBER('MiT Strom Pipeline'!Q6),'MiT Strom Pipeline'!Q6,0),"") -> 3100 | H11: =IF('MiT Strom Pipeline'!R6="WON",IF(ISNUMBER('MiT Strom Pipeline'!O6),'MiT Strom Pipeline'!O6,0),"") -> 75000 | I11: =IF('MiT Strom Pipeline'!R6="WON",'MiT Strom Pipeline'!R6,"") -> WON | J11: =IF('MiT Strom Pipeline'!R6="WON",'MiT Strom Pipeline'!S6,"") -> 100% | K11: =IF('MiT Strom Pipeline'!R6="WON",IF(LEN('MiT Strom Pipeline'!V6)>0,LEFT('MiT Strom Pipeline'!V6,55),""),"") -> ✅ Einsatzplanung läuft – Logistik finalisieren
A12: =IF('MiT Strom Pipeline'!R7="WON",IF(ISNUMBER('MiT Strom Pipeline'!A7),'MiT Strom Pipeline'!A7,""),"") -> 2 | B12: =IF('MiT Strom Pipeline'!R7="WON",'MiT Strom Pipeline'!B7,"") -> Oerlikon Metco Wohlen | C12: =IF('MiT Strom Pipeline'!R7="WON",'MiT Strom Pipeline'!C7,"") -> AG | D12: =IF('MiT Strom Pipeline'!R7="WON",'MiT Strom Pipeline'!D7,"") -> Industrie / Oberfläche | E12: =IF('MiT Strom Pipeline'!R7="WON",'MiT Strom Pipeline'!E7,"") -> 240 kVA Generator | F12: =IF('MiT Strom Pipeline'!R7="WON",IF(ISNUMBER('MiT Strom Pipeline'!I7),'MiT Strom Pipeline'!I7,0),"") -> 13100 | G12: =IF('MiT Strom Pipeline'!R7="WON",IF(ISNUMBER('MiT Strom Pipeline'!Q7),'MiT Strom Pipeline'!Q7,0),"") -> 131 | H12: =IF('MiT Strom Pipeline'!R7="WON",IF(ISNUMBER('MiT Strom Pipeline'!O7),'MiT Strom Pipeline'!O7,0),"") -> 3000 | I12: =IF('MiT Strom Pipeline'!R7="WON",'MiT Strom Pipeline'!R7,"") -> WON | J12: =IF('MiT Strom Pipeline'!R7="WON",'MiT Strom Pipeline'!S7,"") -> 100% | K12: =IF('MiT Strom Pipeline'!R7="WON",IF(LEN('MiT Strom Pipeline'!V7)>0,LEFT('MiT Strom Pipeline'!V7,55),""),"") -> ✅ Abgeschlossen – Invoice prüfen, Referenz sichern
A13: =IF('MiT Strom Pipeline'!R8="WON",IF(ISNUMBER('MiT Strom Pipeline'!A8),'MiT Strom Pipeline'!A8,""),"") -> 3 | B13: =IF('MiT Strom Pipeline'!R8="WON",'MiT Strom Pipeline'!B8,"") -> Siemens | C13: =IF('MiT Strom Pipeline'!R8="WON",'MiT Strom Pipeline'!C8,"") -> ZH | D13: =IF('MiT Strom Pipeline'!R8="WON",'MiT Strom Pipeline'!D8,"") -> Industrie / Elektro | E13: =IF('MiT Strom Pipeline'!R8="WON",'MiT Strom Pipeline'!E8,"") -> 600 kVA Generator | F13: =IF('MiT Strom Pipeline'!R8="WON",IF(ISNUMBER('MiT Strom Pipeline'!I8),'MiT Strom Pipeline'!I8,0),"") -> 10000 | G13: =IF('MiT Strom Pipeline'!R8="WON",IF(ISNUMBER('MiT Strom Pipeline'!Q8),'MiT Strom Pipeline'!Q8,0),"") -> 100 | H13: =IF('MiT Strom Pipeline'!R8="WON",IF(ISNUMBER('MiT Strom Pipeline'!O8),'MiT Strom Pipeline'!O8,0),"") -> 10000 | I13: =IF('MiT Strom Pipeline'!R8="WON",'MiT Strom Pipeline'!R8,"") -> WON | J13: =IF('MiT Strom Pipeline'!R8="WON",'MiT Strom Pipeline'!S8,"") -> 100% | K13: =IF('MiT Strom Pipeline'!R8="WON",IF(LEN('MiT Strom Pipeline'!V8)>0,LEFT('MiT Strom Pipeline'!V8,55),""),"") -> ✅ Referenzschreiben anfordern
A14: =IF('MiT Strom Pipeline'!R9="WON",IF(ISNUMBER('MiT Strom Pipeline'!A9),'MiT Strom Pipeline'!A9,""),"") | B14: =IF('MiT Strom Pipeline'!R9="WON",'MiT Strom Pipeline'!B9,"") | C14: =IF('MiT Strom Pipeline'!R9="WON",'MiT Strom Pipeline'!C9,"") | D14: =IF('MiT Strom Pipeline'!R9="WON",'MiT Strom Pipeline'!D9,"") | E14: =IF('MiT Strom Pipeline'!R9="WON",'MiT Strom Pipeline'!E9,"") | F14: =IF('MiT Strom Pipeline'!R9="WON",IF(ISNUMBER('MiT Strom Pipeline'!I9),'MiT Strom Pipeline'!I9,0),"") | G14: =IF('MiT Strom Pipeline'!R9="WON",IF(ISNUMBER('MiT Strom Pipeline'!Q9),'MiT Strom Pipeline'!Q9,0),"") | H14: =IF('MiT Strom Pipeline'!R9="WON",IF(ISNUMBER('MiT Strom Pipeline'!O9),'MiT Strom Pipeline'!O9,0),"") | I14: =IF('MiT Strom Pipeline'!R9="WON",'MiT Strom Pipeline'!R9,"") | J14: =IF('MiT Strom Pipeline'!R9="WON",'MiT Strom Pipeline'!S9,"") | K14: =IF('MiT Strom Pipeline'!R9="WON",IF(LEN('MiT Strom Pipeline'!V9)>0,LEFT('MiT Strom Pipeline'!V9,55),""),"")
A15: =IF('MiT Strom Pipeline'!R10="WON",IF(ISNUMBER('MiT Strom Pipeline'!A10),'MiT Strom Pipeline'!A10,""),"") | B15: =IF('MiT Strom Pipeline'!R10="WON",'MiT Strom Pipeline'!B10,"") | C15: =IF('MiT Strom Pipeline'!R10="WON",'MiT Strom Pipeline'!C10,"") | D15: =IF('MiT Strom Pipeline'!R10="WON",'MiT Strom Pipeline'!D10,"") | E15: =IF('MiT Strom Pipeline'!R10="WON",'MiT Strom Pipeline'!E10,"") | F15: =IF('MiT Strom Pipeline'!R10="WON",IF(ISNUMBER('MiT Strom Pipeline'!I10),'MiT Strom Pipeline'!I10,0),"") | G15: =IF('MiT Strom Pipeline'!R10="WON",IF(ISNUMBER('MiT Strom Pipeline'!Q10),'MiT Strom Pipeline'!Q10,0),"") | H15: =IF('MiT Strom Pipeline'!R10="WON",IF(ISNUMBER('MiT Strom Pipeline'!O10),'MiT Strom Pipeline'!O10,0),"") | I15: =IF('MiT Strom Pipeline'!R10="WON",'MiT Strom Pipeline'!R10,"") | J15: =IF('MiT Strom Pipeline'!R10="WON",'MiT Strom Pipeline'!S10,"") | K15: =IF('MiT Strom Pipeline'!R10="WON",IF(LEN('MiT Strom Pipeline'!V10)>0,LEFT('MiT Strom Pipeline'!V10,55),""),"")
A16: =IF('MiT Strom Pipeline'!R11="WON",IF(ISNUMBER('MiT Strom Pipeline'!A11),'MiT Strom Pipeline'!A11,""),"") | B16: =IF('MiT Strom Pipeline'!R11="WON",'MiT Strom Pipeline'!B11,"") | C16: =IF('MiT Strom Pipeline'!R11="WON",'MiT Strom Pipeline'!C11,"") | D16: =IF('MiT Strom Pipeline'!R11="WON",'MiT Strom Pipeline'!D11,"") | E16: =IF('MiT Strom Pipeline'!R11="WON",'MiT Strom Pipeline'!E11,"") | F16: =IF('MiT Strom Pipeline'!R11="WON",IF(ISNUMBER('MiT Strom Pipeline'!I11),'MiT Strom Pipeline'!I11,0),"") | G16: =IF('MiT Strom Pipeline'!R11="WON",IF(ISNUMBER('MiT Strom Pipeline'!Q11),'MiT Strom Pipeline'!Q11,0),"") | H16: =IF('MiT Strom Pipeline'!R11="WON",IF(ISNUMBER('MiT Strom Pipeline'!O11),'MiT Strom Pipeline'!O11,0),"") | I16: =IF('MiT Strom Pipeline'!R11="WON",'MiT Strom Pipeline'!R11,"") | J16: =IF('MiT Strom Pipeline'!R11="WON",'MiT Strom Pipeline'!S11,"") | K16: =IF('MiT Strom Pipeline'!R11="WON",IF(LEN('MiT Strom Pipeline'!V11)>0,LEFT('MiT Strom Pipeline'!V11,55),""),"")
A17: =IF('MiT Strom Pipeline'!R12="WON",IF(ISNUMBER('MiT Strom Pipeline'!A12),'MiT Strom Pipeline'!A12,""),"") | B17: =IF('MiT Strom Pipeline'!R12="WON",'MiT Strom Pipeline'!B12,"") | C17: =IF('MiT Strom Pipeline'!R12="WON",'MiT Strom Pipeline'!C12,"") | D17: =IF('MiT Strom Pipeline'!R12="WON",'MiT Strom Pipeline'!D12,"") | E17: =IF('MiT Strom Pipeline'!R12="WON",'MiT Strom Pipeline'!E12,"") | F17: =IF('MiT Strom Pipeline'!R12="WON",IF(ISNUMBER('MiT Strom Pipeline'!I12),'MiT Strom Pipeline'!I12,0),"") | G17: =IF('MiT Strom Pipeline'!R12="WON",IF(ISNUMBER('MiT Strom Pipeline'!Q12),'MiT Strom Pipeline'!Q12,0),"") | H17: =IF('MiT Strom Pipeline'!R12="WON",IF(ISNUMBER('MiT Strom Pipeline'!O12),'MiT Strom Pipeline'!O12,0),"") | I17: =IF('MiT Strom Pipeline'!R12="WON",'MiT Strom Pipeline'!R12,"") | J17: =IF('MiT Strom Pipeline'!R12="WON",'MiT Strom Pipeline'!S12,"") | K17: =IF('MiT Strom Pipeline'!R12="WON",IF(LEN('MiT Strom Pipeline'!V12)>0,LEFT('MiT Strom Pipeline'!V12,55),""),"")
A18: =IF('MiT Strom Pipeline'!R13="WON",IF(ISNUMBER('MiT Strom Pipeline'!A13),'MiT Strom Pipeline'!A13,""),"") | B18: =IF('MiT Strom Pipeline'!R13="WON",'MiT Strom Pipeline'!B13,"") | C18: =IF('MiT Strom Pipeline'!R13="WON",'MiT Strom Pipeline'!C13,"") | D18: =IF('MiT Strom Pipeline'!R13="WON",'MiT Strom Pipeline'!D13,"") | E18: =IF('MiT Strom Pipeline'!R13="WON",'MiT Strom Pipeline'!E13,"") | F18: =IF('MiT Strom Pipeline'!R13="WON",IF(ISNUMBER('MiT Strom Pipeline'!I13),'MiT Strom Pipeline'!I13,0),"") | G18: =IF('MiT Strom Pipeline'!R13="WON",IF(ISNUMBER('MiT Strom Pipeline'!Q13),'MiT Strom Pipeline'!Q13,0),"") | H18: =IF('MiT Strom Pipeline'!R13="WON",IF(ISNUMBER('MiT Strom Pipeline'!O13),'MiT Strom Pipeline'!O13,0),"") | I18: =IF('MiT Strom Pipeline'!R13="WON",'MiT Strom Pipeline'!R13,"") | J18: =IF('MiT Strom Pipeline'!R13="WON",'MiT Strom Pipeline'!S13,"") | K18: =IF('MiT Strom Pipeline'!R13="WON",IF(LEN('MiT Strom Pipeline'!V13)>0,LEFT('MiT Strom Pipeline'!V13,55),""),"")
A19: =IF('MiT Strom Pipeline'!R14="WON",IF(ISNUMBER('MiT Strom Pipeline'!A14),'MiT Strom Pipeline'!A14,""),"") | B19: =IF('MiT Strom Pipeline'!R14="WON",'MiT Strom Pipeline'!B14,"") | C19: =IF('MiT Strom Pipeline'!R14="WON",'MiT Strom Pipeline'!C14,"") | D19: =IF('MiT Strom Pipeline'!R14="WON",'MiT Strom Pipeline'!D14,"") | E19: =IF('MiT Strom Pipeline'!R14="WON",'MiT Strom Pipeline'!E14,"") | F19: =IF('MiT Strom Pipeline'!R14="WON",IF(ISNUMBER('MiT Strom Pipeline'!I14),'MiT Strom Pipeline'!I14,0),"") | G19: =IF('MiT Strom Pipeline'!R14="WON",IF(ISNUMBER('MiT Strom Pipeline'!Q14),'MiT Strom Pipeline'!Q14,0),"") | H19: =IF('MiT Strom Pipeline'!R14="WON",IF(ISNUMBER('MiT Strom Pipeline'!O14),'MiT Strom Pipeline'!O14,0),"") | I19: =IF('MiT Strom Pipeline'!R14="WON",'MiT Strom Pipeline'!R14,"") | J19: =IF('MiT Strom Pipeline'!R14="WON",'MiT Strom Pipeline'!S14,"") | K19: =IF('MiT Strom Pipeline'!R14="WON",IF(LEN('MiT Strom Pipeline'!V14)>0,LEFT('MiT Strom Pipeline'!V14,55),""),"")
A20: =IF('MiT Strom Pipeline'!R15="WON",IF(ISNUMBER('MiT Strom Pipeline'!A15),'MiT Strom Pipeline'!A15,""),"") | B20: =IF('MiT Strom Pipeline'!R15="WON",'MiT Strom Pipeline'!B15,"") | C20: =IF('MiT Strom Pipeline'!R15="WON",'MiT Strom Pipeline'!C15,"") | D20: =IF('MiT Strom Pipeline'!R15="WON",'MiT Strom Pipeline'!D15,"") | E20: =IF('MiT Strom Pipeline'!R15="WON",'MiT Strom Pipeline'!E15,"") | F20: =IF('MiT Strom Pipeline'!R15="WON",IF(ISNUMBER('MiT Strom Pipeline'!I15),'MiT Strom Pipeline'!I15,0),"") | G20: =IF('MiT Strom Pipeline'!R15="WON",IF(ISNUMBER('MiT Strom Pipeline'!Q15),'MiT Strom Pipeline'!Q15,0),"") | H20: =IF('MiT Strom Pipeline'!R15="WON",IF(ISNUMBER('MiT Strom Pipeline'!O15),'MiT Strom Pipeline'!O15,0),"") | I20: =IF('MiT Strom Pipeline'!R15="WON",'MiT Strom Pipeline'!R15,"") | J20: =IF('MiT Strom Pipeline'!R15="WON",'MiT Strom Pipeline'!S15,"") | K20: =IF('MiT Strom Pipeline'!R15="WON",IF(LEN('MiT Strom Pipeline'!V15)>0,LEFT('MiT Strom Pipeline'!V15,55),""),"")
A21: =IF('MiT Strom Pipeline'!R16="WON",IF(ISNUMBER('MiT Strom Pipeline'!A16),'MiT Strom Pipeline'!A16,""),"") | B21: =IF('MiT Strom Pipeline'!R16="WON",'MiT Strom Pipeline'!B16,"") | C21: =IF('MiT Strom Pipeline'!R16="WON",'MiT Strom Pipeline'!C16,"") | D21: =IF('MiT Strom Pipeline'!R16="WON",'MiT Strom Pipeline'!D16,"") | E21: =IF('MiT Strom Pipeline'!R16="WON",'MiT Strom Pipeline'!E16,"") | F21: =IF('MiT Strom Pipeline'!R16="WON",IF(ISNUMBER('MiT Strom Pipeline'!I16),'MiT Strom Pipeline'!I16,0),"") | G21: =IF('MiT Strom Pipeline'!R16="WON",IF(ISNUMBER('MiT Strom Pipeline'!Q16),'MiT Strom Pipeline'!Q16,0),"") | H21: =IF('MiT Strom Pipeline'!R16="WON",IF(ISNUMBER('MiT Strom Pipeline'!O16),'MiT Strom Pipeline'!O16,0),"") | I21: =IF('MiT Strom Pipeline'!R16="WON",'MiT Strom Pipeline'!R16,"") | J21: =IF('MiT Strom Pipeline'!R16="WON",'MiT Strom Pipeline'!S16,"") | K21: =IF('MiT Strom Pipeline'!R16="WON",IF(LEN('MiT Strom Pipeline'!V16)>0,LEFT('MiT Strom Pipeline'!V16,55),""),"")
A22: =IF('MiT Strom Pipeline'!R17="WON",IF(ISNUMBER('MiT Strom Pipeline'!A17),'MiT Strom Pipeline'!A17,""),"") | B22: =IF('MiT Strom Pipeline'!R17="WON",'MiT Strom Pipeline'!B17,"") | C22: =IF('MiT Strom Pipeline'!R17="WON",'MiT Strom Pipeline'!C17,"") | D22: =IF('MiT Strom Pipeline'!R17="WON",'MiT Strom Pipeline'!D17,"") | E22: =IF('MiT Strom Pipeline'!R17="WON",'MiT Strom Pipeline'!E17,"") | F22: =IF('MiT Strom Pipeline'!R17="WON",IF(ISNUMBER('MiT Strom Pipeline'!I17),'MiT Strom Pipeline'!I17,0),"") | G22: =IF('MiT Strom Pipeline'!R17="WON",IF(ISNUMBER('MiT Strom Pipeline'!Q17),'MiT Strom Pipeline'!Q17,0),"") | H22: =IF('MiT Strom Pipeline'!R17="WON",IF(ISNUMBER('MiT Strom Pipeline'!O17),'MiT Strom Pipeline'!O17,0),"") | I22: =IF('MiT Strom Pipeline'!R17="WON",'MiT Strom Pipeline'!R17,"") | J22: =IF('MiT Strom Pipeline'!R17="WON",'MiT Strom Pipeline'!S17,"") | K22: =IF('MiT Strom Pipeline'!R17="WON",IF(LEN('MiT Strom Pipeline'!V17)>0,LEFT('MiT Strom Pipeline'!V17,55),""),"")
... A70: =IF('MiT Strom Pipeline'!R65="WON",IF(ISNUMBER('MiT Strom Pipeline'!A65),'MiT Strom Pipeline'!A65,""),"") | B70: =IF('MiT Strom Pipeline'!R65="WON",'MiT Strom Pipeline'!B65,"") | C70: =IF('MiT Strom Pipeline'!R65="WON",'MiT Strom Pipeline'!C65,"") | D70: =IF('MiT Strom Pipeline'!R65="WON",'MiT Strom Pipeline'!D65,"") | E70: =IF('MiT Strom Pipeline'!R65="WON",'MiT Strom Pipeline'!E65,"") | F70: =IF('MiT Strom Pipeline'!R65="WON",IF(ISNUMBER('MiT Strom Pipeline'!I65),'MiT Strom Pipeline'!I65,0),"") | G70: =IF('MiT Strom Pipeline'!R65="WON",IF(ISNUMBER('MiT Strom Pipeline'!Q65),'MiT Strom Pipeline'!Q65,0),"") | H70: =IF('MiT Strom Pipeline'!R65="WON",IF(ISNUMBER('MiT Strom Pipeline'!O65),'MiT Strom Pipeline'!O65,0),"") | I70: =IF('MiT Strom Pipeline'!R65="WON",'MiT Strom Pipeline'!R65,"") | J70: =IF('MiT Strom Pipeline'!R65="WON",'MiT Strom Pipeline'!S65,"") | K70: =IF('MiT Strom Pipeline'!R65="WON",IF(LEN('MiT Strom Pipeline'!V65)>0,LEFT('MiT Strom Pipeline'!V65,55),""),"")
A71: =IF('MiT Strom Pipeline'!R66="WON",IF(ISNUMBER('MiT Strom Pipeline'!A66),'MiT Strom Pipeline'!A66,""),"") | B71: =IF('MiT Strom Pipeline'!R66="WON",'MiT Strom Pipeline'!B66,"") | F71: =IF('MiT Strom Pipeline'!R66="WON",IF(ISNUMBER('MiT Strom Pipeline'!I66),'MiT Strom Pipeline'!I66,0),"") | G71: =IF('MiT Strom Pipeline'!R66="WON",IF(ISNUMBER('MiT Strom Pipeline'!Q66),'MiT Strom Pipeline'!Q66,0),"") | H71: =IF('MiT Strom Pipeline'!R66="WON",IF(ISNUMBER('MiT Strom Pipeline'!O66),'MiT Strom Pipeline'!O66,0),"") | I71: =IF('MiT Strom Pipeline'!R66="WON",'MiT Strom Pipeline'!R66,"") | J71: =IF('MiT Strom Pipeline'!R66="WON",'MiT Strom Pipeline'!S66,"") | K71: =IF('MiT Strom Pipeline'!R66="WON",IF(LEN('MiT Strom Pipeline'!V66)>0,LEFT('MiT Strom Pipeline'!V66,55),""),"")
A72: =IF('MiT Strom Pipeline'!R67="WON",IF(ISNUMBER('MiT Strom Pipeline'!A67),'MiT Strom Pipeline'!A67,""),"") | B72: =IF('MiT Strom Pipeline'!R67="WON",'MiT Strom Pipeline'!B67,"") | C72: =IF('MiT Strom Pipeline'!R67="WON",'MiT Strom Pipeline'!C67,"") | D72: =IF('MiT Strom Pipeline'!R67="WON",'MiT Strom Pipeline'!D67,"") | E72: =IF('MiT Strom Pipeline'!R67="WON",'MiT Strom Pipeline'!E67,"") | F72: =IF('MiT Strom Pipeline'!R67="WON",IF(ISNUMBER('MiT Strom Pipeline'!I67),'MiT Strom Pipeline'!I67,0),"") | G72: =IF('MiT Strom Pipeline'!R67="WON",IF(ISNUMBER('MiT Strom Pipeline'!Q67),'MiT Strom Pipeline'!Q67,0),"") | H72: =IF('MiT Strom Pipeline'!R67="WON",IF(ISNUMBER('MiT Strom Pipeline'!O67),'MiT Strom Pipeline'!O67,0),"") | I72: =IF('MiT Strom Pipeline'!R67="WON",'MiT Strom Pipeline'!R67,"") | J72: =IF('MiT Strom Pipeline'!R67="WON",'MiT Strom Pipeline'!S67,"") | K72: =IF('MiT Strom Pipeline'!R67="WON",IF(LEN('MiT Strom Pipeline'!V67)>0,LEFT('MiT Strom Pipeline'!V67,55),""),"")
A73: 📄 2. OFFERTE — Versendete & laufende Angebote
A74: # | B74: Kunde / Unternehmen | C74: Kt. | D74: Segment | E74: Leistung / Fleet | F74: Volumen CHF | G74: Gew.Wert CHF | H74: Marge CHF | I74: Status | J74: Wahr.% | K74: Nächster Schritt
A75: =IF(('MiT Strom Pipeline'!R6="offered")+('MiT Strom Pipeline'!R6="to be offered")+('MiT Strom Pipeline'!R6="on hold")>0,IF(ISNUMBER('MiT Strom Pipeline'!A6),'MiT Strom Pipeline'!A6,""),"") | B75: =IF(('MiT Strom Pipeline'!R6="offered")+('MiT Strom Pipeline'!R6="to be offered")+('MiT Strom Pipeline'!R6="on hold")>0,'MiT Strom Pipeline'!B6,"") | C75: =IF(('MiT Strom Pipeline'!R6="offered")+('MiT Strom Pipeline'!R6="to be offered")+('MiT Strom Pipeline'!R6="on hold")>0,'MiT Strom Pipeline'!C6,"") | D75: =IF(('MiT Strom Pipeline'!R6="offered")+('MiT Strom Pipeline'!R6="to be offered")+('MiT Strom Pipeline'!R6="on hold")>0,'MiT Strom Pipeline'!D6,"") | E75: =IF(('MiT Strom Pipeline'!R6="offered")+('MiT Strom Pipeline'!R6="to be offered")+('MiT Strom Pipeline'!R6="on hold")>0,'MiT Strom Pipeline'!E6,"") | F75: =IF(('MiT Strom Pipeline'!R6="offered")+('MiT Strom Pipeline'!R6="to be offered")+('MiT Strom Pipeline'!R6="on hold")>0,IF(ISNUMBER('MiT Strom Pipeline'!I6),'MiT Strom Pipeline'!I6,0),"") | G75: =IF(('MiT Strom Pipeline'!R6="offered")+('MiT Strom Pipeline'!R6="to be offered")+('MiT Strom Pipeline'!R6="on hold")>0,IF(ISNUMBER('MiT Strom Pipeline'!Q6),'MiT Strom Pipeline'!Q6,0),"") | H75: =IF(('MiT Strom Pipeline'!R6="offered")+('MiT Strom Pipeline'!R6="to be offered")+('MiT Strom Pipeline'!R6="on hold")>0,IF(ISNUMBER('MiT Strom Pipeline'!O6),'MiT Strom Pipeline'!O6,0),"") | I75: =IF(('MiT Strom Pipeline'!R6="offered")+('MiT Strom Pipeline'!R6="to be offered")+('MiT Strom Pipeline'!R6="on hold")>0,'MiT Strom Pipeline'!R6,"") | J75: =IF(('MiT Strom Pipeline'!R6="offered")+('MiT Strom Pipeline'!R6="to be offered")+('MiT Strom Pipeline'!R6="on hold")>0,'MiT Strom Pipeline'!S6,"") | K75: =IF(('MiT Strom Pipeline'!R6="offered")+('MiT Strom Pipeline'!R6="to be offered")+('MiT Strom Pipeline'!R6="on hold")>0,IF(LEN('MiT Strom Pipeline'!V6)>0,LEFT('MiT Strom Pipeline'!V6,55),""),"")
A76: =IF(('MiT Strom Pipeline'!R7="offered")+('MiT Strom Pipeline'!R7="to be offered")+('MiT Strom Pipeline'!R7="on hold")>0,IF(ISNUMBER('MiT Strom Pipeline'!A7),'MiT Strom Pipeline'!A7,""),"") | B76: =IF(('MiT Strom Pipeline'!R7="offered")+('MiT Strom Pipeline'!R7="to be offered")+('MiT Strom Pipeline'!R7="on hold")>0,'MiT Strom Pipeline'!B7,"") | C76: =IF(('MiT Strom Pipeline'!R7="offered")+('MiT Strom Pipeline'!R7="to be offered")+('MiT Strom Pipeline'!R7="on hold")>0,'MiT Strom Pipeline'!C7,"") | D76: =IF(('MiT Strom Pipeline'!R7="offered")+('MiT Strom Pipeline'!R7="to be offered")+('MiT Strom Pipeline'!R7="on hold")>0,'MiT Strom Pipeline'!D7,"") | E76: =IF(('MiT Strom Pipeline'!R7="offered")+('MiT Strom Pipeline'!R7="to be offered")+('MiT Strom Pipeline'!R7="on hold")>0,'MiT Strom Pipeline'!E7,"") | F76: =IF(('MiT Strom Pipeline'!R7="offered")+('MiT Strom Pipeline'!R7="to be offered")+('MiT Strom Pipeline'!R7="on hold")>0,IF(ISNUMBER('MiT Strom Pipeline'!I7),'MiT Strom Pipeline'!I7,0),"") | G76: =IF(('MiT Strom Pipeline'!R7="offered")+('MiT Strom Pipeline'!R7="to be offered")+('MiT Strom Pipeline'!R7="on hold")>0,IF(ISNUMBER('MiT Strom Pipeline'!Q7),'MiT Strom Pipeline'!Q7,0),"") | H76: =IF(('MiT Strom Pipeline'!R7="offered")+('MiT Strom Pipeline'!R7="to be offered")+('MiT Strom Pipeline'!R7="on hold")>0,IF(ISNUMBER('MiT Strom Pipeline'!O7),'MiT Strom Pipeline'!O7,0),"") | I76: =IF(('MiT Strom Pipeline'!R7="offered")+('MiT Strom Pipeline'!R7="to be offered")+('MiT Strom Pipeline'!R7="on hold")>0,'MiT Strom Pipeline'!R7,"") | J76: =IF(('MiT Strom Pipeline'!R7="offered")+('MiT Strom Pipeline'!R7="to be offered")+('MiT Strom Pipeline'!R7="on hold")>0,'MiT Strom Pipeline'!S7,"") | K76: =IF(('MiT Strom Pipeline'!R7="offered")+('MiT Strom Pipeline'!R7="to be offered")+('MiT Strom Pipeline'!R7="on hold")>0,IF(LEN('MiT Strom Pipeline'!V7)>0,LEFT('MiT Strom Pipeline'!V7,55),""),"")
A77: =IF(('MiT Strom Pipeline'!R8="offered")+('MiT Strom Pipeline'!R8="to be offered")+('MiT Strom Pipeline'!R8="on hold")>0,IF(ISNUMBER('MiT Strom Pipeline'!A8),'MiT Strom Pipeline'!A8,""),"") | B77: =IF(('MiT Strom Pipeline'!R8="offered")+('MiT Strom Pipeline'!R8="to be offered")+('MiT Strom Pipeline'!R8="on hold")>0,'MiT Strom Pipeline'!B8,"") | C77: =IF(('MiT Strom Pipeline'!R8="offered")+('MiT Strom Pipeline'!R8="to be offered")+('MiT Strom Pipeline'!R8="on hold")>0,'MiT Strom Pipeline'!C8,"") | D77: =IF(('MiT Strom Pipeline'!R8="offered")+('MiT Strom Pipeline'!R8="to be offered")+('MiT Strom Pipeline'!R8="on hold")>0,'MiT Strom Pipeline'!D8,"") | E77: =IF(('MiT Strom Pipeline'!R8="offered")+('MiT Strom Pipeline'!R8="to be offered")+('MiT Strom Pipeline'!R8="on hold")>0,'MiT Strom Pipeline'!E8,"") | F77: =IF(('MiT Strom Pipeline'!R8="offered")+('MiT Strom Pipeline'!R8="to be offered")+('MiT Strom Pipeline'!R8="on hold")>0,IF(ISNUMBER('MiT Strom Pipeline'!I8),'MiT Strom Pipeline'!I8,0),"") | G77: =IF(('MiT Strom Pipeline'!R8="offered")+('MiT Strom Pipeline'!R8="to be offered")+('MiT Strom Pipeline'!R8="on hold")>0,IF(ISNUMBER('MiT Strom Pipeline'!Q8),'MiT Strom Pipeline'!Q8,0),"") | H77: =IF(('MiT Strom Pipeline'!R8="offered")+('MiT Strom Pipeline'!R8="to be offered")+('MiT Strom Pipeline'!R8="on hold")>0,IF(ISNUMBER('MiT Strom Pipeline'!O8),'MiT Strom Pipeline'!O8,0),"") | I77: =IF(('MiT Strom Pipeline'!R8="offered")+('MiT Strom Pipeline'!R8="to be offered")+('MiT Strom Pipeline'!R8="on hold")>0,'MiT Strom Pipeline'!R8,"") | J77: =IF(('MiT Strom Pipeline'!R8="offered")+('MiT Strom Pipeline'!R8="to be offered")+('MiT Strom Pipeline'!R8="on hold")>0,'MiT Strom Pipeline'!S8,"") | K77: =IF(('MiT Strom Pipeline'!R8="offered")+('MiT Strom Pipeline'!R8="to be offered")+('MiT Strom Pipeline'!R8="on hold")>0,IF(LEN('MiT Strom Pipeline'!V8)>0,LEFT('MiT Strom Pipeline'!V8,55),""),"")
A78: =IF(('MiT Strom Pipeline'!R9="offered")+('MiT Strom Pipeline'!R9="to be offered")+('MiT Strom Pipeline'!R9="on hold")>0,IF(ISNUMBER('MiT Strom Pipeline'!A9),'MiT Strom Pipeline'!A9,""),"") -> 4 | B78: =IF(('MiT Strom Pipeline'!R9="offered")+('MiT Strom Pipeline'!R9="to be offered")+('MiT Strom Pipeline'!R9="on hold")>0,'MiT Strom Pipeline'!B9,"") -> Stagelight – OpenAir Frauenfeld | C78: =IF(('MiT Strom Pipeline'!R9="offered")+('MiT Strom Pipeline'!R9="to be offered")+('MiT Strom Pipeline'!R9="on hold")>0,'MiT Strom Pipeline'!C9,"") -> TG | D78: =IF(('MiT Strom Pipeline'!R9="offered")+('MiT Strom Pipeline'!R9="to be offered")+('MiT Strom Pipeline'!R9="on hold")>0,'MiT Strom Pipeline'!D9,"") -> Events & Kultur | E78: =IF(('MiT Strom Pipeline'!R9="offered")+('MiT Strom Pipeline'!R9="to be offered")+('MiT Strom Pipeline'!R9="on hold")>0,'MiT Strom Pipeline'!E9,"") -> ~500 kVA Generator | F78: =IF(('MiT Strom Pipeline'!R9="offered")+('MiT Strom Pipeline'!R9="to be offered")+('MiT Strom Pipeline'!R9="on hold")>0,IF(ISNUMBER('MiT Strom Pipeline'!I9),'MiT Strom Pipeline'!I9,0),"") -> 150000 | G78: =IF(('MiT Strom Pipeline'!R9="offered")+('MiT Strom Pipeline'!R9="to be offered")+('MiT Strom Pipeline'!R9="on hold")>0,IF(ISNUMBER('MiT Strom Pipeline'!Q9),'MiT Strom Pipeline'!Q9,0),"") -> 1350 | H78: =IF(('MiT Strom Pipeline'!R9="offered")+('MiT Strom Pipeline'!R9="to be offered")+('MiT Strom Pipeline'!R9="on hold")>0,IF(ISNUMBER('MiT Strom Pipeline'!O9),'MiT Strom Pipeline'!O9,0),"") -> 39500 | I78: =IF(('MiT Strom Pipeline'!R9="offered")+('MiT Strom Pipeline'!R9="to be offered")+('MiT Strom Pipeline'!R9="on hold")>0,'MiT Strom Pipeline'!R9,"") -> offered | J78: =IF(('MiT Strom Pipeline'!R9="offered")+('MiT Strom Pipeline'!R9="to be offered")+('MiT Strom Pipeline'!R9="on hold")>0,'MiT Strom Pipeline'!S9,"") -> 90% | K78: =IF(('MiT Strom Pipeline'!R9="offered")+('MiT Strom Pipeline'!R9="to be offered")+('MiT Strom Pipeline'!R9="on hold")>0,IF(LEN('MiT Strom Pipeline'!V9)>0,LEFT('MiT Strom Pipeline'!V9,55),""),"") -> Follow-up + Vertragsverhandlung initiieren
A79: =IF(('MiT Strom Pipeline'!R10="offered")+('MiT Strom Pipeline'!R10="to be offered")+('MiT Strom Pipeline'!R10="on hold")>0,IF(ISNUMBER('MiT Strom Pipeline'!A10),'MiT Strom Pipeline'!A10,""),"") -> 6 | B79: =IF(('MiT Strom Pipeline'!R10="offered")+('MiT Strom Pipeline'!R10="to be offered")+('MiT Strom Pipeline'!R10="on hold")>0,'MiT Strom Pipeline'!B10,"") -> Wincasa Solothurn | C79: =IF(('MiT Strom Pipeline'!R10="offered")+('MiT Strom Pipeline'!R10="to be offered")+('MiT Strom Pipeline'!R10="on hold")>0,'MiT Strom Pipeline'!C10,"") -> SO | D79: =IF(('MiT Strom Pipeline'!R10="offered")+('MiT Strom Pipeline'!R10="to be offered")+('MiT Strom Pipeline'!R10="on hold")>0,'MiT Strom Pipeline'!D10,"") -> Immobilien / FM | E79: =IF(('MiT Strom Pipeline'!R10="offered")+('MiT Strom Pipeline'!R10="to be offered")+('MiT Strom Pipeline'!R10="on hold")>0,'MiT Strom Pipeline'!E10,"") -> BESS 1 MWh | F79: =IF(('MiT Strom Pipeline'!R10="offered")+('MiT Strom Pipeline'!R10="to be offered")+('MiT Strom Pipeline'!R10="on hold")>0,IF(ISNUMBER('MiT Strom Pipeline'!I10),'MiT Strom Pipeline'!I10,0),"") -> 390000 | G79: =IF(('MiT Strom Pipeline'!R10="offered")+('MiT Strom Pipeline'!R10="to be offered")+('MiT Strom Pipeline'!R10="on hold")>0,IF(ISNUMBER('MiT Strom Pipeline'!Q10),'MiT Strom Pipeline'!Q10,0),"") -> 1950 | H79: =IF(('MiT Strom Pipeline'!R10="offered")+('MiT Strom Pipeline'!R10="to be offered")+('MiT Strom Pipeline'!R10="on hold")>0,IF(ISNUMBER('MiT Strom Pipeline'!O10),'MiT Strom Pipeline'!O10,0),"") -> 118000 | I79: =IF(('MiT Strom Pipeline'!R10="offered")+('MiT Strom Pipeline'!R10="to be offered")+('MiT Strom Pipeline'!R10="on hold")>0,'MiT Strom Pipeline'!R10,"") -> on hold | J79: =IF(('MiT Strom Pipeline'!R10="offered")+('MiT Strom Pipeline'!R10="to be offered")+('MiT Strom Pipeline'!R10="on hold")>0,'MiT Strom Pipeline'!S10,"") -> 50% | K79: =IF(('MiT Strom Pipeline'!R10="offered")+('MiT Strom Pipeline'!R10="to be offered")+('MiT Strom Pipeline'!R10="on hold")>0,IF(LEN('MiT Strom Pipeline'!V10)>0,LEFT('MiT Strom Pipeline'!V10,55),""),"") -> Entscheider-Meeting anfordern, Businesscase Energie-ROI
A80: =IF(('MiT Strom Pipeline'!R11="offered")+('MiT Strom Pipeline'!R11="to be offered")+('MiT Strom Pipeline'!R11="on hold")>0,IF(ISNUMBER('MiT Strom Pipeline'!A11),'MiT Strom Pipeline'!A11,""),"") | B80: =IF(('MiT Strom Pipeline'!R11="offered")+('MiT Strom Pipeline'!R11="to be offered")+('MiT Strom Pipeline'!R11="on hold")>0,'MiT Strom Pipeline'!B11,"") | C80: =IF(('MiT Strom Pipeline'!R11="offered")+('MiT Strom Pipeline'!R11="to be offered")+('MiT Strom Pipeline'!R11="on hold")>0,'MiT Strom Pipeline'!C11,"") | D80: =IF(('MiT Strom Pipeline'!R11="offered")+('MiT Strom Pipeline'!R11="to be offered")+('MiT Strom Pipeline'!R11="on hold")>0,'MiT Strom Pipeline'!D11,"") | E80: =IF(('MiT Strom Pipeline'!R11="offered")+('MiT Strom Pipeline'!R11="to be offered")+('MiT Strom Pipeline'!R11="on hold")>0,'MiT Strom Pipeline'!E11,"") | F80: =IF(('MiT Strom Pipeline'!R11="offered")+('MiT Strom Pipeline'!R11="to be offered")+('MiT Strom Pipeline'!R11="on hold")>0,IF(ISNUMBER('MiT Strom Pipeline'!I11),'MiT Strom Pipeline'!I11,0),"") | G80: =IF(('MiT Strom Pipeline'!R11="offered")+('MiT Strom Pipeline'!R11="to be offered")+('MiT Strom Pipeline'!R11="on hold")>0,IF(ISNUMBER('MiT Strom Pipeline'!Q11),'MiT Strom Pipeline'!Q11,0),"") | H80: =IF(('MiT Strom Pipeline'!R11="offered")+('MiT Strom Pipeline'!R11="to be offered")+('MiT Strom Pipeline'!R11="on hold")>0,IF(ISNUMBER('MiT Strom Pipeline'!O11),'MiT Strom Pipeline'!O11,0),"") | I80: =IF(('MiT Strom Pipeline'!R11="offered")+('MiT Strom Pipeline'!R11="to be offered")+('MiT Strom Pipeline'!R11="on hold")>0,'MiT Strom Pipeline'!R11,"") | J80: =IF(('MiT Strom Pipeline'!R11="offered")+('MiT Strom Pipeline'!R11="to be offered")+('MiT Strom Pipeline'!R11="on hold")>0,'MiT Strom Pipeline'!S11,"") | K80: =IF(('MiT Strom Pipeline'!R11="offered")+('MiT Strom Pipeline'!R11="to be offered")+('MiT Strom Pipeline'!R11="on hold")>0,IF(LEN('MiT Strom Pipeline'!V11)>0,LEFT('MiT Strom Pipeline'!V11,55),""),"")
A81: =IF(('MiT Strom Pipeline'!R12="offered")+('MiT Strom Pipeline'!R12="to be offered")+('MiT Strom Pipeline'!R12="on hold")>0,IF(ISNUMBER('MiT Strom Pipeline'!A12),'MiT Strom Pipeline'!A12,""),"") | B81: =IF(('MiT Strom Pipeline'!R12="offered")+('MiT Strom Pipeline'!R12="to be offered")+('MiT Strom Pipeline'!R12="on hold")>0,'MiT Strom Pipeline'!B12,"") | C81: =IF(('MiT Strom Pipeline'!R12="offered")+('MiT Strom Pipeline'!R12="to be offered")+('MiT Strom Pipeline'!R12="on hold")>0,'MiT Strom Pipeline'!C12,"") | D81: =IF(('MiT Strom Pipeline'!R12="offered")+('MiT Strom Pipeline'!R12="to be offered")+('MiT Strom Pipeline'!R12="on hold")>0,'MiT Strom Pipeline'!D12,"") | E81: =IF(('MiT Strom Pipeline'!R12="offered")+('MiT Strom Pipeline'!R12="to be offered")+('MiT Strom Pipeline'!R12="on hold")>0,'MiT Strom Pipeline'!E12,"") | F81: =IF(('MiT Strom Pipeline'!R12="offered")+('MiT Strom Pipeline'!R12="to be offered")+('MiT Strom Pipeline'!R12="on hold")>0,IF(ISNUMBER('MiT Strom Pipeline'!I12),'MiT Strom Pipeline'!I12,0),"") | G81: =IF(('MiT Strom Pipeline'!R12="offered")+('MiT Strom Pipeline'!R12="to be offered")+('MiT Strom Pipeline'!R12="on hold")>0,IF(ISNUMBER('MiT Strom Pipeline'!Q12),'MiT Strom Pipeline'!Q12,0),"") | H81: =IF(('MiT Strom Pipeline'!R12="offered")+('MiT Strom Pipeline'!R12="to be offered")+('MiT Strom Pipeline'!R12="on hold")>0,IF(ISNUMBER('MiT Strom Pipeline'!O12),'MiT Strom Pipeline'!O12,0),"") | I81: =IF(('MiT Strom Pipeline'!R12="offered")+('MiT Strom Pipeline'!R12="to be offered")+('MiT Strom Pipeline'!R12="on hold")>0,'MiT Strom Pipeline'!R12,"") | J81: =IF(('MiT Strom Pipeline'!R12="offered")+('MiT Strom Pipeline'!R12="to be offered")+('MiT Strom Pipeline'!R12="on hold")>0,'MiT Strom Pipeline'!S12,"") | K81: =IF(('MiT Strom Pipeline'!R12="offered")+('MiT Strom Pipeline'!R12="to be offered")+('MiT Strom Pipeline'!R12="on hold")>0,IF(LEN('MiT Strom Pipeline'!V12)>0,LEFT('MiT Strom Pipeline'!V12,55),""),"")
A82: =IF(('MiT Strom Pipeline'!R13="offered")+('MiT Strom Pipeline'!R13="to be offered")+('MiT Strom Pipeline'!R13="on hold")>0,IF(ISNUMBER('MiT Strom Pipeline'!A13),'MiT Strom Pipeline'!A13,""),"") | B82: =IF(('MiT Strom Pipeline'!R13="offered")+('MiT Strom Pipeline'!R13="to be offered")+('MiT Strom Pipeline'!R13="on hold")>0,'MiT Strom Pipeline'!B13,"") | C82: =IF(('MiT Strom Pipeline'!R13="offered")+('MiT Strom Pipeline'!R13="to be offered")+('MiT Strom Pipeline'!R13="on hold")>0,'MiT Strom Pipeline'!C13,"") | D82: =IF(('MiT Strom Pipeline'!R13="offered")+('MiT Strom Pipeline'!R13="to be offered")+('MiT Strom Pipeline'!R13="on hold")>0,'MiT Strom Pipeline'!D13,"") | E82: =IF(('MiT Strom Pipeline'!R13="offered")+('MiT Strom Pipeline'!R13="to be offered")+('MiT Strom Pipeline'!R13="on hold")>0,'MiT Strom Pipeline'!E13,"") | F82: =IF(('MiT Strom Pipeline'!R13="offered")+('MiT Strom Pipeline'!R13="to be offered")+('MiT Strom Pipeline'!R13="on hold")>0,IF(ISNUMBER('MiT Strom Pipeline'!I13),'MiT Strom Pipeline'!I13,0),"") | G82: =IF(('MiT Strom Pipeline'!R13="offered")+('MiT Strom Pipeline'!R13="to be offered")+('MiT Strom Pipeline'!R13="on hold")>0,IF(ISNUMBER('MiT Strom Pipeline'!Q13),'MiT Strom Pipeline'!Q13,0),"") | H82: =IF(('MiT Strom Pipeline'!R13="offered")+('MiT Strom Pipeline'!R13="to be offered")+('MiT Strom Pipeline'!R13="on hold")>0,IF(ISNUMBER('MiT Strom Pipeline'!O13),'MiT Strom Pipeline'!O13,0),"") | I82: =IF(('MiT Strom Pipeline'!R13="offered")+('MiT Strom Pipeline'!R13="to be offered")+('MiT Strom Pipeline'!R13="on hold")>0,'MiT Strom Pipeline'!R13,"") | J82: =IF(('MiT Strom Pipeline'!R13="offered")+('MiT Strom Pipeline'!R13="to be offered")+('MiT Strom Pipeline'!R13="on hold")>0,'MiT Strom Pipeline'!S13,"") | K82: =IF(('MiT Strom Pipeline'!R13="offered")+('MiT Strom Pipeline'!R13="to be offered")+('MiT Strom Pipeline'!R13="on hold")>0,IF(LEN('MiT Strom Pipeline'!V13)>0,LEFT('MiT Strom Pipeline'!V13,55),""),"")
A83: =IF(('MiT Strom Pipeline'!R14="offered")+('MiT Strom Pipeline'!R14="to be offered")+('MiT Strom Pipeline'!R14="on hold")>0,IF(ISNUMBER('MiT Strom Pipeline'!A14),'MiT Strom Pipeline'!A14,""),"") | B83: =IF(('MiT Strom Pipeline'!R14="offered")+('MiT Strom Pipeline'!R14="to be offered")+('MiT Strom Pipeline'!R14="on hold")>0,'MiT Strom Pipeline'!B14,"") | C83: =IF(('MiT Strom Pipeline'!R14="offered")+('MiT Strom Pipeline'!R14="to be offered")+('MiT Strom Pipeline'!R14="on hold")>0,'MiT Strom Pipeline'!C14,"") | D83: =IF(('MiT Strom Pipeline'!R14="offered")+('MiT Strom Pipeline'!R14="to be offered")+('MiT Strom Pipeline'!R14="on hold")>0,'MiT Strom Pipeline'!D14,"") | E83: =IF(('MiT Strom Pipeline'!R14="offered")+('MiT Strom Pipeline'!R14="to be offered")+('MiT Strom Pipeline'!R14="on hold")>0,'MiT Strom Pipeline'!E14,"") | F83: =IF(('MiT Strom Pipeline'!R14="offered")+('MiT Strom Pipeline'!R14="to be offered")+('MiT Strom Pipeline'!R14="on hold")>0,IF(ISNUMBER('MiT Strom Pipeline'!I14),'MiT Strom Pipeline'!I14,0),"") | G83: =IF(('MiT Strom Pipeline'!R14="offered")+('MiT Strom Pipeline'!R14="to be offered")+('MiT Strom Pipeline'!R14="on hold")>0,IF(ISNUMBER('MiT Strom Pipeline'!Q14),'MiT Strom Pipeline'!Q14,0),"") | H83: =IF(('MiT Strom Pipeline'!R14="offered")+('MiT Strom Pipeline'!R14="to be offered")+('MiT Strom Pipeline'!R14="on hold")>0,IF(ISNUMBER('MiT Strom Pipeline'!O14),'MiT Strom Pipeline'!O14,0),"") | I83: =IF(('MiT Strom Pipeline'!R14="offered")+('MiT Strom Pipeline'!R14="to be offered")+('MiT Strom Pipeline'!R14="on hold")>0,'MiT Strom Pipeline'!R14,"") | J83: =IF(('MiT Strom Pipeline'!R14="offered")+('MiT Strom Pipeline'!R14="to be offered")+('MiT Strom Pipeline'!R14="on hold")>0,'MiT Strom Pipeline'!S14,"") | K83: =IF(('MiT Strom Pipeline'!R14="offered")+('MiT Strom Pipeline'!R14="to be offered")+('MiT Strom Pipeline'!R14="on hold")>0,IF(LEN('MiT Strom Pipeline'!V14)>0,LEFT('MiT Strom Pipeline'!V14,55),""),"")
A84: =IF(('MiT Strom Pipeline'!R15="offered")+('MiT Strom Pipeline'!R15="to be offered")+('MiT Strom Pipeline'!R15="on hold")>0,IF(ISNUMBER('MiT Strom Pipeline'!A15),'MiT Strom Pipeline'!A15,""),"") | B84: =IF(('MiT Strom Pipeline'!R15="offered")+('MiT Strom Pipeline'!R15="to be offered")+('MiT Strom Pipeline'!R15="on hold")>0,'MiT Strom Pipeline'!B15,"") | C84: =IF(('MiT Strom Pipeline'!R15="offered")+('MiT Strom Pipeline'!R15="to be offered")+('MiT Strom Pipeline'!R15="on hold")>0,'MiT Strom Pipeline'!C15,"") | D84: =IF(('MiT Strom Pipeline'!R15="offered")+('MiT Strom Pipeline'!R15="to be offered")+('MiT Strom Pipeline'!R15="on hold")>0,'MiT Strom Pipeline'!D15,"") | E84: =IF(('MiT Strom Pipeline'!R15="offered")+('MiT Strom Pipeline'!R15="to be offered")+('MiT Strom Pipeline'!R15="on hold")>0,'MiT Strom Pipeline'!E15,"") | F84: =IF(('MiT Strom Pipeline'!R15="offered")+('MiT Strom Pipeline'!R15="to be offered")+('MiT Strom Pipeline'!R15="on hold")>0,IF(ISNUMBER('MiT Strom Pipeline'!I15),'MiT Strom Pipeline'!I15,0),"") | G84: =IF(('MiT Strom Pipeline'!R15="offered")+('MiT Strom Pipeline'!R15="to be offered")+('MiT Strom Pipeline'!R15="on hold")>0,IF(ISNUMBER('MiT Strom Pipeline'!Q15),'MiT Strom Pipeline'!Q15,0),"") | H84: =IF(('MiT Strom Pipeline'!R15="offered")+('MiT Strom Pipeline'!R15="to be offered")+('MiT Strom Pipeline'!R15="on hold")>0,IF(ISNUMBER('MiT Strom Pipeline'!O15),'MiT Strom Pipeline'!O15,0),"") | I84: =IF(('MiT Strom Pipeline'!R15="offered")+('MiT Strom Pipeline'!R15="to be offered")+('MiT Strom Pipeline'!R15="on hold")>0,'MiT Strom Pipeline'!R15,"") | J84: =IF(('MiT Strom Pipeline'!R15="offered")+('MiT Strom Pipeline'!R15="to be offered")+('MiT Strom Pipeline'!R15="on hold")>0,'MiT Strom Pipeline'!S15,"") | K84: =IF(('MiT Strom Pipeline'!R15="offered")+('MiT Strom Pipeline'!R15="to be offered")+('MiT Strom Pipeline'!R15="on hold")>0,IF(LEN('MiT Strom Pipeline'!V15)>0,LEFT('MiT Strom Pipeline'!V15,55),""),"")
A85: =IF(('MiT Strom Pipeline'!R16="offered")+('MiT Strom Pipeline'!R16="to be offered")+('MiT Strom Pipeline'!R16="on hold")>0,IF(ISNUMBER('MiT Strom Pipeline'!A16),'MiT Strom Pipeline'!A16,""),"") | B85: =IF(('MiT Strom Pipeline'!R16="offered")+('MiT Strom Pipeline'!R16="to be offered")+('MiT Strom Pipeline'!R16="on hold")>0,'MiT Strom Pipeline'!B16,"") | C85: =IF(('MiT Strom Pipeline'!R16="offered")+('MiT Strom Pipeline'!R16="to be offered")+('MiT Strom Pipeline'!R16="on hold")>0,'MiT Strom Pipeline'!C16,"") | D85: =IF(('MiT Strom Pipeline'!R16="offered")+('MiT Strom Pipeline'!R16="to be offered")+('MiT Strom Pipeline'!R16="on hold")>0,'MiT Strom Pipeline'!D16,"") | E85: =IF(('MiT Strom Pipeline'!R16="offered")+('MiT Strom Pipeline'!R16="to be offered")+('MiT Strom Pipeline'!R16="on hold")>0,'MiT Strom Pipeline'!E16,"") | F85: =IF(('MiT Strom Pipeline'!R16="offered")+('MiT Strom Pipeline'!R16="to be offered")+('MiT Strom Pipeline'!R16="on hold")>0,IF(ISNUMBER('MiT Strom Pipeline'!I16),'MiT Strom Pipeline'!I16,0),"") | G85: =IF(('MiT Strom Pipeline'!R16="offered")+('MiT Strom Pipeline'!R16="to be offered")+('MiT Strom Pipeline'!R16="on hold")>0,IF(ISNUMBER('MiT Strom Pipeline'!Q16),'MiT Strom Pipeline'!Q16,0),"") | H85: =IF(('MiT Strom Pipeline'!R16="offered")+('MiT Strom Pipeline'!R16="to be offered")+('MiT Strom Pipeline'!R16="on hold")>0,IF(ISNUMBER('MiT Strom Pipeline'!O16),'MiT Strom Pipeline'!O16,0),"") | I85: =IF(('MiT Strom Pipeline'!R16="offered")+('MiT Strom Pipeline'!R16="to be offered")+('MiT Strom Pipeline'!R16="on hold")>0,'MiT Strom Pipeline'!R16,"") | J85: =IF(('MiT Strom Pipeline'!R16="offered")+('MiT Strom Pipeline'!R16="to be offered")+('MiT Strom Pipeline'!R16="on hold")>0,'MiT Strom Pipeline'!S16,"") | K85: =IF(('MiT Strom Pipeline'!R16="offered")+('MiT Strom Pipeline'!R16="to be offered")+('MiT Strom Pipeline'!R16="on hold")>0,IF(LEN('MiT Strom Pipeline'!V16)>0,LEFT('MiT Strom Pipeline'!V16,55),""),"")
A86: =IF(('MiT Strom Pipeline'!R17="offered")+('MiT Strom Pipeline'!R17="to be offered")+('MiT Strom Pipeline'!R17="on hold")>0,IF(ISNUMBER('MiT Strom Pipeline'!A17),'MiT Strom Pipeline'!A17,""),"") -> 13 | B86: =IF(('MiT Strom Pipeline'!R17="offered")+('MiT Strom Pipeline'!R17="to be offered")+('MiT Strom Pipeline'!R17="on hold")>0,'MiT Strom Pipeline'!B17,"") -> Proxima Fusion AG | C86: =IF(('MiT Strom Pipeline'!R17="offered")+('MiT Strom Pipeline'!R17="to be offered")+('MiT Strom Pipeline'!R17="on hold")>0,'MiT Strom Pipeline'!C17,"") -> ZH | D86: =IF(('MiT Strom Pipeline'!R17="offered")+('MiT Strom Pipeline'!R17="to be offered")+('MiT Strom Pipeline'!R17="on hold")>0,'MiT Strom Pipeline'!D17,"") -> Forschung / Hightech | E86: =IF(('MiT Strom Pipeline'!R17="offered")+('MiT Strom Pipeline'!R17="to be offered")+('MiT Strom Pipeline'!R17="on hold")>0,'MiT Strom Pipeline'!E17,"") -> BESS 1 MWh | F86: =IF(('MiT Strom Pipeline'!R17="offered")+('MiT Strom Pipeline'!R17="to be offered")+('MiT Strom Pipeline'!R17="on hold")>0,IF(ISNUMBER('MiT Strom Pipeline'!I17),'MiT Strom Pipeline'!I17,0),"") -> 365003 | G86: =IF(('MiT Strom Pipeline'!R17="offered")+('MiT Strom Pipeline'!R17="to be offered")+('MiT Strom Pipeline'!R17="on hold")>0,IF(ISNUMBER('MiT Strom Pipeline'!Q17),'MiT Strom Pipeline'!Q17,0),"") -> 182501.5 | H86: =IF(('MiT Strom Pipeline'!R17="offered")+('MiT Strom Pipeline'!R17="to be offered")+('MiT Strom Pipeline'!R17="on hold")>0,IF(ISNUMBER('MiT Strom Pipeline'!O17),'MiT Strom Pipeline'!O17,0),"") -> 0 | I86: =IF(('MiT Strom Pipeline'!R17="offered")+('MiT Strom Pipeline'!R17="to be offered")+('MiT Strom Pipeline'!R17="on hold")>0,'MiT Strom Pipeline'!R17,"") -> offered | J86: =IF(('MiT Strom Pipeline'!R17="offered")+('MiT Strom Pipeline'!R17="to be offered")+('MiT Strom Pipeline'!R17="on hold")>0,'MiT Strom Pipeline'!S17,"") -> 50 | K86: =IF(('MiT Strom Pipeline'!R17="offered")+('MiT Strom Pipeline'!R17="to be offered")+('MiT Strom Pipeline'!R17="on hold")>0,IF(LEN('MiT Strom Pipeline'!V17)>0,LEFT('MiT Strom Pipeline'!V17,55),""),"") -> Technisches Gespräch – USV + PQ-Anforderungen klären, K
... A134: =IF(('MiT Strom Pipeline'!R65="offered")+('MiT Strom Pipeline'!R65="to be offered")+('MiT Strom Pipeline'!R65="on hold")>0,IF(ISNUMBER('MiT Strom Pipeline'!A65),'MiT Strom Pipeline'!A65,""),"") | B134: =IF(('MiT Strom Pipeline'!R65="offered")+('MiT Strom Pipeline'!R65="to be offered")+('MiT Strom Pipeline'!R65="on hold")>0,'MiT Strom Pipeline'!B65,"") | C134: =IF(('MiT Strom Pipeline'!R65="offered")+('MiT Strom Pipeline'!R65="to be offered")+('MiT Strom Pipeline'!R65="on hold")>0,'MiT Strom Pipeline'!C65,"") | D134: =IF(('MiT Strom Pipeline'!R65="offered")+('MiT Strom Pipeline'!R65="to be offered")+('MiT Strom Pipeline'!R65="on hold")>0,'MiT Strom Pipeline'!D65,"") | E134: =IF(('MiT Strom Pipeline'!R65="offered")+('MiT Strom Pipeline'!R65="to be offered")+('MiT Strom Pipeline'!R65="on hold")>0,'MiT Strom Pipeline'!E65,"") | F134: =IF(('MiT Strom Pipeline'!R65="offered")+('MiT Strom Pipeline'!R65="to be offered")+('MiT Strom Pipeline'!R65="on hold")>0,IF(ISNUMBER('MiT Strom Pipeline'!I65),'MiT Strom Pipeline'!I65,0),"") | G134: =IF(('MiT Strom Pipeline'!R65="offered")+('MiT Strom Pipeline'!R65="to be offered")+('MiT Strom Pipeline'!R65="on hold")>0,IF(ISNUMBER('MiT Strom Pipeline'!Q65),'MiT Strom Pipeline'!Q65,0),"") | H134: =IF(('MiT Strom Pipeline'!R65="offered")+('MiT Strom Pipeline'!R65="to be offered")+('MiT Strom Pipeline'!R65="on hold")>0,IF(ISNUMBER('MiT Strom Pipeline'!O65),'MiT Strom Pipeline'!O65,0),"") | I134: =IF(('MiT Strom Pipeline'!R65="offered")+('MiT Strom Pipeline'!R65="to be offered")+('MiT Strom Pipeline'!R65="on hold")>0,'MiT Strom Pipeline'!R65,"") | J134: =IF(('MiT Strom Pipeline'!R65="offered")+('MiT Strom Pipeline'!R65="to be offered")+('MiT Strom Pipeline'!R65="on hold")>0,'MiT Strom Pipeline'!S65,"") | K134: =IF(('MiT Strom Pipeline'!R65="offered")+('MiT Strom Pipeline'!R65="to be offered")+('MiT Strom Pipeline'!R65="on hold")>0,IF(LEN('MiT Strom Pipeline'!V65)>0,LEFT('MiT Strom Pipeline'!V65,55),""),"")
A135: =IF(('MiT Strom Pipeline'!R66="offered")+('MiT Strom Pipeline'!R66="to be offered")+('MiT Strom Pipeline'!R66="on hold")>0,IF(ISNUMBER('MiT Strom Pipeline'!A66),'MiT Strom Pipeline'!A66,""),"") | B135: =IF(('MiT Strom Pipeline'!R66="offered")+('MiT Strom Pipeline'!R66="to be offered")+('MiT Strom Pipeline'!R66="on hold")>0,'MiT Strom Pipeline'!B66,"") | F135: =IF(('MiT Strom Pipeline'!R66="offered")+('MiT Strom Pipeline'!R66="to be offered")+('MiT Strom Pipeline'!R66="on hold")>0,IF(ISNUMBER('MiT Strom Pipeline'!I66),'MiT Strom Pipeline'!I66,0),"") | G135: =IF(('MiT Strom Pipeline'!R66="offered")+('MiT Strom Pipeline'!R66="to be offered")+('MiT Strom Pipeline'!R66="on hold")>0,IF(ISNUMBER('MiT Strom Pipeline'!Q66),'MiT Strom Pipeline'!Q66,0),"") | H135: =IF(('MiT Strom Pipeline'!R66="offered")+('MiT Strom Pipeline'!R66="to be offered")+('MiT Strom Pipeline'!R66="on hold")>0,IF(ISNUMBER('MiT Strom Pipeline'!O66),'MiT Strom Pipeline'!O66,0),"") | I135: =IF(('MiT Strom Pipeline'!R66="offered")+('MiT Strom Pipeline'!R66="to be offered")+('MiT Strom Pipeline'!R66="on hold")>0,'MiT Strom Pipeline'!R66,"") | J135: =IF(('MiT Strom Pipeline'!R66="offered")+('MiT Strom Pipeline'!R66="to be offered")+('MiT Strom Pipeline'!R66="on hold")>0,'MiT Strom Pipeline'!S66,"") | K135: =IF(('MiT Strom Pipeline'!R66="offered")+('MiT Strom Pipeline'!R66="to be offered")+('MiT Strom Pipeline'!R66="on hold")>0,IF(LEN('MiT Strom Pipeline'!V66)>0,LEFT('MiT Strom Pipeline'!V66,55),""),"")
A136: =IF(('MiT Strom Pipeline'!R67="offered")+('MiT Strom Pipeline'!R67="to be offered")+('MiT Strom Pipeline'!R67="on hold")>0,IF(ISNUMBER('MiT Strom Pipeline'!A67),'MiT Strom Pipeline'!A67,""),"") | B136: =IF(('MiT Strom Pipeline'!R67="offered")+('MiT Strom Pipeline'!R67="to be offered")+('MiT Strom Pipeline'!R67="on hold")>0,'MiT Strom Pipeline'!B67,"") | C136: =IF(('MiT Strom Pipeline'!R67="offered")+('MiT Strom Pipeline'!R67="to be offered")+('MiT Strom Pipeline'!R67="on hold")>0,'MiT Strom Pipeline'!C67,"") | D136: =IF(('MiT Strom Pipeline'!R67="offered")+('MiT Strom Pipeline'!R67="to be offered")+('MiT Strom Pipeline'!R67="on hold")>0,'MiT Strom Pipeline'!D67,"") | E136: =IF(('MiT Strom Pipeline'!R67="offered")+('MiT Strom Pipeline'!R67="to be offered")+('MiT Strom Pipeline'!R67="on hold")>0,'MiT Strom Pipeline'!E67,"") | F136: =IF(('MiT Strom Pipeline'!R67="offered")+('MiT Strom Pipeline'!R67="to be offered")+('MiT Strom Pipeline'!R67="on hold")>0,IF(ISNUMBER('MiT Strom Pipeline'!I67),'MiT Strom Pipeline'!I67,0),"") | G136: =IF(('MiT Strom Pipeline'!R67="offered")+('MiT Strom Pipeline'!R67="to be offered")+('MiT Strom Pipeline'!R67="on hold")>0,IF(ISNUMBER('MiT Strom Pipeline'!Q67),'MiT Strom Pipeline'!Q67,0),"") | H136: =IF(('MiT Strom Pipeline'!R67="offered")+('MiT Strom Pipeline'!R67="to be offered")+('MiT Strom Pipeline'!R67="on hold")>0,IF(ISNUMBER('MiT Strom Pipeline'!O67),'MiT Strom Pipeline'!O67,0),"") | I136: =IF(('MiT Strom Pipeline'!R67="offered")+('MiT Strom Pipeline'!R67="to be offered")+('MiT Strom Pipeline'!R67="on hold")>0,'MiT Strom Pipeline'!R67,"") | J136: =IF(('MiT Strom Pipeline'!R67="offered")+('MiT Strom Pipeline'!R67="to be offered")+('MiT Strom Pipeline'!R67="on hold")>0,'MiT Strom Pipeline'!S67,"") | K136: =IF(('MiT Strom Pipeline'!R67="offered")+('MiT Strom Pipeline'!R67="to be offered")+('MiT Strom Pipeline'!R67="on hold")>0,IF(LEN('MiT Strom Pipeline'!V67)>0,LEFT('MiT Strom Pipeline'!V67,55),""),"")
A137: 🎯 3. OPPORTUNITÄT — Qualifizierte Leads
...

Sheet Dashboard
A1: ⚡ MiT Strom Schweiz | Sales Dashboard | Mai 2026
A2: Mobil in Time AG · An Aggreko Company · Burak Ücöz · Neue Einträge in «MiT Strom Pipeline» (bis Zeile 100) erscheinen automatisch.
A5: ✅ WON | D5: 📄 OFFERTE | G5: 🎯 OPP. | I5: 📊 GESAMT
A6: =SUMIFS('MiT Strom Pipeline'!I$6:I$904,'MiT Strom Pipeline'!R$6:R$904,"WON") -> 333100 | D6: =SUMIFS('MiT Strom Pipeline'!I$6:I$904,'MiT Strom Pipeline'!R$6:R$904,"offered")+SUMIFS('MiT Strom Pipeline'!I$6:I$904,'MiT Strom Pipeline'!R$6:R$904,"to be offered")+SUMIFS('MiT Strom Pipeline'!I$6:I$904,'MiT Strom Pipeline'!R$6:R$904,"on hold") -> 3866028.6 | G6: =SUMIFS('MiT Strom Pipeline'!I$6:I$904,'MiT Strom Pipeline'!R$6:R$904,"follow-up")+SUMIFS('MiT Strom Pipeline'!I$6:I$904,'MiT Strom Pipeline'!R$6:R$904,"Evaluation")+SUMIFS('MiT Strom Pipeline'!I$6:I$904,'MiT Strom Pipeline'!R$6:R$904,"tbd")+SUMIFS('MiT Strom Pipeline'!I$6:I$904,'MiT Strom Pipeline'!R$6:R$904,"In evaluation") -> 672987.69 | I6: =SUMIFS('MiT Strom Pipeline'!I$6:I$904,'MiT Strom Pipeline'!R$6:R$904,"WON")+SUMIFS('MiT Strom Pipeline'!I$6:I$904,'MiT Strom Pipeline'!R$6:R$904,"offered")+SUMIFS('MiT Strom Pipeline'!I$6:I$904,'MiT Strom Pipeline'!R$6:R$904,"to be offered")+SUMIFS('MiT Strom Pipeline'!I$6:I$904,'MiT Strom Pipeline'!R$6:R$904,"on hold")+SUMIFS('MiT Strom Pipeline'!I$6:I$904,'MiT Strom Pipeline'!R$6:R$904,"follow-up")+SUMIFS('MiT Strom Pipeline'!I$6:I$904,'MiT Strom Pipeline'!R$6:R$904,"Evaluation")+SUMIFS('MiT Strom Pipeline'!I$6:I$904,'MiT Strom Pipeline'!R$6:R$904,"tbd")+SUMIFS('MiT Strom Pipeline'!I$6:I$904,'MiT Strom Pipeline'!R$6:R$904,"In evaluation") -> 4872116.3
A7: =COUNTIF('MiT Strom Pipeline'!R$6:R$904,"WON") -> 4 | D7: =COUNTIF('MiT Strom Pipeline'!R$6:R$904,"offered")+COUNTIF('MiT Strom Pipeline'!R$6:R$904,"to be offered")+COUNTIF('MiT Strom Pipeline'!R$6:R$904,"on hold") -> 12 | G7: =COUNTIF('MiT Strom Pipeline'!R$6:R$904,"follow-up")+COUNTIF('MiT Strom Pipeline'!R$6:R$904,"Evaluation")+COUNTIF('MiT Strom Pipeline'!R$6:R$904,"tbd")+COUNTIF('MiT Strom Pipeline'!R$6:R$904,"In evaluation") -> 16 | I7: =COUNTIF('MiT Strom Pipeline'!R$6:R$904,"WON")+COUNTIF('MiT Strom Pipeline'!R$6:R$904,"offered")+COUNTIF('MiT Strom Pipeline'!R$6:R$904,"to be offered")+COUNTIF('MiT Strom Pipeline'!R$6:R$904,"on hold")+COUNTIF('MiT Strom Pipeline'!R$6:R$904,"follow-up")+COUNTIF('MiT Strom Pipeline'!R$6:R$904,"Evaluation")+COUNTIF('MiT Strom Pipeline'!R$6:R$904,"tbd")+COUNTIF('MiT Strom Pipeline'!R$6:R$904,"In evaluation") -> 32
A9: ✅ 1. AUFTRAGSEINGANG (WON) — Gewonnene Aufträge
A10: # | B10: Kunde / Unternehmen | C10: Kt. | D10: Segment | E10: Leistung / Fleet | F10: Volumen CHF | G10: Gew.Wert CHF | H10: Status | I10: Wahr.% | J10: Nächster Schritt
A11: =IF('MiT Strom Pipeline'!R6="WON",IF(ISNUMBER('MiT Strom Pipeline'!A6),'MiT Strom Pipeline'!A6,""),"") -> 1 | B11: =IF('MiT Strom Pipeline'!R6="WON",'MiT Strom Pipeline'!B6,"") -> Ice Hockey Championship | C11: =IF('MiT Strom Pipeline'!R6="WON",'MiT Strom Pipeline'!C6,"") -> ZH | D11: =IF('MiT Strom Pipeline'!R6="WON",'MiT Strom Pipeline'!D6,"") -> Events & Sport | E11: =IF('MiT Strom Pipeline'!R6="WON",'MiT Strom Pipeline'!E6,"") -> 2×600+2×200 kVA | F11: =IF('MiT Strom Pipeline'!R6="WON",IF(ISNUMBER('MiT Strom Pipeline'!I6),'MiT Strom Pipeline'!I6,0),"") -> 310000 | G11: =IF('MiT Strom Pipeline'!R6="WON",IF(ISNUMBER('MiT Strom Pipeline'!Q6),'MiT Strom Pipeline'!Q6,0),"") -> 3100 | H11: =IF('MiT Strom Pipeline'!R6="WON",'MiT Strom Pipeline'!R6,"") -> WON | I11: =IF('MiT Strom Pipeline'!R6="WON",'MiT Strom Pipeline'!S6,"") -> 100% | J11: =IF('MiT Strom Pipeline'!R6="WON",IF(LEN('MiT Strom Pipeline'!V6)>0,LEFT('MiT Strom Pipeline'!V6,55),""),"") -> ✅ Einsatzplanung läuft – Logistik finalisieren
A12: =IF('MiT Strom Pipeline'!R7="WON",IF(ISNUMBER('MiT Strom Pipeline'!A7),'MiT Strom Pipeline'!A7,""),"") -> 2 | B12: =IF('MiT Strom Pipeline'!R7="WON",'MiT Strom Pipeline'!B7,"") -> Oerlikon Metco Wohlen | C12: =IF('MiT Strom Pipeline'!R7="WON",'MiT Strom Pipeline'!C7,"") -> AG | D12: =IF('MiT Strom Pipeline'!R7="WON",'MiT Strom Pipeline'!D7,"") -> Industrie / Oberfläche | E12: =IF('MiT Strom Pipeline'!R7="WON",'MiT Strom Pipeline'!E7,"") -> 240 kVA Generator | F12: =IF('MiT Strom Pipeline'!R7="WON",IF(ISNUMBER('MiT Strom Pipeline'!I7),'MiT Strom Pipeline'!I7,0),"") -> 13100 | G12: =IF('MiT Strom Pipeline'!R7="WON",IF(ISNUMBER('MiT Strom Pipeline'!Q7),'MiT Strom Pipeline'!Q7,0),"") -> 131 | H12: =IF('MiT Strom Pipeline'!R7="WON",'MiT Strom Pipeline'!R7,"") -> WON | I12: =IF('MiT Strom Pipeline'!R7="WON",'MiT Strom Pipeline'!S7,"") -> 100% | J12: =IF('MiT Strom Pipeline'!R7="WON",IF(LEN('MiT Strom Pipeline'!V7)>0,LEFT('MiT Strom Pipeline'!V7,55),""),"") -> ✅ Abgeschlossen – Invoice prüfen, Referenz sichern
A13: =IF('MiT Strom Pipeline'!R8="WON",IF(ISNUMBER('MiT Strom Pipeline'!A8),'MiT Strom Pipeline'!A8,""),"") -> 3 | B13: =IF('MiT Strom Pipeline'!R8="WON",'MiT Strom Pipeline'!B8,"") -> Siemens | C13: =IF('MiT Strom Pipeline'!R8="WON",'MiT Strom Pipeline'!C8,"") -> ZH | D13: =IF('MiT Strom Pipeline'!R8="WON",'MiT Strom Pipeline'!D8,"") -> Industrie / Elektro | E13: =IF('MiT Strom Pipeline'!R8="WON",'MiT Strom Pipeline'!E8,"") -> 600 kVA Generator | F13: =IF('MiT Strom Pipeline'!R8="WON",IF(ISNUMBER('MiT Strom Pipeline'!I8),'MiT Strom Pipeline'!I8,0),"") -> 10000 | G13: =IF('MiT Strom Pipeline'!R8="WON",IF(ISNUMBER('MiT Strom Pipeline'!Q8),'MiT Strom Pipeline'!Q8,0),"") -> 100 | H13: =IF('MiT Strom Pipeline'!R8="WON",'MiT Strom Pipeline'!R8,"") -> WON | I13: =IF('MiT Strom Pipeline'!R8="WON",'MiT Strom Pipeline'!S8,"") -> 100% | J13: =IF('MiT Strom Pipeline'!R8="WON",IF(LEN('MiT Strom Pipeline'!V8)>0,LEFT('MiT Strom Pipeline'!V8,55),""),"") -> ✅ Referenzschreiben anfordern
A14: =IF('MiT Strom Pipeline'!R9="WON",IF(ISNUMBER('MiT Strom Pipeline'!A9),'MiT Strom Pipeline'!A9,""),"") | B14: =IF('MiT Strom Pipeline'!R9="WON",'MiT Strom Pipeline'!B9,"") | C14: =IF('MiT Strom Pipeline'!R9="WON",'MiT Strom Pipeline'!C9,"") | D14: =IF('MiT Strom Pipeline'!R9="WON",'MiT Strom Pipeline'!D9,"") | E14: =IF('MiT Strom Pipeline'!R9="WON",'MiT Strom Pipeline'!E9,"") | F14: =IF('MiT Strom Pipeline'!R9="WON",IF(ISNUMBER('MiT Strom Pipeline'!I9),'MiT Strom Pipeline'!I9,0),"") | G14: =IF('MiT Strom Pipeline'!R9="WON",IF(ISNUMBER('MiT Strom Pipeline'!Q9),'MiT Strom Pipeline'!Q9,0),"") | H14: =IF('MiT Strom Pipeline'!R9="WON",'MiT Strom Pipeline'!R9,"") | I14: =IF('MiT Strom Pipeline'!R9="WON",'MiT Strom Pipeline'!S9,"") | J14: =IF('MiT Strom Pipeline'!R9="WON",IF(LEN('MiT Strom Pipeline'!V9)>0,LEFT('MiT Strom Pipeline'!V9,55),""),"")
A15: =IF('MiT Strom Pipeline'!R10="WON",IF(ISNUMBER('MiT Strom Pipeline'!A10),'MiT Strom Pipeline'!A10,""),"") | B15: =IF('MiT Strom Pipeline'!R10="WON",'MiT Strom Pipeline'!B10,"") | C15: =IF('MiT Strom Pipeline'!R10="WON",'MiT Strom Pipeline'!C10,"") | D15: =IF('MiT Strom Pipeline'!R10="WON",'MiT Strom Pipeline'!D10,"") | E15: =IF('MiT Strom Pipeline'!R10="WON",'MiT Strom Pipeline'!E10,"") | F15: =IF('MiT Strom Pipeline'!R10="WON",IF(ISNUMBER('MiT Strom Pipeline'!I10),'MiT Strom Pipeline'!I10,0),"") | G15: =IF('MiT Strom Pipeline'!R10="WON",IF(ISNUMBER('MiT Strom Pipeline'!Q10),'MiT Strom Pipeline'!Q10,0),"") | H15: =IF('MiT Strom Pipeline'!R10="WON",'MiT Strom Pipeline'!R10,"") | I15: =IF('MiT Strom Pipeline'!R10="WON",'MiT Strom Pipeline'!S10,"") | J15: =IF('MiT Strom Pipeline'!R10="WON",IF(LEN('MiT Strom Pipeline'!V10)>0,LEFT('MiT Strom Pipeline'!V10,55),""),"")
A16: =IF('MiT Strom Pipeline'!R11="WON",IF(ISNUMBER('MiT Strom Pipeline'!A11),'MiT Strom Pipeline'!A11,""),"") | B16: =IF('MiT Strom Pipeline'!R11="WON",'MiT Strom Pipeline'!B11,"") | C16: =IF('MiT Strom Pipeline'!R11="WON",'MiT Strom Pipeline'!C11,"") | D16: =IF('MiT Strom Pipeline'!R11="WON",'MiT Strom Pipeline'!D11,"") | E16: =IF('MiT Strom Pipeline'!R11="WON",'MiT Strom Pipeline'!E11,"") | F16: =IF('MiT Strom Pipeline'!R11="WON",IF(ISNUMBER('MiT Strom Pipeline'!I11),'MiT Strom Pipeline'!I11,0),"") | G16: =IF('MiT Strom Pipeline'!R11="WON",IF(ISNUMBER('MiT Strom Pipeline'!Q11),'MiT Strom Pipeline'!Q11,0),"") | H16: =IF('MiT Strom Pipeline'!R11="WON",'MiT Strom Pipeline'!R11,"") | I16: =IF('MiT Strom Pipeline'!R11="WON",'MiT Strom Pipeline'!S11,"") | J16: =IF('MiT Strom Pipeline'!R11="WON",IF(LEN('MiT Strom Pipeline'!V11)>0,LEFT('MiT Strom Pipeline'!V11,55),""),"")
A17: =IF('MiT Strom Pipeline'!R12="WON",IF(ISNUMBER('MiT Strom Pipeline'!A12),'MiT Strom Pipeline'!A12,""),"") | B17: =IF('MiT Strom Pipeline'!R12="WON",'MiT Strom Pipeline'!B12,"") | C17: =IF('MiT Strom Pipeline'!R12="WON",'MiT Strom Pipeline'!C12,"") | D17: =IF('MiT Strom Pipeline'!R12="WON",'MiT Strom Pipeline'!D12,"") | E17: =IF('MiT Strom Pipeline'!R12="WON",'MiT Strom Pipeline'!E12,"") | F17: =IF('MiT Strom Pipeline'!R12="WON",IF(ISNUMBER('MiT Strom Pipeline'!I12),'MiT Strom Pipeline'!I12,0),"") | G17: =IF('MiT Strom Pipeline'!R12="WON",IF(ISNUMBER('MiT Strom Pipeline'!Q12),'MiT Strom Pipeline'!Q12,0),"") | H17: =IF('MiT Strom Pipeline'!R12="WON",'MiT Strom Pipeline'!R12,"") | I17: =IF('MiT Strom Pipeline'!R12="WON",'MiT Strom Pipeline'!S12,"") | J17: =IF('MiT Strom Pipeline'!R12="WON",IF(LEN('MiT Strom Pipeline'!V12)>0,LEFT('MiT Strom Pipeline'!V12,55),""),"")
A18: =IF('MiT Strom Pipeline'!R13="WON",IF(ISNUMBER('MiT Strom Pipeline'!A13),'MiT Strom Pipeline'!A13,""),"") | B18: =IF('MiT Strom Pipeline'!R13="WON",'MiT Strom Pipeline'!B13,"") | C18: =IF('MiT Strom Pipeline'!R13="WON",'MiT Strom Pipeline'!C13,"") | D18: =IF('MiT Strom Pipeline'!R13="WON",'MiT Strom Pipeline'!D13,"") | E18: =IF('MiT Strom Pipeline'!R13="WON",'MiT Strom Pipeline'!E13,"") | F18: =IF('MiT Strom Pipeline'!R13="WON",IF(ISNUMBER('MiT Strom Pipeline'!I13),'MiT Strom Pipeline'!I13,0),"") | G18: =IF('MiT Strom Pipeline'!R13="WON",IF(ISNUMBER('MiT Strom Pipeline'!Q13),'MiT Strom Pipeline'!Q13,0),"") | H18: =IF('MiT Strom Pipeline'!R13="WON",'MiT Strom Pipeline'!R13,"") | I18: =IF('MiT Strom Pipeline'!R13="WON",'MiT Strom Pipeline'!S13,"") | J18: =IF('MiT Strom Pipeline'!R13="WON",IF(LEN('MiT Strom Pipeline'!V13)>0,LEFT('MiT Strom Pipeline'!V13,55),""),"")
A19: =IF('MiT Strom Pipeline'!R14="WON",IF(ISNUMBER('MiT Strom Pipeline'!A14),'MiT Strom Pipeline'!A14,""),"") | B19: =IF('MiT Strom Pipeline'!R14="WON",'MiT Strom Pipeline'!B14,"") | C19: =IF('MiT Strom Pipeline'!R14="WON",'MiT Strom Pipeline'!C14,"") | D19: =IF('MiT Strom Pipeline'!R14="WON",'MiT Strom Pipeline'!D14,"") | E19: =IF('MiT Strom Pipeline'!R14="WON",'MiT Strom Pipeline'!E14,"") | F19: =IF('MiT Strom Pipeline'!R14="WON",IF(ISNUMBER('MiT Strom Pipeline'!I14),'MiT Strom Pipeline'!I14,0),"") | G19: =IF('MiT Strom Pipeline'!R14="WON",IF(ISNUMBER('MiT Strom Pipeline'!Q14),'MiT Strom Pipeline'!Q14,0),"") | H19: =IF('MiT Strom Pipeline'!R14="WON",'MiT Strom Pipeline'!R14,"") | I19: =IF('MiT Strom Pipeline'!R14="WON",'MiT Strom Pipeline'!S14,"") | J19: =IF('MiT Strom Pipeline'!R14="WON",IF(LEN('MiT Strom Pipeline'!V14)>0,LEFT('MiT Strom Pipeline'!V14,55),""),"")
A20: =IF('MiT Strom Pipeline'!R15="WON",IF(ISNUMBER('MiT Strom Pipeline'!A15),'MiT Strom Pipeline'!A15,""),"") | B20: =IF('MiT Strom Pipeline'!R15="WON",'MiT Strom Pipeline'!B15,"") | C20: =IF('MiT Strom Pipeline'!R15="WON",'MiT Strom Pipeline'!C15,"") | D20: =IF('MiT Strom Pipeline'!R15="WON",'MiT Strom Pipeline'!D15,"") | E20: =IF('MiT Strom Pipeline'!R15="WON",'MiT Strom Pipeline'!E15,"") | F20: =IF('MiT Strom Pipeline'!R15="WON",IF(ISNUMBER('MiT Strom Pipeline'!I15),'MiT Strom Pipeline'!I15,0),"") | G20: =IF('MiT Strom Pipeline'!R15="WON",IF(ISNUMBER('MiT Strom Pipeline'!Q15),'MiT Strom Pipeline'!Q15,0),"") | H20: =IF('MiT Strom Pipeline'!R15="WON",'MiT Strom Pipeline'!R15,"") | I20: =IF('MiT Strom Pipeline'!R15="WON",'MiT Strom Pipeline'!S15,"") | J20: =IF('MiT Strom Pipeline'!R15="WON",IF(LEN('MiT Strom Pipeline'!V15)>0,LEFT('MiT Strom Pipeline'!V15,55),""),"")
A21: =IF('MiT Strom Pipeline'!R16="WON",IF(ISNUMBER('MiT Strom Pipeline'!A16),'MiT Strom Pipeline'!A16,""),"") | B21: =IF('MiT Strom Pipeline'!R16="WON",'MiT Strom Pipeline'!B16,"") | C21: =IF('MiT Strom Pipeline'!R16="WON",'MiT Strom Pipeline'!C16,"") | D21: =IF('MiT Strom Pipeline'!R16="WON",'MiT Strom Pipeline'!D16,"") | E21: =IF('MiT Strom Pipeline'!R16="WON",'MiT Strom Pipeline'!E16,"") | F21: =IF('MiT Strom Pipeline'!R16="WON",IF(ISNUMBER('MiT Strom Pipeline'!I16),'MiT Strom Pipeline'!I16,0),"") | G21: =IF('MiT Strom Pipeline'!R16="WON",IF(ISNUMBER('MiT Strom Pipeline'!Q16),'MiT Strom Pipeline'!Q16,0),"") | H21: =IF('MiT Strom Pipeline'!R16="WON",'MiT Strom Pipeline'!R16,"") | I21: =IF('MiT Strom Pipeline'!R16="WON",'MiT Strom Pipeline'!S16,"") | J21: =IF('MiT Strom Pipeline'!R16="WON",IF(LEN('MiT Strom Pipeline'!V16)>0,LEFT('MiT Strom Pipeline'!V16,55),""),"")
A22: =IF('MiT Strom Pipeline'!R17="WON",IF(ISNUMBER('MiT Strom Pipeline'!A17),'MiT Strom Pipeline'!A17,""),"") | B22: =IF('MiT Strom Pipeline'!R17="WON",'MiT Strom Pipeline'!B17,"") | C22: =IF('MiT Strom Pipeline'!R17="WON",'MiT Strom Pipeline'!C17,"") | D22: =IF('MiT Strom Pipeline'!R17="WON",'MiT Strom Pipeline'!D17,"") | E22: =IF('MiT Strom Pipeline'!R17="WON",'MiT Strom Pipeline'!E17,"") | F22: =IF('MiT Strom Pipeline'!R17="WON",IF(ISNUMBER('MiT Strom Pipeline'!I17),'MiT Strom Pipeline'!I17,0),"") | G22: =IF('MiT Strom Pipeline'!R17="WON",IF(ISNUMBER('MiT Strom Pipeline'!Q17),'MiT Strom Pipeline'!Q17,0),"") | H22: =IF('MiT Strom Pipeline'!R17="WON",'MiT Strom Pipeline'!R17,"") | I22: =IF('MiT Strom Pipeline'!R17="WON",'MiT Strom Pipeline'!S17,"") | J22: =IF('MiT Strom Pipeline'!R17="WON",IF(LEN('MiT Strom Pipeline'!V17)>0,LEFT('MiT Strom Pipeline'!V17,55),""),"")
