Workbook

Sheet 📊 Dashboard
A1: MiT CRM — Live Dashboard
A2: Auswertungen werden bei jeder Datenänderung in 'Kunden-Datenbank' automatisch aktualisiert.
A4: 📈 Kennzahlen
A5: Kontakte gesamt | B5: Prio A | C5: Prio B | D5: Prio C | E5: Mit E-Mail | F5: Mit Telefon
A6: =COUNTA('📋 Kunden-Datenbank'!$D$4:$D$817) | B6: =COUNTIF('📋 Kunden-Datenbank'!$B$4:$B$817,"A") | C6: =COUNTIF('📋 Kunden-Datenbank'!$B$4:$B$817,"B") | D6: =COUNTIF('📋 Kunden-Datenbank'!$B$4:$B$817,"C") | E6: =COUNTIF('📋 Kunden-Datenbank'!$J$4:$J$817,"?*@?*.?*") | F6: =COUNTA('📋 Kunden-Datenbank'!$K$4:$K$817)
A8: 🏷️ Segment-Verteilung
A9: Segment | B9: Anzahl | C9: % Anteil
A10: EVU/Netzbetreiber | B10: =COUNTIF('📋 Kunden-Datenbank'!$C$4:$C$817,A10) | C10: =IFERROR(B10/COUNTA('📋 Kunden-Datenbank'!$D$4:$D$817),0)
A11: Spital/Klinik | B11: =COUNTIF('📋 Kunden-Datenbank'!$C$4:$C$817,A11) | C11: =IFERROR(B11/COUNTA('📋 Kunden-Datenbank'!$D$4:$D$817),0)
A12: Pharma/Chemie | B12: =COUNTIF('📋 Kunden-Datenbank'!$C$4:$C$817,A12) | C12: =IFERROR(B12/COUNTA('📋 Kunden-Datenbank'!$D$4:$D$817),0)
A13: Rechenzentrum/IT | B13: =COUNTIF('📋 Kunden-Datenbank'!$C$4:$C$817,A13) | C13: =IFERROR(B13/COUNTA('📋 Kunden-Datenbank'!$D$4:$D$817),0)
A14: Industrie/Maschinenbau | B14: =COUNTIF('📋 Kunden-Datenbank'!$C$4:$C$817,A14) | C14: =IFERROR(B14/COUNTA('📋 Kunden-Datenbank'!$D$4:$D$817),0)
A15: Bau/Infrastruktur | B15: =COUNTIF('📋 Kunden-Datenbank'!$C$4:$C$817,A15) | C15: =IFERROR(B15/COUNTA('📋 Kunden-Datenbank'!$D$4:$D$817),0)
A16: Gemeinde/Öffentlich | B16: =COUNTIF('📋 Kunden-Datenbank'!$C$4:$C$817,A16) | C16: =IFERROR(B16/COUNTA('📋 Kunden-Datenbank'!$D$4:$D$817),0)
A17: Bergbahn/Tourismus | B17: =COUNTIF('📋 Kunden-Datenbank'!$C$4:$C$817,A17) | C17: =IFERROR(B17/COUNTA('📋 Kunden-Datenbank'!$D$4:$D$817),0)
A18: Events/Messen | B18: =COUNTIF('📋 Kunden-Datenbank'!$C$4:$C$817,A18) | C18: =IFERROR(B18/COUNTA('📋 Kunden-Datenbank'!$D$4:$D$817),0)
A19: Elektroplaner/Engineering | B19: =COUNTIF('📋 Kunden-Datenbank'!$C$4:$C$817,A19) | C19: =IFERROR(B19/COUNTA('📋 Kunden-Datenbank'!$D$4:$D$817),0)
A20: Forschung/Bildung | B20: =COUNTIF('📋 Kunden-Datenbank'!$C$4:$C$817,A20) | C20: =IFERROR(B20/COUNTA('📋 Kunden-Datenbank'!$D$4:$D$817),0)
A21: Lebensmittel/Food | B21: =COUNTIF('📋 Kunden-Datenbank'!$C$4:$C$817,A21) | C21: =IFERROR(B21/COUNTA('📋 Kunden-Datenbank'!$D$4:$D$817),0)
A23: 🏔️ Kanton-Verteilung
A24: Kanton | B24: Anzahl
A25: ZH | B25: =COUNTIF('📋 Kunden-Datenbank'!$G$4:$G$817,A25)
A26: BE | B26: =COUNTIF('📋 Kunden-Datenbank'!$G$4:$G$817,A26)
A27: LU | B27: =COUNTIF('📋 Kunden-Datenbank'!$G$4:$G$817,A27)
A28: AG | B28: =COUNTIF('📋 Kunden-Datenbank'!$G$4:$G$817,A28)
A29: SG | B29: =COUNTIF('📋 Kunden-Datenbank'!$G$4:$G$817,A29)
A30: GE | B30: =COUNTIF('📋 Kunden-Datenbank'!$G$4:$G$817,A30)
A31: BS | B31: =COUNTIF('📋 Kunden-Datenbank'!$G$4:$G$817,A31)
A32: BL | B32: =COUNTIF('📋 Kunden-Datenbank'!$G$4:$G$817,A32)
A33: SO | B33: =COUNTIF('📋 Kunden-Datenbank'!$G$4:$G$817,A33)
A34: TG | B34: =COUNTIF('📋 Kunden-Datenbank'!$G$4:$G$817,A34)
A35: VS | B35: =COUNTIF('📋 Kunden-Datenbank'!$G$4:$G$817,A35)
A36: VD | B36: =COUNTIF('📋 Kunden-Datenbank'!$G$4:$G$817,A36)
... A50: JU | B50: =COUNTIF('📋 Kunden-Datenbank'!$G$4:$G$817,A50)
D52: 🎯 Pipeline-Status
D53: Status | E53: Anzahl | G53: ⏰ Follow-ups
D54: offen | E54: =COUNTIF('📋 Kunden-Datenbank'!$M$4:$M$817,D54) | G54: Überfällig | H54: =SUMPRODUCT(('📋 Kunden-Datenbank'!$Q$4:$Q$817<TODAY())*('📋 Kunden-Datenbank'!$Q$4:$Q$817<>""))
D55: kontaktiert | E55: =COUNTIF('📋 Kunden-Datenbank'!$M$4:$M$817,D55) | G55: Diese Woche | H55: =SUMPRODUCT(('📋 Kunden-Datenbank'!$Q$4:$Q$817>=TODAY())*('📋 Kunden-Datenbank'!$Q$4:$Q$817<=TODAY()+7))
D56: in Gespräch | E56: =COUNTIF('📋 Kunden-Datenbank'!$M$4:$M$817,D56) | G56: Nächste 30 Tage | H56: =SUMPRODUCT(('📋 Kunden-Datenbank'!$Q$4:$Q$817>=TODAY())*('📋 Kunden-Datenbank'!$Q$4:$Q$817<=TODAY()+30))
D57: Angebot gesendet | E57: =COUNTIF('📋 Kunden-Datenbank'!$M$4:$M$817,D57)
...

Sheet 📋 Kunden-Datenbank
A1: MiT CRM — Kunden-Datenbank Vorlage | Mobil in Time AG
A2: → Diese Datei direkt in MiT CRM importieren: Header > '📥 Importieren' > Datei wählen. Spalten werden automatisch erkannt.
A3: Nr. | B3: Prio | C3: Segment | D3: Firmenname * | E3: Ort | F3: PLZ | G3: Kanton | H3: Ansprechpartner | I3: Funktion / Titel | J3: E-Mail | K3: Telefon | L3: Website | M3: Status | N3: Nächster Schritt | O3: Bedarf / kVA | P3: Hauptprodukt | Q3: Follow-up Datum | R3: Notizen | S3: Internes
A4: 1 | B4: A | C4: EVU/Netzbetreiber | D4: AEW Energie AG | E4: Aarau | F4: 5001 | G4: AG | H4: Leiter Netzbetrieb | I4: Dipl. El.-Ing. | J4: info@aew.ch | K4: +41 62 834 21 11 | M4: offen | N4: Netzbetrieb AEW; Revisionskalender anfragen | O4: 0.5 Mio. Kunden; 15 Unterwerke; MS/HS-Revisionen; BESS | P4: BESS | R4: Adr: Obere Vorstadt 2, 5001 Aarau | Kantonaler EVU AG; 0.5 Mio. Kunden | S4: Kantonaler EVU
A5: 2 | B5: A | C5: EVU/Netzbetreiber | D5: Axpo Group AG | E5: Baden | F5: 5401 | G5: AG | H5: Leiter Netzoperationen CH | I5: MSc El.-Ing. | J5: info@axpo.com | K5: +41 56 200 21 11 | M5: offen | N5: Netzbetrieb Axpo Baden; Aggreko-Synergien ansprechen | O5: MS/HS-Revisionen Kraftwerke; Netzersatz 5–20 MVA; BESS; CHF 1'261 Mio. EBIT 2024 | P5: BESS | R5: Adr: Parkstrasse 23, 5401 Baden | Grösstes Energieunternehmen CH | S5: Energiekonzern
A6: 3 | B6: A | C6: EVU/Netzbetreiber | D6: Swissgrid AG | E6: Laufenburg | F6: 5242 | G6: AG | H6: Leiter Grid Operations | I6: MSc El.-Ing. | J6: info@swissgrid.ch | K6: +41 58 580 21 11 | M6: offen | N6: Grid Operations Swissgrid Laufenburg kontaktieren | O6: Übertragungsnetz CH; HS-Revisionen; CHF 317 Mio. Invest 2024 | R6: Adr: Neumattstrasse 19, 5242 Laufenburg | CH-Übertragungsnetzbetreiber | S6: Übertragungsnetz
A7: 4 | B7: A | C7: EVU/Netzbetreiber | D7: Stadtwerk Aarau AG | E7: Aarau | F7: 5001 | G7: AG | H7: Betriebsleiter | I7: Dipl. El.-Ing. | J7: info@stadtwerk-aarau.ch | K7: +41 62 834 41 41 | M7: offen | N7: Betriebsleiter Stadtwerk Aarau kontaktieren | O7: Stadtversorgung Aarau: MS-Revisionen; NEA Stadtgebäude | P7: Wärme | R7: Adr: Buchserstrasse 26, 5001 Aarau | Stadtwerk Aarau; Strom+Gas+Wärme | S7: Stadtwerk
A8: 5 | B8: A | C8: Pharma/Chemie | D8: ABB Schweiz AG (Werke Baden/Dättwil) | E8: Baden | F8: 5400 | G8: AG | H8: Energiemanager Schweiz | I8: MSc El.-Ing. | J8: info@ch.abb.com | K8: +41 58 585 00 00 | M8: offen | N8: Energiemanager ABB Baden; FU-PQ-Pitch Q2 2026 | O8: FU-Prüfstände 5 MVA; 3'850 MA CH; PQ; EMV; ISO 50001; 8 CH-Standorte | P8: Generator | R8: Adr: Bruggerstrasse 72, 5400 Baden | USD 32.85 Mrd. 2024; 104'400 MA ww | S8: Elektrotechnik
A9: 6 | B9: A | C9: Pharma/Chemie | D9: Alstom Schweiz AG (Werk Birr) | E9: Birr | F9: 5242 | G9: AG | H9: Betriebsleiter Elektro | I9: Dipl. El.-Ing. | J9: contact-birr@alstom.com | K9: +41 56 205 20 00 | M9: offen | N9: Betriebsleiter Alstom Birr; Schweiss-PQ-Pitch | O9: Lokomotivbau: Schweissanlagen + Prüfstände 2 MVA; PQ; EMV | R9: Adr: Birmigstrasse 73, 5242 Birr | Schweissen = stärkste NRW CH | S9: Bahnfahrzeuge
A10: 7 | B10: A | C10: Spital/Klinik | D10: Kantonsspital Aarau AG (KSA) | E10: Aarau | F10: 5001 | G10: AG | H10: Leiter TGM | I10: MSc El.-Ing. | J10: info@ksa.ch | K10: +41 62 838 41 41 | M10: offen | N10: TGM KSA; Neubau Dreiklang = Baustrom | O10: NEA 4× 500 kVA; USV OP/ICU; 5'300 MA; Neubau Dreiklang 2026 | P10: USV | R10: Adr: Tellstrasse 25, 5001 Aarau | 5'300 MA; Neubau Dreiklang läuft | S10: Kantonsspital
A11: 8 | B11: A | C11: Spital/Klinik | D11: Kantonsspital Baden AG (KSB) | E11: Baden | F11: 5404 | G11: AG | H11: Betriebsleiter Technik | I11: Dipl. El.-Ing. | J11: info@ksb.ch | K11: +41 56 486 11 11 | M11: offen | N11: Betriebsleiter KSB; Betriebsphase-Vertrag anstreben | O11: NEA 3× 400 kVA; USV OP; Neubau Gesundheitscampus 2023 | P11: USV | R11: Adr: Im Ergel 1, 5404 Baden | Neubau 2023; ETH-Kooperation | S11: Kantonsspital
A12: 9 | B12: A | C12: Bau/Infrastruktur | D12: Kernkraftwerk Beznau AG | E12: Döttingen | F12: 5312 | G12: AG | H12: Technischer Leiter | I12: MSc El.-Ing. | J12: info@beznau.ch | K12: +41 56 268 91 11 | M12: offen | N12: Technischen Leiter KKW Beznau; Revisionsplanung anfragen | O12: Revisionen KKW 1+2; mobile MS-Einspeisung 50–100 MVA; Netzersatz | P12: Generator | R12: Adr: Werkstrasse 1, 5312 Döttingen | Ältestes KKW Welt; grösster MS-Bedarf CH | S12: Kernkraftwerk
A13: 10 | B13: A | C13: Bau/Infrastruktur | D13: Kernkraftwerk Leibstadt AG | E13: Leibstadt | F13: 5325 | G13: AG | H13: Technischer Leiter | I13: MSc El.-Ing. | J13: info@kkl.ch | K13: +41 56 267 71 11 | M13: offen | N13: Technischen Leiter KKL; Revisionsplanung anfragen | O13: Revisionen KKW; mobile MS-Einspeisung 100+ MVA; Netzersatz | P13: Generator | R13: Adr: Kernkraftwerk, 5325 Leibstadt | Leistungsstärkstes KKW CH (1'220 MW) | S13: Kernkraftwerk
A14: 11 | B14: A | C14: Forschung/Bildung | D14: Paul Scherrer Institut (PSI) | E14: Villigen | F14: 5232 | G14: AG | H14: Betriebsleiter Energie | I14: MSc El.-Ing. | J14: info@psi.ch | K14: +41 56 310 21 11 | M14: offen | N14: Betriebsleiter Energie PSI; Forschungsstrasse 111 Villigen | O14: Synchrotron: NEA 10 MVA; USV Beschleuniger; PQ Spezial | P14: USV | R14: Adr: Forschungsstrasse 111, 5232 Villigen | Grösstes Forschungsinstitut CH | S14: Forschungsinstitut
A15: 12 | B15: A | C15: Pharma/Chemie | D15: Siegfried AG (Werk Zofingen) | E15: Zofingen | F15: 4800 | G15: AG | H15: Energiemanager | I15: MSc Chemie | J15: info@siegfried.ch | K15: +41 62 746 11 11 | M15: offen | N15: Energiemanager Siegfried Zofingen; GMP-Pitch | O15: Wirkstoff GMP: NEA 2 MVA; USV; PQ Reinraum; ISO 50001 | P15: USV | R15: Adr: Untere Brühlstrasse 4, 4800 Zofingen | GMP Wirkstoff | S15: Spezialchemie
A16: 13 | B16: A | C16: Pharma/Chemie | D16: DSM-Firmenich (Werk Sisseln) | E16: Sisseln | F16: 4334 | G16: AG | H16: Betriebsleiter Technik | I16: MSc Chemie | J16: info@dsm-firmenich.com | K16: +41 62 866 11 11 | M16: offen | N16: Betriebsleiter DSM Sisseln; Kälte-CRM prüfen | O16: Vitamin GMP: NEA 3 MVA; USV; PQ Reinraum; ISO 50001 | P16: USV | R16: Adr: Hauptstrasse 4, 4334 Sisseln | Vitamin-Weltproduktion; GMP | S16: Vitamine/Pharma
A17: 14 | B17: A | C17: Pharma/Chemie | D17: Dottikon ES Holding AG | E17: Dottikon | F17: 5605 | G17: AG | H17: Betriebsleiter Elektro | I17: MSc Chemie | J17: info@dottikon.com | K17: +41 56 616 81 11 | M17: offen | N17: Betriebsleiter Dottikon ES; GMP-Pitch | O17: Feinchemie GMP: NEA 1.5 MVA; USV; PQ Reaktoren; +18% Wachstum 2024 | P17: USV | R17: Adr: Industriestrasse 17, 5605 Dottikon | CHF 385 Mio. Umsatz; 18% Wachstum | S17: Feinchemie
A18: 15 | B18: A | C18: Pharma/Chemie | D18: Franke Holding AG | E18: Aarburg | F18: 4663 | G18: AG | H18: Betriebsleiter Technik | I18: Dipl. El.-Ing. | J18: info@franke.com | K18: +41 62 787 31 31 | M18: offen | N18: Betriebsleiter Franke Aarburg; FU-PQ-Pitch | O18: Küchensysteme: NEA 1 MVA; FU-Pressanlagen; PQ; ISO 50001 | R18: Adr: Franke-Strasse 2, 4663 Aarburg | Weltführer Küchensysteme | S18: Küchen/Kaffee
A19: 16 | B19: A | C19: Pharma/Chemie | D19: Delica AG (Nestlé FREY) | E19: Buchs AG | F19: 5033 | G19: AG | H19: Betriebsleiter Technik | I19: Techniker | J19: info@delica.ch | K19: +41 62 837 61 11 | M19: offen | N19: MiT-CRM: Delica als Kältekunde prüfen | O19: Schokolade FREY: NEA Kühlkette 1 MVA; FU-Temperierer; ISO 50001 | P19: Kälte | R19: Adr: Javastrasse 20, 5033 Buchs AG | Grösster Schokoladenproduzent CH | S19: Schokolade
A20: 17 | B20: A | C20: Pharma/Chemie | D20: Feldschlösschen Getränke AG | E20: Rheinfelden | F20: 4310 | G20: AG | H20: Betriebsleiter Technik | I20: Dipl. El.-Ing. | J20: info@feldschloesschen.ch | K20: +41 61 835 22 22 | M20: offen | N20: MiT-CRM: Feldschlösschen als Kältekunde prüfen | O20: Brauerei: NEA Kühlkette 2 MVA; FU-Abfüller; ISO 50001 | P20: Kälte | R20: Adr: Theophil Roniger-Strasse, 4310 Rheinfelden | Grösste Brauerei CH | S20: Brauerei
A21: 18 | B21: A | C21: Pharma/Chemie | D21: Lonza AG (Kaiseraugst) | E21: Kaiseraugst | F21: 4303 | G21: AG | H21: Energiemanager | I21: MSc Chemie | J21: energy@lonza.com | K21: +41 61 316 12 34 | M21: offen | N21: Energiemanager Lonza Kaiseraugst; GMP-Pitch | O21: Biopharma GMP: NEA 4 MVA; USV; PQ Reinräume | P21: USV | R21: Adr: Lonzastrasse 1, 4303 Kaiseraugst | GMP-Biopharma; AG/BL-Grenze | S21: Biopharma
A22: 19 | B22: A | C22: Bau/Infrastruktur | D22: ARA Region Aarau AG | E22: Aarau | F22: 5000 | G22: AG | H22: Betriebsleiter ARA | I22: Techniker | J22: info@ara-aarau.ch | K22: +41 62 824 44 80 | M22: offen | N22: Betriebsleiter ARA Aarau; simap.ch Alert AG | O22: NEA-Pflicht 1× 500 kVA; Aare-Gewässerschutz; 24h | P22: Generator | R22: Adr: Aarestrasse 130, 5000 Aarau | Aare-Schutz; Ausschreibungspflicht | S22: ARA
A23: 20 | B23: B | C23: Pharma/Chemie | D23: Rivella AG | E23: Rothrist | F23: 4852 | G23: AG | H23: Betriebsleiter Technik | I23: Techniker | J23: info@rivella.ch | K23: +41 62 785 41 11 | M23: offen | N23: MiT-CRM: Rivella als Kältekunde prüfen | O23: Getränke: NEA Kühlkette 300 kVA; FU-Abfüllanlagen | P23: Kälte | R23: Adr: Sportstrasse 2, 4852 Rothrist | Nationalgetränk CH; Kühlkette | S23: Nahrungsmittel
A24: 21 | B24: B | C24: Pharma/Chemie | D24: Hero AG | E24: Brugg | F24: 5201 | G24: AG | H24: Betriebsleiter Technik | I24: Techniker | J24: info@hero.ch | K24: +41 56 441 21 21 | M24: offen | N24: MiT-CRM: Hero Brugg als Kältekunde prüfen | O24: Nahrungsmittel: NEA Kühlkette 300 kVA; FU-Abfüller | P24: Kälte | R24: Adr: Lindenstrasse 33, 5201 Brugg | Babynahrung+Konfitüren; Kühlkette | S24: Nahrungsmittel
A25: 22 | B25: B | C25: Pharma/Chemie | D25: Novartis F&E Stein AG | E25: Stein AG | F25: 4153 | G25: AG | H25: Facility Manager | I25: MSc El.-Ing. | J25: info@novartis.com | K25: +41 61 705 11 11 | M25: offen | N25: Facility Manager Novartis Stein; GMP-Pitch | O25: F&E GMP: NEA 2 MVA; USV Labors; PQ Reinräume | P25: USV | R25: Adr: Lichstrasse 35, 4153 Stein AG | Novartis F&E; GMP | S25: Forschung Pharma
A26: 23 | B26: B | C26: Rechenzentrum/IT | D26: Aargauische Kantonalbank (AKB) | E26: Aarau | F26: 5001 | G26: AG | H26: Leiter IT-Infrastruktur | I26: MSc Inf. | J26: info@akb.ch | K26: +41 62 835 77 77 | M26: offen | N26: IT-Infrastruktur AKB; FINMA-Argument | O26: USV RZ 2× 200 kVA; NEA; PQ FINMA | P26: USV | R26: Adr: Bahnhofstrasse 58, 5001 Aarau | Kantonalbank AG; FINMA | S26: Kantonalbank
A27: 24 | B27: B | C27: Spital/Klinik | D27: Spital Zofingen AG | E27: Zofingen | F27: 4800 | G27: AG | H27: Betriebsleiter | I27: Techniker | J27: info@spitalzofingen.ch | K27: +41 62 746 15 15 | M27: offen | N27: Betriebsleiter Spital Zofingen; simap.ch AG | O27: NEA 1× 300 kVA; USV; Swiss Medical Network | P27: USV | R27: Adr: Mühlethalstrasse 27, 4800 Zofingen | Swiss Medical Network | S27: Spital
A28: 25 | B28: B | C28: Gemeinde/Öffentlich | D28: Kanton Aargau (Hochbauamt) | E28: Aarau | F28: 5001 | G28: AG | H28: Leiter Hochbauamt | I28: Kantonsbauingenieur | J28: hba@ag.ch | K28: +41 62 835 24 00 | M28: offen | N28: Hochbauamt AG; simap.ch Alert Kanton AG | O28: NEA kantonale Gebäude; 200+ Liegenschaften; Rahmenvertrag | R28: Adr: Entfelderstrasse 22, 5001 Aarau | Industriekanton Nr. 1 CH | S28: Kanton
A29: 26 | B29: B | C29: Bau/Infrastruktur | D29: Eniwa AG RZ Buchs | E29: Aarau | F29: 5000 | G29: AG | H29: Betriebsleiter RZ | I29: Techniker | J29: info@eniwa.ch | K29: +41 62 838 91 11 | M29: offen | N29: Betriebsleiter Eniwa RZ Buchs kontaktieren | O29: RZ Buchs: 200 m² ausgebaut 2023; NEA; USV; PQ | P29: USV | R29: Adr: Obere Vorstadt 2, 5000 Aarau | RZ auf 200 m² ausgebaut 2023 | S29: Rechenzentrum
A30: 27 | B30: B | C30: Spital/Klinik | D30: RehaClinic AG Baden | E30: Baden | F30: 5404 | G30: AG | H30: Betriebsleiter | I30: Techniker | J30: info@rehaclinic.ch | K30: +41 56 485 00 00 | M30: offen | N30: Betriebsleiter RehaClinic Baden kontaktieren | O30: Reha-Klinik: NEA 1× 200 kVA; USV; mehrere AG-Standorte | P30: USV | R30: Adr: Mellingerstrasse 2, 5404 Baden | RehaClinic AG; mehrere Standorte | S30: Rehaklinik
A31: 28 | B31: C | C31: EVU/Netzbetreiber | D31: EW Baden AG | E31: Baden | F31: 5400 | G31: AG | H31: Betriebsleiter | I31: Dipl. El.-Ing. | J31: info@ewbaden.ch | K31: +41 56 200 80 00 | M31: offen | N31: EW Baden; simap.ch Alert Baden AG | O31: Stadtversorgung Baden: MS-Revisionen; NEA Stadtgebäude | R31: Adr: Mellingerstrasse 207, 5400 Baden | Stadtwerk Baden | S31: Stadtwerk Baden
A32: 29 | B32: C | C32: Pharma/Chemie | D32: Zweifel Pomy-Chips AG | E32: Zürich-Höngg | F32: 8049 | G32: AG | H32: Betriebsleiter Technik | I32: Techniker | J32: info@zweifel.ch | K32: +41 44 344 71 11 | M32: offen | N32: MiT-CRM: Zweifel als Kältekunde prüfen | O32: Chips-Produktion: NEA Kühlkette 300 kVA; FU-Frittieranlagen | P32: Kälte | R32: Adr: Erlenmattstrasse 6, 8049 ZH | Zweifel Chips; Kühlkette | S32: Nahrungsmittel
A33: 30 | B33: C | C33: Bau/Infrastruktur | D33: ARA Limeco AG | E33: Dietikon | F33: 8953 | G33: AG | H33: Betriebsleiter | I33: Techniker | J33: info@limeco.ch | K33: +41 43 322 55 00 | M33: offen | N33: Betriebsleiter Limeco; simap.ch Alert | O33: NEA-Pflicht 1× 400 kVA; Limmat-Schutz; interkantonal AG/ZH | P33: Generator | R33: Adr: Reussinsel 1, 8953 Dietikon | ARA Limeco; Limmat-Schutz | S33: ARA
A34: 31 | B34: C | C34: Spital/Klinik | D34: Kantonsspital Muri AG | E34: Muri | F34: 5630 | G34: AG | H34: Betriebsleiter | I34: Techniker | J34: info@spital-muri.ch | K34: +41 56 675 11 11 | M34: offen | N34: Betriebsleiter Spital Muri kontaktieren | O34: NEA 1× 250 kVA; USV; alpine Lage Freiamt | P34: USV | R34: Adr: Kantonsstrasse 32, 5630 Muri | Regionalspital Freiamt AG | S34: Bezirksspital
A35: 32 | B35: C | C35: Pharma/Chemie | D35: Huntsman Advanced Materials (AG-Region) | E35: Dürrenäsch | F35: 5606 | G35: AG | H35: Betriebsleiter Elektro | I35: MSc Chemie | J35: info@huntsman.com | K35: +41 62 768 11 11 | M35: offen | N35: Betriebsleiter Huntsman AG kontaktieren | O35: Chemieproduktion: NEA 1 MVA; FU-Antriebe; PQ; EMV | R35: Adr: Dürrenäsch, 5606 AG | Spezialchemie; FU-Antriebe intensiv | S35: Chemie/Wirkstoffe
A36: 33 | B36: C | C36: Gemeinde/Öffentlich | D36: [MiT AG-Kältekunde Nr. 1] | E36: Aarau | F36: 5000 | G36: AG | H36: Energieverantwortlicher | I36: Betriebsleiter | K36: (MiT-CRM) | M36: offen | N36: MiT-CRM Roberto/Stefan: AG-Kunden ohne Strom sofort prüfen | O36: Strom-Add-on zu MiT-Wärme/Kälte AG | R36: Schnellster Weg: AG-Warmlead Bestandsbasis | S36: Cross-Sell MiT
A37: 34 | B37: A | C37: EVU/Netzbetreiber | D37: EW Appenzell AG (Innerrhoden) | E37: Appenzell | F37: 9050 | G37: AI | H37: Leiter Netzbetrieb | I37: Dipl. El.-Ing. | J37: info@ewa-ai.ch | K37: +41 71 788 16 16 | M37: offen | N37: Netzbetrieb EWA AI; Burgstrasse 1 Appenzell; Revisionskalender | O37: Stromversorgung AI; MS-Revisionen; NEA Gemeindegebäude; Netz AI; Wasserkraft Sitter | P37: Generator | R37: Adr: Burgstrasse 1, 9050 Appenzell | Kantonaler EVU AI; Wasserkraft Sitter | S37: Kantonaler EVU
A38: 35 | B38: A | C38: Spital/Klinik | D38: Kantonsspital AI (Spital Appenzell) | E38: Appenzell | F38: 9050 | G38: AI | H38: Betriebsleiter Technik | I38: Techniker | J38: info@ksai.ch | K38: +41 71 788 41 11 | M38: offen | N38: Betriebsleiter KSAI; Spitalstrasse 4 Appenzell; NIV Art. 13 | O38: NEA 1× 250 kVA; USV OP/ICU; 400 MA; einziges Spital AI; NIV Art. 13 | P38: USV | R38: Adr: Spitalstrasse 4, 9050 Appenzell | Einziges Spital AI; 400 MA; NIV Art. 13 | S38: Kantonsspital
A39: 36 | B39: A | C39: Pharma/Chemie | D39: Brauerei Locher AG (Appenzeller Bier) | E39: Appenzell | F39: 9050 | G39: AI | H39: Betriebsleiter Technik | I39: Dipl. El.-Ing. | J39: info@locher.ch | K39: +41 71 788 01 40 | M39: offen | N39: MiT-CRM: Locher Brauerei als Kältekunde prüfen; Strom+Kälte | O39: Brauerei + Destillerie: NEA Kühlkette 400 kVA; FU-Abfüllanlagen; ISO 50001 | P39: Kälte | R39: Adr: Brauereiplatz 1, 9050 Appenzell | Appenzeller Bier + Alpstein; Kühlkette; 200 MA | S39: Brauerei
A40: 37 | B40: A | C40: Pharma/Chemie | D40: Sennerei Schwende AI (Appenzeller Käse) | E40: Schwende | F40: 9057 | G40: AI | H40: Betriebsleiter | I40: Techniker | J40: info@appenzeller.com | K40: +41 71 799 11 90 | M40: offen | N40: MiT-CRM: Sennerei AI als Kältekunde prüfen | O40: Käse-Produktion AI: NEA Kühlkette 200 kVA; ISO 50001; Appenzeller Sorte | P40: Kälte | R40: Adr: Schwende, 9057 AI | Appenzeller Käse Sorte; Kühlkette; Handcheese | S40: Käserei/Dairy
...

Sheet 📖 Anleitung
B1: MiT CRM — Import-Anleitung & Feldbeschreibungen
B3: 🚀 Import-Schritte
B4: Schritt 1 | C4: Daten in Tabelle 'Kunden-Datenbank' eintragen
B5: Schritt 2 | C5: Datei speichern als .xlsx oder .csv
B6: Schritt 3 | C6: MiT CRM öffnen → Header-Button '📥 Importieren' klicken
B7: Schritt 4 | C7: Datei hineinziehen oder auswählen
B8: Schritt 5 | C8: KI erkennt Spalten automatisch — Vorschau prüfen
B9: Schritt 6 | C9: 'Importieren' klicken → Daten verteilen sich auf alle Tabs
B11: 📋 Pflichtfelder & Dropdown-Werte
B12: Firmenname * | C12: Pflichtfeld — Import schlägt fehl wenn leer
B13: Prio | C13: Werte: A · B · C (A=hoch, B=mittel, C=niedrig)
B14: Segment | C14: EVU/Netzbetreiber · Spital/Klinik · Pharma/Chemie · Rechenzentrum/IT · Industrie/Maschinenbau · Bau/Infrastruktur · Gemeinde/Öffentlich · Bergbahn/Tourismus · Events/Messen · Elektroplaner/Engineering · Forschung/Bildung · Lebensmittel/Food
B15: Kanton | C15: Zweistelliges Kürzel: ZH, BE, LU, AG, SG, GE, BS, BL, SO, TG, VS, VD, FR, GR, AR, AI, SZ, ZG, TI, NE, UR, OW, NW, GL, SH, JU
B16: Status | C16: offen · kontaktiert · in Gespräch · Angebot gesendet · aktiv · inaktiv
B17: Hauptprodukt | C17: Generator · BESS · Notstrom/USV · USV · BESS + Generator · PQ-Analyse · Wärme · Kälte · Trafo · Mobile MS-Verteilung · Kabel · Baustromverteiler
B18: Follow-up Datum | C18: Format: TT.MM.JJJJ — überfällige Termine werden rot markiert
B20: 🗺️ Karte: Standort-Koordinaten
B21: Ort (Stadt) | C21: → Karte zeigt exakten Stadtpin statt Kantonshauptort
B22: PLZ | C22: → Feinere Geocodierung bei mehreren Firmen in einer Stadt
B23: Kanton | C23: → Fallback wenn Ort nicht erkannt wird
B24: Tipp | C24: Je mehr Felder ausgefüllt, desto präziser die Kartenposition
B26: ⚡ Auto-Verteilung auf CRM-Tabs
B27: 👥 Kontakte | C27: Alle importierten Zeilen als Kontakte
B28: 🗺️ Karte | C28: Pins an exakter Stadt-Position
B29: 🏔️ Kantone | C29: 26 Kantone mit Kontakt-Anzahl befüllt
B30: 🎯 Pipeline | C30: Prio A+B mit Nächstem Schritt → Deals
B31: ✅ Aufgaben | C31: Nächster Schritt + Follow-up Datum → Aufgaben
B32: 🏷️ Tags | C32: Segment + Prio automatisch als Tags
B33: 📞 Dialer | C33: Alle Kontakte mit Telefon → Kaltakquise Queue
B35: 🛡️ Eingebaute Validierung
B36: Dropdowns | C36: Prio, Segment, Kanton, Status, Hauptprodukt sind Dropdown-gesteuert
B37: Farbcodes | C37: Prio A/B/C, Status und überfällige Follow-ups werden automatisch eingefärbt
B38: Dashboard | C38: Tab '📊 Dashboard' enthält Live-Auswertungen aller Stammdaten

Sheet 🏷️ Segmente & Produkte
B1: Segment-Referenz & Produkt-Matrix
B3: Segment | C3: Unterbereich (Beispiele) | D3: Empfohlene MiT-Produkte | E3: Prio-Tendenz
B4: EVU/Netzbetreiber | C4: Kantonale EVU, Stadtwerke, Verteilnetzbetreiber | D4: Generator, Mobile MS-Verteilung, BESS, PQ-Analyse | E4: A
B5: Spital/Klinik | C5: Akutspitäler, Kliniken, Pflegeheime, Reha | D5: Notstrom NIV Art.13, USV, Generator, BESS | E5: A
B6: Pharma/Chemie | C6: Wirkstoff, Galenik, Biotech, Labore | D6: Generator Stage V, BESS, PQ-Monitoring Kl.A | E6: A
B7: Rechenzentrum/IT | C7: Colocation, Enterprise RZ, Telekom-Infra | D7: BESS + Generator, USV, PQ-Analyse IEC 61000-4-30 | E7: A
B8: Industrie/Maschinenbau | C8: CNC-Fertigung, Giesserei, Automobilzulieferer | D8: Generator, Parallelschaltung, Kabel, Trafo | E8: B
B9: Bau/Infrastruktur | C9: Hochbau, Tiefbau, Tunnel, Sanierung | D9: Generator, Baustromverteiler, Kabel, IBC Tank | E9: B
B10: Gemeinde/Öffentlich | C10: Gemeinden, Kantone, Wasserversorgung, Kläranlage | D10: Generator, Notstrom, BESS | E10: B
B11: Bergbahn/Tourismus | C11: Ski-Resorts, Hotels, Seilbahnen, Events | D11: Generator, Wärme, Kälte, BESS | E11: B
B12: Events/Messen | C12: Messen, Festivals, Grossevents, Konzerte | D12: Generator, Kälte, Wärme, Kabel, Verteiler | E12: B/C
B13: Elektroplaner/Engineering | C13: Ingenieurbüros, TGA-Planer, Architekten | D13: Alle Produkte (Planungsunterstützung) | E13: C
B14: Forschung/Bildung | C14: ETH/EPFL, Fachhochschulen, Forschungsinstitute | D14: USV, BESS, Generator, PQ-Analyse | E14: B
B15: Lebensmittel/Food | C15: Molkereien, Fleischverarbeitung, Bäckereien | D15: Generator, Kälte, BESS | E15: B
