Workbook

Sheet Dashboard
J1: Status | K1: Aufgaben
B2: PROJEKTSTEUERUNG | J2: offen | K2: =COUNTIF(Aufgaben[Status],"offen")
B3: MiT-PWR-WIN-2026-001 | DPR Construction / Vantage Datacenter ZRH12 | J3: in Arbeit | K3: =COUNTIF(Aufgaben[Status],"in Arbeit")
E4: AUFGABEN-STATUS | J4: erledigt | K4: =COUNTIF(Aufgaben[Status],"erledigt")
B5: Projekt-Nr. | C5: MiT-PWR-WIN-2026-001 | E5: Offen | F5: =COUNTIF(Aufgaben[Status],"offen") | J5: kritisch | K5: =COUNTIF(Aufgaben[Status],"kritisch")
B6: Kunde / Auftraggeber | C6: DPR Construction (Abschluss in CHF) | E6: In Arbeit | F6: =COUNTIF(Aufgaben[Status],"in Arbeit") | J6: verschoben | K6: =COUNTIF(Aufgaben[Status],"verschoben")
B7: Endkunde / Standort | C7: Vantage Datacenter ZRH12, Fabrikstrasse 10/12, 8404 Winterthur | E7: Erledigt | F7: =COUNTIF(Aufgaben[Status],"erledigt")
B8: Auftragnehmer | C8: Mobil in Time AG (Subunternehmer von DPR) | E8: Kritisch / blockiert | F8: =COUNTIF(Aufgaben[Status],"kritisch")
B9: Unterlieferant | C9: Aggreko Deutschland GmbH (Intercompany, Back-to-Back) | E9: Ueberfaellig (offen, Termin < heute) | F9: =SUMPRODUCT((Aufgaben[Status]<>"erledigt")*(Aufgaben[Termin]<>"")*(Aufgaben[Termin]<TODAY()))
B10: Paket A | C10: 6-MVA-Loadbank-Test, Angebot P-640380-3, PO E3-A25002-49A | E10: Fortschritt Aufgaben | F10: =IFERROR(COUNTIF(Aufgaben[Status],"erledigt")/COUNTA(Aufgaben[Nr.]),0) | G10: =REPT("█",ROUND(F10*12,0))&REPT("░",12-ROUND(F10*12,0))
B11: Paket B | C11: 8-MW-Heat-Load-Test (54x 200 kW), Angebot P-650395-2, PO E3-A25002-49B | E11: MEILENSTEINE
B12: Einkaufsvolumen (Referenz) | C12: EUR 590'840.34 netto (Aggreko; keine CHF-Verkaufspreise hier) | E12: Meilensteine gesamt | F12: =COUNTA(Meilensteine[Nr.])
B13: Projektleiter | C13: Burak Uecoez | E13: davon erledigt | F13: =COUNTIF(Meilensteine[Status],"erledigt")
B14: Sprache | C14: Deutsch (Schweizer Schreibweise) | E14: davon kritisch | F14: =COUNTIF(Meilensteine[Status],"kritisch")
B15: Stand | C15: =TEXT(TODAY(),"DD.MM.YYYY") | E15: Fortschritt Meilensteine | F15: =IFERROR(COUNTIF(Meilensteine[Status],"erledigt")/COUNTA(Meilensteine[Nr.]),0) | G15: =REPT("█",ROUND(F15*12,0))&REPT("░",12-ROUND(F15*12,0))
B17: COUNTDOWN | E17: PROJEKTSTATUS (AMPEL)
B18: Tage bis naechster Meilenstein | C18: =IFERROR(B26-TODAY(),"") | E18: =IF(SUMPRODUCT((Aufgaben[Status]<>"erledigt")*(Aufgaben[Termin]<>"")*(Aufgaben[Termin]<TODAY()))>0,"KRITISCH - ueberfaellige Aufgaben",IF(COUNTIF(Meilensteine[Status],"kritisch")+COUNTIF(Aufgaben[Status],"kritisch")>0,"ACHTUNG - kritische Punkte offen","AUF KURS - keine Ueberfaelligkeiten"))
B19: Tage bis Entsendefrist Aggreko (24.07.) | C19: =DATE(2026,7,24)-TODAY() | E19: Diese Woche faellig (Aufgaben) | F19: =SUMPRODUCT((Aufgaben[Status]<>"erledigt")*(Aufgaben[Termin]>=TODAY())*(Aufgaben[Termin]<TODAY()+7))
B20: Tage bis Lieferung Headloads (03.08.) | C20: =DATE(2026,8,3)-TODAY() | E20: TESTS & LIEFERUNGEN
B21: Tage bis Mietende Loadbank (02.11.) | C21: =DATE(2026,11,2)-TODAY() | E21: Tests bestanden | F21: =COUNTIF(Testprotokolle[Ergebnis],"bestanden")
B22: Tage bis Closeout-Abgabe (30.11.) | C22: =DATE(2026,11,30)-TODAY() | E22: Lieferungen offen | F22: =COUNTIF(Logistik[Status],"offen")
E23: STOPP-PUNKTE & RISIKEN (offen)
B24: NAECHSTE 5 MEILENSTEINE | E24: Auswirkung hoch | F24: =COUNTIFS(Risiken[Auswirkung],"hoch",Risiken[Status],"<>erledigt")
B25: Plantermin | C25: Meilenstein | E25: Status | F25: =COUNTIFS(Risiken[Auswirkung],"mittel",Risiken[Status],"<>erledigt")
B26: =IFERROR(INT(SMALL(Meilensteine!$L$2:$L$26,1)),"") | C26: =IFERROR(INDEX(Meilensteine!$B$2:$B$26,MATCH(SMALL(Meilensteine!$L$2:$L$26,1),Meilensteine!$L$2:$L$26,0)),"") | E26: =IFERROR(INDEX(Meilensteine!$G$2:$G$26,MATCH(SMALL(Meilensteine!$L$2:$L$26,1),Meilensteine!$L$2:$L$26,0)),"") | F26: =COUNTIFS(Risiken[Auswirkung],"niedrig",Risiken[Status],"<>erledigt")
B27: =IFERROR(INT(SMALL(Meilensteine!$L$2:$L$26,2)),"") | C27: =IFERROR(INDEX(Meilensteine!$B$2:$B$26,MATCH(SMALL(Meilensteine!$L$2:$L$26,2),Meilensteine!$L$2:$L$26,0)),"") | E27: =IFERROR(INDEX(Meilensteine!$G$2:$G$26,MATCH(SMALL(Meilensteine!$L$2:$L$26,2),Meilensteine!$L$2:$L$26,0)),"")
B28: =IFERROR(INT(SMALL(Meilensteine!$L$2:$L$26,3)),"") | C28: =IFERROR(INDEX(Meilensteine!$B$2:$B$26,MATCH(SMALL(Meilensteine!$L$2:$L$26,3),Meilensteine!$L$2:$L$26,0)),"") | E28: =IFERROR(INDEX(Meilensteine!$G$2:$G$26,MATCH(SMALL(Meilensteine!$L$2:$L$26,3),Meilensteine!$L$2:$L$26,0)),"") | F28: =WORKDAY(DATE(2026,11,2),-5)-TODAY() | G28: =WORKDAY(DATE(2026,11,2),-5)
B29: =IFERROR(INT(SMALL(Meilensteine!$L$2:$L$26,4)),"") | C29: =IFERROR(INDEX(Meilensteine!$B$2:$B$26,MATCH(SMALL(Meilensteine!$L$2:$L$26,4),Meilensteine!$L$2:$L$26,0)),"") | E29: =IFERROR(INDEX(Meilensteine!$G$2:$G$26,MATCH(SMALL(Meilensteine!$L$2:$L$26,4),Meilensteine!$L$2:$L$26,0)),"") | F29: =WORKDAY(DATE(2026,12,11),-5)-TODAY() | G29: =WORKDAY(DATE(2026,12,11),-5)
B30: =IFERROR(INT(SMALL(Meilensteine!$L$2:$L$26,5)),"") | C30: =IFERROR(INDEX(Meilensteine!$B$2:$B$26,MATCH(SMALL(Meilensteine!$L$2:$L$26,5),Meilensteine!$L$2:$L$26,0)),"") | E30: =IFERROR(INDEX(Meilensteine!$G$2:$G$26,MATCH(SMALL(Meilensteine!$L$2:$L$26,5),Meilensteine!$L$2:$L$26,0)),"")
E31: offen gesamt | F31: =COUNTIFS(Aenderungslog[Typ],"Entscheid",Aenderungslog[Status],"offen")
B32: Werte aktualisieren sich automatisch. Farben: gruen=ok, gelb=in Arbeit, orange=Achtung, rot=kritisch. | E32: davon ueberfaellig | F32: =SUMPRODUCT((Aenderungslog[Typ]="Entscheid")*(Aenderungslog[Status]="offen")*(Aenderungslog[Termin]<>"")*(Aenderungslog[Termin]<TODAY()))
B34: OFFENE AUFGABEN JE OWNER
B35: Owner | C35: offen
B36: Burak | C36: =SUMPRODUCT(--ISNUMBER(SEARCH($B36,Aufgaben[Owner])),--(Aufgaben[Status]<>"erledigt"))
B37: Stefan | C37: =SUMPRODUCT(--ISNUMBER(SEARCH($B37,Aufgaben[Owner])),--(Aufgaben[Status]<>"erledigt"))
B38: Markus | C38: =SUMPRODUCT(--ISNUMBER(SEARCH($B38,Aufgaben[Owner])),--(Aufgaben[Status]<>"erledigt"))
B39: Ann-Kathrin | C39: =SUMPRODUCT(--ISNUMBER(SEARCH($B39,Aufgaben[Owner])),--(Aufgaben[Status]<>"erledigt"))
B40: Sarah | C40: =SUMPRODUCT(--ISNUMBER(SEARCH($B40,Aufgaben[Owner])),--(Aufgaben[Status]<>"erledigt"))
B41: Samuel | C41: =SUMPRODUCT(--ISNUMBER(SEARCH($B41,Aufgaben[Owner])),--(Aufgaben[Status]<>"erledigt"))
B42: Stephan | C42: =SUMPRODUCT(--ISNUMBER(SEARCH($B42,Aufgaben[Owner])),--(Aufgaben[Status]<>"erledigt"))
...

Sheet Wochenbericht
B2: WOCHENBERICHT
B3: MiT-PWR-WIN-2026-001 | DPR Construction / Vantage ZRH12 Winterthur
B4: ="Berichtswoche: KW "&WEEKNUM(TODAY(),21)&" | Stand: "&TEXT(TODAY(),"DD.MM.YYYY")&" | PL: Burak Uecoez"
B6: =IF(SUMPRODUCT((Aufgaben[Status]<>"erledigt")*(Aufgaben[Termin]<>"")*(Aufgaben[Termin]<TODAY()))>0,"KRITISCH - ueberfaellige Aufgaben",IF(COUNTIF(Meilensteine[Status],"kritisch")+COUNTIF(Aufgaben[Status],"kritisch")>0,"ACHTUNG - kritische Punkte offen","AUF KURS - keine Ueberfaelligkeiten"))
B8: KENNZAHLEN
B9: Aufgaben offen | D9: =COUNTIF(Aufgaben[Status],"offen")
B10: in Arbeit | D10: =COUNTIF(Aufgaben[Status],"in Arbeit")
B11: erledigt (gesamt) | D11: =COUNTIF(Aufgaben[Status],"erledigt")
B12: kritisch | D12: =COUNTIF(Aufgaben[Status],"kritisch")
B13: ueberfaellig | D13: =SUMPRODUCT((Aufgaben[Status]<>"erledigt")*(Aufgaben[Termin]<>"")*(Aufgaben[Termin]<TODAY()))
B14: davon diese Woche erledigt | D14: =COUNTIFS(Aufgaben[Erledigt am],">="&(TODAY()-7),Aufgaben[Erledigt am],"<="&TODAY())
B16: NAECHSTE 5 MEILENSTEINE
B17: Plantermin | C17: Meilenstein | D17: Status
B18: =IFERROR(INT(SMALL(Meilensteine!$L$2:$L$26,1)),"") | C18: =IFERROR(INDEX(Meilensteine!$B$2:$B$26,MATCH(SMALL(Meilensteine!$L$2:$L$26,1),Meilensteine!$L$2:$L$26,0)),"") | D18: =IFERROR(INDEX(Meilensteine!$G$2:$G$26,MATCH(SMALL(Meilensteine!$L$2:$L$26,1),Meilensteine!$L$2:$L$26,0)),"")
B19: =IFERROR(INT(SMALL(Meilensteine!$L$2:$L$26,2)),"") | C19: =IFERROR(INDEX(Meilensteine!$B$2:$B$26,MATCH(SMALL(Meilensteine!$L$2:$L$26,2),Meilensteine!$L$2:$L$26,0)),"") | D19: =IFERROR(INDEX(Meilensteine!$G$2:$G$26,MATCH(SMALL(Meilensteine!$L$2:$L$26,2),Meilensteine!$L$2:$L$26,0)),"")
B20: =IFERROR(INT(SMALL(Meilensteine!$L$2:$L$26,3)),"") | C20: =IFERROR(INDEX(Meilensteine!$B$2:$B$26,MATCH(SMALL(Meilensteine!$L$2:$L$26,3),Meilensteine!$L$2:$L$26,0)),"") | D20: =IFERROR(INDEX(Meilensteine!$G$2:$G$26,MATCH(SMALL(Meilensteine!$L$2:$L$26,3),Meilensteine!$L$2:$L$26,0)),"")
B21: =IFERROR(INT(SMALL(Meilensteine!$L$2:$L$26,4)),"") | C21: =IFERROR(INDEX(Meilensteine!$B$2:$B$26,MATCH(SMALL(Meilensteine!$L$2:$L$26,4),Meilensteine!$L$2:$L$26,0)),"") | D21: =IFERROR(INDEX(Meilensteine!$G$2:$G$26,MATCH(SMALL(Meilensteine!$L$2:$L$26,4),Meilensteine!$L$2:$L$26,0)),"")
B22: =IFERROR(INT(SMALL(Meilensteine!$L$2:$L$26,5)),"") | C22: =IFERROR(INDEX(Meilensteine!$B$2:$B$26,MATCH(SMALL(Meilensteine!$L$2:$L$26,5),Meilensteine!$L$2:$L$26,0)),"") | D22: =IFERROR(INDEX(Meilensteine!$G$2:$G$26,MATCH(SMALL(Meilensteine!$L$2:$L$26,5),Meilensteine!$L$2:$L$26,0)),"")
B24: OFFENE STOPP-PUNKTE & RISIKEN (Auswirkung hoch)
B25: =IFERROR(INDEX('Stopp-Punkte & Risiken'!$C$1:$C$50,SMALL('Stopp-Punkte & Risiken'!$K$2:$K$40,1))&" ["&INDEX('Stopp-Punkte & Risiken'!$F$1:$F$50,SMALL('Stopp-Punkte & Risiken'!$K$2:$K$40,1))&", bis "&TEXT(INDEX('Stopp-Punkte & Risiken'!$G$1:$G$50,SMALL('Stopp-Punkte & Risiken'!$K$2:$K$40,1)),"DD.MM.")&"]","")
B26: =IFERROR(INDEX('Stopp-Punkte & Risiken'!$C$1:$C$50,SMALL('Stopp-Punkte & Risiken'!$K$2:$K$40,2))&" ["&INDEX('Stopp-Punkte & Risiken'!$F$1:$F$50,SMALL('Stopp-Punkte & Risiken'!$K$2:$K$40,2))&", bis "&TEXT(INDEX('Stopp-Punkte & Risiken'!$G$1:$G$50,SMALL('Stopp-Punkte & Risiken'!$K$2:$K$40,2)),"DD.MM.")&"]","")
B27: =IFERROR(INDEX('Stopp-Punkte & Risiken'!$C$1:$C$50,SMALL('Stopp-Punkte & Risiken'!$K$2:$K$40,3))&" ["&INDEX('Stopp-Punkte & Risiken'!$F$1:$F$50,SMALL('Stopp-Punkte & Risiken'!$K$2:$K$40,3))&", bis "&TEXT(INDEX('Stopp-Punkte & Risiken'!$G$1:$G$50,SMALL('Stopp-Punkte & Risiken'!$K$2:$K$40,3)),"DD.MM.")&"]","")
B28: =IFERROR(INDEX('Stopp-Punkte & Risiken'!$C$1:$C$50,SMALL('Stopp-Punkte & Risiken'!$K$2:$K$40,4))&" ["&INDEX('Stopp-Punkte & Risiken'!$F$1:$F$50,SMALL('Stopp-Punkte & Risiken'!$K$2:$K$40,4))&", bis "&TEXT(INDEX('Stopp-Punkte & Risiken'!$G$1:$G$50,SMALL('Stopp-Punkte & Risiken'!$K$2:$K$40,4)),"DD.MM.")&"]","")
B29: =IFERROR(INDEX('Stopp-Punkte & Risiken'!$C$1:$C$50,SMALL('Stopp-Punkte & Risiken'!$K$2:$K$40,5))&" ["&INDEX('Stopp-Punkte & Risiken'!$F$1:$F$50,SMALL('Stopp-Punkte & Risiken'!$K$2:$K$40,5))&", bis "&TEXT(INDEX('Stopp-Punkte & Risiken'!$G$1:$G$50,SMALL('Stopp-Punkte & Risiken'!$K$2:$K$40,5)),"DD.MM.")&"]","")
B30: =IFERROR(INDEX('Stopp-Punkte & Risiken'!$C$1:$C$50,SMALL('Stopp-Punkte & Risiken'!$K$2:$K$40,6))&" ["&INDEX('Stopp-Punkte & Risiken'!$F$1:$F$50,SMALL('Stopp-Punkte & Risiken'!$K$2:$K$40,6))&", bis "&TEXT(INDEX('Stopp-Punkte & Risiken'!$G$1:$G$50,SMALL('Stopp-Punkte & Risiken'!$K$2:$K$40,6)),"DD.MM.")&"]","")
B32: OFFENE ENTSCHEIDE
B33: =IFERROR(INDEX('Aenderungslog & Entscheide'!$D$1:$D$60,SMALL('Aenderungslog & Entscheide'!$H$2:$H$40,1))&" ["&INDEX('Aenderungslog & Entscheide'!$B$1:$B$60,SMALL('Aenderungslog & Entscheide'!$H$2:$H$40,1))&"]","")
B34: =IFERROR(INDEX('Aenderungslog & Entscheide'!$D$1:$D$60,SMALL('Aenderungslog & Entscheide'!$H$2:$H$40,2))&" ["&INDEX('Aenderungslog & Entscheide'!$B$1:$B$60,SMALL('Aenderungslog & Entscheide'!$H$2:$H$40,2))&"]","")
B35: =IFERROR(INDEX('Aenderungslog & Entscheide'!$D$1:$D$60,SMALL('Aenderungslog & Entscheide'!$H$2:$H$40,3))&" ["&INDEX('Aenderungslog & Entscheide'!$B$1:$B$60,SMALL('Aenderungslog & Entscheide'!$H$2:$H$40,3))&"]","")
B36: =IFERROR(INDEX('Aenderungslog & Entscheide'!$D$1:$D$60,SMALL('Aenderungslog & Entscheide'!$H$2:$H$40,4))&" ["&INDEX('Aenderungslog & Entscheide'!$B$1:$B$60,SMALL('Aenderungslog & Entscheide'!$H$2:$H$40,4))&"]","")
B38: OFF-HIRE-FRISTEN
B39: ="Loadbank: Off-Hire melden bis "&TEXT(WORKDAY(DATE(2026,11,2),-5),"DD.MM.YYYY")&" (noch "&(WORKDAY(DATE(2026,11,2),-5)-TODAY())&" Tage)"
B40: ="Headloads: Off-Hire melden bis "&TEXT(WORKDAY(DATE(2026,12,11),-5),"DD.MM.YYYY")&" (noch "&(WORKDAY(DATE(2026,12,11),-5)-TODAY())&" Tage)"
B42: FORTSCHRITT DIESE WOCHE (manuell ausfuellen)
B48: PROBLEME & NAECHSTE SCHRITTE (manuell ausfuellen)
B54: Als PDF exportieren (Datei > Exportieren) und an DPR senden. Enthaelt KEINE EUR-Einkaufspreise.

Sheet Terminplan
A1: TERMINPLAN 2026 - Wochenraster (KW 29-53)
A2: Nr. | B2: Phase / Meilenstein | C2: Start / Termin | D2: Ende / Status | E2: KW29 | F2: KW30 | G2: KW31 | H2: KW32 | I2: KW33 | J2: KW34 | K2: KW35 | L2: KW36 | M2: KW37 | N2: KW38 | O2: KW39 | P2: KW40 | Q2: KW41 | R2: KW42 | S2: KW43 | T2: KW44 | U2: KW45 | V2: KW46 | W2: KW47 | X2: KW48 | Y2: KW49 | Z2: KW50 | AA2: KW51 | AB2: KW52 | AC2: KW53
E3: 46216 | F3: 46223 | G3: 46230 | H3: 46237 | I3: 46244 | J3: 46251 | K3: 46258 | L3: 46265 | M3: 46272 | N3: 46279 | O3: 46286 | P3: 46293 | Q3: 46300 | R3: 46307 | S3: 46314 | T3: 46321 | U3: 46328 | V3: 46335 | W3: 46342 | X3: 46349 | Y3: 46356 | Z3: 46363 | AA3: 46370 | AB3: 46377 | AC3: 46384
A4: 1 | B4: Vertraege & Compliance | C4: 46219 | D4: 46231
A5: 2 | B5: Projektvorbereitung & Mobilisierung | C5: 46219 | D5: 46237
A6: 3 | B6: Heat-Load (Headloads) - Miete | C6: 46237 | D6: 46367
A7: 4 | B7: Loadbank 6 MVA - Miete | C7: 46251 | D7: 46328
A8: 5 | B8: Testphase / Inbetriebnahme | C8: 46237 | D8: 46328
A9: 6 | B9: 3-MW-Block (Abruf) | C9: 46248 | D9: 46272
A10: 7 | B10: 5-MW-Block (Abruf) | C10: 46273 | D10: 46295
A11: 8 | B11: Demontage | C11: 46370 | D11: 46370
A12: 9 | B12: Closeout & Dokumentation | C12: 46356 | D12: 46387
A14: MEILENSTEINE (◆ = Termin in dieser Woche)
A15: =Meilensteine!$A$2 | B15: =Meilensteine!$B$2 | C15: =Meilensteine!$D$2 | D15: =Meilensteine!$G$2 | E15: =IF(AND(Meilensteine!$D$2>=E$3,Meilensteine!$D$2<E$3+7),"◆","") | F15: =IF(AND(Meilensteine!$D$2>=F$3,Meilensteine!$D$2<F$3+7),"◆","") | G15: =IF(AND(Meilensteine!$D$2>=G$3,Meilensteine!$D$2<G$3+7),"◆","") | H15: =IF(AND(Meilensteine!$D$2>=H$3,Meilensteine!$D$2<H$3+7),"◆","") | I15: =IF(AND(Meilensteine!$D$2>=I$3,Meilensteine!$D$2<I$3+7),"◆","") | J15: =IF(AND(Meilensteine!$D$2>=J$3,Meilensteine!$D$2<J$3+7),"◆","") | K15: =IF(AND(Meilensteine!$D$2>=K$3,Meilensteine!$D$2<K$3+7),"◆","") | L15: =IF(AND(Meilensteine!$D$2>=L$3,Meilensteine!$D$2<L$3+7),"◆","") | ... AC15: =IF(AND(Meilensteine!$D$2>=AC$3,Meilensteine!$D$2<AC$3+7),"◆","")
A16: =Meilensteine!$A$3 | B16: =Meilensteine!$B$3 | C16: =Meilensteine!$D$3 | D16: =Meilensteine!$G$3 | E16: =IF(AND(Meilensteine!$D$3>=E$3,Meilensteine!$D$3<E$3+7),"◆","") | F16: =IF(AND(Meilensteine!$D$3>=F$3,Meilensteine!$D$3<F$3+7),"◆","") | G16: =IF(AND(Meilensteine!$D$3>=G$3,Meilensteine!$D$3<G$3+7),"◆","") | H16: =IF(AND(Meilensteine!$D$3>=H$3,Meilensteine!$D$3<H$3+7),"◆","") | I16: =IF(AND(Meilensteine!$D$3>=I$3,Meilensteine!$D$3<I$3+7),"◆","") | J16: =IF(AND(Meilensteine!$D$3>=J$3,Meilensteine!$D$3<J$3+7),"◆","") | K16: =IF(AND(Meilensteine!$D$3>=K$3,Meilensteine!$D$3<K$3+7),"◆","") | L16: =IF(AND(Meilensteine!$D$3>=L$3,Meilensteine!$D$3<L$3+7),"◆","") | ... AC16: =IF(AND(Meilensteine!$D$3>=AC$3,Meilensteine!$D$3<AC$3+7),"◆","")
A17: =Meilensteine!$A$4 | B17: =Meilensteine!$B$4 | C17: =Meilensteine!$D$4 | D17: =Meilensteine!$G$4 | E17: =IF(AND(Meilensteine!$D$4>=E$3,Meilensteine!$D$4<E$3+7),"◆","") | F17: =IF(AND(Meilensteine!$D$4>=F$3,Meilensteine!$D$4<F$3+7),"◆","") | G17: =IF(AND(Meilensteine!$D$4>=G$3,Meilensteine!$D$4<G$3+7),"◆","") | H17: =IF(AND(Meilensteine!$D$4>=H$3,Meilensteine!$D$4<H$3+7),"◆","") | I17: =IF(AND(Meilensteine!$D$4>=I$3,Meilensteine!$D$4<I$3+7),"◆","") | J17: =IF(AND(Meilensteine!$D$4>=J$3,Meilensteine!$D$4<J$3+7),"◆","") | K17: =IF(AND(Meilensteine!$D$4>=K$3,Meilensteine!$D$4<K$3+7),"◆","") | L17: =IF(AND(Meilensteine!$D$4>=L$3,Meilensteine!$D$4<L$3+7),"◆","") | ... AC17: =IF(AND(Meilensteine!$D$4>=AC$3,Meilensteine!$D$4<AC$3+7),"◆","")
A18: =Meilensteine!$A$5 | B18: =Meilensteine!$B$5 | C18: =Meilensteine!$D$5 | D18: =Meilensteine!$G$5 | E18: =IF(AND(Meilensteine!$D$5>=E$3,Meilensteine!$D$5<E$3+7),"◆","") | F18: =IF(AND(Meilensteine!$D$5>=F$3,Meilensteine!$D$5<F$3+7),"◆","") | G18: =IF(AND(Meilensteine!$D$5>=G$3,Meilensteine!$D$5<G$3+7),"◆","") | H18: =IF(AND(Meilensteine!$D$5>=H$3,Meilensteine!$D$5<H$3+7),"◆","") | I18: =IF(AND(Meilensteine!$D$5>=I$3,Meilensteine!$D$5<I$3+7),"◆","") | J18: =IF(AND(Meilensteine!$D$5>=J$3,Meilensteine!$D$5<J$3+7),"◆","") | K18: =IF(AND(Meilensteine!$D$5>=K$3,Meilensteine!$D$5<K$3+7),"◆","") | L18: =IF(AND(Meilensteine!$D$5>=L$3,Meilensteine!$D$5<L$3+7),"◆","") | ... AC18: =IF(AND(Meilensteine!$D$5>=AC$3,Meilensteine!$D$5<AC$3+7),"◆","")
A19: =Meilensteine!$A$6 | B19: =Meilensteine!$B$6 | C19: =Meilensteine!$D$6 | D19: =Meilensteine!$G$6 | E19: =IF(AND(Meilensteine!$D$6>=E$3,Meilensteine!$D$6<E$3+7),"◆","") | F19: =IF(AND(Meilensteine!$D$6>=F$3,Meilensteine!$D$6<F$3+7),"◆","") | G19: =IF(AND(Meilensteine!$D$6>=G$3,Meilensteine!$D$6<G$3+7),"◆","") | H19: =IF(AND(Meilensteine!$D$6>=H$3,Meilensteine!$D$6<H$3+7),"◆","") | I19: =IF(AND(Meilensteine!$D$6>=I$3,Meilensteine!$D$6<I$3+7),"◆","") | J19: =IF(AND(Meilensteine!$D$6>=J$3,Meilensteine!$D$6<J$3+7),"◆","") | K19: =IF(AND(Meilensteine!$D$6>=K$3,Meilensteine!$D$6<K$3+7),"◆","") | L19: =IF(AND(Meilensteine!$D$6>=L$3,Meilensteine!$D$6<L$3+7),"◆","") | ... AC19: =IF(AND(Meilensteine!$D$6>=AC$3,Meilensteine!$D$6<AC$3+7),"◆","")
A20: =Meilensteine!$A$7 | B20: =Meilensteine!$B$7 | C20: =Meilensteine!$D$7 | D20: =Meilensteine!$G$7 | E20: =IF(AND(Meilensteine!$D$7>=E$3,Meilensteine!$D$7<E$3+7),"◆","") | F20: =IF(AND(Meilensteine!$D$7>=F$3,Meilensteine!$D$7<F$3+7),"◆","") | G20: =IF(AND(Meilensteine!$D$7>=G$3,Meilensteine!$D$7<G$3+7),"◆","") | H20: =IF(AND(Meilensteine!$D$7>=H$3,Meilensteine!$D$7<H$3+7),"◆","") | I20: =IF(AND(Meilensteine!$D$7>=I$3,Meilensteine!$D$7<I$3+7),"◆","") | J20: =IF(AND(Meilensteine!$D$7>=J$3,Meilensteine!$D$7<J$3+7),"◆","") | K20: =IF(AND(Meilensteine!$D$7>=K$3,Meilensteine!$D$7<K$3+7),"◆","") | L20: =IF(AND(Meilensteine!$D$7>=L$3,Meilensteine!$D$7<L$3+7),"◆","") | ... AC20: =IF(AND(Meilensteine!$D$7>=AC$3,Meilensteine!$D$7<AC$3+7),"◆","")
A21: =Meilensteine!$A$8 | B21: =Meilensteine!$B$8 | C21: =Meilensteine!$D$8 | D21: =Meilensteine!$G$8 | E21: =IF(AND(Meilensteine!$D$8>=E$3,Meilensteine!$D$8<E$3+7),"◆","") | F21: =IF(AND(Meilensteine!$D$8>=F$3,Meilensteine!$D$8<F$3+7),"◆","") | G21: =IF(AND(Meilensteine!$D$8>=G$3,Meilensteine!$D$8<G$3+7),"◆","") | H21: =IF(AND(Meilensteine!$D$8>=H$3,Meilensteine!$D$8<H$3+7),"◆","") | I21: =IF(AND(Meilensteine!$D$8>=I$3,Meilensteine!$D$8<I$3+7),"◆","") | J21: =IF(AND(Meilensteine!$D$8>=J$3,Meilensteine!$D$8<J$3+7),"◆","") | K21: =IF(AND(Meilensteine!$D$8>=K$3,Meilensteine!$D$8<K$3+7),"◆","") | L21: =IF(AND(Meilensteine!$D$8>=L$3,Meilensteine!$D$8<L$3+7),"◆","") | ... AC21: =IF(AND(Meilensteine!$D$8>=AC$3,Meilensteine!$D$8<AC$3+7),"◆","")
A22: =Meilensteine!$A$9 | B22: =Meilensteine!$B$9 | C22: =Meilensteine!$D$9 | D22: =Meilensteine!$G$9 | E22: =IF(AND(Meilensteine!$D$9>=E$3,Meilensteine!$D$9<E$3+7),"◆","") | F22: =IF(AND(Meilensteine!$D$9>=F$3,Meilensteine!$D$9<F$3+7),"◆","") | G22: =IF(AND(Meilensteine!$D$9>=G$3,Meilensteine!$D$9<G$3+7),"◆","") | H22: =IF(AND(Meilensteine!$D$9>=H$3,Meilensteine!$D$9<H$3+7),"◆","") | I22: =IF(AND(Meilensteine!$D$9>=I$3,Meilensteine!$D$9<I$3+7),"◆","") | J22: =IF(AND(Meilensteine!$D$9>=J$3,Meilensteine!$D$9<J$3+7),"◆","") | K22: =IF(AND(Meilensteine!$D$9>=K$3,Meilensteine!$D$9<K$3+7),"◆","") | L22: =IF(AND(Meilensteine!$D$9>=L$3,Meilensteine!$D$9<L$3+7),"◆","") | ... AC22: =IF(AND(Meilensteine!$D$9>=AC$3,Meilensteine!$D$9<AC$3+7),"◆","")
A23: =Meilensteine!$A$10 | B23: =Meilensteine!$B$10 | C23: =Meilensteine!$D$10 | D23: =Meilensteine!$G$10 | E23: =IF(AND(Meilensteine!$D$10>=E$3,Meilensteine!$D$10<E$3+7),"◆","") | F23: =IF(AND(Meilensteine!$D$10>=F$3,Meilensteine!$D$10<F$3+7),"◆","") | G23: =IF(AND(Meilensteine!$D$10>=G$3,Meilensteine!$D$10<G$3+7),"◆","") | H23: =IF(AND(Meilensteine!$D$10>=H$3,Meilensteine!$D$10<H$3+7),"◆","") | I23: =IF(AND(Meilensteine!$D$10>=I$3,Meilensteine!$D$10<I$3+7),"◆","") | J23: =IF(AND(Meilensteine!$D$10>=J$3,Meilensteine!$D$10<J$3+7),"◆","") | K23: =IF(AND(Meilensteine!$D$10>=K$3,Meilensteine!$D$10<K$3+7),"◆","") | L23: =IF(AND(Meilensteine!$D$10>=L$3,Meilensteine!$D$10<L$3+7),"◆","") | ... AC23: =IF(AND(Meilensteine!$D$10>=AC$3,Meilensteine!$D$10<AC$3+7),"◆","")
A24: =Meilensteine!$A$11 | B24: =Meilensteine!$B$11 | C24: =Meilensteine!$D$11 | D24: =Meilensteine!$G$11 | E24: =IF(AND(Meilensteine!$D$11>=E$3,Meilensteine!$D$11<E$3+7),"◆","") | F24: =IF(AND(Meilensteine!$D$11>=F$3,Meilensteine!$D$11<F$3+7),"◆","") | G24: =IF(AND(Meilensteine!$D$11>=G$3,Meilensteine!$D$11<G$3+7),"◆","") | H24: =IF(AND(Meilensteine!$D$11>=H$3,Meilensteine!$D$11<H$3+7),"◆","") | I24: =IF(AND(Meilensteine!$D$11>=I$3,Meilensteine!$D$11<I$3+7),"◆","") | J24: =IF(AND(Meilensteine!$D$11>=J$3,Meilensteine!$D$11<J$3+7),"◆","") | K24: =IF(AND(Meilensteine!$D$11>=K$3,Meilensteine!$D$11<K$3+7),"◆","") | L24: =IF(AND(Meilensteine!$D$11>=L$3,Meilensteine!$D$11<L$3+7),"◆","") | ... AC24: =IF(AND(Meilensteine!$D$11>=AC$3,Meilensteine!$D$11<AC$3+7),"◆","")
A25: =Meilensteine!$A$12 | B25: =Meilensteine!$B$12 | C25: =Meilensteine!$D$12 | D25: =Meilensteine!$G$12 | E25: =IF(AND(Meilensteine!$D$12>=E$3,Meilensteine!$D$12<E$3+7),"◆","") | F25: =IF(AND(Meilensteine!$D$12>=F$3,Meilensteine!$D$12<F$3+7),"◆","") | G25: =IF(AND(Meilensteine!$D$12>=G$3,Meilensteine!$D$12<G$3+7),"◆","") | H25: =IF(AND(Meilensteine!$D$12>=H$3,Meilensteine!$D$12<H$3+7),"◆","") | I25: =IF(AND(Meilensteine!$D$12>=I$3,Meilensteine!$D$12<I$3+7),"◆","") | J25: =IF(AND(Meilensteine!$D$12>=J$3,Meilensteine!$D$12<J$3+7),"◆","") | K25: =IF(AND(Meilensteine!$D$12>=K$3,Meilensteine!$D$12<K$3+7),"◆","") | L25: =IF(AND(Meilensteine!$D$12>=L$3,Meilensteine!$D$12<L$3+7),"◆","") | ... AC25: =IF(AND(Meilensteine!$D$12>=AC$3,Meilensteine!$D$12<AC$3+7),"◆","")
A26: =Meilensteine!$A$13 | B26: =Meilensteine!$B$13 | C26: =Meilensteine!$D$13 | D26: =Meilensteine!$G$13 | E26: =IF(AND(Meilensteine!$D$13>=E$3,Meilensteine!$D$13<E$3+7),"◆","") | F26: =IF(AND(Meilensteine!$D$13>=F$3,Meilensteine!$D$13<F$3+7),"◆","") | G26: =IF(AND(Meilensteine!$D$13>=G$3,Meilensteine!$D$13<G$3+7),"◆","") | H26: =IF(AND(Meilensteine!$D$13>=H$3,Meilensteine!$D$13<H$3+7),"◆","") | I26: =IF(AND(Meilensteine!$D$13>=I$3,Meilensteine!$D$13<I$3+7),"◆","") | J26: =IF(AND(Meilensteine!$D$13>=J$3,Meilensteine!$D$13<J$3+7),"◆","") | K26: =IF(AND(Meilensteine!$D$13>=K$3,Meilensteine!$D$13<K$3+7),"◆","") | L26: =IF(AND(Meilensteine!$D$13>=L$3,Meilensteine!$D$13<L$3+7),"◆","") | ... AC26: =IF(AND(Meilensteine!$D$13>=AC$3,Meilensteine!$D$13<AC$3+7),"◆","")
A27: =Meilensteine!$A$14 | B27: =Meilensteine!$B$14 | C27: =Meilensteine!$D$14 | D27: =Meilensteine!$G$14 | E27: =IF(AND(Meilensteine!$D$14>=E$3,Meilensteine!$D$14<E$3+7),"◆","") | F27: =IF(AND(Meilensteine!$D$14>=F$3,Meilensteine!$D$14<F$3+7),"◆","") | G27: =IF(AND(Meilensteine!$D$14>=G$3,Meilensteine!$D$14<G$3+7),"◆","") | H27: =IF(AND(Meilensteine!$D$14>=H$3,Meilensteine!$D$14<H$3+7),"◆","") | I27: =IF(AND(Meilensteine!$D$14>=I$3,Meilensteine!$D$14<I$3+7),"◆","") | J27: =IF(AND(Meilensteine!$D$14>=J$3,Meilensteine!$D$14<J$3+7),"◆","") | K27: =IF(AND(Meilensteine!$D$14>=K$3,Meilensteine!$D$14<K$3+7),"◆","") | L27: =IF(AND(Meilensteine!$D$14>=L$3,Meilensteine!$D$14<L$3+7),"◆","") | ... AC27: =IF(AND(Meilensteine!$D$14>=AC$3,Meilensteine!$D$14<AC$3+7),"◆","")
A28: =Meilensteine!$A$15 | B28: =Meilensteine!$B$15 | C28: =Meilensteine!$D$15 | D28: =Meilensteine!$G$15 | E28: =IF(AND(Meilensteine!$D$15>=E$3,Meilensteine!$D$15<E$3+7),"◆","") | F28: =IF(AND(Meilensteine!$D$15>=F$3,Meilensteine!$D$15<F$3+7),"◆","") | G28: =IF(AND(Meilensteine!$D$15>=G$3,Meilensteine!$D$15<G$3+7),"◆","") | H28: =IF(AND(Meilensteine!$D$15>=H$3,Meilensteine!$D$15<H$3+7),"◆","") | I28: =IF(AND(Meilensteine!$D$15>=I$3,Meilensteine!$D$15<I$3+7),"◆","") | J28: =IF(AND(Meilensteine!$D$15>=J$3,Meilensteine!$D$15<J$3+7),"◆","") | K28: =IF(AND(Meilensteine!$D$15>=K$3,Meilensteine!$D$15<K$3+7),"◆","") | L28: =IF(AND(Meilensteine!$D$15>=L$3,Meilensteine!$D$15<L$3+7),"◆","") | ... AC28: =IF(AND(Meilensteine!$D$15>=AC$3,Meilensteine!$D$15<AC$3+7),"◆","")
A29: =Meilensteine!$A$16 | B29: =Meilensteine!$B$16 | C29: =Meilensteine!$D$16 | D29: =Meilensteine!$G$16 | E29: =IF(AND(Meilensteine!$D$16>=E$3,Meilensteine!$D$16<E$3+7),"◆","") | F29: =IF(AND(Meilensteine!$D$16>=F$3,Meilensteine!$D$16<F$3+7),"◆","") | G29: =IF(AND(Meilensteine!$D$16>=G$3,Meilensteine!$D$16<G$3+7),"◆","") | H29: =IF(AND(Meilensteine!$D$16>=H$3,Meilensteine!$D$16<H$3+7),"◆","") | I29: =IF(AND(Meilensteine!$D$16>=I$3,Meilensteine!$D$16<I$3+7),"◆","") | J29: =IF(AND(Meilensteine!$D$16>=J$3,Meilensteine!$D$16<J$3+7),"◆","") | K29: =IF(AND(Meilensteine!$D$16>=K$3,Meilensteine!$D$16<K$3+7),"◆","") | L29: =IF(AND(Meilensteine!$D$16>=L$3,Meilensteine!$D$16<L$3+7),"◆","") | ... AC29: =IF(AND(Meilensteine!$D$16>=AC$3,Meilensteine!$D$16<AC$3+7),"◆","")
A30: =Meilensteine!$A$17 | B30: =Meilensteine!$B$17 | C30: =Meilensteine!$D$17 | D30: =Meilensteine!$G$17 | E30: =IF(AND(Meilensteine!$D$17>=E$3,Meilensteine!$D$17<E$3+7),"◆","") | F30: =IF(AND(Meilensteine!$D$17>=F$3,Meilensteine!$D$17<F$3+7),"◆","") | G30: =IF(AND(Meilensteine!$D$17>=G$3,Meilensteine!$D$17<G$3+7),"◆","") | H30: =IF(AND(Meilensteine!$D$17>=H$3,Meilensteine!$D$17<H$3+7),"◆","") | I30: =IF(AND(Meilensteine!$D$17>=I$3,Meilensteine!$D$17<I$3+7),"◆","") | J30: =IF(AND(Meilensteine!$D$17>=J$3,Meilensteine!$D$17<J$3+7),"◆","") | K30: =IF(AND(Meilensteine!$D$17>=K$3,Meilensteine!$D$17<K$3+7),"◆","") | L30: =IF(AND(Meilensteine!$D$17>=L$3,Meilensteine!$D$17<L$3+7),"◆","") | ... AC30: =IF(AND(Meilensteine!$D$17>=AC$3,Meilensteine!$D$17<AC$3+7),"◆","")
A31: =Meilensteine!$A$18 | B31: =Meilensteine!$B$18 | C31: =Meilensteine!$D$18 | D31: =Meilensteine!$G$18 | E31: =IF(AND(Meilensteine!$D$18>=E$3,Meilensteine!$D$18<E$3+7),"◆","") | F31: =IF(AND(Meilensteine!$D$18>=F$3,Meilensteine!$D$18<F$3+7),"◆","") | G31: =IF(AND(Meilensteine!$D$18>=G$3,Meilensteine!$D$18<G$3+7),"◆","") | H31: =IF(AND(Meilensteine!$D$18>=H$3,Meilensteine!$D$18<H$3+7),"◆","") | I31: =IF(AND(Meilensteine!$D$18>=I$3,Meilensteine!$D$18<I$3+7),"◆","") | J31: =IF(AND(Meilensteine!$D$18>=J$3,Meilensteine!$D$18<J$3+7),"◆","") | K31: =IF(AND(Meilensteine!$D$18>=K$3,Meilensteine!$D$18<K$3+7),"◆","") | L31: =IF(AND(Meilensteine!$D$18>=L$3,Meilensteine!$D$18<L$3+7),"◆","") | ... AC31: =IF(AND(Meilensteine!$D$18>=AC$3,Meilensteine!$D$18<AC$3+7),"◆","")
A32: =Meilensteine!$A$19 | B32: =Meilensteine!$B$19 | C32: =Meilensteine!$D$19 | D32: =Meilensteine!$G$19 | E32: =IF(AND(Meilensteine!$D$19>=E$3,Meilensteine!$D$19<E$3+7),"◆","") | F32: =IF(AND(Meilensteine!$D$19>=F$3,Meilensteine!$D$19<F$3+7),"◆","") | G32: =IF(AND(Meilensteine!$D$19>=G$3,Meilensteine!$D$19<G$3+7),"◆","") | H32: =IF(AND(Meilensteine!$D$19>=H$3,Meilensteine!$D$19<H$3+7),"◆","") | I32: =IF(AND(Meilensteine!$D$19>=I$3,Meilensteine!$D$19<I$3+7),"◆","") | J32: =IF(AND(Meilensteine!$D$19>=J$3,Meilensteine!$D$19<J$3+7),"◆","") | K32: =IF(AND(Meilensteine!$D$19>=K$3,Meilensteine!$D$19<K$3+7),"◆","") | L32: =IF(AND(Meilensteine!$D$19>=L$3,Meilensteine!$D$19<L$3+7),"◆","") | ... AC32: =IF(AND(Meilensteine!$D$19>=AC$3,Meilensteine!$D$19<AC$3+7),"◆","")
A33: =Meilensteine!$A$20 | B33: =Meilensteine!$B$20 | C33: =Meilensteine!$D$20 | D33: =Meilensteine!$G$20 | E33: =IF(AND(Meilensteine!$D$20>=E$3,Meilensteine!$D$20<E$3+7),"◆","") | F33: =IF(AND(Meilensteine!$D$20>=F$3,Meilensteine!$D$20<F$3+7),"◆","") | G33: =IF(AND(Meilensteine!$D$20>=G$3,Meilensteine!$D$20<G$3+7),"◆","") | H33: =IF(AND(Meilensteine!$D$20>=H$3,Meilensteine!$D$20<H$3+7),"◆","") | I33: =IF(AND(Meilensteine!$D$20>=I$3,Meilensteine!$D$20<I$3+7),"◆","") | J33: =IF(AND(Meilensteine!$D$20>=J$3,Meilensteine!$D$20<J$3+7),"◆","") | K33: =IF(AND(Meilensteine!$D$20>=K$3,Meilensteine!$D$20<K$3+7),"◆","") | L33: =IF(AND(Meilensteine!$D$20>=L$3,Meilensteine!$D$20<L$3+7),"◆","") | ... AC33: =IF(AND(Meilensteine!$D$20>=AC$3,Meilensteine!$D$20<AC$3+7),"◆","")
A34: =Meilensteine!$A$21 | B34: =Meilensteine!$B$21 | C34: =Meilensteine!$D$21 | D34: =Meilensteine!$G$21 | E34: =IF(AND(Meilensteine!$D$21>=E$3,Meilensteine!$D$21<E$3+7),"◆","") | F34: =IF(AND(Meilensteine!$D$21>=F$3,Meilensteine!$D$21<F$3+7),"◆","") | G34: =IF(AND(Meilensteine!$D$21>=G$3,Meilensteine!$D$21<G$3+7),"◆","") | H34: =IF(AND(Meilensteine!$D$21>=H$3,Meilensteine!$D$21<H$3+7),"◆","") | I34: =IF(AND(Meilensteine!$D$21>=I$3,Meilensteine!$D$21<I$3+7),"◆","") | J34: =IF(AND(Meilensteine!$D$21>=J$3,Meilensteine!$D$21<J$3+7),"◆","") | K34: =IF(AND(Meilensteine!$D$21>=K$3,Meilensteine!$D$21<K$3+7),"◆","") | L34: =IF(AND(Meilensteine!$D$21>=L$3,Meilensteine!$D$21<L$3+7),"◆","") | ... AC34: =IF(AND(Meilensteine!$D$21>=AC$3,Meilensteine!$D$21<AC$3+7),"◆","")
A35: =Meilensteine!$A$22 | B35: =Meilensteine!$B$22 | C35: =Meilensteine!$D$22 | D35: =Meilensteine!$G$22 | E35: =IF(AND(Meilensteine!$D$22>=E$3,Meilensteine!$D$22<E$3+7),"◆","") | F35: =IF(AND(Meilensteine!$D$22>=F$3,Meilensteine!$D$22<F$3+7),"◆","") | G35: =IF(AND(Meilensteine!$D$22>=G$3,Meilensteine!$D$22<G$3+7),"◆","") | H35: =IF(AND(Meilensteine!$D$22>=H$3,Meilensteine!$D$22<H$3+7),"◆","") | I35: =IF(AND(Meilensteine!$D$22>=I$3,Meilensteine!$D$22<I$3+7),"◆","") | J35: =IF(AND(Meilensteine!$D$22>=J$3,Meilensteine!$D$22<J$3+7),"◆","") | K35: =IF(AND(Meilensteine!$D$22>=K$3,Meilensteine!$D$22<K$3+7),"◆","") | L35: =IF(AND(Meilensteine!$D$22>=L$3,Meilensteine!$D$22<L$3+7),"◆","") | ... AC35: =IF(AND(Meilensteine!$D$22>=AC$3,Meilensteine!$D$22<AC$3+7),"◆","")
A36: =Meilensteine!$A$23 | B36: =Meilensteine!$B$23 | C36: =Meilensteine!$D$23 | D36: =Meilensteine!$G$23 | E36: =IF(AND(Meilensteine!$D$23>=E$3,Meilensteine!$D$23<E$3+7),"◆","") | F36: =IF(AND(Meilensteine!$D$23>=F$3,Meilensteine!$D$23<F$3+7),"◆","") | G36: =IF(AND(Meilensteine!$D$23>=G$3,Meilensteine!$D$23<G$3+7),"◆","") | H36: =IF(AND(Meilensteine!$D$23>=H$3,Meilensteine!$D$23<H$3+7),"◆","") | I36: =IF(AND(Meilensteine!$D$23>=I$3,Meilensteine!$D$23<I$3+7),"◆","") | J36: =IF(AND(Meilensteine!$D$23>=J$3,Meilensteine!$D$23<J$3+7),"◆","") | K36: =IF(AND(Meilensteine!$D$23>=K$3,Meilensteine!$D$23<K$3+7),"◆","") | L36: =IF(AND(Meilensteine!$D$23>=L$3,Meilensteine!$D$23<L$3+7),"◆","") | ... AC36: =IF(AND(Meilensteine!$D$23>=AC$3,Meilensteine!$D$23<AC$3+7),"◆","")
A37: =Meilensteine!$A$24 | B37: =Meilensteine!$B$24 | C37: =Meilensteine!$D$24 | D37: =Meilensteine!$G$24 | E37: =IF(AND(Meilensteine!$D$24>=E$3,Meilensteine!$D$24<E$3+7),"◆","") | F37: =IF(AND(Meilensteine!$D$24>=F$3,Meilensteine!$D$24<F$3+7),"◆","") | G37: =IF(AND(Meilensteine!$D$24>=G$3,Meilensteine!$D$24<G$3+7),"◆","") | H37: =IF(AND(Meilensteine!$D$24>=H$3,Meilensteine!$D$24<H$3+7),"◆","") | I37: =IF(AND(Meilensteine!$D$24>=I$3,Meilensteine!$D$24<I$3+7),"◆","") | J37: =IF(AND(Meilensteine!$D$24>=J$3,Meilensteine!$D$24<J$3+7),"◆","") | K37: =IF(AND(Meilensteine!$D$24>=K$3,Meilensteine!$D$24<K$3+7),"◆","") | L37: =IF(AND(Meilensteine!$D$24>=L$3,Meilensteine!$D$24<L$3+7),"◆","") | ... AC37: =IF(AND(Meilensteine!$D$24>=AC$3,Meilensteine!$D$24<AC$3+7),"◆","")
A38: =Meilensteine!$A$25 | B38: =Meilensteine!$B$25 | C38: =Meilensteine!$D$25 | D38: =Meilensteine!$G$25 | E38: =IF(AND(Meilensteine!$D$25>=E$3,Meilensteine!$D$25<E$3+7),"◆","") | F38: =IF(AND(Meilensteine!$D$25>=F$3,Meilensteine!$D$25<F$3+7),"◆","") | G38: =IF(AND(Meilensteine!$D$25>=G$3,Meilensteine!$D$25<G$3+7),"◆","") | H38: =IF(AND(Meilensteine!$D$25>=H$3,Meilensteine!$D$25<H$3+7),"◆","") | I38: =IF(AND(Meilensteine!$D$25>=I$3,Meilensteine!$D$25<I$3+7),"◆","") | J38: =IF(AND(Meilensteine!$D$25>=J$3,Meilensteine!$D$25<J$3+7),"◆","") | K38: =IF(AND(Meilensteine!$D$25>=K$3,Meilensteine!$D$25<K$3+7),"◆","") | L38: =IF(AND(Meilensteine!$D$25>=L$3,Meilensteine!$D$25<L$3+7),"◆","") | ... AC38: =IF(AND(Meilensteine!$D$25>=AC$3,Meilensteine!$D$25<AC$3+7),"◆","")
A39: =Meilensteine!$A$26 | B39: =Meilensteine!$B$26 | C39: =Meilensteine!$D$26 | D39: =Meilensteine!$G$26 | E39: =IF(AND(Meilensteine!$D$26>=E$3,Meilensteine!$D$26<E$3+7),"◆","") | F39: =IF(AND(Meilensteine!$D$26>=F$3,Meilensteine!$D$26<F$3+7),"◆","") | G39: =IF(AND(Meilensteine!$D$26>=G$3,Meilensteine!$D$26<G$3+7),"◆","") | H39: =IF(AND(Meilensteine!$D$26>=H$3,Meilensteine!$D$26<H$3+7),"◆","") | I39: =IF(AND(Meilensteine!$D$26>=I$3,Meilensteine!$D$26<I$3+7),"◆","") | J39: =IF(AND(Meilensteine!$D$26>=J$3,Meilensteine!$D$26<J$3+7),"◆","") | K39: =IF(AND(Meilensteine!$D$26>=K$3,Meilensteine!$D$26<K$3+7),"◆","") | L39: =IF(AND(Meilensteine!$D$26>=L$3,Meilensteine!$D$26<L$3+7),"◆","") | ... AC39: =IF(AND(Meilensteine!$D$26>=AC$3,Meilensteine!$D$26<AC$3+7),"◆","")
B41: ◆ = Meilenstein-Termin | oranger Balken = aktive Phase | blau hinterlegte Spalte = aktuelle Woche. Zeitachse: Montag der jeweiligen KW.

Sheet Meilensteine
A1: Nr. | B1: Meilenstein | C1: Phase | D1: Plantermin | E1: KW | F1: Ist-Termin | G1: Status | H1: Verantwortlich | I1: Countdown (Tage) | J1: Vorgaenger (Nr.) | K1: Bemerkung | L1: (Hilfsspalte)
A2: 1 | B2: bSuite-Aufnahme | C2: Vorbereitung | D2: 46219.333 | E2: =IF($D2="","","KW "&WEEKNUM($D2,21)) | G2: offen | H2: Sarah | I2: =IF($G2="erledigt","✔",IF($D2="","",INT($D2)-TODAY())) | K2: 08:00, mit Ann-Kathrin & Burak | L2: =IF(AND($G2<>"erledigt",$D2<>"",$D2>=TODAY()),$D2+ROW()/10000,"")
A3: 2 | B3: Unterlagenpaket an DPR (Versicherung, HR-Auszug, Zeichnungsberechtigte, Zollprozess) | C3: Vorbereitung | D3: 46219.5 | E3: =IF($D3="","","KW "&WEEKNUM($D3,21)) | G3: offen | H3: Ann-Kathrin & Markus | I3: =IF($G3="erledigt","✔",IF($D3="","",INT($D3)-TODAY())) | K3: 12:00 an Roxana Minor | L3: =IF(AND($G3<>"erledigt",$D3<>"",$D3>=TODAY()),$D3+ROW()/10000,"")
A4: 3 | B4: Unterschriften Diessenhofen | C4: Vorbereitung | D4: 46219 | E4: =IF($D4="","","KW "&WEEKNUM($D4,21)) | G4: offen | H4: Stefan | I4: =IF($G4="erledigt","✔",IF($D4="","",INT($D4)-TODAY())) | K4: Nachmittags | L4: =IF(AND($G4<>"erledigt",$D4<>"",$D4>=TODAY()),$D4+ROW()/10000,"")
A5: 4 | B5: Abstimmungs-Call Aggreko DE | C5: Vorbereitung | D5: 46220.375 | E5: =IF($D5="","","KW "&WEEKNUM($D5,21)) | G5: offen | H5: Burak / Stephan | I5: =IF($G5="erledigt","✔",IF($D5="","",INT($D5)-TODAY())) | K5: 16.07. 14:00 oder 17.07. 09:00 | L5: =IF(AND($G5<>"erledigt",$D5<>"",$D5>=TODAY()),$D5+ROW()/10000,"")
A6: 5 | B6: PO-Korrekturliste an DPR | C6: Vorbereitung | D6: 46220 | E6: =IF($D6="","","KW "&WEEKNUM($D6,21)) | G6: offen | H6: Burak | I6: =IF($G6="erledigt","✔",IF($D6="","",INT($D6)-TODAY())) | J6: 4 | K6: 49A: 78/110 Tage; 49B: 131/110 Tage | L6: =IF(AND($G6<>"erledigt",$D6<>"",$D6>=TODAY()),$D6+ROW()/10000,"")
A7: 6 | B7: RAMS-Abgabe Hammertech | C7: Vorbereitung | D7: 46223 | E7: =IF($D7="","","KW "&WEEKNUM($D7,21)) | G7: offen | H7: Samuel | I7: =IF($G7="erledigt","✔",IF($D7="","",INT($D7)-TODAY())) | K7: inkl. Personenliste Aggreko | L7: =IF(AND($G7<>"erledigt",$D7<>"",$D7>=TODAY()),$D7+ROW()/10000,"")
A8: 7 | B8: Personenliste Aggreko | C8: Vorbereitung | D8: 46223 | E8: =IF($D8="","","KW "&WEEKNUM($D8,21)) | G8: offen | H8: Aggreko | I8: =IF($G8="erledigt","✔",IF($D8="","",INT($D8)-TODAY())) | L8: =IF(AND($G8<>"erledigt",$D8<>"",$D8>=TODAY()),$D8+ROW()/10000,"")
A9: 8 | B9: NDA MiT-DPR unterzeichnet | C9: Vorbereitung | D9: 46225 | E9: =IF($D9="","","KW "&WEEKNUM($D9,21)) | G9: offen | H9: Stefan / Stephan | I9: =IF($G9="erledigt","✔",IF($D9="","",INT($D9)-TODAY())) | K9: eigene NDA, Partei MiT AG | L9: =IF(AND($G9<>"erledigt",$D9<>"",$D9>=TODAY()),$D9+ROW()/10000,"")
A10: 9 | B10: Entsendemeldung Aggreko-Personal | C10: Vorbereitung | D10: 46227 | E10: =IF($D10="","","KW "&WEEKNUM($D10,21)) | G10: offen | H10: Aggreko | I10: =IF($G10="erledigt","✔",IF($D10="","",INT($D10)-TODAY())) | J10: 7 | K10: gesetzlich spaetestens 26.07. | L10: =IF(AND($G10<>"erledigt",$D10<>"",$D10>=TODAY()),$D10+ROW()/10000,"")
A11: 10 | B11: PO 49A/49B final signiert | C11: Vorbereitung | D11: 46227 | E11: =IF($D11="","","KW "&WEEKNUM($D11,21)) | G11: offen | H11: Stefan | I11: =IF($G11="erledigt","✔",IF($D11="","",INT($D11)-TODAY())) | J11: 5 | K11: nach Korrekturliste; Long-Lead-Frist startet | L11: =IF(AND($G11<>"erledigt",$D11<>"",$D11>=TODAY()),$D11+ROW()/10000,"")
A12: 11 | B12: Zollprozess DE-CH schriftlich bestaetigt | C12: Vorbereitung | D12: 46231 | E12: =IF($D12="","","KW "&WEEKNUM($D12,21)) | G12: offen | H12: Markus | I12: =IF($G12="erledigt","✔",IF($D12="","",INT($D12)-TODAY())) | K12: Equipment vs. Kraftstoff | L12: =IF(AND($G12<>"erledigt",$D12<>"",$D12>=TODAY()),$D12+ROW()/10000,"")
A13: 12 | B13: WORKcontrol-Badges + Site Inductions + Kickoff-Meeting DPR | C13: Vorbereitung | D13: 46234 | E13: =IF($D13="","","KW "&WEEKNUM($D13,21)) | G13: offen | H13: Ann-Kathrin | I13: =IF($G13="erledigt","✔",IF($D13="","",INT($D13)-TODAY())) | J13: 9 | K13: vor 03.08. | L13: =IF(AND($G13<>"erledigt",$D13<>"",$D13>=TODAY()),$D13+ROW()/10000,"")
A14: 13 | B14: Lieferung Head-Load-Test | C14: Ausfuehrung | D14: 46237 | E14: =IF($D14="","","KW "&WEEKNUM($D14,21)) | G14: offen | H14: Aggreko | I14: =IF($G14="erledigt","✔",IF($D14="","",INT($D14)-TODAY())) | J14: 12 | K14: 54x 200 kW | L14: =IF(AND($G14<>"erledigt",$D14<>"",$D14>=TODAY()),$D14+ROW()/10000,"")
A15: 14 | B15: Site Setup & Einweisung Headloads | C15: Ausfuehrung | D15: 46239 | E15: =IF($D15="","","KW "&WEEKNUM($D15,21)) | G15: offen | H15: Aggreko / MiT | I15: =IF($G15="erledigt","✔",IF($D15="","",INT($D15)-TODAY())) | J15: 13 | L15: =IF(AND($G15<>"erledigt",$D15<>"",$D15>=TODAY()),$D15+ROW()/10000,"")
A16: 15 | B16: Testbeginn Heat-Load | C16: Ausfuehrung | D16: 46244 | E16: =IF($D16="","","KW "&WEEKNUM($D16,21)) | G16: offen | H16: Burak / Samuel | I16: =IF($G16="erledigt","✔",IF($D16="","",INT($D16)-TODAY())) | J16: 14 | L16: =IF(AND($G16<>"erledigt",$D16<>"",$D16>=TODAY()),$D16+ROW()/10000,"")
A17: 16 | B17: Abruf 3-MW-Block | C17: Ausfuehrung | D17: 46248 | E17: =IF($D17="","","KW "&WEEKNUM($D17,21)) | G17: offen | H17: Burak | I17: =IF($G17="erledigt","✔",IF($D17="","",INT($D17)-TODAY())) | J17: 15 | K17: Mitte August | L17: =IF(AND($G17<>"erledigt",$D17<>"",$D17>=TODAY()),$D17+ROW()/10000,"")
A18: 17 | B18: Lieferung Loadbank 6 MVA | C18: Ausfuehrung | D18: 46251 | E18: =IF($D18="","","KW "&WEEKNUM($D18,21)) | G18: offen | H18: Aggreko | I18: =IF($G18="erledigt","✔",IF($D18="","",INT($D18)-TODAY())) | J18: 12 | L18: =IF(AND($G18<>"erledigt",$D18<>"",$D18>=TODAY()),$D18+ROW()/10000,"")
A19: 18 | B19: Testbeginn Loadbank | C19: Ausfuehrung | D19: 46253 | E19: =IF($D19="","","KW "&WEEKNUM($D19,21)) | G19: offen | H19: Burak / Samuel | I19: =IF($G19="erledigt","✔",IF($D19="","",INT($D19)-TODAY())) | J19: 17 | L19: =IF(AND($G19<>"erledigt",$D19<>"",$D19>=TODAY()),$D19+ROW()/10000,"")
A20: 19 | B20: Abruf 5-MW-Block | C20: Ausfuehrung | D20: 46273 | E20: =IF($D20="","","KW "&WEEKNUM($D20,21)) | G20: offen | H20: Burak | I20: =IF($G20="erledigt","✔",IF($D20="","",INT($D20)-TODAY())) | J20: 16 | K20: 2. September-Woche | L20: =IF(AND($G20<>"erledigt",$D20<>"",$D20>=TODAY()),$D20+ROW()/10000,"")
A21: 20 | B21: Zwischenstand / Review mit DPR | C21: Ausfuehrung | D21: 46295 | E21: =IF($D21="","","KW "&WEEKNUM($D21,21)) | G21: offen | H21: Burak | I21: =IF($G21="erledigt","✔",IF($D21="","",INT($D21)-TODAY())) | K21: Quartalsende | L21: =IF(AND($G21<>"erledigt",$D21<>"",$D21>=TODAY()),$D21+ROW()/10000,"")
A22: 21 | B22: Mietende Loadbank | C22: Ausfuehrung | D22: 46328 | E22: =IF($D22="","","KW "&WEEKNUM($D22,21)) | G22: offen | H22: Burak / Samuel | I22: =IF($G22="erledigt","✔",IF($D22="","",INT($D22)-TODAY())) | J22: 18 | K22: Datum strittig - PO-Fehler | L22: =IF(AND($G22<>"erledigt",$D22<>"",$D22>=TODAY()),$D22+ROW()/10000,"")
A23: 22 | B23: Closeout-Paket EN+DE an DPR | C23: Abschluss | D23: 46356 | E23: =IF($D23="","","KW "&WEEKNUM($D23,21)) | G23: offen | H23: Burak / Stephan | I23: =IF($G23="erledigt","✔",IF($D23="","",INT($D23)-TODAY())) | J23: 20 | K23: 15 Tage vor Leistungsende | L23: =IF(AND($G23<>"erledigt",$D23<>"",$D23>=TODAY()),$D23+ROW()/10000,"")
A24: 23 | B24: Mietende Headloads | C24: Ausfuehrung | D24: 46367 | E24: =IF($D24="","","KW "&WEEKNUM($D24,21)) | G24: offen | H24: Burak / Samuel | I24: =IF($G24="erledigt","✔",IF($D24="","",INT($D24)-TODAY())) | J24: 15 | L24: =IF(AND($G24<>"erledigt",$D24<>"",$D24>=TODAY()),$D24+ROW()/10000,"")
A25: 24 | B25: Demontage | C25: Abschluss | D25: 46370 | E25: =IF($D25="","","KW "&WEEKNUM($D25,21)) | G25: offen | H25: Aggreko / MiT | I25: =IF($G25="erledigt","✔",IF($D25="","",INT($D25)-TODAY())) | J25: 23 | L25: =IF(AND($G25<>"erledigt",$D25<>"",$D25>=TODAY()),$D25+ROW()/10000,"")
A26: 25 | B26: Abnahme & Restpunkte mit DPR | C26: Abschluss | D26: 46371 | E26: =IF($D26="","","KW "&WEEKNUM($D26,21)) | G26: offen | H26: Burak | I26: =IF($G26="erledigt","✔",IF($D26="","",INT($D26)-TODAY())) | J26: 24 | L26: =IF(AND($G26<>"erledigt",$D26<>"",$D26>=TODAY()),$D26+ROW()/10000,"")

Sheet Aufgaben
A1: Nr. | B1: Aufgabe | C1: Paket | D1: Owner | E1: Termin | F1: Status | G1: Prioritaet | H1: Bemerkung | I1: Erledigt am
A2: 1 | B2: Versicherungsnachweis via Finance beschaffen | C2: Admin | D2: Markus | E2: 46219 | F2: offen | G2: hoch
A3: 2 | B3: Zollprozess DE-CH schriftlich klaeren (Kostentraeger; Equipment voruebergehende Verwendung vs. Kraftstoff definitive Einfuhr) | C3: Admin | D3: Markus | E3: 46220 | F3: offen | G3: hoch
A4: 3 | B4: Deckungssummen bei Roxana Minor erfragen | C4: Admin | D4: Markus | E4: 46220 | F4: offen | G4: mittel
A5: 4 | B5: HR-Auszug nachfassen | C5: Admin | D5: Ann-Kathrin | E5: 46219 | F5: offen | G5: hoch
A6: 5 | B6: Beide Angebote im MiT-Layout aufbereiten | C6: beide | D6: Ann-Kathrin | E6: 46220 | F6: offen | G6: mittel | H6: P-640380-3 / P-650395-2
A7: 6 | B7: WORKcontrol-Registrierung MiT | C7: Admin | D7: Ann-Kathrin | E7: 46227 | F7: offen | G7: hoch | H7: vor Badges; CHF 25/Person Erstanmeldung
A8: 7 | B8: Versand Gesamtpaket an Roxana Minor (Tanya cc) | C8: Admin | D8: Ann-Kathrin | E8: 46219.5 | F8: offen | G8: hoch
A9: 8 | B9: Unterschriften leisten (Diessenhofen) | C9: Admin | D9: Stefan | E9: 46219 | F9: offen | G9: hoch | H9: Donnerstag nachmittags
A10: 9 | B10: Entscheid EUR/CHF-Kurs und Absicherung mit Olli | C10: Admin | D10: Stefan | E10: 46220 | F10: offen | G10: hoch | H10: FX-Risiko
A11: 10 | B11: Verhandlungslinie Korrekturliste festlegen | C11: beide | D11: Stefan | E11: 46220 | F11: offen | G11: hoch
A12: 11 | B12: bSuite-Anlage + Intercompany-Beauftragung Aggreko (Back-to-Back) | C12: beide | D12: Sarah | E12: 46219 | F12: offen | G12: hoch
A13: 12 | B13: RAMS-Praxischeck: Anlieferung/8-t-Kranhub, Installation, Testbetrieb, Betankung/Leckage, Demobilisierung | C13: beide | D13: Samuel | E13: 46223 | F13: offen | G13: hoch | H13: 5 Taetigkeiten, Hammertech
A14: 13 | B14: PO-Korrekturliste erstellen und einreichen | C14: beide | D14: Burak / Stephan | E14: 46220 | F14: offen | G14: hoch | H14: 49A 78/110 Tage; 49B 131/110 Tage
A15: 14 | B15: Schriftliche Aggreko-Terminbestaetigung 03.08. / 17.08. einholen | C15: beide | D15: Burak | E15: 46223 | F15: offen | G15: hoch
A16: 15 | B16: Staffelungs-Fakturierung klaeren (5-MW-Block ab Abruf oder Mietbeginn?) | C16: beide | D16: Burak | E16: 46227 | F16: offen | G16: mittel
A17: 16 | B17: PL-Benennung Aggreko DE + englischsprachiger Supervisor | C17: beide | D17: Burak | E17: 46223 | F17: offen | G17: mittel
A18: 17 | B18: Schwerlast-Strombedarf bei DPR einreichen | C18: beide | D18: Burak | E18: 46227 | F18: offen | G18: hoch | H18: Monatsfrist laeuft
A19: 18 | B19: NDA MiT-DPR anstossen | C19: Admin | D19: Burak | E19: 46220 | F19: offen | G19: hoch | H19: eigene NDA; vor Unterzeichnung 22.07.
A20: 19 | B20: Kranfrage / Lift Plan / Rigger klaeren | C20: beide | D20: Burak | E20: 46231 | F20: offen | G20: mittel
A21: 20 | B21: 24/7-Kontaktkette beidseitig aufstellen | C21: beide | D21: Burak | E21: 46234 | F21: offen | G21: mittel | H21: vor Lieferung 03.08.; 01.08. = Bundesfeier
A22: 21 | B22: Tank-Standort mit 110%-Auffangwanne im Logistikplan festlegen | C22: Headload | D22: Burak | E22: 46233 | F22: offen | G22: hoch
A23: 22 | B23: Haftpflichtnachweis Aggreko einfordern | C23: Admin | D23: Burak | E23: 46224 | F23: offen | G23: hoch
A24: 23 | B24: Long-Lead-Liste vorbereiten | C24: beide | D24: Burak | E24: 46226 | F24: offen | G24: hoch | H24: 3-Tage-Frist ab Vertragsunterzeichnung!
A25: 24 | B25: Winterbetrieb ab Oktober in Offerte aufnehmen | C25: beide | D25: Burak | E25: 46225 | F25: offen | G25: mittel

Sheet Termine & Meetings
A1: Nr. | B1: Meeting | C1: Rhythmus | D1: Dauer | E1: Teilnahmepflicht | F1: Status | G1: Bemerkung
A2: 1 | B2: Kickoff-Meeting DPR | C2: einmalig (vor 03.08.) | D2: 2 h | E2: PL, Foreman, Safety Manager (Pflicht) | F2: offen | G2: aus Supplemental Conditions r2
A3: 2 | B3: Safety Orientation | C3: einmalig je Person | D3: 1 h | E3: alle vor Ort Taetigen | F3: offen | G3: vor erstem Zutritt
A4: 3 | B4: Subcontractor Progress Meeting | C4: woechentlich | D4: 1 h | E4: PL | F4: offen
A5: 4 | B5: BIM-Meeting | C5: woechentlich | D5: 2 h | E5: nach Anforderung DPR | F5: offen
A6: 5 | B6: EHS-Meeting | C6: woechentlich | D6: 1 h | E6: Safety / PL | F6: offen
A7: 6 | B7: Pull Planning | C7: woechentlich | D7: 2 h | E7: PL / Foreman | F7: offen
A8: 7 | B8: DABS (Daily Activity Briefing) | C8: taeglich | D8: 30 Min | E8: Crew vor Ort | F8: offen
A9: 8 | B9: Long-Lead-Status-Reporting | C9: 14-taeglich | D9: - | E9: PL | F9: offen | G9: Bericht an DPR (siehe Wochenbericht)
A10: 9 | B10: Record Drawings | C10: monatlich | D10: - | E10: PL | F10: offen | G10: Stand der Dokumentation

Sheet Personal & Zutritt
A1: Nr. | B1: Name | C1: Firma | D1: Funktion | E1: Entsendemeldung | F1: WORKcontrol-Ausweis (Status/Nr.) | G1: Site Induction | H1: Status | I1: Bemerkung
A2: 1 | B2: Uecoez, Burak | C2: MiT | D2: Projektleiter | E2: n.a. | F2: n.a. | H2: in Arbeit | I2: Gesamtkoordination
A3: 2 | B3: N.N. (PL Aggreko DE) | C3: Aggreko | D3: Projektleiter | E3: offen | F3: offen | H3: offen | I3: Benennung ausstehend
A4: 3 | B4: N.N. Supervisor (englischsprachig) | C4: Aggreko | D4: Supervisor | E4: offen | F4: offen | H4: offen | I4: Anforderung DPR
A5: 4 | B5: N.N. Servicetechniker 1 | C5: Aggreko | D5: Techniker | E5: offen | F5: offen | H5: offen | I5: Entsendefrist 24.07.
A6: 5 | B6: N.N. Servicetechniker 2 | C6: Aggreko | D6: Techniker | E6: offen | F6: offen | H6: offen | I6: Entsendefrist 24.07.
A7: 6 | B7: N.N. Servicetechniker 3 | C7: Aggreko | D7: Techniker | E7: offen | F7: offen | H7: offen | I7: Entsendefrist 24.07.
A8: 7 | B8: N.N. Servicetechniker 4 | C8: Aggreko | D8: Techniker | E8: offen | F8: offen | H8: offen | I8: Entsendefrist 24.07.
A9: 8 | B9: N.N. DPR Site Contact | C9: DPR | D9: Bauleitung | E9: n.a. | F9: n.a. | H9: offen | I9: Ansprechpartner vor Ort
B11: WICHTIG: Frist Entsendemeldung 24.07. (gesetzlich spaetestens 26.07.). Ohne validierten WORKcontrol-Ausweis kein Zutritt. Kosten CHF 25/Person Erstanmeldung.

Sheet Schichtplan
A1: Nr. | B1: Datum | C1: KW | D1: Name | E1: Firma | F1: Funktion | G1: Von | H1: Bis | I1: Vor Ort | J1: Bemerkung
A2: 1 | C2: =IF($B2="","","KW "&WEEKNUM($B2,21))
A3: 2 | C3: =IF($B3="","","KW "&WEEKNUM($B3,21))
A4: 3 | C4: =IF($B4="","","KW "&WEEKNUM($B4,21))
A5: 4 | C5: =IF($B5="","","KW "&WEEKNUM($B5,21))
A6: 5 | C6: =IF($B6="","","KW "&WEEKNUM($B6,21))
A7: 6 | C7: =IF($B7="","","KW "&WEEKNUM($B7,21))
A8: 7 | C8: =IF($B8="","","KW "&WEEKNUM($B8,21))
A9: 8 | C9: =IF($B9="","","KW "&WEEKNUM($B9,21))
A10: 9 | C10: =IF($B10="","","KW "&WEEKNUM($B10,21))
A11: 10 | C11: =IF($B11="","","KW "&WEEKNUM($B11,21))
A12: 11 | C12: =IF($B12="","","KW "&WEEKNUM($B12,21))
A13: 12 | C13: =IF($B13="","","KW "&WEEKNUM($B13,21))
... A21: 20 | C21: =IF($B21="","","KW "&WEEKNUM($B21,21))
B23: Anwesenheit vor Ort je Tag erfassen (DABS-Pflicht, 24/7-Kette siehe Kontakte). KW berechnet sich automatisch.

Sheet Lieferungen & Logistik
A1: Nr. | B1: Lieferung / Gegenstand | C1: Paket | D1: Anlieferung geplant | E1: Ort | F1: Kran/Lift | G1: Tank/Containment | H1: Verantwortlich | I1: Status | J1: Bemerkung
A2: 1 | B2: Headloads (54x 200 kW) | C2: Headload | D2: 46237 | E2: ZRH12 Winterthur | F2: ja | G2: - | H2: Aggreko | I2: offen | J2: Lift Plan + Rigger; 8-t-Kranhub
A3: 2 | B3: Loadbank 6 MVA | C3: Loadbank | D3: 46251 | E3: ZRH12 Winterthur | F3: ja | G3: - | H3: Aggreko | I3: offen | J3: Kranfrage klaeren
A4: 3 | B4: Tank / Betankung | C4: Headload | D4: vor Testbeginn | E4: ZRH12 Winterthur | F4: nein | G4: 110%-Auffangwanne | H4: Burak | I4: offen | J4: Standort im Logistikplan Rev. C04
A5: 4 | B5: Kabel- & Anschlussmaterial | C5: beide | D5: vor Testbeginn | E5: ZRH12 Winterthur | F5: nein | G5: - | H5: Aggreko | I5: offen
A6: 5 | B6: Ruecktransport Loadbank | C6: Loadbank | D6: 46328 | E6: ab ZRH12 | F6: ja | G6: - | H6: Aggreko | I6: offen | J6: Off-Hire 5 Arbeitstage vorher melden
A7: 6 | B7: Ruecktransport Headloads | C7: Headload | D7: 46367 | E7: ab ZRH12 | F7: ja | G7: - | H7: Aggreko | I7: offen | J7: Off-Hire 5 Arbeitstage vorher melden
A8: 7 | B8: Demontage & Abtransport | C8: beide | D8: 46370 | E8: ZRH12 Winterthur | F8: ja | G8: - | H8: Aggreko | I8: offen

Sheet Testprotokolle
A1: Nr. | B1: Test / Messung | C1: Paket | D1: Datum | E1: Sollwert | F1: Istwert | G1: Einheit | H1: Ergebnis | I1: Pruefer | J1: Foto/Nachweis | K1: Bemerkung
A2: 1 | B2: Sichtpruefung & Anschlusskontrolle | C2: Loadbank | E2: i.O. | G2: - | H2: offen | J2: offen
A3: 2 | B3: Isolationspruefung | C3: Loadbank | G3: MOhm | H3: offen | J3: offen
A4: 3 | B4: Lastschritt 25% (1.5 MVA) | C4: Loadbank | E4: 1.5 | G4: MVA | H4: offen | J4: offen
A5: 4 | B5: Lastschritt 50% (3.0 MVA) | C5: Loadbank | E5: 3 | G5: MVA | H5: offen | J5: offen
A6: 5 | B6: Lastschritt 75% (4.5 MVA) | C6: Loadbank | E6: 4.5 | G6: MVA | H6: offen | J6: offen
A7: 6 | B7: Lastschritt 100% (6.0 MVA) | C7: Loadbank | E7: 6 | G7: MVA | H7: offen | J7: offen
A8: 7 | B8: Frequenzstabilitaet | C8: Loadbank | E8: 50 | G8: Hz | H8: offen | J8: offen
A9: 8 | B9: Sichtpruefung Headloads | C9: Headload | E9: i.O. | G9: - | H9: offen | J9: offen
A10: 9 | B10: Lastschritt 2 MW | C10: Headload | E10: 2 | G10: MW | H10: offen | J10: offen
A11: 10 | B11: Lastschritt 3 MW (Abruf-Block) | C11: Headload | E11: 3 | G11: MW | H11: offen | J11: offen
A12: 11 | B12: Lastschritt 4 MW | C12: Headload | E12: 4 | G12: MW | H12: offen | J12: offen
A13: 12 | B13: Lastschritt 5 MW (Abruf-Block) | C13: Headload | E13: 5 | G13: MW | H13: offen | J13: offen
A14: 13 | B14: Lastschritt 6 MW | C14: Headload | E14: 6 | G14: MW | H14: offen | J14: offen
A15: 14 | B15: Lastschritt 8 MW (Volllast) | C15: Headload | E15: 8 | G15: MW | H15: offen | J15: offen
A16: 15 | B16: Waermeabfuhr-Nachweis (Dauerlauf) | C16: Headload | E16: - | G16: - | H16: offen | J16: offen
A17: 16 | B17: Not-Aus / Sicherheitskette | C17: beide | E17: i.O. | G17: - | H17: offen | J17: offen
B19: Istwerte, Datum, Pruefer und Foto-Nachweis vor Ort eintragen. Ergebnis = Basis fuer das Closeout-Paket. Keine Fotos nach aussen (NDA).

Sheet Fuel-Log
A1: Nr. | B1: Datum | C1: Menge (Liter) | D1: Lieferschein-Nr. | E1: Zoll-Kategorie | F1: Auffangwanne geprueft | G1: Erfasst von | H1: Bemerkung
A2: 1
A3: 2
A4: 3
A5: 4
A6: 5
A7: 6
A8: 7
A9: 8
A10: 9
A11: 10
A12: 11
A13: 12
... A16: 15
B18: Total Liter | C18: =SUM(FuelLog[Menge (Liter)])
B19: Kraftstoff = definitive Einfuhr (Zoll!). Fuel Unreturned wird mit EUR 2.20/l belastet. Betankung nur am Standort mit 110%-Auffangwanne.

Sheet Stopp-Punkte & Risiken
A1: Nr. | B1: Typ | C1: Beschreibung | D1: Auswirkung | E1: Wahrscheinlichkeit | F1: Owner | G1: Termin | H1: Status | I1: Massnahme | K1: (Hilfsspalte)
A2: 1 | B2: Stopp-Punkt | C2: PO 49A: 78 statt 110 Tage berechnet, Differenz ca. EUR 87'700 | D2: hoch | E2: hoch | F2: Burak | G2: 46220 | H2: offen | I2: Korrekturliste an DPR mit korrigierter Tagesberechnung | K2: =IF(AND($H2<>"erledigt",$D2="hoch"),ROW(),"")
A3: 2 | B3: Stopp-Punkt | C3: PO 49B: 131 statt 110 Tage, Vertragsende 02.11. falsch, englische Anlagenliste nennt falsches Angebot | D3: hoch | E3: hoch | F3: Burak | G3: 46220 | H3: offen | I3: Korrekturliste an DPR; Anlagenliste ersetzen | K3: =IF(AND($H3<>"erledigt",$D3="hoch"),ROW(),"")
A4: 3 | B4: Stopp-Punkt | C4: Parteien auf MiT AG umschreiben + eigene NDA; DPR-Entitaet AG vs. GmbH klaeren | D4: hoch | E4: hoch | F4: Stefan / Stephan | G4: 46223 | H4: offen | I4: PO-Parteien anpassen, NDA MiT-DPR anstossen | K4: =IF(AND($H4<>"erledigt",$D4="hoch"),ROW(),"")
A5: 4 | B5: Entscheid | C5: Festpreis DPR vs. Aufwandspreise Aggreko (Transport/Techniker) | D5: hoch | E5: mittel | F5: Stefan | G5: 46223 | H5: offen | I5: Preismodell final abstimmen; Puffer einrechnen | K5: =IF(AND($H5<>"erledigt",$D5="hoch"),ROW(),"")
A6: 5 | B6: Stopp-Punkt | C6: Preisformel in POs nennt nur Tagesmiete, Total enthaelt aber Einmalkosten | D6: mittel | E6: hoch | F6: Burak | G6: 46220 | H6: offen | I6: In Korrekturliste aufnehmen | K6: =IF(AND($H6<>"erledigt",$D6="hoch"),ROW(),"")
A7: 6 | B7: Risiko | C7: FX-Risiko EUR-Einkauf vs. CHF-Verkauf | D7: mittel | E7: mittel | F7: Stefan | G7: 46220 | H7: offen | I7: Kurs/Absicherung mit Olli entscheiden | K7: =IF(AND($H7<>"erledigt",$D7="hoch"),ROW(),"")
A8: 7 | B8: Risiko | C8: Keine schriftliche Aggreko-Terminbestaetigung 03.08. / 17.08. | D8: hoch | E8: mittel | F8: Burak | G8: 46223 | H8: offen | I8: Schriftliche Bestaetigung einholen | K8: =IF(AND($H8<>"erledigt",$D8="hoch"),ROW(),"")
A9: 8 | B9: Risiko | C9: Hochsaison-Verfuegbarkeit Equipment/Personal Aggreko | D9: mittel | E9: mittel | F9: Aggreko | G9: 46223 | H9: offen | I9: Fruehzeitige Fixierung, Terminbestaetigung | K9: =IF(AND($H9<>"erledigt",$D9="hoch"),ROW(),"")
A10: 9 | B10: Risiko | C10: Entsende-/Bewilligungsfristen (24.07., gesetzlich 26.07.) | D10: hoch | E10: mittel | F10: Aggreko | G10: 46227 | H10: offen | I10: Entsendemeldung fristgerecht einreichen | K10: =IF(AND($H10<>"erledigt",$D10="hoch"),ROW(),"")
A11: 10 | B11: Stopp-Punkt | C11: Waermeabfuhr 8 MW als DPR-Verantwortung schriftlich fixieren | D11: hoch | E11: mittel | F11: DPR | G11: 46227 | H11: offen | I11: Schriftliche Bestaetigung DPR einholen | K11: =IF(AND($H11<>"erledigt",$D11="hoch"),ROW(),"")
A12: 11 | B12: Risiko | C12: DPR-Kuendigungsrecht jederzeit kostenlos vs. Aggreko-Storno 30/100% | D12: hoch | E12: mittel | F12: Stefan | G12: 46227 | H12: offen | I12: Back-to-Back-Regelung in Intercompany-Order | K12: =IF(AND($H12<>"erledigt",$D12="hoch"),ROW(),"")
A13: 12 | B13: Risiko | C13: NDA-Sperre: kein Vantage-Kontakt, keine Aussenkommunikation, keine Fotos | D13: hoch | E13: niedrig | F13: Burak | G13: 46219 | H13: offen | I13: Team briefen; Kommunikation nur ueber DPR | K13: =IF(AND($H13<>"erledigt",$D13="hoch"),ROW(),"")

Sheet Kommerziell
A1: Nr. | B1: Position | C1: Paket | D1: EUR-Wert (Einkauf, Referenz) | E1: Rechnungsstatus | F1: Zahlungsziel | G1: CHF Verkauf | H1: Bemerkung
A2: 1 | B2: Angebot P-640380-3 - Loadbank 6 MVA (Miete + Einmalkosten) | C2: Loadbank | D2: 310328.5 | E2: offen | F2: 30 Tage | G2: [Innendienst/ARM] | H2: PO E3-A25002-49A; Basis 110 Tage
A3: 2 | B3: Angebot P-650395-2 - Headload 8 MW (Miete + Einmalkosten) | C3: Headload | D3: 280511.84 | E3: offen | F3: 30 Tage | G3: [Innendienst/ARM] | H3: PO E3-A25002-49B; Basis 110 Tage
A4: 3 | B4: Einkaufsvolumen total | C4: beide | D4: =D2+D3 | F4: - | G4: [Innendienst/ARM] | H4: Summe beider Angebote
A5: 4 | B5: Transport (Schaetzposition) | C5: beide | E5: offen | F5: 30 Tage | G5: [Innendienst/ARM] | H5: nach Aufwand gemaess Angebot
A6: 5 | B6: Technikereinsaetze (Schaetzposition) | C6: beide | E6: offen | F6: 30 Tage | G6: [Innendienst/ARM] | H6: nach Aufwand gemaess Angebot
A7: 6 | B7: Fuel Unreturned | C7: Headload | D7: 2.2 | E7: offen | F7: 30 Tage | G7: [Innendienst/ARM] | H7: EUR 2.20 pro Liter; Mengen siehe Fuel-Log
A8: 7 | B8: Off-Hire-Fristen | C8: beide | F8: - | G8: [Innendienst/ARM] | H8: Abmeldung 5 Arbeitstage im Voraus, sonst Weiterberechnung
A9: 8 | B9: Rate 1 (Staffelungs-Fakturierung) | C9: beide | E9: offen | F9: 30 Tage | G9: [Innendienst/ARM] | H9: Staffelung klaeren: 5-MW ab Abruf oder Mietbeginn?
A10: 9 | B10: Rate 2 (Staffelungs-Fakturierung) | C10: beide | E10: offen | F10: 30 Tage | G10: [Innendienst/ARM]
A11: 10 | B11: Schlussrechnung | C11: beide | E11: offen | F11: 30 Tage | G11: [Innendienst/ARM] | H11: nach Abnahme / Closeout
B13: Nur EUR-Einkaufsreferenzen (Aggreko). CHF-Verkaufspreise ausschliesslich via Innendienst/ARM - hier bewusst NICHT gefuehrt (Vertraulichkeit/Marge).

Sheet Trend
A1: TREND - offene Aufgaben & erledigte Meilensteine (jeden Freitag eintragen)
A2: Aktueller Stand (zum Uebertragen): | C2: =COUNTA(Aufgaben[Nr.])-COUNTIF(Aufgaben[Status],"erledigt") | D2: =COUNTIF(Meilensteine[Status],"erledigt")
A4: KW | B4: Datum (Fr) | C4: Aufgaben offen | D4: Meilensteine erledigt | E4: Bemerkung
A5: KW29 | B5: 46220
A6: KW30 | B6: 46227
A7: KW31 | B7: 46234
A8: KW32 | B8: 46241
A9: KW33 | B9: 46248
A10: KW34 | B10: 46255
A11: KW35 | B11: 46262
A12: KW36 | B12: 46269
A13: KW37 | B13: 46276
A14: KW38 | B14: 46283
A15: KW39 | B15: 46290
A16: KW40 | B16: 46297
... A28: KW52 | B28: 46381
A30: Jeden Freitag die beiden Werte aus Zeile 2 als ZAHL eintragen (kopieren > Werte einfuegen). So entsteht der Verlauf - ganz ohne Makros.

Sheet Dokumente
A1: Nr. | B1: Dokument | C1: Version/Datum | D1: Quelle | E1: SharePoint-Link | F1: Status | G1: Bemerkung
A2: 1 | B2: Angebot P-640380-3 (Loadbank 6 MVA) | C2: 30.04.2026 | D2: Aggreko | E2: [SharePoint-Projektordner] | F2: final
A3: 2 | B3: Proposal P-650395-2 (Headload 8 MW) | C3: 30.04.2026 | D3: Aggreko | E3: [SharePoint-Projektordner] | F3: final
A4: 3 | B4: PO E3-A25002-49A (Loadbank) | C4: V0 | D4: DPR | E4: [SharePoint-Projektordner] | F4: Entwurf | G4: Korrekturliste laeuft
A5: 4 | B5: PO E3-A25002-49B (Headload) | C5: V0 | D5: DPR | E5: [SharePoint-Projektordner] | F5: Entwurf | G5: Korrekturliste laeuft
A6: 5 | B6: NDA (Partei Aggreko) | C6: unsigniert | D6: DPR | E6: [SharePoint-Projektordner] | F6: ueberholt | G6: bei MiT-Konstellation ueberholt - neue NDA MiT-DPR noetig
A7: 6 | B7: Anlage Versicherung | C7: - | D7: DPR | E7: [SharePoint-Projektordner] | F7: Entwurf | G7: Deckungssummen offen
A8: 7 | B8: Logistikplan Phase 2 | C8: Rev. C04 | D8: DPR | E8: [SharePoint-Projektordner] | F8: final | G8: Tank-Standort ergaenzen
A9: 8 | B9: Supplemental Conditions | C9: r2 | D9: DPR | E9: [SharePoint-Projektordner] | F9: final | G9: Meeting-Pflichten siehe Blatt Termine & Meetings
A10: 9 | B10: Compliance WORKcontrol | C10: - | D10: DPR | E10: [SharePoint-Projektordner] | F10: final
A11: 10 | B11: EHS-Plan | C11: Rev. 4 / 22.01.2026 | D11: DPR | E11: [SharePoint-Projektordner] | F11: final
A12: 11 | B12: Einzelanalyse 01 | C12: - | D12: MiT | E12: [SharePoint-Projektordner] | F12: final
A13: 12 | B13: Einzelanalyse 02 | C13: - | D13: MiT | E13: [SharePoint-Projektordner] | F13: final
A14: 13 | B14: Einzelanalyse 03 | C14: - | D14: MiT | E14: [SharePoint-Projektordner] | F14: final
A15: 14 | B15: Einzelanalyse 04 | C15: - | D15: MiT | E15: [SharePoint-Projektordner] | F15: final
A16: 15 | B16: Einzelanalyse 05 | C16: - | D16: MiT | E16: [SharePoint-Projektordner] | F16: final
A17: 16 | B17: Einzelanalyse 06 | C17: - | D17: MiT | E17: [SharePoint-Projektordner] | F17: final
A18: 17 | B18: Einzelanalyse 07 | C18: - | D18: MiT | E18: [SharePoint-Projektordner] | F18: final
A19: 18 | B19: Einzelanalyse 08 | C19: - | D19: MiT | E19: [SharePoint-Projektordner] | F19: final
A20: 19 | B20: Einzelanalyse 09 | C20: - | D20: MiT | E20: [SharePoint-Projektordner] | F20: final
A21: 20 | B21: Einzelanalyse 10 | C21: - | D21: MiT | E21: [SharePoint-Projektordner] | F21: final
A22: 21 | B22: Einzelanalyse 11 | C22: - | D22: MiT | E22: [SharePoint-Projektordner] | F22: final
