Workbook

Sheet 📑 Executive PDF
A1: ⚡ MiT Strom Schweiz — Executive Sales Summary
A2: Mobil in Time AG · An Aggreko Company · Burak Ücöz
A3: ="Stand: "&TEXT(TODAY(),"DD.MM.YYYY")&" · Live aus Pipeline" -> Stand: 10.08.2026 · Live aus Pipeline
B5: ✅ WON | E5: 📄 OFFERTE | G5: 🎯 OPPORTUNITÄT
B6: =Dashboard!A6 -> 1428553.1 | E6: =Dashboard!D6 -> 5433596.1 | G6: =Dashboard!G6 -> 0
B8: =Dashboard!A7&IF(Dashboard!A7=1," Deal"," Deals") -> 12 Deals | E8: =Dashboard!D7&IF(Dashboard!D7=1," Deal"," Deals") -> 33 Deals | G8: =Dashboard!G7&IF(Dashboard!G7=1," Deal"," Deals") -> 1 Deal
B10: ="📊 PIPELINE: "&TEXT(Dashboard!I6,"#,##0")&" CHF · "&Dashboard!I7&" Deals · ⚖️ GEWICHTET: "&TEXT('⚖️ Wahrscheinlichkeit'!$G$22,"#,##0")&" CHF" -> 📊 PIPELINE: 6,862,149 CHF · 46 Deals · ⚖️ GEWICHTET: 1,628,426 CHF
B12: 🏆 Top 5 WON-Deals (nach Volumen)
B13: # | C13: Kunde | D13: Kt. | E13: Projektstart | F13: Segment | G13: Volumen | H13: Projektende
B14: 1 | C14: =IFERROR(INDEX('MiT Strom Pipeline'!B6:B860,MATCH(LARGE('MiT Strom Pipeline'!AK6:AK860,1),'MiT Strom Pipeline'!AK6:AK860,0)),"") -> Ice Hockey Championship | D14: =IFERROR(INDEX('MiT Strom Pipeline'!C6:C860,MATCH(LARGE('MiT Strom Pipeline'!AK6:AK860,1),'MiT Strom Pipeline'!AK6:AK860,0)),"") -> ZH | E14: =IFERROR(IF(ISNUMBER(INDEX('MiT Strom Pipeline'!$O$6:$O$860,MATCH(LARGE('MiT Strom Pipeline'!$AK$6:$AK$860,1),'MiT Strom Pipeline'!$AK$6:$AK$860,0))),INDEX('MiT Strom Pipeline'!$O$6:$O$860,MATCH(LARGE('MiT Strom Pipeline'!$AK$6:$AK$860,1),'MiT Strom Pipeline'!$AK$6:$AK$860,0)),IF(INDEX('MiT Strom Pipeline'!$H$6:$H$860,MATCH(LARGE('MiT Strom Pipeline'!$AK$6:$AK$860,1),'MiT Strom Pipeline'!$AK$6:$AK$860,0))="","",INDEX('MiT Strom Pipeline'!$H$6:$H$860,MATCH(LARGE('MiT Strom Pipeline'!$AK$6:$AK$860,1),'MiT Strom Pipeline'!$AK$6:$AK$860,0)))),"") -> Mai | F14: =IFERROR(INDEX('MiT Strom Pipeline'!D6:D860,MATCH(LARGE('MiT Strom Pipeline'!AK6:AK860,1),'MiT Strom Pipeline'!AK6:AK860,0)),"") -> Events & Sport | G14: =IFERROR(INDEX('MiT Strom Pipeline'!I6:I860,MATCH(LARGE('MiT Strom Pipeline'!AK6:AK860,1),'MiT Strom Pipeline'!AK6:AK860,0)),"") -> 380000 | H14: =IFERROR(IF(ISNUMBER(INDEX('MiT Strom Pipeline'!$P$6:$P$860,MATCH(LARGE('MiT Strom Pipeline'!$AK$6:$AK$860,1),'MiT Strom Pipeline'!$AK$6:$AK$860,0))),INDEX('MiT Strom Pipeline'!$P$6:$P$860,MATCH(LARGE('MiT Strom Pipeline'!$AK$6:$AK$860,1),'MiT Strom Pipeline'!$AK$6:$AK$860,0)),""),"")
B15: 2 | C15: =IFERROR(INDEX('MiT Strom Pipeline'!B6:B860,MATCH(LARGE('MiT Strom Pipeline'!AK6:AK860,2),'MiT Strom Pipeline'!AK6:AK860,0)),"") -> DPR Heat Loadbank | D15: =IFERROR(INDEX('MiT Strom Pipeline'!C6:C860,MATCH(LARGE('MiT Strom Pipeline'!AK6:AK860,2),'MiT Strom Pipeline'!AK6:AK860,0)),"") -> ZH | E15: =IFERROR(IF(ISNUMBER(INDEX('MiT Strom Pipeline'!$O$6:$O$860,MATCH(LARGE('MiT Strom Pipeline'!$AK$6:$AK$860,2),'MiT Strom Pipeline'!$AK$6:$AK$860,0))),INDEX('MiT Strom Pipeline'!$O$6:$O$860,MATCH(LARGE('MiT Strom Pipeline'!$AK$6:$AK$860,2),'MiT Strom Pipeline'!$AK$6:$AK$860,0)),IF(INDEX('MiT Strom Pipeline'!$H$6:$H$860,MATCH(LARGE('MiT Strom Pipeline'!$AK$6:$AK$860,2),'MiT Strom Pipeline'!$AK$6:$AK$860,0))="","",INDEX('MiT Strom Pipeline'!$H$6:$H$860,MATCH(LARGE('MiT Strom Pipeline'!$AK$6:$AK$860,2),'MiT Strom Pipeline'!$AK$6:$AK$860,0)))),"") -> Aug | F15: =IFERROR(INDEX('MiT Strom Pipeline'!D6:D860,MATCH(LARGE('MiT Strom Pipeline'!AK6:AK860,2),'MiT Strom Pipeline'!AK6:AK860,0)),"") -> Datacenter | G15: =IFERROR(INDEX('MiT Strom Pipeline'!I6:I860,MATCH(LARGE('MiT Strom Pipeline'!AK6:AK860,2),'MiT Strom Pipeline'!AK6:AK860,0)),"") -> 333790 | H15: =IFERROR(IF(ISNUMBER(INDEX('MiT Strom Pipeline'!$P$6:$P$860,MATCH(LARGE('MiT Strom Pipeline'!$AK$6:$AK$860,2),'MiT Strom Pipeline'!$AK$6:$AK$860,0))),INDEX('MiT Strom Pipeline'!$P$6:$P$860,MATCH(LARGE('MiT Strom Pipeline'!$AK$6:$AK$860,2),'MiT Strom Pipeline'!$AK$6:$AK$860,0)),""),"")
B16: 3 | C16: =IFERROR(INDEX('MiT Strom Pipeline'!B6:B860,MATCH(LARGE('MiT Strom Pipeline'!AK6:AK860,3),'MiT Strom Pipeline'!AK6:AK860,0)),"") -> DPR Generator Loadbank Test | D16: =IFERROR(INDEX('MiT Strom Pipeline'!C6:C860,MATCH(LARGE('MiT Strom Pipeline'!AK6:AK860,3),'MiT Strom Pipeline'!AK6:AK860,0)),"") -> ZH | E16: =IFERROR(IF(ISNUMBER(INDEX('MiT Strom Pipeline'!$O$6:$O$860,MATCH(LARGE('MiT Strom Pipeline'!$AK$6:$AK$860,3),'MiT Strom Pipeline'!$AK$6:$AK$860,0))),INDEX('MiT Strom Pipeline'!$O$6:$O$860,MATCH(LARGE('MiT Strom Pipeline'!$AK$6:$AK$860,3),'MiT Strom Pipeline'!$AK$6:$AK$860,0)),IF(INDEX('MiT Strom Pipeline'!$H$6:$H$860,MATCH(LARGE('MiT Strom Pipeline'!$AK$6:$AK$860,3),'MiT Strom Pipeline'!$AK$6:$AK$860,0))="","",INDEX('MiT Strom Pipeline'!$H$6:$H$860,MATCH(LARGE('MiT Strom Pipeline'!$AK$6:$AK$860,3),'MiT Strom Pipeline'!$AK$6:$AK$860,0)))),"") -> Aug | F16: =IFERROR(INDEX('MiT Strom Pipeline'!D6:D860,MATCH(LARGE('MiT Strom Pipeline'!AK6:AK860,3),'MiT Strom Pipeline'!AK6:AK860,0)),"") -> Datacenter | G16: =IFERROR(INDEX('MiT Strom Pipeline'!I6:I860,MATCH(LARGE('MiT Strom Pipeline'!AK6:AK860,3),'MiT Strom Pipeline'!AK6:AK860,0)),"") -> 331889.15 | H16: =IFERROR(IF(ISNUMBER(INDEX('MiT Strom Pipeline'!$P$6:$P$860,MATCH(LARGE('MiT Strom Pipeline'!$AK$6:$AK$860,3),'MiT Strom Pipeline'!$AK$6:$AK$860,0))),INDEX('MiT Strom Pipeline'!$P$6:$P$860,MATCH(LARGE('MiT Strom Pipeline'!$AK$6:$AK$860,3),'MiT Strom Pipeline'!$AK$6:$AK$860,0)),""),"")
B17: 4 | C17: =IFERROR(INDEX('MiT Strom Pipeline'!B6:B860,MATCH(LARGE('MiT Strom Pipeline'!AK6:AK860,4),'MiT Strom Pipeline'!AK6:AK860,0)),"") -> Stagelight – OpenAir Frauenfeld | D17: =IFERROR(INDEX('MiT Strom Pipeline'!C6:C860,MATCH(LARGE('MiT Strom Pipeline'!AK6:AK860,4),'MiT Strom Pipeline'!AK6:AK860,0)),"") -> TG | E17: =IFERROR(IF(ISNUMBER(INDEX('MiT Strom Pipeline'!$O$6:$O$860,MATCH(LARGE('MiT Strom Pipeline'!$AK$6:$AK$860,4),'MiT Strom Pipeline'!$AK$6:$AK$860,0))),INDEX('MiT Strom Pipeline'!$O$6:$O$860,MATCH(LARGE('MiT Strom Pipeline'!$AK$6:$AK$860,4),'MiT Strom Pipeline'!$AK$6:$AK$860,0)),IF(INDEX('MiT Strom Pipeline'!$H$6:$H$860,MATCH(LARGE('MiT Strom Pipeline'!$AK$6:$AK$860,4),'MiT Strom Pipeline'!$AK$6:$AK$860,0))="","",INDEX('MiT Strom Pipeline'!$H$6:$H$860,MATCH(LARGE('MiT Strom Pipeline'!$AK$6:$AK$860,4),'MiT Strom Pipeline'!$AK$6:$AK$860,0)))),"") -> Juli | F17: =IFERROR(INDEX('MiT Strom Pipeline'!D6:D860,MATCH(LARGE('MiT Strom Pipeline'!AK6:AK860,4),'MiT Strom Pipeline'!AK6:AK860,0)),"") -> Events & Kultur | G17: =IFERROR(INDEX('MiT Strom Pipeline'!I6:I860,MATCH(LARGE('MiT Strom Pipeline'!AK6:AK860,4),'MiT Strom Pipeline'!AK6:AK860,0)),"") -> 150000 | H17: =IFERROR(IF(ISNUMBER(INDEX('MiT Strom Pipeline'!$P$6:$P$860,MATCH(LARGE('MiT Strom Pipeline'!$AK$6:$AK$860,4),'MiT Strom Pipeline'!$AK$6:$AK$860,0))),INDEX('MiT Strom Pipeline'!$P$6:$P$860,MATCH(LARGE('MiT Strom Pipeline'!$AK$6:$AK$860,4),'MiT Strom Pipeline'!$AK$6:$AK$860,0)),""),"")
B18: 5 | C18: =IFERROR(INDEX('MiT Strom Pipeline'!B6:B860,MATCH(LARGE('MiT Strom Pipeline'!AK6:AK860,5),'MiT Strom Pipeline'!AK6:AK860,0)),"") -> Murg Flums Energie | D18: =IFERROR(INDEX('MiT Strom Pipeline'!C6:C860,MATCH(LARGE('MiT Strom Pipeline'!AK6:AK860,5),'MiT Strom Pipeline'!AK6:AK860,0)),"") -> SG | E18: =IFERROR(IF(ISNUMBER(INDEX('MiT Strom Pipeline'!$O$6:$O$860,MATCH(LARGE('MiT Strom Pipeline'!$AK$6:$AK$860,5),'MiT Strom Pipeline'!$AK$6:$AK$860,0))),INDEX('MiT Strom Pipeline'!$O$6:$O$860,MATCH(LARGE('MiT Strom Pipeline'!$AK$6:$AK$860,5),'MiT Strom Pipeline'!$AK$6:$AK$860,0)),IF(INDEX('MiT Strom Pipeline'!$H$6:$H$860,MATCH(LARGE('MiT Strom Pipeline'!$AK$6:$AK$860,5),'MiT Strom Pipeline'!$AK$6:$AK$860,0))="","",INDEX('MiT Strom Pipeline'!$H$6:$H$860,MATCH(LARGE('MiT Strom Pipeline'!$AK$6:$AK$860,5),'MiT Strom Pipeline'!$AK$6:$AK$860,0)))),"") -> Auf Abruf | F18: =IFERROR(INDEX('MiT Strom Pipeline'!D6:D860,MATCH(LARGE('MiT Strom Pipeline'!AK6:AK860,5),'MiT Strom Pipeline'!AK6:AK860,0)),"") -> EVU / Energie | G18: =IFERROR(INDEX('MiT Strom Pipeline'!I6:I860,MATCH(LARGE('MiT Strom Pipeline'!AK6:AK860,5),'MiT Strom Pipeline'!AK6:AK860,0)),"") -> 96658.69 | H18: =IFERROR(IF(ISNUMBER(INDEX('MiT Strom Pipeline'!$P$6:$P$860,MATCH(LARGE('MiT Strom Pipeline'!$AK$6:$AK$860,5),'MiT Strom Pipeline'!$AK$6:$AK$860,0))),INDEX('MiT Strom Pipeline'!$P$6:$P$860,MATCH(LARGE('MiT Strom Pipeline'!$AK$6:$AK$860,5),'MiT Strom Pipeline'!$AK$6:$AK$860,0)),""),"")
B21: 📊 Status-Verteilung Pipeline
B22: Status | D22: Anzahl | E22: Volumen CHF | G22: Anteil %
B23: ✅ WON | D23: =COUNTIF('MiT Strom Pipeline'!R6:R860,"WON") -> 12 | E23: =SUMIFS('MiT Strom Pipeline'!I6:I860,'MiT Strom Pipeline'!R6:R860,"WON") -> 1428553.1 | G23: =IFERROR(E23/Dashboard!I6,0) -> 0.20817867
B24: 📄 Offerte (inkl. To Offer) | D24: =COUNTIF('MiT Strom Pipeline'!R6:R860,"offered")+COUNTIF('MiT Strom Pipeline'!R6:R860,"to be offered") -> 29 | E24: =SUMIFS('MiT Strom Pipeline'!I6:I860,'MiT Strom Pipeline'!R6:R860,"offered")+SUMIFS('MiT Strom Pipeline'!I6:I860,'MiT Strom Pipeline'!R6:R860,"to be offered") -> 4887938.3 | G24: =IFERROR(E24/Dashboard!I6,0) -> 0.71230428
B25: 🎯 Follow-Up | D25: =COUNTIF('MiT Strom Pipeline'!R6:R860,"follow-up") -> 0 | E25: =SUMIFS('MiT Strom Pipeline'!I6:I860,'MiT Strom Pipeline'!R6:R860,"follow-up") -> 0 | G25: =IFERROR(E25/Dashboard!I6,0) -> 0
B26: 🔍 Evaluation (inkl. In Eval) | D26: =COUNTIF('MiT Strom Pipeline'!R6:R860,"Evaluation")+COUNTIF('MiT Strom Pipeline'!R6:R860,"In evaluation") -> 0 | E26: =SUMIFS('MiT Strom Pipeline'!I6:I860,'MiT Strom Pipeline'!R6:R860,"Evaluation")+SUMIFS('MiT Strom Pipeline'!I6:I860,'MiT Strom Pipeline'!R6:R860,"In evaluation") -> 0 | G26: =IFERROR(E26/Dashboard!I6,0) -> 0
B27: ⏸ On Hold | D27: =COUNTIF('MiT Strom Pipeline'!R6:R860,"on hold") -> 4 | E27: =SUMIFS('MiT Strom Pipeline'!I6:I860,'MiT Strom Pipeline'!R6:R860,"on hold") -> 545657.8 | G27: =IFERROR(E27/Dashboard!I6,0) -> 0.079517041
B28: ❓ TBD | D28: =COUNTIF('MiT Strom Pipeline'!R6:R860,"tbd") -> 1 | E28: =SUMIFS('MiT Strom Pipeline'!I6:I860,'MiT Strom Pipeline'!R6:R860,"tbd") -> 0 | G28: =IFERROR(E28/Dashboard!I6,0) -> 0
B29: ❌ LOST | D29: =COUNTIF('MiT Strom Pipeline'!R6:R860,"LOST") -> 7 | E29: =SUMIFS('MiT Strom Pipeline'!I6:I860,'MiT Strom Pipeline'!R6:R860,"LOST") -> 78251.62 | G29: =IFERROR(E29/Dashboard!I6,0) -> 0.011403369
B30: 🚫 Declined | D30: =COUNTIF('MiT Strom Pipeline'!R6:R860,"Declined") -> 13 | E30: =SUMIFS('MiT Strom Pipeline'!I6:I860,'MiT Strom Pipeline'!R6:R860,"Declined") -> 96029.01 | G30: =IFERROR(E30/Dashboard!I6,0) -> 0.013994014
B32: ⚖️ Gewichtete Pipeline nach Aggreko-Bewertung
B33: Wahrsch.-Band | D33: Faktor | E33: Umsatz CHF | G33: Gewichtet CHF
B34: ='⚖️ Wahrscheinlichkeit'!$A$17 -> 0 – 44 % | D34: ='⚖️ Wahrscheinlichkeit'!$D$17 -> 0 | E34: ='⚖️ Wahrscheinlichkeit'!$F$17 -> 5092182.2 | G34: ='⚖️ Wahrscheinlichkeit'!$G$17 -> 0
B35: ='⚖️ Wahrscheinlichkeit'!$A$18 -> 45 – 59 % | D35: ='⚖️ Wahrscheinlichkeit'!$D$18 -> 0.3 | E35: ='⚖️ Wahrscheinlichkeit'!$F$18 -> 0 | G35: ='⚖️ Wahrscheinlichkeit'!$G$18 -> 0
B36: ='⚖️ Wahrscheinlichkeit'!$A$19 -> 60 – 89 % | D36: ='⚖️ Wahrscheinlichkeit'!$D$19 -> 0.5 | E36: ='⚖️ Wahrscheinlichkeit'!$F$19 -> 268500.23 | G36: ='⚖️ Wahrscheinlichkeit'!$G$19 -> 134250.11
B37: ='⚖️ Wahrscheinlichkeit'!$A$20 -> 90 – 99 % | D37: ='⚖️ Wahrscheinlichkeit'!$D$20 -> 0.9 | E37: ='⚖️ Wahrscheinlichkeit'!$F$20 -> 72913.72 | G37: ='⚖️ Wahrscheinlichkeit'!$G$20 -> 65622.348
B38: ='⚖️ Wahrscheinlichkeit'!$A$21 -> 100 % · WON | D38: ='⚖️ Wahrscheinlichkeit'!$D$21 -> 1 | E38: ='⚖️ Wahrscheinlichkeit'!$F$21 -> 1428553.1 | G38: ='⚖️ Wahrscheinlichkeit'!$G$21 -> 1428553.1
B39: TOTAL aktiv | E39: ='⚖️ Wahrscheinlichkeit'!$F$22 -> 6862149.2 | G39: ='⚖️ Wahrscheinlichkeit'!$G$22 -> 1628425.6
B40: ="Faktoren: 0–44 % → 0 % | 45–59 % → 30 % | 60–89 % → 50 % | 90–99 % → 90 % | 100 % → 100 % · Gewichtungsgrad: "&TEXT('⚖️ Wahrscheinlichkeit'!$H$22,"0.0%") -> Faktoren: 0–44 % → 0 % | 45–59 % → 30 % | 60–89 % → 50 % | 90–99 % → 90 % | 100 % → 100 % · Gewichtungsgrad: 23.7%
B42: 📋 Nachweis & Zeitraum — wie die Zahlen zu lesen sind
B43: WON netto (ohne MwSt) | E43: =SUMPRODUCT(--('MiT Strom Pipeline'!$R$6:$R$860="WON"),'MiT Strom Pipeline'!$AZ$6:$AZ$860) -> 1321510.8
B44: davon durch Auftrag/PO belegt | E44: =SUMPRODUCT('MiT Strom Pipeline'!$AT$6:$AT$860,'MiT Strom Pipeline'!$AL$6:$AL$860) -> 0
B45: Nachweisquote | E45: =IFERROR(SUMPRODUCT('MiT Strom Pipeline'!$AT$6:$AT$860,'MiT Strom Pipeline'!$AL$6:$AL$860)/SUMIFS('MiT Strom Pipeline'!$I$6:$I$860,'MiT Strom Pipeline'!$R$6:$R$860,"WON"),0) -> 0
B46: Deals mit erfasstem Projektzeitraum | E46: =SUMPRODUCT('MiT Strom Pipeline'!$AP$6:$AP$860,'MiT Strom Pipeline'!$AY$6:$AY$860)&" von "&SUMPRODUCT('MiT Strom Pipeline'!$AP$6:$AP$860) -> 0 von 46
B47: ="Offene Pflichtangaben: "&'📋 Definitionen & Klärung'!$C$23&" · Definitionen und offene Punkte: Blatt «📋 Definitionen & Klärung»" -> Offene Pflichtangaben: 101 · Definitionen und offene Punkte: Blatt «📋 Definitionen & Klärung»
A49: 🖨 Strg+P → Als PDF speichern · Druckbereich ist bereits gesetzt (A4 Hochformat)

Sheet 📄 Report
A1: MiT Strom Schweiz — Sales-Report
A2: Mobil in Time AG · An Aggreko Company · Burak Ücöz
A3: ="Stand: "&TEXT(TODAY(),"DD.MM.YYYY")&" · Auto-Update via Pipeline-Daten" -> Stand: 10.08.2026 · Auto-Update via Pipeline-Daten
A5: Key Performance Indicators
A6: KPI | B6: Wert CHF | C6: Anzahl | D6: Anteil
A7: ✅ WON | B7: =Dashboard!A6 -> 1428553.1 | C7: =Dashboard!A7 -> 12 | D7: =IFERROR(B7/$B$10,0) -> 0.20817867
A8: 📄 Offerte | B8: =Dashboard!D6 -> 5433596.1 | C8: =Dashboard!D7 -> 33 | D8: =IFERROR(B8/$B$10,0) -> 0.79182133
A9: 🎯 Opportunität | B9: =Dashboard!G6 -> 0 | C9: =Dashboard!G7 -> 1 | D9: =IFERROR(B9/$B$10,0) -> 0
A10: 📊 TOTAL Pipeline | B10: =Dashboard!I6 -> 6862149.2 | C10: =Dashboard!I7 -> 46 | D10: =IFERROR(B10/$B$10,0) -> 1
A11: ⚖️ Gewichtet | B11: ='⚖️ Wahrscheinlichkeit'!$G$22 -> 1628425.6 | C11: ='⚖️ Wahrscheinlichkeit'!$E$22 -> 46 | D11: =IFERROR(B11/$B$10,0) -> 0.23730548
A12: 📋 WON belegt | B12: =SUMPRODUCT('MiT Strom Pipeline'!$AT$6:$AT$860,'MiT Strom Pipeline'!$AL$6:$AL$860) -> 0 | C12: =SUMPRODUCT('MiT Strom Pipeline'!$AT$6:$AT$860) -> 0 | D12: =IFERROR(SUMPRODUCT('MiT Strom Pipeline'!$AT$6:$AT$860,'MiT Strom Pipeline'!$AL$6:$AL$860)/SUMIFS('MiT Strom Pipeline'!$I$6:$I$860,'MiT Strom Pipeline'!$R$6:$R$860,"WON"),0) -> 0 | E12: =IFERROR(SUMPRODUCT('MiT Strom Pipeline'!$AT$6:$AT$860,'MiT Strom Pipeline'!$AL$6:$AL$860)/SUMIFS('MiT Strom Pipeline'!$I$6:$I$860,'MiT Strom Pipeline'!$R$6:$R$860,"WON"),0) -> 0
A13: Top Kantone (nach Volumen) | J13: _kt | K13: _vol | L13: _rankkey
A14: Rang | B14: Kanton | C14: Volumen CHF | D14: Anzahl Deals | E14: WON-Rate | J14: AG | K14: =SUMIF('MiT Strom Pipeline'!$C$6:$C$860,J14,'MiT Strom Pipeline'!$I$6:$I$860) -> 444672.95 | L14: =K14+(26-ROW())*0.0001 -> 444672.95
A15: 1 | B15: =IFERROR(INDEX($J$14:$J$39,MATCH(LARGE($L$14:$L$39,1),$L$14:$L$39,0)),"") -> ZH | C15: =IF(B15="","",SUMIF('MiT Strom Pipeline'!$C$6:$C$860,B15,'MiT Strom Pipeline'!$I$6:$I$860)) -> 2732239 | D15: =IF(B15="","",COUNTIF('MiT Strom Pipeline'!$C$6:$C$860,B15)) -> 25 | E15: =IF(OR(B15="",D15=0),"",COUNTIFS('MiT Strom Pipeline'!$C$6:$C$860,B15,'MiT Strom Pipeline'!$R$6:$R$860,"WON")/D15) -> 0.2 | J15: AI | K15: =SUMIF('MiT Strom Pipeline'!$C$6:$C$860,J15,'MiT Strom Pipeline'!$I$6:$I$860) -> 0 | L15: =K15+(26-ROW())*0.0001 -> 0.0011
A16: 2 | B16: =IFERROR(INDEX($J$14:$J$39,MATCH(LARGE($L$14:$L$39,2),$L$14:$L$39,0)),"") -> SH | C16: =IF(B16="","",SUMIF('MiT Strom Pipeline'!$C$6:$C$860,B16,'MiT Strom Pipeline'!$I$6:$I$860)) -> 2637287.6 | D16: =IF(B16="","",COUNTIF('MiT Strom Pipeline'!$C$6:$C$860,B16)) -> 5 | E16: =IF(OR(B16="",D16=0),"",COUNTIFS('MiT Strom Pipeline'!$C$6:$C$860,B16,'MiT Strom Pipeline'!$R$6:$R$860,"WON")/D16) -> 0.2 | J16: AR | K16: =SUMIF('MiT Strom Pipeline'!$C$6:$C$860,J16,'MiT Strom Pipeline'!$I$6:$I$860) -> 0 | L16: =K16+(26-ROW())*0.0001 -> 0.001
A17: 3 | B17: =IFERROR(INDEX($J$14:$J$39,MATCH(LARGE($L$14:$L$39,3),$L$14:$L$39,0)),"") -> AG | C17: =IF(B17="","",SUMIF('MiT Strom Pipeline'!$C$6:$C$860,B17,'MiT Strom Pipeline'!$I$6:$I$860)) -> 444672.95 | D17: =IF(B17="","",COUNTIF('MiT Strom Pipeline'!$C$6:$C$860,B17)) -> 7 | E17: =IF(OR(B17="",D17=0),"",COUNTIFS('MiT Strom Pipeline'!$C$6:$C$860,B17,'MiT Strom Pipeline'!$R$6:$R$860,"WON")/D17) -> 0.14285714 | J17: BE | K17: =SUMIF('MiT Strom Pipeline'!$C$6:$C$860,J17,'MiT Strom Pipeline'!$I$6:$I$860) -> 58012.12 | L17: =K17+(26-ROW())*0.0001 -> 58012.121
A18: 4 | B18: =IFERROR(INDEX($J$14:$J$39,MATCH(LARGE($L$14:$L$39,4),$L$14:$L$39,0)),"") -> SO | C18: =IF(B18="","",SUMIF('MiT Strom Pipeline'!$C$6:$C$860,B18,'MiT Strom Pipeline'!$I$6:$I$860)) -> 390750.65 | D18: =IF(B18="","",COUNTIF('MiT Strom Pipeline'!$C$6:$C$860,B18)) -> 2 | E18: =IF(OR(B18="",D18=0),"",COUNTIFS('MiT Strom Pipeline'!$C$6:$C$860,B18,'MiT Strom Pipeline'!$R$6:$R$860,"WON")/D18) -> 0 | J18: BL | K18: =SUMIF('MiT Strom Pipeline'!$C$6:$C$860,J18,'MiT Strom Pipeline'!$I$6:$I$860) -> 13472.18 | L18: =K18+(26-ROW())*0.0001 -> 13472.181
A19: 5 | B19: =IFERROR(INDEX($J$14:$J$39,MATCH(LARGE($L$14:$L$39,5),$L$14:$L$39,0)),"") -> VS | C19: =IF(B19="","",SUMIF('MiT Strom Pipeline'!$C$6:$C$860,B19,'MiT Strom Pipeline'!$I$6:$I$860)) -> 303790.2 | D19: =IF(B19="","",COUNTIF('MiT Strom Pipeline'!$C$6:$C$860,B19)) -> 3 | E19: =IF(OR(B19="",D19=0),"",COUNTIFS('MiT Strom Pipeline'!$C$6:$C$860,B19,'MiT Strom Pipeline'!$R$6:$R$860,"WON")/D19) -> 0.33333333 | J19: BS | K19: =SUMIF('MiT Strom Pipeline'!$C$6:$C$860,J19,'MiT Strom Pipeline'!$I$6:$I$860) -> 13866.21 | L19: =K19+(26-ROW())*0.0001 -> 13866.211
A20: 6 | B20: =IFERROR(INDEX($J$14:$J$39,MATCH(LARGE($L$14:$L$39,6),$L$14:$L$39,0)),"") -> TG | C20: =IF(B20="","",SUMIF('MiT Strom Pipeline'!$C$6:$C$860,B20,'MiT Strom Pipeline'!$I$6:$I$860)) -> 160817.26 | D20: =IF(B20="","",COUNTIF('MiT Strom Pipeline'!$C$6:$C$860,B20)) -> 3 | E20: =IF(OR(B20="",D20=0),"",COUNTIFS('MiT Strom Pipeline'!$C$6:$C$860,B20,'MiT Strom Pipeline'!$R$6:$R$860,"WON")/D20) -> 0.66666667 | J20: FR | K20: =SUMIF('MiT Strom Pipeline'!$C$6:$C$860,J20,'MiT Strom Pipeline'!$I$6:$I$860) -> 0 | L20: =K20+(26-ROW())*0.0001 -> 0.0006
A21: 7 | B21: =IFERROR(INDEX($J$14:$J$39,MATCH(LARGE($L$14:$L$39,7),$L$14:$L$39,0)),"") -> SG | C21: =IF(B21="","",SUMIF('MiT Strom Pipeline'!$C$6:$C$860,B21,'MiT Strom Pipeline'!$I$6:$I$860)) -> 101192.62 | D21: =IF(B21="","",COUNTIF('MiT Strom Pipeline'!$C$6:$C$860,B21)) -> 3 | E21: =IF(OR(B21="",D21=0),"",COUNTIFS('MiT Strom Pipeline'!$C$6:$C$860,B21,'MiT Strom Pipeline'!$R$6:$R$860,"WON")/D21) -> 0.33333333 | J21: GE | K21: =SUMIF('MiT Strom Pipeline'!$C$6:$C$860,J21,'MiT Strom Pipeline'!$I$6:$I$860) -> 38885 | L21: =K21+(26-ROW())*0.0001 -> 38885.001
A22: 8 | B22: =IFERROR(INDEX($J$14:$J$39,MATCH(LARGE($L$14:$L$39,8),$L$14:$L$39,0)),"") -> GR | C22: =IF(B22="","",SUMIF('MiT Strom Pipeline'!$C$6:$C$860,B22,'MiT Strom Pipeline'!$I$6:$I$860)) -> 77325.62 | D22: =IF(B22="","",COUNTIF('MiT Strom Pipeline'!$C$6:$C$860,B22)) -> 2 | E22: =IF(OR(B22="",D22=0),"",COUNTIFS('MiT Strom Pipeline'!$C$6:$C$860,B22,'MiT Strom Pipeline'!$R$6:$R$860,"WON")/D22) -> 0 | J22: GL | K22: =SUMIF('MiT Strom Pipeline'!$C$6:$C$860,J22,'MiT Strom Pipeline'!$I$6:$I$860) -> 0 | L22: =K22+(26-ROW())*0.0001 -> 0.0004
A23: 9 | B23: =IFERROR(INDEX($J$14:$J$39,MATCH(LARGE($L$14:$L$39,9),$L$14:$L$39,0)),"") -> BE | C23: =IF(B23="","",SUMIF('MiT Strom Pipeline'!$C$6:$C$860,B23,'MiT Strom Pipeline'!$I$6:$I$860)) -> 58012.12 | D23: =IF(B23="","",COUNTIF('MiT Strom Pipeline'!$C$6:$C$860,B23)) -> 5 | E23: =IF(OR(B23="",D23=0),"",COUNTIFS('MiT Strom Pipeline'!$C$6:$C$860,B23,'MiT Strom Pipeline'!$R$6:$R$860,"WON")/D23) -> 0 | J23: GR | K23: =SUMIF('MiT Strom Pipeline'!$C$6:$C$860,J23,'MiT Strom Pipeline'!$I$6:$I$860) -> 77325.62 | L23: =K23+(26-ROW())*0.0001 -> 77325.62
A24: 10 | B24: =IFERROR(INDEX($J$14:$J$39,MATCH(LARGE($L$14:$L$39,10),$L$14:$L$39,0)),"") -> ZG | C24: =IF(B24="","",SUMIF('MiT Strom Pipeline'!$C$6:$C$860,B24,'MiT Strom Pipeline'!$I$6:$I$860)) -> 40491.67 | D24: =IF(B24="","",COUNTIF('MiT Strom Pipeline'!$C$6:$C$860,B24)) -> 1 | E24: =IF(OR(B24="",D24=0),"",COUNTIFS('MiT Strom Pipeline'!$C$6:$C$860,B24,'MiT Strom Pipeline'!$R$6:$R$860,"WON")/D24) -> 0 | J24: JU | K24: =SUMIF('MiT Strom Pipeline'!$C$6:$C$860,J24,'MiT Strom Pipeline'!$I$6:$I$860) -> 0 | L24: =K24+(26-ROW())*0.0001 -> 0.0002
J25: LU | K25: =SUMIF('MiT Strom Pipeline'!$C$6:$C$860,J25,'MiT Strom Pipeline'!$I$6:$I$860) -> 23626.77 | L25: =K25+(26-ROW())*0.0001 -> 23626.77
J26: NE | K26: =SUMIF('MiT Strom Pipeline'!$C$6:$C$860,J26,'MiT Strom Pipeline'!$I$6:$I$860) -> 0 | L26: =K26+(26-ROW())*0.0001 -> 0
A27: Top WON-Deals | J27: NW | K27: =SUMIF('MiT Strom Pipeline'!$C$6:$C$860,J27,'MiT Strom Pipeline'!$I$6:$I$860) -> 0 | L27: =K27+(26-ROW())*0.0001 -> -0.0001
A28: Rang | B28: Kunde | C28: Kanton | D28: Segment | E28: Volumen CHF | F28: Projektstart | G28: Projektende | J28: OW | K28: =SUMIF('MiT Strom Pipeline'!$C$6:$C$860,J28,'MiT Strom Pipeline'!$I$6:$I$860) -> 0 | L28: =K28+(26-ROW())*0.0001 -> -0.0002
A29: 1 | B29: =IFERROR(INDEX('MiT Strom Pipeline'!$B$6:$B$860,MATCH(LARGE('MiT Strom Pipeline'!$AK$6:$AK$860,1),'MiT Strom Pipeline'!$AK$6:$AK$860,0)),"") -> Ice Hockey Championship | C29: =IFERROR(INDEX('MiT Strom Pipeline'!$C$6:$C$860,MATCH(LARGE('MiT Strom Pipeline'!$AK$6:$AK$860,1),'MiT Strom Pipeline'!$AK$6:$AK$860,0)),"") -> ZH | D29: =IFERROR(INDEX('MiT Strom Pipeline'!$D$6:$D$860,MATCH(LARGE('MiT Strom Pipeline'!$AK$6:$AK$860,1),'MiT Strom Pipeline'!$AK$6:$AK$860,0)),"") -> Events & Sport | E29: =IFERROR(INDEX('MiT Strom Pipeline'!$I$6:$I$860,MATCH(LARGE('MiT Strom Pipeline'!$AK$6:$AK$860,1),'MiT Strom Pipeline'!$AK$6:$AK$860,0)),"") -> 380000 | F29: =IFERROR(IF(ISNUMBER(INDEX('MiT Strom Pipeline'!$O$6:$O$860,MATCH(LARGE('MiT Strom Pipeline'!$AK$6:$AK$860,1),'MiT Strom Pipeline'!$AK$6:$AK$860,0))),INDEX('MiT Strom Pipeline'!$O$6:$O$860,MATCH(LARGE('MiT Strom Pipeline'!$AK$6:$AK$860,1),'MiT Strom Pipeline'!$AK$6:$AK$860,0)),IF(INDEX('MiT Strom Pipeline'!$H$6:$H$860,MATCH(LARGE('MiT Strom Pipeline'!$AK$6:$AK$860,1),'MiT Strom Pipeline'!$AK$6:$AK$860,0))="","",INDEX('MiT Strom Pipeline'!$H$6:$H$860,MATCH(LARGE('MiT Strom Pipeline'!$AK$6:$AK$860,1),'MiT Strom Pipeline'!$AK$6:$AK$860,0)))),"") -> Mai | G29: =IFERROR(IF(ISNUMBER(INDEX('MiT Strom Pipeline'!$P$6:$P$860,MATCH(LARGE('MiT Strom Pipeline'!$AK$6:$AK$860,1),'MiT Strom Pipeline'!$AK$6:$AK$860,0))),INDEX('MiT Strom Pipeline'!$P$6:$P$860,MATCH(LARGE('MiT Strom Pipeline'!$AK$6:$AK$860,1),'MiT Strom Pipeline'!$AK$6:$AK$860,0)),""),"") | J29: SG | K29: =SUMIF('MiT Strom Pipeline'!$C$6:$C$860,J29,'MiT Strom Pipeline'!$I$6:$I$860) -> 101192.62 | L29: =K29+(26-ROW())*0.0001 -> 101192.62
A30: 2 | B30: =IFERROR(INDEX('MiT Strom Pipeline'!$B$6:$B$860,MATCH(LARGE('MiT Strom Pipeline'!$AK$6:$AK$860,2),'MiT Strom Pipeline'!$AK$6:$AK$860,0)),"") -> DPR Heat Loadbank | C30: =IFERROR(INDEX('MiT Strom Pipeline'!$C$6:$C$860,MATCH(LARGE('MiT Strom Pipeline'!$AK$6:$AK$860,2),'MiT Strom Pipeline'!$AK$6:$AK$860,0)),"") -> ZH | D30: =IFERROR(INDEX('MiT Strom Pipeline'!$D$6:$D$860,MATCH(LARGE('MiT Strom Pipeline'!$AK$6:$AK$860,2),'MiT Strom Pipeline'!$AK$6:$AK$860,0)),"") -> Datacenter | E30: =IFERROR(INDEX('MiT Strom Pipeline'!$I$6:$I$860,MATCH(LARGE('MiT Strom Pipeline'!$AK$6:$AK$860,2),'MiT Strom Pipeline'!$AK$6:$AK$860,0)),"") -> 333790 | F30: =IFERROR(IF(ISNUMBER(INDEX('MiT Strom Pipeline'!$O$6:$O$860,MATCH(LARGE('MiT Strom Pipeline'!$AK$6:$AK$860,2),'MiT Strom Pipeline'!$AK$6:$AK$860,0))),INDEX('MiT Strom Pipeline'!$O$6:$O$860,MATCH(LARGE('MiT Strom Pipeline'!$AK$6:$AK$860,2),'MiT Strom Pipeline'!$AK$6:$AK$860,0)),IF(INDEX('MiT Strom Pipeline'!$H$6:$H$860,MATCH(LARGE('MiT Strom Pipeline'!$AK$6:$AK$860,2),'MiT Strom Pipeline'!$AK$6:$AK$860,0))="","",INDEX('MiT Strom Pipeline'!$H$6:$H$860,MATCH(LARGE('MiT Strom Pipeline'!$AK$6:$AK$860,2),'MiT Strom Pipeline'!$AK$6:$AK$860,0)))),"") -> Aug | G30: =IFERROR(IF(ISNUMBER(INDEX('MiT Strom Pipeline'!$P$6:$P$860,MATCH(LARGE('MiT Strom Pipeline'!$AK$6:$AK$860,2),'MiT Strom Pipeline'!$AK$6:$AK$860,0))),INDEX('MiT Strom Pipeline'!$P$6:$P$860,MATCH(LARGE('MiT Strom Pipeline'!$AK$6:$AK$860,2),'MiT Strom Pipeline'!$AK$6:$AK$860,0)),""),"") | J30: SH | K30: =SUMIF('MiT Strom Pipeline'!$C$6:$C$860,J30,'MiT Strom Pipeline'!$I$6:$I$860) -> 2637287.6 | L30: =K30+(26-ROW())*0.0001 -> 2637287.6
A31: 3 | B31: =IFERROR(INDEX('MiT Strom Pipeline'!$B$6:$B$860,MATCH(LARGE('MiT Strom Pipeline'!$AK$6:$AK$860,3),'MiT Strom Pipeline'!$AK$6:$AK$860,0)),"") -> DPR Generator Loadbank Test | C31: =IFERROR(INDEX('MiT Strom Pipeline'!$C$6:$C$860,MATCH(LARGE('MiT Strom Pipeline'!$AK$6:$AK$860,3),'MiT Strom Pipeline'!$AK$6:$AK$860,0)),"") -> ZH | D31: =IFERROR(INDEX('MiT Strom Pipeline'!$D$6:$D$860,MATCH(LARGE('MiT Strom Pipeline'!$AK$6:$AK$860,3),'MiT Strom Pipeline'!$AK$6:$AK$860,0)),"") -> Datacenter | E31: =IFERROR(INDEX('MiT Strom Pipeline'!$I$6:$I$860,MATCH(LARGE('MiT Strom Pipeline'!$AK$6:$AK$860,3),'MiT Strom Pipeline'!$AK$6:$AK$860,0)),"") -> 331889.15 | F31: =IFERROR(IF(ISNUMBER(INDEX('MiT Strom Pipeline'!$O$6:$O$860,MATCH(LARGE('MiT Strom Pipeline'!$AK$6:$AK$860,3),'MiT Strom Pipeline'!$AK$6:$AK$860,0))),INDEX('MiT Strom Pipeline'!$O$6:$O$860,MATCH(LARGE('MiT Strom Pipeline'!$AK$6:$AK$860,3),'MiT Strom Pipeline'!$AK$6:$AK$860,0)),IF(INDEX('MiT Strom Pipeline'!$H$6:$H$860,MATCH(LARGE('MiT Strom Pipeline'!$AK$6:$AK$860,3),'MiT Strom Pipeline'!$AK$6:$AK$860,0))="","",INDEX('MiT Strom Pipeline'!$H$6:$H$860,MATCH(LARGE('MiT Strom Pipeline'!$AK$6:$AK$860,3),'MiT Strom Pipeline'!$AK$6:$AK$860,0)))),"") -> Aug | G31: =IFERROR(IF(ISNUMBER(INDEX('MiT Strom Pipeline'!$P$6:$P$860,MATCH(LARGE('MiT Strom Pipeline'!$AK$6:$AK$860,3),'MiT Strom Pipeline'!$AK$6:$AK$860,0))),INDEX('MiT Strom Pipeline'!$P$6:$P$860,MATCH(LARGE('MiT Strom Pipeline'!$AK$6:$AK$860,3),'MiT Strom Pipeline'!$AK$6:$AK$860,0)),""),"") | J31: SO | K31: =SUMIF('MiT Strom Pipeline'!$C$6:$C$860,J31,'MiT Strom Pipeline'!$I$6:$I$860) -> 390750.65 | L31: =K31+(26-ROW())*0.0001 -> 390750.65
A32: 4 | B32: =IFERROR(INDEX('MiT Strom Pipeline'!$B$6:$B$860,MATCH(LARGE('MiT Strom Pipeline'!$AK$6:$AK$860,4),'MiT Strom Pipeline'!$AK$6:$AK$860,0)),"") -> Stagelight – OpenAir Frauenfeld | C32: =IFERROR(INDEX('MiT Strom Pipeline'!$C$6:$C$860,MATCH(LARGE('MiT Strom Pipeline'!$AK$6:$AK$860,4),'MiT Strom Pipeline'!$AK$6:$AK$860,0)),"") -> TG | D32: =IFERROR(INDEX('MiT Strom Pipeline'!$D$6:$D$860,MATCH(LARGE('MiT Strom Pipeline'!$AK$6:$AK$860,4),'MiT Strom Pipeline'!$AK$6:$AK$860,0)),"") -> Events & Kultur | E32: =IFERROR(INDEX('MiT Strom Pipeline'!$I$6:$I$860,MATCH(LARGE('MiT Strom Pipeline'!$AK$6:$AK$860,4),'MiT Strom Pipeline'!$AK$6:$AK$860,0)),"") -> 150000 | F32: =IFERROR(IF(ISNUMBER(INDEX('MiT Strom Pipeline'!$O$6:$O$860,MATCH(LARGE('MiT Strom Pipeline'!$AK$6:$AK$860,4),'MiT Strom Pipeline'!$AK$6:$AK$860,0))),INDEX('MiT Strom Pipeline'!$O$6:$O$860,MATCH(LARGE('MiT Strom Pipeline'!$AK$6:$AK$860,4),'MiT Strom Pipeline'!$AK$6:$AK$860,0)),IF(INDEX('MiT Strom Pipeline'!$H$6:$H$860,MATCH(LARGE('MiT Strom Pipeline'!$AK$6:$AK$860,4),'MiT Strom Pipeline'!$AK$6:$AK$860,0))="","",INDEX('MiT Strom Pipeline'!$H$6:$H$860,MATCH(LARGE('MiT Strom Pipeline'!$AK$6:$AK$860,4),'MiT Strom Pipeline'!$AK$6:$AK$860,0)))),"") -> Juli | G32: =IFERROR(IF(ISNUMBER(INDEX('MiT Strom Pipeline'!$P$6:$P$860,MATCH(LARGE('MiT Strom Pipeline'!$AK$6:$AK$860,4),'MiT Strom Pipeline'!$AK$6:$AK$860,0))),INDEX('MiT Strom Pipeline'!$P$6:$P$860,MATCH(LARGE('MiT Strom Pipeline'!$AK$6:$AK$860,4),'MiT Strom Pipeline'!$AK$6:$AK$860,0)),""),"") | J32: SZ | K32: =SUMIF('MiT Strom Pipeline'!$C$6:$C$860,J32,'MiT Strom Pipeline'!$I$6:$I$860) -> 0 | L32: =K32+(26-ROW())*0.0001 -> -0.0006
A33: 5 | B33: =IFERROR(INDEX('MiT Strom Pipeline'!$B$6:$B$860,MATCH(LARGE('MiT Strom Pipeline'!$AK$6:$AK$860,5),'MiT Strom Pipeline'!$AK$6:$AK$860,0)),"") -> Murg Flums Energie | C33: =IFERROR(INDEX('MiT Strom Pipeline'!$C$6:$C$860,MATCH(LARGE('MiT Strom Pipeline'!$AK$6:$AK$860,5),'MiT Strom Pipeline'!$AK$6:$AK$860,0)),"") -> SG | D33: =IFERROR(INDEX('MiT Strom Pipeline'!$D$6:$D$860,MATCH(LARGE('MiT Strom Pipeline'!$AK$6:$AK$860,5),'MiT Strom Pipeline'!$AK$6:$AK$860,0)),"") -> EVU / Energie | E33: =IFERROR(INDEX('MiT Strom Pipeline'!$I$6:$I$860,MATCH(LARGE('MiT Strom Pipeline'!$AK$6:$AK$860,5),'MiT Strom Pipeline'!$AK$6:$AK$860,0)),"") -> 96658.69 | F33: =IFERROR(IF(ISNUMBER(INDEX('MiT Strom Pipeline'!$O$6:$O$860,MATCH(LARGE('MiT Strom Pipeline'!$AK$6:$AK$860,5),'MiT Strom Pipeline'!$AK$6:$AK$860,0))),INDEX('MiT Strom Pipeline'!$O$6:$O$860,MATCH(LARGE('MiT Strom Pipeline'!$AK$6:$AK$860,5),'MiT Strom Pipeline'!$AK$6:$AK$860,0)),IF(INDEX('MiT Strom Pipeline'!$H$6:$H$860,MATCH(LARGE('MiT Strom Pipeline'!$AK$6:$AK$860,5),'MiT Strom Pipeline'!$AK$6:$AK$860,0))="","",INDEX('MiT Strom Pipeline'!$H$6:$H$860,MATCH(LARGE('MiT Strom Pipeline'!$AK$6:$AK$860,5),'MiT Strom Pipeline'!$AK$6:$AK$860,0)))),"") -> Auf Abruf | G33: =IFERROR(IF(ISNUMBER(INDEX('MiT Strom Pipeline'!$P$6:$P$860,MATCH(LARGE('MiT Strom Pipeline'!$AK$6:$AK$860,5),'MiT Strom Pipeline'!$AK$6:$AK$860,0))),INDEX('MiT Strom Pipeline'!$P$6:$P$860,MATCH(LARGE('MiT Strom Pipeline'!$AK$6:$AK$860,5),'MiT Strom Pipeline'!$AK$6:$AK$860,0)),""),"") | J33: TG | K33: =SUMIF('MiT Strom Pipeline'!$C$6:$C$860,J33,'MiT Strom Pipeline'!$I$6:$I$860) -> 160817.26 | L33: =K33+(26-ROW())*0.0001 -> 160817.26
A34: 6 | B34: =IFERROR(INDEX('MiT Strom Pipeline'!$B$6:$B$860,MATCH(LARGE('MiT Strom Pipeline'!$AK$6:$AK$860,6),'MiT Strom Pipeline'!$AK$6:$AK$860,0)),"") -> Gampeln | C34: =IFERROR(INDEX('MiT Strom Pipeline'!$C$6:$C$860,MATCH(LARGE('MiT Strom Pipeline'!$AK$6:$AK$860,6),'MiT Strom Pipeline'!$AK$6:$AK$860,0)),"") -> VS | D34: =IFERROR(INDEX('MiT Strom Pipeline'!$D$6:$D$860,MATCH(LARGE('MiT Strom Pipeline'!$AK$6:$AK$860,6),'MiT Strom Pipeline'!$AK$6:$AK$860,0)),"") -> Event | E34: =IFERROR(INDEX('MiT Strom Pipeline'!$I$6:$I$860,MATCH(LARGE('MiT Strom Pipeline'!$AK$6:$AK$860,6),'MiT Strom Pipeline'!$AK$6:$AK$860,0)),"") -> 80621.21 | F34: =IFERROR(IF(ISNUMBER(INDEX('MiT Strom Pipeline'!$O$6:$O$860,MATCH(LARGE('MiT Strom Pipeline'!$AK$6:$AK$860,6),'MiT Strom Pipeline'!$AK$6:$AK$860,0))),INDEX('MiT Strom Pipeline'!$O$6:$O$860,MATCH(LARGE('MiT Strom Pipeline'!$AK$6:$AK$860,6),'MiT Strom Pipeline'!$AK$6:$AK$860,0)),IF(INDEX('MiT Strom Pipeline'!$H$6:$H$860,MATCH(LARGE('MiT Strom Pipeline'!$AK$6:$AK$860,6),'MiT Strom Pipeline'!$AK$6:$AK$860,0))="","",INDEX('MiT Strom Pipeline'!$H$6:$H$860,MATCH(LARGE('MiT Strom Pipeline'!$AK$6:$AK$860,6),'MiT Strom Pipeline'!$AK$6:$AK$860,0)))),"") -> Aug | G34: =IFERROR(IF(ISNUMBER(INDEX('MiT Strom Pipeline'!$P$6:$P$860,MATCH(LARGE('MiT Strom Pipeline'!$AK$6:$AK$860,6),'MiT Strom Pipeline'!$AK$6:$AK$860,0))),INDEX('MiT Strom Pipeline'!$P$6:$P$860,MATCH(LARGE('MiT Strom Pipeline'!$AK$6:$AK$860,6),'MiT Strom Pipeline'!$AK$6:$AK$860,0)),""),"") | J34: TI | K34: =SUMIF('MiT Strom Pipeline'!$C$6:$C$860,J34,'MiT Strom Pipeline'!$I$6:$I$860) -> 0 | L34: =K34+(26-ROW())*0.0001 -> -0.0008
A35: 7 | B35: =IFERROR(INDEX('MiT Strom Pipeline'!$B$6:$B$860,MATCH(LARGE('MiT Strom Pipeline'!$AK$6:$AK$860,7),'MiT Strom Pipeline'!$AK$6:$AK$860,0)),"") -> EIDG AMT Agroscope | C35: =IFERROR(INDEX('MiT Strom Pipeline'!$C$6:$C$860,MATCH(LARGE('MiT Strom Pipeline'!$AK$6:$AK$860,7),'MiT Strom Pipeline'!$AK$6:$AK$860,0)),"") -> ZH | D35: =IFERROR(INDEX('MiT Strom Pipeline'!$D$6:$D$860,MATCH(LARGE('MiT Strom Pipeline'!$AK$6:$AK$860,7),'MiT Strom Pipeline'!$AK$6:$AK$860,0)),"") -> Forschung | E35: =IFERROR(INDEX('MiT Strom Pipeline'!$I$6:$I$860,MATCH(LARGE('MiT Strom Pipeline'!$AK$6:$AK$860,7),'MiT Strom Pipeline'!$AK$6:$AK$860,0)),"") -> 13533 | F35: =IFERROR(IF(ISNUMBER(INDEX('MiT Strom Pipeline'!$O$6:$O$860,MATCH(LARGE('MiT Strom Pipeline'!$AK$6:$AK$860,7),'MiT Strom Pipeline'!$AK$6:$AK$860,0))),INDEX('MiT Strom Pipeline'!$O$6:$O$860,MATCH(LARGE('MiT Strom Pipeline'!$AK$6:$AK$860,7),'MiT Strom Pipeline'!$AK$6:$AK$860,0)),IF(INDEX('MiT Strom Pipeline'!$H$6:$H$860,MATCH(LARGE('MiT Strom Pipeline'!$AK$6:$AK$860,7),'MiT Strom Pipeline'!$AK$6:$AK$860,0))="","",INDEX('MiT Strom Pipeline'!$H$6:$H$860,MATCH(LARGE('MiT Strom Pipeline'!$AK$6:$AK$860,7),'MiT Strom Pipeline'!$AK$6:$AK$860,0)))),"") -> Aug | G35: =IFERROR(IF(ISNUMBER(INDEX('MiT Strom Pipeline'!$P$6:$P$860,MATCH(LARGE('MiT Strom Pipeline'!$AK$6:$AK$860,7),'MiT Strom Pipeline'!$AK$6:$AK$860,0))),INDEX('MiT Strom Pipeline'!$P$6:$P$860,MATCH(LARGE('MiT Strom Pipeline'!$AK$6:$AK$860,7),'MiT Strom Pipeline'!$AK$6:$AK$860,0)),""),"") | J35: UR | K35: =SUMIF('MiT Strom Pipeline'!$C$6:$C$860,J35,'MiT Strom Pipeline'!$I$6:$I$860) -> 0 | L35: =K35+(26-ROW())*0.0001 -> -0.0009
A36: 8 | B36: =IFERROR(INDEX('MiT Strom Pipeline'!$B$6:$B$860,MATCH(LARGE('MiT Strom Pipeline'!$AK$6:$AK$860,8),'MiT Strom Pipeline'!$AK$6:$AK$860,0)),"") -> GETEC Park.Swiss AG | C36: =IFERROR(INDEX('MiT Strom Pipeline'!$C$6:$C$860,MATCH(LARGE('MiT Strom Pipeline'!$AK$6:$AK$860,8),'MiT Strom Pipeline'!$AK$6:$AK$860,0)),"") -> BL | D36: =IFERROR(INDEX('MiT Strom Pipeline'!$D$6:$D$860,MATCH(LARGE('MiT Strom Pipeline'!$AK$6:$AK$860,8),'MiT Strom Pipeline'!$AK$6:$AK$860,0)),"") -> Industrie | E36: =IFERROR(INDEX('MiT Strom Pipeline'!$I$6:$I$860,MATCH(LARGE('MiT Strom Pipeline'!$AK$6:$AK$860,8),'MiT Strom Pipeline'!$AK$6:$AK$860,0)),"") -> 13472.18 | F36: =IFERROR(IF(ISNUMBER(INDEX('MiT Strom Pipeline'!$O$6:$O$860,MATCH(LARGE('MiT Strom Pipeline'!$AK$6:$AK$860,8),'MiT Strom Pipeline'!$AK$6:$AK$860,0))),INDEX('MiT Strom Pipeline'!$O$6:$O$860,MATCH(LARGE('MiT Strom Pipeline'!$AK$6:$AK$860,8),'MiT Strom Pipeline'!$AK$6:$AK$860,0)),IF(INDEX('MiT Strom Pipeline'!$H$6:$H$860,MATCH(LARGE('MiT Strom Pipeline'!$AK$6:$AK$860,8),'MiT Strom Pipeline'!$AK$6:$AK$860,0))="","",INDEX('MiT Strom Pipeline'!$H$6:$H$860,MATCH(LARGE('MiT Strom Pipeline'!$AK$6:$AK$860,8),'MiT Strom Pipeline'!$AK$6:$AK$860,0)))),"") -> August | G36: =IFERROR(IF(ISNUMBER(INDEX('MiT Strom Pipeline'!$P$6:$P$860,MATCH(LARGE('MiT Strom Pipeline'!$AK$6:$AK$860,8),'MiT Strom Pipeline'!$AK$6:$AK$860,0))),INDEX('MiT Strom Pipeline'!$P$6:$P$860,MATCH(LARGE('MiT Strom Pipeline'!$AK$6:$AK$860,8),'MiT Strom Pipeline'!$AK$6:$AK$860,0)),""),"") | J36: VD | K36: =SUMIF('MiT Strom Pipeline'!$C$6:$C$860,J36,'MiT Strom Pipeline'!$I$6:$I$860) -> 0 | L36: =K36+(26-ROW())*0.0001 -> -0.001
A37: 9 | B37: =IFERROR(INDEX('MiT Strom Pipeline'!$B$6:$B$860,MATCH(LARGE('MiT Strom Pipeline'!$AK$6:$AK$860,9),'MiT Strom Pipeline'!$AK$6:$AK$860,0)),"") -> Oerlikon Metco Wohlen | C37: =IFERROR(INDEX('MiT Strom Pipeline'!$C$6:$C$860,MATCH(LARGE('MiT Strom Pipeline'!$AK$6:$AK$860,9),'MiT Strom Pipeline'!$AK$6:$AK$860,0)),"") -> AG | D37: =IFERROR(INDEX('MiT Strom Pipeline'!$D$6:$D$860,MATCH(LARGE('MiT Strom Pipeline'!$AK$6:$AK$860,9),'MiT Strom Pipeline'!$AK$6:$AK$860,0)),"") -> Industrie / Oberfläche | E37: =IFERROR(INDEX('MiT Strom Pipeline'!$I$6:$I$860,MATCH(LARGE('MiT Strom Pipeline'!$AK$6:$AK$860,9),'MiT Strom Pipeline'!$AK$6:$AK$860,0)),"") -> 13100 | F37: =IFERROR(IF(ISNUMBER(INDEX('MiT Strom Pipeline'!$O$6:$O$860,MATCH(LARGE('MiT Strom Pipeline'!$AK$6:$AK$860,9),'MiT Strom Pipeline'!$AK$6:$AK$860,0))),INDEX('MiT Strom Pipeline'!$O$6:$O$860,MATCH(LARGE('MiT Strom Pipeline'!$AK$6:$AK$860,9),'MiT Strom Pipeline'!$AK$6:$AK$860,0)),IF(INDEX('MiT Strom Pipeline'!$H$6:$H$860,MATCH(LARGE('MiT Strom Pipeline'!$AK$6:$AK$860,9),'MiT Strom Pipeline'!$AK$6:$AK$860,0))="","",INDEX('MiT Strom Pipeline'!$H$6:$H$860,MATCH(LARGE('MiT Strom Pipeline'!$AK$6:$AK$860,9),'MiT Strom Pipeline'!$AK$6:$AK$860,0)))),"") -> April | G37: =IFERROR(IF(ISNUMBER(INDEX('MiT Strom Pipeline'!$P$6:$P$860,MATCH(LARGE('MiT Strom Pipeline'!$AK$6:$AK$860,9),'MiT Strom Pipeline'!$AK$6:$AK$860,0))),INDEX('MiT Strom Pipeline'!$P$6:$P$860,MATCH(LARGE('MiT Strom Pipeline'!$AK$6:$AK$860,9),'MiT Strom Pipeline'!$AK$6:$AK$860,0)),""),"") | J37: VS | K37: =SUMIF('MiT Strom Pipeline'!$C$6:$C$860,J37,'MiT Strom Pipeline'!$I$6:$I$860) -> 303790.2 | L37: =K37+(26-ROW())*0.0001 -> 303790.2
A38: 10 | B38: =IFERROR(INDEX('MiT Strom Pipeline'!$B$6:$B$860,MATCH(LARGE('MiT Strom Pipeline'!$AK$6:$AK$860,10),'MiT Strom Pipeline'!$AK$6:$AK$860,0)),"") -> Siemens | C38: =IFERROR(INDEX('MiT Strom Pipeline'!$C$6:$C$860,MATCH(LARGE('MiT Strom Pipeline'!$AK$6:$AK$860,10),'MiT Strom Pipeline'!$AK$6:$AK$860,0)),"") -> ZH | D38: =IFERROR(INDEX('MiT Strom Pipeline'!$D$6:$D$860,MATCH(LARGE('MiT Strom Pipeline'!$AK$6:$AK$860,10),'MiT Strom Pipeline'!$AK$6:$AK$860,0)),"") -> Industrie / Elektro | E38: =IFERROR(INDEX('MiT Strom Pipeline'!$I$6:$I$860,MATCH(LARGE('MiT Strom Pipeline'!$AK$6:$AK$860,10),'MiT Strom Pipeline'!$AK$6:$AK$860,0)),"") -> 10000 | F38: =IFERROR(IF(ISNUMBER(INDEX('MiT Strom Pipeline'!$O$6:$O$860,MATCH(LARGE('MiT Strom Pipeline'!$AK$6:$AK$860,10),'MiT Strom Pipeline'!$AK$6:$AK$860,0))),INDEX('MiT Strom Pipeline'!$O$6:$O$860,MATCH(LARGE('MiT Strom Pipeline'!$AK$6:$AK$860,10),'MiT Strom Pipeline'!$AK$6:$AK$860,0)),IF(INDEX('MiT Strom Pipeline'!$H$6:$H$860,MATCH(LARGE('MiT Strom Pipeline'!$AK$6:$AK$860,10),'MiT Strom Pipeline'!$AK$6:$AK$860,0))="","",INDEX('MiT Strom Pipeline'!$H$6:$H$860,MATCH(LARGE('MiT Strom Pipeline'!$AK$6:$AK$860,10),'MiT Strom Pipeline'!$AK$6:$AK$860,0)))),"") -> tbd | G38: =IFERROR(IF(ISNUMBER(INDEX('MiT Strom Pipeline'!$P$6:$P$860,MATCH(LARGE('MiT Strom Pipeline'!$AK$6:$AK$860,10),'MiT Strom Pipeline'!$AK$6:$AK$860,0))),INDEX('MiT Strom Pipeline'!$P$6:$P$860,MATCH(LARGE('MiT Strom Pipeline'!$AK$6:$AK$860,10),'MiT Strom Pipeline'!$AK$6:$AK$860,0)),""),"") | J38: ZG | K38: =SUMIF('MiT Strom Pipeline'!$C$6:$C$860,J38,'MiT Strom Pipeline'!$I$6:$I$860) -> 40491.67 | L38: =K38+(26-ROW())*0.0001 -> 40491.669
J39: ZH | K39: =SUMIF('MiT Strom Pipeline'!$C$6:$C$860,J39,'MiT Strom Pipeline'!$I$6:$I$860) -> 2732239 | L39: =K39+(26-ROW())*0.0001 -> 2732239
A40: ↻ Auto-Update aus Pipeline · Sortiert nach Volumen ↓ · Nur WON mit numerischem Volumen
A43: ⚖️ Wahrscheinlichkeits-Bewertung (Aggreko-Modell)
...

Sheet CEO Report
A1: ="⚡ MiT Strom Schweiz — CEO Sales Report · "&TEXT(TODAY(),"MMMM YYYY") -> ⚡ MiT Strom Schweiz — CEO Sales Report · August 2026
A2: Mobil in Time AG · An Aggreko Company · Burak Ücöz · Neue Einträge in «MiT Strom Pipeline» erscheinen automatisch.
A5: ✅ AUFTRAGSEINGANG (WON) | E5: 📄 OFFERTE — Laufend | I5: 🎯 OPPORTUNITÄT
A6: =SUMIFS('MiT Strom Pipeline'!I$6:I$860,'MiT Strom Pipeline'!R$6:R$860,"WON") -> 1428553.1 | E6: =SUMIFS('MiT Strom Pipeline'!I$6:I$860,'MiT Strom Pipeline'!R$6:R$860,"offered")+SUMIFS('MiT Strom Pipeline'!I$6:I$860,'MiT Strom Pipeline'!R$6:R$860,"to be offered")+SUMIFS('MiT Strom Pipeline'!I$6:I$860,'MiT Strom Pipeline'!R$6:R$860,"on hold") -> 5433596.1 | I6: =SUMIFS('MiT Strom Pipeline'!I$6:I$860,'MiT Strom Pipeline'!R$6:R$860,"follow-up")+SUMIFS('MiT Strom Pipeline'!I$6:I$860,'MiT Strom Pipeline'!R$6:R$860,"Evaluation")+SUMIFS('MiT Strom Pipeline'!I$6:I$860,'MiT Strom Pipeline'!R$6:R$860,"tbd")+SUMIFS('MiT Strom Pipeline'!I$6:I$860,'MiT Strom Pipeline'!R$6:R$860,"In evaluation") -> 0
A7: =COUNTIF('MiT Strom Pipeline'!R$6:R$860,"WON") -> 12 | E7: =COUNTIF('MiT Strom Pipeline'!R$6:R$860,"offered")+COUNTIF('MiT Strom Pipeline'!R$6:R$860,"to be offered")+COUNTIF('MiT Strom Pipeline'!R$6:R$860,"on hold") -> 33 | I7: =COUNTIF('MiT Strom Pipeline'!R$6:R$860,"follow-up")+COUNTIF('MiT Strom Pipeline'!R$6:R$860,"Evaluation")+COUNTIF('MiT Strom Pipeline'!R$6:R$860,"tbd")+COUNTIF('MiT Strom Pipeline'!R$6:R$860,"In evaluation") -> 1
A8: ="⚖️ Gewichtete Pipeline (Aggreko-Faktoren 0 / 30 / 50 / 90 %): "&TEXT(SUMIFS('MiT Strom Pipeline'!$Q$6:$Q$860,'MiT Strom Pipeline'!$R$6:$R$860,"WON")+SUMIFS('MiT Strom Pipeline'!$Q$6:$Q$860,'MiT Strom Pipeline'!$R$6:$R$860,"offered")+SUMIFS('MiT Strom Pipeline'!$Q$6:$Q$860,'MiT Strom Pipeline'!$R$6:$R$860,"to be offered")+SUMIFS('MiT Strom Pipeline'!$Q$6:$Q$860,'MiT Strom Pipeline'!$R$6:$R$860,"on hold")+SUMIFS('MiT Strom Pipeline'!$Q$6:$Q$860,'MiT Strom Pipeline'!$R$6:$R$860,"follow-up")+SUMIFS('MiT Strom Pipeline'!$Q$6:$Q$860,'MiT Strom Pipeline'!$R$6:$R$860,"Evaluation")+SUMIFS('MiT Strom Pipeline'!$Q$6:$Q$860,'MiT Strom Pipeline'!$R$6:$R$860,"In evaluation")+SUMIFS('MiT Strom Pipeline'!$Q$6:$Q$860,'MiT Strom Pipeline'!$R$6:$R$860,"tbd"),"#,##0")&" CHF · davon Offerte: "&TEXT(SUMIFS('MiT Strom Pipeline'!$Q$6:$Q$860,'MiT Strom Pipeline'!$R$6:$R$860,"offered")+SUMIFS('MiT Strom Pipeline'!$Q$6:$Q$860,'MiT Strom Pipeline'!$R$6:$R$860,"to be offered")+SUMIFS('MiT Strom Pipeline'!$Q$6:$Q$860,'MiT Strom Pipeline'!$R$6:$R$860,"on hold"),"#,##0")&" CHF · Opportunität: "&TEXT(SUMIFS('MiT Strom Pipeline'!$Q$6:$Q$860,'MiT Strom Pipeline'!$R$6:$R$860,"follow-up")+SUMIFS('MiT Strom Pipeline'!$Q$6:$Q$860,'MiT Strom Pipeline'!$R$6:$R$860,"Evaluation")+SUMIFS('MiT Strom Pipeline'!$Q$6:$Q$860,'MiT Strom Pipeline'!$R$6:$R$860,"In evaluation")+SUMIFS('MiT Strom Pipeline'!$Q$6:$Q$860,'MiT Strom Pipeline'!$R$6:$R$860,"tbd"),"#,##0")&" CHF · Modell: Blatt «⚖️ Wahrscheinlichkeit»" -> ⚖️ Gewichtete Pipeline (Aggreko-Faktoren 0 / 30 / 50 / 90 %): 1,628,426 CHF · davon Offerte: 199,872 CHF · Opportunität: 0 CHF · Modell: Blatt «⚖️ Wahrscheinlichkeit»
A9: ✅ 1. AUFTRAGSEINGANG (WON) — Bestätigte Aufträge
A10: # | B10: Kunde / Unternehmen | C10: Kt. | D10: Segment | E10: Projektstart | F10: Projektende | G10: Volumen CHF | H10: Gew.Wert CHF | I10: Leistung / Fleet | J10: Status | K10: Wahr.% | L10: Nächster Schritt | M10: Auftrag / PO-Nr. | N10: Prüfstatus
A11: =IF($U11="","",IF(ISNUMBER(INDEX('MiT Strom Pipeline'!$A$1:$A$860,$U11)),INDEX('MiT Strom Pipeline'!$A$1:$A$860,$U11),"")) -> 1 | B11: =IF($U11="","",IF(INDEX('MiT Strom Pipeline'!$B$1:$B$860,$U11)="","",INDEX('MiT Strom Pipeline'!$B$1:$B$860,$U11))) -> Ice Hockey Championship | C11: =IF($U11="","",IF(INDEX('MiT Strom Pipeline'!$C$1:$C$860,$U11)="","",INDEX('MiT Strom Pipeline'!$C$1:$C$860,$U11))) -> ZH | D11: =IF($U11="","",IF(INDEX('MiT Strom Pipeline'!$D$1:$D$860,$U11)="","",INDEX('MiT Strom Pipeline'!$D$1:$D$860,$U11))) -> Events & Sport | E11: =IF($U11="","",IF(ISNUMBER(INDEX('MiT Strom Pipeline'!$O$1:$O$860,$U11)),INDEX('MiT Strom Pipeline'!$O$1:$O$860,$U11),IF(INDEX('MiT Strom Pipeline'!$H$1:$H$860,$U11)="","",INDEX('MiT Strom Pipeline'!$H$1:$H$860,$U11)))) -> Mai | F11: =IF($U11="","",IF(ISNUMBER(INDEX('MiT Strom Pipeline'!$P$1:$P$860,$U11)),INDEX('MiT Strom Pipeline'!$P$1:$P$860,$U11),"")) | G11: =IF($U11="","",IF(ISNUMBER(INDEX('MiT Strom Pipeline'!$I$1:$I$860,$U11)),INDEX('MiT Strom Pipeline'!$I$1:$I$860,$U11),0)) -> 380000 | H11: =IF($U11="","",IF(ISNUMBER(INDEX('MiT Strom Pipeline'!$Q$1:$Q$860,$U11)),INDEX('MiT Strom Pipeline'!$Q$1:$Q$860,$U11),0)) -> 380000 | I11: =IF($U11="","",IF(INDEX('MiT Strom Pipeline'!$E$1:$E$860,$U11)="","",INDEX('MiT Strom Pipeline'!$E$1:$E$860,$U11))) -> 2×600+2×200 kVA | J11: =IF($U11="","",INDEX('MiT Strom Pipeline'!$R$1:$R$860,$U11)) -> WON | K11: =IF($U11="","",IF(ISNUMBER(INDEX('MiT Strom Pipeline'!$S$1:$S$860,$U11)),INDEX('MiT Strom Pipeline'!$S$1:$S$860,$U11),"")) -> 1 | L11: =IF($U11="","",IF(LEN(INDEX('MiT Strom Pipeline'!$V$1:$V$860,$U11))>0,LEFT(INDEX('MiT Strom Pipeline'!$V$1:$V$860,$U11),55),"")) -> Abgeschlossen | M11: =IF($U11="","",IF(INDEX('MiT Strom Pipeline'!$AF$1:$AF$860,$U11)="","",INDEX('MiT Strom Pipeline'!$AF$1:$AF$860,$U11))) | N11: =IF($U11="","",IF(INDEX('MiT Strom Pipeline'!$BB$1:$BB$860,$U11)="","",INDEX('MiT Strom Pipeline'!$BB$1:$BB$860,$U11))) -> ⛔ Nachweis fehlt | U11: =IFERROR(MATCH(1,'MiT Strom Pipeline'!$AM$6:$AM$860,0)+5,"") -> 9
A12: =IF($U12="","",IF(ISNUMBER(INDEX('MiT Strom Pipeline'!$A$1:$A$860,$U12)),INDEX('MiT Strom Pipeline'!$A$1:$A$860,$U12),"")) -> 2 | B12: =IF($U12="","",IF(INDEX('MiT Strom Pipeline'!$B$1:$B$860,$U12)="","",INDEX('MiT Strom Pipeline'!$B$1:$B$860,$U12))) -> Oerlikon Metco Wohlen | C12: =IF($U12="","",IF(INDEX('MiT Strom Pipeline'!$C$1:$C$860,$U12)="","",INDEX('MiT Strom Pipeline'!$C$1:$C$860,$U12))) -> AG | D12: =IF($U12="","",IF(INDEX('MiT Strom Pipeline'!$D$1:$D$860,$U12)="","",INDEX('MiT Strom Pipeline'!$D$1:$D$860,$U12))) -> Industrie / Oberfläche | E12: =IF($U12="","",IF(ISNUMBER(INDEX('MiT Strom Pipeline'!$O$1:$O$860,$U12)),INDEX('MiT Strom Pipeline'!$O$1:$O$860,$U12),IF(INDEX('MiT Strom Pipeline'!$H$1:$H$860,$U12)="","",INDEX('MiT Strom Pipeline'!$H$1:$H$860,$U12)))) -> April | F12: =IF($U12="","",IF(ISNUMBER(INDEX('MiT Strom Pipeline'!$P$1:$P$860,$U12)),INDEX('MiT Strom Pipeline'!$P$1:$P$860,$U12),"")) | G12: =IF($U12="","",IF(ISNUMBER(INDEX('MiT Strom Pipeline'!$I$1:$I$860,$U12)),INDEX('MiT Strom Pipeline'!$I$1:$I$860,$U12),0)) -> 13100 | H12: =IF($U12="","",IF(ISNUMBER(INDEX('MiT Strom Pipeline'!$Q$1:$Q$860,$U12)),INDEX('MiT Strom Pipeline'!$Q$1:$Q$860,$U12),0)) -> 13100 | I12: =IF($U12="","",IF(INDEX('MiT Strom Pipeline'!$E$1:$E$860,$U12)="","",INDEX('MiT Strom Pipeline'!$E$1:$E$860,$U12))) -> 240 kVA Generator | J12: =IF($U12="","",INDEX('MiT Strom Pipeline'!$R$1:$R$860,$U12)) -> WON | K12: =IF($U12="","",IF(ISNUMBER(INDEX('MiT Strom Pipeline'!$S$1:$S$860,$U12)),INDEX('MiT Strom Pipeline'!$S$1:$S$860,$U12),"")) -> 1 | L12: =IF($U12="","",IF(LEN(INDEX('MiT Strom Pipeline'!$V$1:$V$860,$U12))>0,LEFT(INDEX('MiT Strom Pipeline'!$V$1:$V$860,$U12),55),"")) -> Abgeschlossen | M12: =IF($U12="","",IF(INDEX('MiT Strom Pipeline'!$AF$1:$AF$860,$U12)="","",INDEX('MiT Strom Pipeline'!$AF$1:$AF$860,$U12))) | N12: =IF($U12="","",IF(INDEX('MiT Strom Pipeline'!$BB$1:$BB$860,$U12)="","",INDEX('MiT Strom Pipeline'!$BB$1:$BB$860,$U12))) -> ⛔ Nachweis fehlt | U12: =IFERROR(MATCH(2,'MiT Strom Pipeline'!$AM$6:$AM$860,0)+5,"") -> 10
A13: =IF($U13="","",IF(ISNUMBER(INDEX('MiT Strom Pipeline'!$A$1:$A$860,$U13)),INDEX('MiT Strom Pipeline'!$A$1:$A$860,$U13),"")) -> 3 | B13: =IF($U13="","",IF(INDEX('MiT Strom Pipeline'!$B$1:$B$860,$U13)="","",INDEX('MiT Strom Pipeline'!$B$1:$B$860,$U13))) -> Siemens | C13: =IF($U13="","",IF(INDEX('MiT Strom Pipeline'!$C$1:$C$860,$U13)="","",INDEX('MiT Strom Pipeline'!$C$1:$C$860,$U13))) -> ZH | D13: =IF($U13="","",IF(INDEX('MiT Strom Pipeline'!$D$1:$D$860,$U13)="","",INDEX('MiT Strom Pipeline'!$D$1:$D$860,$U13))) -> Industrie / Elektro | E13: =IF($U13="","",IF(ISNUMBER(INDEX('MiT Strom Pipeline'!$O$1:$O$860,$U13)),INDEX('MiT Strom Pipeline'!$O$1:$O$860,$U13),IF(INDEX('MiT Strom Pipeline'!$H$1:$H$860,$U13)="","",INDEX('MiT Strom Pipeline'!$H$1:$H$860,$U13)))) -> tbd | F13: =IF($U13="","",IF(ISNUMBER(INDEX('MiT Strom Pipeline'!$P$1:$P$860,$U13)),INDEX('MiT Strom Pipeline'!$P$1:$P$860,$U13),"")) | G13: =IF($U13="","",IF(ISNUMBER(INDEX('MiT Strom Pipeline'!$I$1:$I$860,$U13)),INDEX('MiT Strom Pipeline'!$I$1:$I$860,$U13),0)) -> 10000 | H13: =IF($U13="","",IF(ISNUMBER(INDEX('MiT Strom Pipeline'!$Q$1:$Q$860,$U13)),INDEX('MiT Strom Pipeline'!$Q$1:$Q$860,$U13),0)) -> 10000 | I13: =IF($U13="","",IF(INDEX('MiT Strom Pipeline'!$E$1:$E$860,$U13)="","",INDEX('MiT Strom Pipeline'!$E$1:$E$860,$U13))) -> 600 kVA Generator | J13: =IF($U13="","",INDEX('MiT Strom Pipeline'!$R$1:$R$860,$U13)) -> WON | K13: =IF($U13="","",IF(ISNUMBER(INDEX('MiT Strom Pipeline'!$S$1:$S$860,$U13)),INDEX('MiT Strom Pipeline'!$S$1:$S$860,$U13),"")) -> 1 | L13: =IF($U13="","",IF(LEN(INDEX('MiT Strom Pipeline'!$V$1:$V$860,$U13))>0,LEFT(INDEX('MiT Strom Pipeline'!$V$1:$V$860,$U13),55),"")) -> Abgeschlossen | M13: =IF($U13="","",IF(INDEX('MiT Strom Pipeline'!$AF$1:$AF$860,$U13)="","",INDEX('MiT Strom Pipeline'!$AF$1:$AF$860,$U13))) | N13: =IF($U13="","",IF(INDEX('MiT Strom Pipeline'!$BB$1:$BB$860,$U13)="","",INDEX('MiT Strom Pipeline'!$BB$1:$BB$860,$U13))) -> ⛔ Nachweis fehlt | U13: =IFERROR(MATCH(3,'MiT Strom Pipeline'!$AM$6:$AM$860,0)+5,"") -> 12
A14: =IF($U14="","",IF(ISNUMBER(INDEX('MiT Strom Pipeline'!$A$1:$A$860,$U14)),INDEX('MiT Strom Pipeline'!$A$1:$A$860,$U14),"")) -> 4 | B14: =IF($U14="","",IF(INDEX('MiT Strom Pipeline'!$B$1:$B$860,$U14)="","",INDEX('MiT Strom Pipeline'!$B$1:$B$860,$U14))) -> Stagelight – OpenAir Frauenfeld | C14: =IF($U14="","",IF(INDEX('MiT Strom Pipeline'!$C$1:$C$860,$U14)="","",INDEX('MiT Strom Pipeline'!$C$1:$C$860,$U14))) -> TG | D14: =IF($U14="","",IF(INDEX('MiT Strom Pipeline'!$D$1:$D$860,$U14)="","",INDEX('MiT Strom Pipeline'!$D$1:$D$860,$U14))) -> Events & Kultur | E14: =IF($U14="","",IF(ISNUMBER(INDEX('MiT Strom Pipeline'!$O$1:$O$860,$U14)),INDEX('MiT Strom Pipeline'!$O$1:$O$860,$U14),IF(INDEX('MiT Strom Pipeline'!$H$1:$H$860,$U14)="","",INDEX('MiT Strom Pipeline'!$H$1:$H$860,$U14)))) -> Juli | F14: =IF($U14="","",IF(ISNUMBER(INDEX('MiT Strom Pipeline'!$P$1:$P$860,$U14)),INDEX('MiT Strom Pipeline'!$P$1:$P$860,$U14),"")) | G14: =IF($U14="","",IF(ISNUMBER(INDEX('MiT Strom Pipeline'!$I$1:$I$860,$U14)),INDEX('MiT Strom Pipeline'!$I$1:$I$860,$U14),0)) -> 150000 | H14: =IF($U14="","",IF(ISNUMBER(INDEX('MiT Strom Pipeline'!$Q$1:$Q$860,$U14)),INDEX('MiT Strom Pipeline'!$Q$1:$Q$860,$U14),0)) -> 150000 | I14: =IF($U14="","",IF(INDEX('MiT Strom Pipeline'!$E$1:$E$860,$U14)="","",INDEX('MiT Strom Pipeline'!$E$1:$E$860,$U14))) -> ~500 kVA Generator | J14: =IF($U14="","",INDEX('MiT Strom Pipeline'!$R$1:$R$860,$U14)) -> WON | K14: =IF($U14="","",IF(ISNUMBER(INDEX('MiT Strom Pipeline'!$S$1:$S$860,$U14)),INDEX('MiT Strom Pipeline'!$S$1:$S$860,$U14),"")) -> 1 | L14: =IF($U14="","",IF(LEN(INDEX('MiT Strom Pipeline'!$V$1:$V$860,$U14))>0,LEFT(INDEX('MiT Strom Pipeline'!$V$1:$V$860,$U14),55),"")) -> Abgeschlossen | M14: =IF($U14="","",IF(INDEX('MiT Strom Pipeline'!$AF$1:$AF$860,$U14)="","",INDEX('MiT Strom Pipeline'!$AF$1:$AF$860,$U14))) | N14: =IF($U14="","",IF(INDEX('MiT Strom Pipeline'!$BB$1:$BB$860,$U14)="","",INDEX('MiT Strom Pipeline'!$BB$1:$BB$860,$U14))) -> ⛔ Nachweis fehlt | U14: =IFERROR(MATCH(4,'MiT Strom Pipeline'!$AM$6:$AM$860,0)+5,"") -> 13
A15: =IF($U15="","",IF(ISNUMBER(INDEX('MiT Strom Pipeline'!$A$1:$A$860,$U15)),INDEX('MiT Strom Pipeline'!$A$1:$A$860,$U15),"")) -> 10 | B15: =IF($U15="","",IF(INDEX('MiT Strom Pipeline'!$B$1:$B$860,$U15)="","",INDEX('MiT Strom Pipeline'!$B$1:$B$860,$U15))) -> Murg Flums Energie | C15: =IF($U15="","",IF(INDEX('MiT Strom Pipeline'!$C$1:$C$860,$U15)="","",INDEX('MiT Strom Pipeline'!$C$1:$C$860,$U15))) -> SG | D15: =IF($U15="","",IF(INDEX('MiT Strom Pipeline'!$D$1:$D$860,$U15)="","",INDEX('MiT Strom Pipeline'!$D$1:$D$860,$U15))) -> EVU / Energie | E15: =IF($U15="","",IF(ISNUMBER(INDEX('MiT Strom Pipeline'!$O$1:$O$860,$U15)),INDEX('MiT Strom Pipeline'!$O$1:$O$860,$U15),IF(INDEX('MiT Strom Pipeline'!$H$1:$H$860,$U15)="","",INDEX('MiT Strom Pipeline'!$H$1:$H$860,$U15)))) -> Auf Abruf | F15: =IF($U15="","",IF(ISNUMBER(INDEX('MiT Strom Pipeline'!$P$1:$P$860,$U15)),INDEX('MiT Strom Pipeline'!$P$1:$P$860,$U15),"")) | G15: =IF($U15="","",IF(ISNUMBER(INDEX('MiT Strom Pipeline'!$I$1:$I$860,$U15)),INDEX('MiT Strom Pipeline'!$I$1:$I$860,$U15),0)) -> 96658.69 | H15: =IF($U15="","",IF(ISNUMBER(INDEX('MiT Strom Pipeline'!$Q$1:$Q$860,$U15)),INDEX('MiT Strom Pipeline'!$Q$1:$Q$860,$U15),0)) -> 96658.69 | I15: =IF($U15="","",IF(INDEX('MiT Strom Pipeline'!$E$1:$E$860,$U15)="","",INDEX('MiT Strom Pipeline'!$E$1:$E$860,$U15))) -> 250 kVA Generator | J15: =IF($U15="","",INDEX('MiT Strom Pipeline'!$R$1:$R$860,$U15)) -> WON | K15: =IF($U15="","",IF(ISNUMBER(INDEX('MiT Strom Pipeline'!$S$1:$S$860,$U15)),INDEX('MiT Strom Pipeline'!$S$1:$S$860,$U15),"")) -> 1 | L15: =IF($U15="","",IF(LEN(INDEX('MiT Strom Pipeline'!$V$1:$V$860,$U15))>0,LEFT(INDEX('MiT Strom Pipeline'!$V$1:$V$860,$U15),55),"")) -> Abrufbereitschaft | M15: =IF($U15="","",IF(INDEX('MiT Strom Pipeline'!$AF$1:$AF$860,$U15)="","",INDEX('MiT Strom Pipeline'!$AF$1:$AF$860,$U15))) | N15: =IF($U15="","",IF(INDEX('MiT Strom Pipeline'!$BB$1:$BB$860,$U15)="","",INDEX('MiT Strom Pipeline'!$BB$1:$BB$860,$U15))) -> ⛔ Nachweis fehlt | U15: =IFERROR(MATCH(5,'MiT Strom Pipeline'!$AM$6:$AM$860,0)+5,"") -> 14
A16: =IF($U16="","",IF(ISNUMBER(INDEX('MiT Strom Pipeline'!$A$1:$A$860,$U16)),INDEX('MiT Strom Pipeline'!$A$1:$A$860,$U16),"")) -> 21 | B16: =IF($U16="","",IF(INDEX('MiT Strom Pipeline'!$B$1:$B$860,$U16)="","",INDEX('MiT Strom Pipeline'!$B$1:$B$860,$U16))) -> X-Event | C16: =IF($U16="","",IF(INDEX('MiT Strom Pipeline'!$C$1:$C$860,$U16)="","",INDEX('MiT Strom Pipeline'!$C$1:$C$860,$U16))) -> SH | D16: =IF($U16="","",IF(INDEX('MiT Strom Pipeline'!$D$1:$D$860,$U16)="","",INDEX('MiT Strom Pipeline'!$D$1:$D$860,$U16))) -> Events / Medien | E16: =IF($U16="","",IF(ISNUMBER(INDEX('MiT Strom Pipeline'!$O$1:$O$860,$U16)),INDEX('MiT Strom Pipeline'!$O$1:$O$860,$U16),IF(INDEX('MiT Strom Pipeline'!$H$1:$H$860,$U16)="","",INDEX('MiT Strom Pipeline'!$H$1:$H$860,$U16)))) -> Juni | F16: =IF($U16="","",IF(ISNUMBER(INDEX('MiT Strom Pipeline'!$P$1:$P$860,$U16)),INDEX('MiT Strom Pipeline'!$P$1:$P$860,$U16),"")) | G16: =IF($U16="","",IF(ISNUMBER(INDEX('MiT Strom Pipeline'!$I$1:$I$860,$U16)),INDEX('MiT Strom Pipeline'!$I$1:$I$860,$U16),0)) -> 0 | H16: =IF($U16="","",IF(ISNUMBER(INDEX('MiT Strom Pipeline'!$Q$1:$Q$860,$U16)),INDEX('MiT Strom Pipeline'!$Q$1:$Q$860,$U16),0)) -> 0 | I16: =IF($U16="","",IF(INDEX('MiT Strom Pipeline'!$E$1:$E$860,$U16)="","",INDEX('MiT Strom Pipeline'!$E$1:$E$860,$U16))) -> 100 kVA Generator | J16: =IF($U16="","",INDEX('MiT Strom Pipeline'!$R$1:$R$860,$U16)) -> WON | K16: =IF($U16="","",IF(ISNUMBER(INDEX('MiT Strom Pipeline'!$S$1:$S$860,$U16)),INDEX('MiT Strom Pipeline'!$S$1:$S$860,$U16),"")) -> 1 | L16: =IF($U16="","",IF(LEN(INDEX('MiT Strom Pipeline'!$V$1:$V$860,$U16))>0,LEFT(INDEX('MiT Strom Pipeline'!$V$1:$V$860,$U16),55),"")) -> Abgeschlossen | M16: =IF($U16="","",IF(INDEX('MiT Strom Pipeline'!$AF$1:$AF$860,$U16)="","",INDEX('MiT Strom Pipeline'!$AF$1:$AF$860,$U16))) | N16: =IF($U16="","",IF(INDEX('MiT Strom Pipeline'!$BB$1:$BB$860,$U16)="","",INDEX('MiT Strom Pipeline'!$BB$1:$BB$860,$U16))) -> ⛔ Nachweis fehlt | U16: =IFERROR(MATCH(6,'MiT Strom Pipeline'!$AM$6:$AM$860,0)+5,"") -> 15
A17: =IF($U17="","",IF(ISNUMBER(INDEX('MiT Strom Pipeline'!$A$1:$A$860,$U17)),INDEX('MiT Strom Pipeline'!$A$1:$A$860,$U17),"")) -> 29 | B17: =IF($U17="","",IF(INDEX('MiT Strom Pipeline'!$B$1:$B$860,$U17)="","",INDEX('MiT Strom Pipeline'!$B$1:$B$860,$U17))) -> Gampeln | C17: =IF($U17="","",IF(INDEX('MiT Strom Pipeline'!$C$1:$C$860,$U17)="","",INDEX('MiT Strom Pipeline'!$C$1:$C$860,$U17))) -> VS | D17: =IF($U17="","",IF(INDEX('MiT Strom Pipeline'!$D$1:$D$860,$U17)="","",INDEX('MiT Strom Pipeline'!$D$1:$D$860,$U17))) -> Event | E17: =IF($U17="","",IF(ISNUMBER(INDEX('MiT Strom Pipeline'!$O$1:$O$860,$U17)),INDEX('MiT Strom Pipeline'!$O$1:$O$860,$U17),IF(INDEX('MiT Strom Pipeline'!$H$1:$H$860,$U17)="","",INDEX('MiT Strom Pipeline'!$H$1:$H$860,$U17)))) -> Aug | F17: =IF($U17="","",IF(ISNUMBER(INDEX('MiT Strom Pipeline'!$P$1:$P$860,$U17)),INDEX('MiT Strom Pipeline'!$P$1:$P$860,$U17),"")) | G17: =IF($U17="","",IF(ISNUMBER(INDEX('MiT Strom Pipeline'!$I$1:$I$860,$U17)),INDEX('MiT Strom Pipeline'!$I$1:$I$860,$U17),0)) -> 80621.21 | H17: =IF($U17="","",IF(ISNUMBER(INDEX('MiT Strom Pipeline'!$Q$1:$Q$860,$U17)),INDEX('MiT Strom Pipeline'!$Q$1:$Q$860,$U17),0)) -> 80621.21 | I17: =IF($U17="","",IF(INDEX('MiT Strom Pipeline'!$E$1:$E$860,$U17)="","",INDEX('MiT Strom Pipeline'!$E$1:$E$860,$U17))) -> 6x300 kVA, 9x200 kVA Generator ,1x150 kWH BESS | J17: =IF($U17="","",INDEX('MiT Strom Pipeline'!$R$1:$R$860,$U17)) -> WON | K17: =IF($U17="","",IF(ISNUMBER(INDEX('MiT Strom Pipeline'!$S$1:$S$860,$U17)),INDEX('MiT Strom Pipeline'!$S$1:$S$860,$U17),"")) -> 1 | L17: =IF($U17="","",IF(LEN(INDEX('MiT Strom Pipeline'!$V$1:$V$860,$U17))>0,LEFT(INDEX('MiT Strom Pipeline'!$V$1:$V$860,$U17),55),"")) -> Abgeschlossen | M17: =IF($U17="","",IF(INDEX('MiT Strom Pipeline'!$AF$1:$AF$860,$U17)="","",INDEX('MiT Strom Pipeline'!$AF$1:$AF$860,$U17))) | N17: =IF($U17="","",IF(INDEX('MiT Strom Pipeline'!$BB$1:$BB$860,$U17)="","",INDEX('MiT Strom Pipeline'!$BB$1:$BB$860,$U17))) -> ⛔ Nachweis fehlt | U17: =IFERROR(MATCH(7,'MiT Strom Pipeline'!$AM$6:$AM$860,0)+5,"") -> 22
A18: =IF($U18="","",IF(ISNUMBER(INDEX('MiT Strom Pipeline'!$A$1:$A$860,$U18)),INDEX('MiT Strom Pipeline'!$A$1:$A$860,$U18),"")) -> 50 | B18: =IF($U18="","",IF(INDEX('MiT Strom Pipeline'!$B$1:$B$860,$U18)="","",INDEX('MiT Strom Pipeline'!$B$1:$B$860,$U18))) -> EIDG AMT Agroscope | C18: =IF($U18="","",IF(INDEX('MiT Strom Pipeline'!$C$1:$C$860,$U18)="","",INDEX('MiT Strom Pipeline'!$C$1:$C$860,$U18))) -> ZH | D18: =IF($U18="","",IF(INDEX('MiT Strom Pipeline'!$D$1:$D$860,$U18)="","",INDEX('MiT Strom Pipeline'!$D$1:$D$860,$U18))) -> Forschung | E18: =IF($U18="","",IF(ISNUMBER(INDEX('MiT Strom Pipeline'!$O$1:$O$860,$U18)),INDEX('MiT Strom Pipeline'!$O$1:$O$860,$U18),IF(INDEX('MiT Strom Pipeline'!$H$1:$H$860,$U18)="","",INDEX('MiT Strom Pipeline'!$H$1:$H$860,$U18)))) -> Aug | F18: =IF($U18="","",IF(ISNUMBER(INDEX('MiT Strom Pipeline'!$P$1:$P$860,$U18)),INDEX('MiT Strom Pipeline'!$P$1:$P$860,$U18),"")) | G18: =IF($U18="","",IF(ISNUMBER(INDEX('MiT Strom Pipeline'!$I$1:$I$860,$U18)),INDEX('MiT Strom Pipeline'!$I$1:$I$860,$U18),0)) -> 13533 | H18: =IF($U18="","",IF(ISNUMBER(INDEX('MiT Strom Pipeline'!$Q$1:$Q$860,$U18)),INDEX('MiT Strom Pipeline'!$Q$1:$Q$860,$U18),0)) -> 13533 | I18: =IF($U18="","",IF(INDEX('MiT Strom Pipeline'!$E$1:$E$860,$U18)="","",INDEX('MiT Strom Pipeline'!$E$1:$E$860,$U18))) -> 450 kVA | J18: =IF($U18="","",INDEX('MiT Strom Pipeline'!$R$1:$R$860,$U18)) -> WON | K18: =IF($U18="","",IF(ISNUMBER(INDEX('MiT Strom Pipeline'!$S$1:$S$860,$U18)),INDEX('MiT Strom Pipeline'!$S$1:$S$860,$U18),"")) -> 1 | L18: =IF($U18="","",IF(LEN(INDEX('MiT Strom Pipeline'!$V$1:$V$860,$U18))>0,LEFT(INDEX('MiT Strom Pipeline'!$V$1:$V$860,$U18),55),"")) -> Abgeschlossen | M18: =IF($U18="","",IF(INDEX('MiT Strom Pipeline'!$AF$1:$AF$860,$U18)="","",INDEX('MiT Strom Pipeline'!$AF$1:$AF$860,$U18))) | N18: =IF($U18="","",IF(INDEX('MiT Strom Pipeline'!$BB$1:$BB$860,$U18)="","",INDEX('MiT Strom Pipeline'!$BB$1:$BB$860,$U18))) -> ⛔ Nachweis fehlt | U18: =IFERROR(MATCH(8,'MiT Strom Pipeline'!$AM$6:$AM$860,0)+5,"") -> 60
A19: =IF($U19="","",IF(ISNUMBER(INDEX('MiT Strom Pipeline'!$A$1:$A$860,$U19)),INDEX('MiT Strom Pipeline'!$A$1:$A$860,$U19),"")) -> 51 | B19: =IF($U19="","",IF(INDEX('MiT Strom Pipeline'!$B$1:$B$860,$U19)="","",INDEX('MiT Strom Pipeline'!$B$1:$B$860,$U19))) -> (Megger) Power Diagnostix Service GmbH | C19: =IF($U19="","",IF(INDEX('MiT Strom Pipeline'!$C$1:$C$860,$U19)="","",INDEX('MiT Strom Pipeline'!$C$1:$C$860,$U19))) -> TG | D19: =IF($U19="","",IF(INDEX('MiT Strom Pipeline'!$D$1:$D$860,$U19)="","",INDEX('MiT Strom Pipeline'!$D$1:$D$860,$U19))) -> EVU | E19: =IF($U19="","",IF(ISNUMBER(INDEX('MiT Strom Pipeline'!$O$1:$O$860,$U19)),INDEX('MiT Strom Pipeline'!$O$1:$O$860,$U19),IF(INDEX('MiT Strom Pipeline'!$H$1:$H$860,$U19)="","",INDEX('MiT Strom Pipeline'!$H$1:$H$860,$U19)))) -> Juli | F19: =IF($U19="","",IF(ISNUMBER(INDEX('MiT Strom Pipeline'!$P$1:$P$860,$U19)),INDEX('MiT Strom Pipeline'!$P$1:$P$860,$U19),"")) | G19: =IF($U19="","",IF(ISNUMBER(INDEX('MiT Strom Pipeline'!$I$1:$I$860,$U19)),INDEX('MiT Strom Pipeline'!$I$1:$I$860,$U19),0)) -> 5488.9 | H19: =IF($U19="","",IF(ISNUMBER(INDEX('MiT Strom Pipeline'!$Q$1:$Q$860,$U19)),INDEX('MiT Strom Pipeline'!$Q$1:$Q$860,$U19),0)) -> 5488.9 | I19: =IF($U19="","",IF(INDEX('MiT Strom Pipeline'!$E$1:$E$860,$U19)="","",INDEX('MiT Strom Pipeline'!$E$1:$E$860,$U19))) -> 600 kVA | J19: =IF($U19="","",INDEX('MiT Strom Pipeline'!$R$1:$R$860,$U19)) -> WON | K19: =IF($U19="","",IF(ISNUMBER(INDEX('MiT Strom Pipeline'!$S$1:$S$860,$U19)),INDEX('MiT Strom Pipeline'!$S$1:$S$860,$U19),"")) -> 1 | L19: =IF($U19="","",IF(LEN(INDEX('MiT Strom Pipeline'!$V$1:$V$860,$U19))>0,LEFT(INDEX('MiT Strom Pipeline'!$V$1:$V$860,$U19),55),"")) -> Abgeschlossen | M19: =IF($U19="","",IF(INDEX('MiT Strom Pipeline'!$AF$1:$AF$860,$U19)="","",INDEX('MiT Strom Pipeline'!$AF$1:$AF$860,$U19))) | N19: =IF($U19="","",IF(INDEX('MiT Strom Pipeline'!$BB$1:$BB$860,$U19)="","",INDEX('MiT Strom Pipeline'!$BB$1:$BB$860,$U19))) -> ⛔ Nachweis fehlt | U19: =IFERROR(MATCH(9,'MiT Strom Pipeline'!$AM$6:$AM$860,0)+5,"") -> 61
