Workbook

Sheet 📑 Executive PDF
A1: ⚡ MiT Strom Schweiz — Executive Sales Summary
A2: Mobil in Time AG · An Aggreko Company · Burak Ücöz
A3: ="Stand: "&TEXT(TODAY(),"DD.MM.YYYY")&" · Live aus Pipeline" -> Stand: DD.08.YYYY · Live aus Pipeline
B5: ✅ WON | E5: 📄 OFFERTE | G5: 🎯 OPPORTUNITÄT
B6: =Dashboard!A6 -> 1428553.1 | E6: =Dashboard!D6 -> 5433596.1 | G6: =Dashboard!G6 -> 0
B8: =Dashboard!A7&" Deals" -> 12 Deals | E8: =Dashboard!D7&" Deals" -> 33 Deals | G8: =Dashboard!G7&" Deals" -> 1 Deals
B10: ="📊 GESAMT-PIPELINE: "&TEXT(Dashboard!I6,"#,##0")&" CHF · "&Dashboard!I7&" aktive Deals" -> 📊 GESAMT-PIPELINE: 6862149,230 CHF · 46 aktive Deals
B12: 🏆 Top 5 WON-Deals (nach Volumen)
B13: # | C13: Kunde | D13: Kt. | E13: Start | F13: Segment | G13: Volumen | H13: Marge
B14: 1 | C14: =IFERROR(INDEX('MiT Strom Pipeline'!B6:B860,MATCH(LARGE('MiT Strom Pipeline'!Z6:Z860,1),'MiT Strom Pipeline'!Z6:Z860,0)),"") -> Ice Hockey Championship | D14: =IFERROR(INDEX('MiT Strom Pipeline'!C6:C860,MATCH(LARGE('MiT Strom Pipeline'!Z6:Z860,1),'MiT Strom Pipeline'!Z6:Z860,0)),"") -> ZH | E14: =IFERROR(INDEX('MiT Strom Pipeline'!H6:H860,MATCH(LARGE('MiT Strom Pipeline'!Z6:Z860,1),'MiT Strom Pipeline'!Z6:Z860,0)),"") -> Mai | F14: =IFERROR(INDEX('MiT Strom Pipeline'!D6:D860,MATCH(LARGE('MiT Strom Pipeline'!Z6:Z860,1),'MiT Strom Pipeline'!Z6:Z860,0)),"") -> Events & Sport | G14: =IFERROR(INDEX('MiT Strom Pipeline'!I6:I860,MATCH(LARGE('MiT Strom Pipeline'!Z6:Z860,1),'MiT Strom Pipeline'!Z6:Z860,0)),"") -> 380000 | H14: =IFERROR(INDEX('MiT Strom Pipeline'!O6:O860,MATCH(LARGE('MiT Strom Pipeline'!Z6:Z860,1),'MiT Strom Pipeline'!Z6:Z860,0)),"") -> 145000
B15: 2 | C15: =IFERROR(INDEX('MiT Strom Pipeline'!B6:B860,MATCH(LARGE('MiT Strom Pipeline'!Z6:Z860,2),'MiT Strom Pipeline'!Z6:Z860,0)),"") -> DPR Heat Loadbank | D15: =IFERROR(INDEX('MiT Strom Pipeline'!C6:C860,MATCH(LARGE('MiT Strom Pipeline'!Z6:Z860,2),'MiT Strom Pipeline'!Z6:Z860,0)),"") -> ZH | E15: =IFERROR(INDEX('MiT Strom Pipeline'!H6:H860,MATCH(LARGE('MiT Strom Pipeline'!Z6:Z860,2),'MiT Strom Pipeline'!Z6:Z860,0)),"") -> Aug | F15: =IFERROR(INDEX('MiT Strom Pipeline'!D6:D860,MATCH(LARGE('MiT Strom Pipeline'!Z6:Z860,2),'MiT Strom Pipeline'!Z6:Z860,0)),"") -> Datacenter | G15: =IFERROR(INDEX('MiT Strom Pipeline'!I6:I860,MATCH(LARGE('MiT Strom Pipeline'!Z6:Z860,2),'MiT Strom Pipeline'!Z6:Z860,0)),"") -> 333790 | H15: =IFERROR(INDEX('MiT Strom Pipeline'!O6:O860,MATCH(LARGE('MiT Strom Pipeline'!Z6:Z860,2),'MiT Strom Pipeline'!Z6:Z860,0)),"") -> -25011.09
B16: 3 | C16: =IFERROR(INDEX('MiT Strom Pipeline'!B6:B860,MATCH(LARGE('MiT Strom Pipeline'!Z6:Z860,3),'MiT Strom Pipeline'!Z6:Z860,0)),"") -> DPR Generator Loadbank Test | D16: =IFERROR(INDEX('MiT Strom Pipeline'!C6:C860,MATCH(LARGE('MiT Strom Pipeline'!Z6:Z860,3),'MiT Strom Pipeline'!Z6:Z860,0)),"") -> ZH | E16: =IFERROR(INDEX('MiT Strom Pipeline'!H6:H860,MATCH(LARGE('MiT Strom Pipeline'!Z6:Z860,3),'MiT Strom Pipeline'!Z6:Z860,0)),"") -> Aug | F16: =IFERROR(INDEX('MiT Strom Pipeline'!D6:D860,MATCH(LARGE('MiT Strom Pipeline'!Z6:Z860,3),'MiT Strom Pipeline'!Z6:Z860,0)),"") -> Datacenter | G16: =IFERROR(INDEX('MiT Strom Pipeline'!I6:I860,MATCH(LARGE('MiT Strom Pipeline'!Z6:Z860,3),'MiT Strom Pipeline'!Z6:Z860,0)),"") -> 331889.15 | H16: =IFERROR(INDEX('MiT Strom Pipeline'!O6:O860,MATCH(LARGE('MiT Strom Pipeline'!Z6:Z860,3),'MiT Strom Pipeline'!Z6:Z860,0)),"") -> -24868.66
B17: 4 | C17: =IFERROR(INDEX('MiT Strom Pipeline'!B6:B860,MATCH(LARGE('MiT Strom Pipeline'!Z6:Z860,4),'MiT Strom Pipeline'!Z6:Z860,0)),"") -> Stagelight – OpenAir Frauenfeld | D17: =IFERROR(INDEX('MiT Strom Pipeline'!C6:C860,MATCH(LARGE('MiT Strom Pipeline'!Z6:Z860,4),'MiT Strom Pipeline'!Z6:Z860,0)),"") -> TG | E17: =IFERROR(INDEX('MiT Strom Pipeline'!H6:H860,MATCH(LARGE('MiT Strom Pipeline'!Z6:Z860,4),'MiT Strom Pipeline'!Z6:Z860,0)),"") -> Juli | F17: =IFERROR(INDEX('MiT Strom Pipeline'!D6:D860,MATCH(LARGE('MiT Strom Pipeline'!Z6:Z860,4),'MiT Strom Pipeline'!Z6:Z860,0)),"") -> Events & Kultur | G17: =IFERROR(INDEX('MiT Strom Pipeline'!I6:I860,MATCH(LARGE('MiT Strom Pipeline'!Z6:Z860,4),'MiT Strom Pipeline'!Z6:Z860,0)),"") -> 150000 | H17: =IFERROR(INDEX('MiT Strom Pipeline'!O6:O860,MATCH(LARGE('MiT Strom Pipeline'!Z6:Z860,4),'MiT Strom Pipeline'!Z6:Z860,0)),"") -> 39500
B18: 5 | C18: =IFERROR(INDEX('MiT Strom Pipeline'!B6:B860,MATCH(LARGE('MiT Strom Pipeline'!Z6:Z860,5),'MiT Strom Pipeline'!Z6:Z860,0)),"") -> Murg Flums Energie | D18: =IFERROR(INDEX('MiT Strom Pipeline'!C6:C860,MATCH(LARGE('MiT Strom Pipeline'!Z6:Z860,5),'MiT Strom Pipeline'!Z6:Z860,0)),"") -> SG | E18: =IFERROR(INDEX('MiT Strom Pipeline'!H6:H860,MATCH(LARGE('MiT Strom Pipeline'!Z6:Z860,5),'MiT Strom Pipeline'!Z6:Z860,0)),"") -> Auf Abruf | F18: =IFERROR(INDEX('MiT Strom Pipeline'!D6:D860,MATCH(LARGE('MiT Strom Pipeline'!Z6:Z860,5),'MiT Strom Pipeline'!Z6:Z860,0)),"") -> EVU / Energie | G18: =IFERROR(INDEX('MiT Strom Pipeline'!I6:I860,MATCH(LARGE('MiT Strom Pipeline'!Z6:Z860,5),'MiT Strom Pipeline'!Z6:Z860,0)),"") -> 96658.69 | H18: =IFERROR(INDEX('MiT Strom Pipeline'!O6:O860,MATCH(LARGE('MiT Strom Pipeline'!Z6:Z860,5),'MiT Strom Pipeline'!Z6:Z860,0)),"") -> 7242.69
B21: 📊 Status-Verteilung Pipeline
B22: Status | D22: Anzahl | E22: Volumen CHF | G22: Anteil %
B23: ✅ WON | D23: =COUNTIF('MiT Strom Pipeline'!R6:R860,"WON") -> 12 | E23: =SUMIFS('MiT Strom Pipeline'!I6:I860,'MiT Strom Pipeline'!R6:R860,"WON") -> 1428553.1 | G23: =IFERROR(E23/Dashboard!I6,0) -> 0.20817867
B24: 📄 Offerte (inkl. To Offer) | D24: =COUNTIF('MiT Strom Pipeline'!R6:R860,"offered")+COUNTIF('MiT Strom Pipeline'!R6:R860,"to be offered") -> 29 | E24: =SUMIFS('MiT Strom Pipeline'!I6:I860,'MiT Strom Pipeline'!R6:R860,"offered")+SUMIFS('MiT Strom Pipeline'!I6:I860,'MiT Strom Pipeline'!R6:R860,"to be offered") -> 4887938.3 | G24: =IFERROR(E24/Dashboard!I6,0) -> 0.71230428
B25: 🎯 Follow-Up | D25: =COUNTIF('MiT Strom Pipeline'!R6:R860,"follow-up") -> 0 | E25: =SUMIFS('MiT Strom Pipeline'!I6:I860,'MiT Strom Pipeline'!R6:R860,"follow-up") -> 0 | G25: =IFERROR(E25/Dashboard!I6,0) -> 0
B26: 🔍 Evaluation (inkl. In Eval) | D26: =COUNTIF('MiT Strom Pipeline'!R6:R860,"Evaluation")+COUNTIF('MiT Strom Pipeline'!R6:R860,"In evaluation") -> 0 | E26: =SUMIFS('MiT Strom Pipeline'!I6:I860,'MiT Strom Pipeline'!R6:R860,"Evaluation")+SUMIFS('MiT Strom Pipeline'!I6:I860,'MiT Strom Pipeline'!R6:R860,"In evaluation") -> 0 | G26: =IFERROR(E26/Dashboard!I6,0) -> 0
B27: ⏸ On Hold | D27: =COUNTIF('MiT Strom Pipeline'!R6:R860,"on hold") -> 4 | E27: =SUMIFS('MiT Strom Pipeline'!I6:I860,'MiT Strom Pipeline'!R6:R860,"on hold") -> 545657.8 | G27: =IFERROR(E27/Dashboard!I6,0) -> 0.079517041
B28: ❓ TBD | D28: =COUNTIF('MiT Strom Pipeline'!R6:R860,"tbd") -> 1 | E28: =SUMIFS('MiT Strom Pipeline'!I6:I860,'MiT Strom Pipeline'!R6:R860,"tbd") -> 0 | G28: =IFERROR(E28/Dashboard!I6,0) -> 0
B29: ❌ LOST | D29: =COUNTIF('MiT Strom Pipeline'!R6:R860,"LOST") -> 7 | E29: =SUMIFS('MiT Strom Pipeline'!I6:I860,'MiT Strom Pipeline'!R6:R860,"LOST") -> 78251.62 | G29: =IFERROR(E29/Dashboard!I6,0) -> 0.011403369
B30: 🚫 Declined | D30: =COUNTIF('MiT Strom Pipeline'!R6:R860,"Declined") -> 13 | E30: =SUMIFS('MiT Strom Pipeline'!I6:I860,'MiT Strom Pipeline'!R6:R860,"Declined") -> 96029.01 | G30: =IFERROR(E30/Dashboard!I6,0) -> 0.013994014
A35: 🖨 Strg+P → Als PDF speichern · Druckbereich ist bereits gesetzt (A4 Hochformat)

Sheet 📄 Report
A1: MiT Strom Schweiz — Sales-Report
A2: Mobil in Time AG · An Aggreko Company · Burak Ücöz
A3: ="Stand: "&TEXT(TODAY(),"DD.MM.YYYY")&" · Auto-Update via Pipeline-Daten" -> Stand: DD.08.YYYY · Auto-Update via Pipeline-Daten
A5: Key Performance Indicators
A6: KPI | B6: Wert CHF | C6: Anzahl | D6: Anteil
A7: ✅ WON | B7: =Dashboard!A6 -> 1428553.1 | C7: =Dashboard!A7 -> 12 | D7: =IFERROR(B7/$B$10,0) -> 0.20817867
A8: 📄 Offerte | B8: =Dashboard!D6 -> 5433596.1 | C8: =Dashboard!D7 -> 33 | D8: =IFERROR(B8/$B$10,0) -> 0.79182133
A9: 🎯 Opportunität | B9: =Dashboard!G6 -> 0 | C9: =Dashboard!G7 -> 1 | D9: =IFERROR(B9/$B$10,0) -> 0
A10: 📊 TOTAL Pipeline | B10: =Dashboard!I6 -> 6862149.2 | C10: =Dashboard!I7 -> 46 | D10: =IFERROR(B10/$B$10,0) -> 1
A13: Top Kantone (nach Volumen) | J13: _kt | K13: _vol | L13: _rankkey
A14: Rang | B14: Kanton | C14: Volumen CHF | D14: Anzahl Deals | E14: WON-Rate | J14: AG | K14: =SUMIF('MiT Strom Pipeline'!$C$6:$C$860,J14,'MiT Strom Pipeline'!$I$6:$I$860) -> 444672.95 | L14: =K14+(26-ROW())*0.0001 -> 444672.95
A15: 1 | B15: =IFERROR(INDEX($J$14:$J$39,MATCH(LARGE($L$14:$L$39,1),$L$14:$L$39,0)),"") -> ZH | C15: =IF(B15="","",SUMIF('MiT Strom Pipeline'!$C$6:$C$860,B15,'MiT Strom Pipeline'!$I$6:$I$860)) -> 2732239 | D15: =IF(B15="","",COUNTIF('MiT Strom Pipeline'!$C$6:$C$860,B15)) -> 25 | E15: =IF(OR(B15="",D15=0),"",COUNTIFS('MiT Strom Pipeline'!$C$6:$C$860,B15,'MiT Strom Pipeline'!$R$6:$R$860,"WON")/D15) -> 0.2 | J15: AI | K15: =SUMIF('MiT Strom Pipeline'!$C$6:$C$860,J15,'MiT Strom Pipeline'!$I$6:$I$860) -> 0 | L15: =K15+(26-ROW())*0.0001 -> 0.0011
A16: 2 | B16: =IFERROR(INDEX($J$14:$J$39,MATCH(LARGE($L$14:$L$39,2),$L$14:$L$39,0)),"") -> SH | C16: =IF(B16="","",SUMIF('MiT Strom Pipeline'!$C$6:$C$860,B16,'MiT Strom Pipeline'!$I$6:$I$860)) -> 2637287.6 | D16: =IF(B16="","",COUNTIF('MiT Strom Pipeline'!$C$6:$C$860,B16)) -> 5 | E16: =IF(OR(B16="",D16=0),"",COUNTIFS('MiT Strom Pipeline'!$C$6:$C$860,B16,'MiT Strom Pipeline'!$R$6:$R$860,"WON")/D16) -> 0.2 | J16: AR | K16: =SUMIF('MiT Strom Pipeline'!$C$6:$C$860,J16,'MiT Strom Pipeline'!$I$6:$I$860) -> 0 | L16: =K16+(26-ROW())*0.0001 -> 0.001
A17: 3 | B17: =IFERROR(INDEX($J$14:$J$39,MATCH(LARGE($L$14:$L$39,3),$L$14:$L$39,0)),"") -> AG | C17: =IF(B17="","",SUMIF('MiT Strom Pipeline'!$C$6:$C$860,B17,'MiT Strom Pipeline'!$I$6:$I$860)) -> 444672.95 | D17: =IF(B17="","",COUNTIF('MiT Strom Pipeline'!$C$6:$C$860,B17)) -> 7 | E17: =IF(OR(B17="",D17=0),"",COUNTIFS('MiT Strom Pipeline'!$C$6:$C$860,B17,'MiT Strom Pipeline'!$R$6:$R$860,"WON")/D17) -> 0.14285714 | J17: BE | K17: =SUMIF('MiT Strom Pipeline'!$C$6:$C$860,J17,'MiT Strom Pipeline'!$I$6:$I$860) -> 58012.12 | L17: =K17+(26-ROW())*0.0001 -> 58012.121
A18: 4 | B18: =IFERROR(INDEX($J$14:$J$39,MATCH(LARGE($L$14:$L$39,4),$L$14:$L$39,0)),"") -> SO | C18: =IF(B18="","",SUMIF('MiT Strom Pipeline'!$C$6:$C$860,B18,'MiT Strom Pipeline'!$I$6:$I$860)) -> 390750.65 | D18: =IF(B18="","",COUNTIF('MiT Strom Pipeline'!$C$6:$C$860,B18)) -> 2 | E18: =IF(OR(B18="",D18=0),"",COUNTIFS('MiT Strom Pipeline'!$C$6:$C$860,B18,'MiT Strom Pipeline'!$R$6:$R$860,"WON")/D18) -> 0 | J18: BL | K18: =SUMIF('MiT Strom Pipeline'!$C$6:$C$860,J18,'MiT Strom Pipeline'!$I$6:$I$860) -> 13472.18 | L18: =K18+(26-ROW())*0.0001 -> 13472.181
A19: 5 | B19: =IFERROR(INDEX($J$14:$J$39,MATCH(LARGE($L$14:$L$39,5),$L$14:$L$39,0)),"") -> VS | C19: =IF(B19="","",SUMIF('MiT Strom Pipeline'!$C$6:$C$860,B19,'MiT Strom Pipeline'!$I$6:$I$860)) -> 303790.2 | D19: =IF(B19="","",COUNTIF('MiT Strom Pipeline'!$C$6:$C$860,B19)) -> 3 | E19: =IF(OR(B19="",D19=0),"",COUNTIFS('MiT Strom Pipeline'!$C$6:$C$860,B19,'MiT Strom Pipeline'!$R$6:$R$860,"WON")/D19) -> 0.33333333 | J19: BS | K19: =SUMIF('MiT Strom Pipeline'!$C$6:$C$860,J19,'MiT Strom Pipeline'!$I$6:$I$860) -> 13866.21 | L19: =K19+(26-ROW())*0.0001 -> 13866.211
A20: 6 | B20: =IFERROR(INDEX($J$14:$J$39,MATCH(LARGE($L$14:$L$39,6),$L$14:$L$39,0)),"") -> TG | C20: =IF(B20="","",SUMIF('MiT Strom Pipeline'!$C$6:$C$860,B20,'MiT Strom Pipeline'!$I$6:$I$860)) -> 160817.26 | D20: =IF(B20="","",COUNTIF('MiT Strom Pipeline'!$C$6:$C$860,B20)) -> 3 | E20: =IF(OR(B20="",D20=0),"",COUNTIFS('MiT Strom Pipeline'!$C$6:$C$860,B20,'MiT Strom Pipeline'!$R$6:$R$860,"WON")/D20) -> 0.66666667 | J20: FR | K20: =SUMIF('MiT Strom Pipeline'!$C$6:$C$860,J20,'MiT Strom Pipeline'!$I$6:$I$860) -> 0 | L20: =K20+(26-ROW())*0.0001 -> 0.0006
A21: 7 | B21: =IFERROR(INDEX($J$14:$J$39,MATCH(LARGE($L$14:$L$39,7),$L$14:$L$39,0)),"") -> SG | C21: =IF(B21="","",SUMIF('MiT Strom Pipeline'!$C$6:$C$860,B21,'MiT Strom Pipeline'!$I$6:$I$860)) -> 101192.62 | D21: =IF(B21="","",COUNTIF('MiT Strom Pipeline'!$C$6:$C$860,B21)) -> 3 | E21: =IF(OR(B21="",D21=0),"",COUNTIFS('MiT Strom Pipeline'!$C$6:$C$860,B21,'MiT Strom Pipeline'!$R$6:$R$860,"WON")/D21) -> 0.33333333 | J21: GE | K21: =SUMIF('MiT Strom Pipeline'!$C$6:$C$860,J21,'MiT Strom Pipeline'!$I$6:$I$860) -> 38885 | L21: =K21+(26-ROW())*0.0001 -> 38885.001
A22: 8 | B22: =IFERROR(INDEX($J$14:$J$39,MATCH(LARGE($L$14:$L$39,8),$L$14:$L$39,0)),"") -> GR | C22: =IF(B22="","",SUMIF('MiT Strom Pipeline'!$C$6:$C$860,B22,'MiT Strom Pipeline'!$I$6:$I$860)) -> 77325.62 | D22: =IF(B22="","",COUNTIF('MiT Strom Pipeline'!$C$6:$C$860,B22)) -> 2 | E22: =IF(OR(B22="",D22=0),"",COUNTIFS('MiT Strom Pipeline'!$C$6:$C$860,B22,'MiT Strom Pipeline'!$R$6:$R$860,"WON")/D22) -> 0 | J22: GL | K22: =SUMIF('MiT Strom Pipeline'!$C$6:$C$860,J22,'MiT Strom Pipeline'!$I$6:$I$860) -> 0 | L22: =K22+(26-ROW())*0.0001 -> 0.0004
A23: 9 | B23: =IFERROR(INDEX($J$14:$J$39,MATCH(LARGE($L$14:$L$39,9),$L$14:$L$39,0)),"") -> BE | C23: =IF(B23="","",SUMIF('MiT Strom Pipeline'!$C$6:$C$860,B23,'MiT Strom Pipeline'!$I$6:$I$860)) -> 58012.12 | D23: =IF(B23="","",COUNTIF('MiT Strom Pipeline'!$C$6:$C$860,B23)) -> 5 | E23: =IF(OR(B23="",D23=0),"",COUNTIFS('MiT Strom Pipeline'!$C$6:$C$860,B23,'MiT Strom Pipeline'!$R$6:$R$860,"WON")/D23) -> 0 | J23: GR | K23: =SUMIF('MiT Strom Pipeline'!$C$6:$C$860,J23,'MiT Strom Pipeline'!$I$6:$I$860) -> 77325.62 | L23: =K23+(26-ROW())*0.0001 -> 77325.62
A24: 10 | B24: =IFERROR(INDEX($J$14:$J$39,MATCH(LARGE($L$14:$L$39,10),$L$14:$L$39,0)),"") -> ZG | C24: =IF(B24="","",SUMIF('MiT Strom Pipeline'!$C$6:$C$860,B24,'MiT Strom Pipeline'!$I$6:$I$860)) -> 40491.67 | D24: =IF(B24="","",COUNTIF('MiT Strom Pipeline'!$C$6:$C$860,B24)) -> 1 | E24: =IF(OR(B24="",D24=0),"",COUNTIFS('MiT Strom Pipeline'!$C$6:$C$860,B24,'MiT Strom Pipeline'!$R$6:$R$860,"WON")/D24) -> 0 | J24: JU | K24: =SUMIF('MiT Strom Pipeline'!$C$6:$C$860,J24,'MiT Strom Pipeline'!$I$6:$I$860) -> 0 | L24: =K24+(26-ROW())*0.0001 -> 0.0002
J25: LU | K25: =SUMIF('MiT Strom Pipeline'!$C$6:$C$860,J25,'MiT Strom Pipeline'!$I$6:$I$860) -> 23626.77 | L25: =K25+(26-ROW())*0.0001 -> 23626.77
J26: NE | K26: =SUMIF('MiT Strom Pipeline'!$C$6:$C$860,J26,'MiT Strom Pipeline'!$I$6:$I$860) -> 0 | L26: =K26+(26-ROW())*0.0001 -> 0
A27: Top WON-Deals | J27: NW | K27: =SUMIF('MiT Strom Pipeline'!$C$6:$C$860,J27,'MiT Strom Pipeline'!$I$6:$I$860) -> 0 | L27: =K27+(26-ROW())*0.0001 -> -0.0001
A28: Rang | B28: Kunde | C28: Kanton | D28: Segment | E28: Volumen CHF | F28: Marge CHF | G28: Start | J28: OW | K28: =SUMIF('MiT Strom Pipeline'!$C$6:$C$860,J28,'MiT Strom Pipeline'!$I$6:$I$860) -> 0 | L28: =K28+(26-ROW())*0.0001 -> -0.0002
A29: 1 | B29: =IFERROR(INDEX('MiT Strom Pipeline'!$B$6:$B$860,MATCH(LARGE('MiT Strom Pipeline'!$Z$6:$Z$860,1),'MiT Strom Pipeline'!$Z$6:$Z$860,0)),"") -> Ice Hockey Championship | C29: =IFERROR(INDEX('MiT Strom Pipeline'!$C$6:$C$860,MATCH(LARGE('MiT Strom Pipeline'!$Z$6:$Z$860,1),'MiT Strom Pipeline'!$Z$6:$Z$860,0)),"") -> ZH | D29: =IFERROR(INDEX('MiT Strom Pipeline'!$D$6:$D$860,MATCH(LARGE('MiT Strom Pipeline'!$Z$6:$Z$860,1),'MiT Strom Pipeline'!$Z$6:$Z$860,0)),"") -> Events & Sport | E29: =IFERROR(LARGE('MiT Strom Pipeline'!$Z$6:$Z$860,1),"") -> 380000 | F29: =IFERROR(INDEX('MiT Strom Pipeline'!$O$6:$O$860,MATCH(LARGE('MiT Strom Pipeline'!$Z$6:$Z$860,1),'MiT Strom Pipeline'!$Z$6:$Z$860,0)),"") -> 145000 | G29: =IFERROR(INDEX('MiT Strom Pipeline'!H6:H860,MATCH(LARGE('MiT Strom Pipeline'!Z6:Z860,1),'MiT Strom Pipeline'!Z6:Z860,0)),"") -> Mai | J29: SG | K29: =SUMIF('MiT Strom Pipeline'!$C$6:$C$860,J29,'MiT Strom Pipeline'!$I$6:$I$860) -> 101192.62 | L29: =K29+(26-ROW())*0.0001 -> 101192.62
A30: 2 | B30: =IFERROR(INDEX('MiT Strom Pipeline'!$B$6:$B$860,MATCH(LARGE('MiT Strom Pipeline'!$Z$6:$Z$860,2),'MiT Strom Pipeline'!$Z$6:$Z$860,0)),"") -> DPR Heat Loadbank | C30: =IFERROR(INDEX('MiT Strom Pipeline'!$C$6:$C$860,MATCH(LARGE('MiT Strom Pipeline'!$Z$6:$Z$860,2),'MiT Strom Pipeline'!$Z$6:$Z$860,0)),"") -> ZH | D30: =IFERROR(INDEX('MiT Strom Pipeline'!$D$6:$D$860,MATCH(LARGE('MiT Strom Pipeline'!$Z$6:$Z$860,2),'MiT Strom Pipeline'!$Z$6:$Z$860,0)),"") -> Datacenter | E30: =IFERROR(LARGE('MiT Strom Pipeline'!$Z$6:$Z$860,2),"") -> 333790 | F30: =IFERROR(INDEX('MiT Strom Pipeline'!$O$6:$O$860,MATCH(LARGE('MiT Strom Pipeline'!$Z$6:$Z$860,2),'MiT Strom Pipeline'!$Z$6:$Z$860,0)),"") -> -25011.09 | G30: =IFERROR(INDEX('MiT Strom Pipeline'!H6:H860,MATCH(LARGE('MiT Strom Pipeline'!Z6:Z860,2),'MiT Strom Pipeline'!Z6:Z860,0)),"") -> Aug | J30: SH | K30: =SUMIF('MiT Strom Pipeline'!$C$6:$C$860,J30,'MiT Strom Pipeline'!$I$6:$I$860) -> 2637287.6 | L30: =K30+(26-ROW())*0.0001 -> 2637287.6
A31: 3 | B31: =IFERROR(INDEX('MiT Strom Pipeline'!$B$6:$B$860,MATCH(LARGE('MiT Strom Pipeline'!$Z$6:$Z$860,3),'MiT Strom Pipeline'!$Z$6:$Z$860,0)),"") -> DPR Generator Loadbank Test | C31: =IFERROR(INDEX('MiT Strom Pipeline'!$C$6:$C$860,MATCH(LARGE('MiT Strom Pipeline'!$Z$6:$Z$860,3),'MiT Strom Pipeline'!$Z$6:$Z$860,0)),"") -> ZH | D31: =IFERROR(INDEX('MiT Strom Pipeline'!$D$6:$D$860,MATCH(LARGE('MiT Strom Pipeline'!$Z$6:$Z$860,3),'MiT Strom Pipeline'!$Z$6:$Z$860,0)),"") -> Datacenter | E31: =IFERROR(LARGE('MiT Strom Pipeline'!$Z$6:$Z$860,3),"") -> 331889.15 | F31: =IFERROR(INDEX('MiT Strom Pipeline'!$O$6:$O$860,MATCH(LARGE('MiT Strom Pipeline'!$Z$6:$Z$860,3),'MiT Strom Pipeline'!$Z$6:$Z$860,0)),"") -> -24868.66 | G31: =IFERROR(INDEX('MiT Strom Pipeline'!H6:H860,MATCH(LARGE('MiT Strom Pipeline'!Z6:Z860,3),'MiT Strom Pipeline'!Z6:Z860,0)),"") -> Aug | J31: SO | K31: =SUMIF('MiT Strom Pipeline'!$C$6:$C$860,J31,'MiT Strom Pipeline'!$I$6:$I$860) -> 390750.65 | L31: =K31+(26-ROW())*0.0001 -> 390750.65
A32: 4 | B32: =IFERROR(INDEX('MiT Strom Pipeline'!$B$6:$B$860,MATCH(LARGE('MiT Strom Pipeline'!$Z$6:$Z$860,4),'MiT Strom Pipeline'!$Z$6:$Z$860,0)),"") -> Stagelight – OpenAir Frauenfeld | C32: =IFERROR(INDEX('MiT Strom Pipeline'!$C$6:$C$860,MATCH(LARGE('MiT Strom Pipeline'!$Z$6:$Z$860,4),'MiT Strom Pipeline'!$Z$6:$Z$860,0)),"") -> TG | D32: =IFERROR(INDEX('MiT Strom Pipeline'!$D$6:$D$860,MATCH(LARGE('MiT Strom Pipeline'!$Z$6:$Z$860,4),'MiT Strom Pipeline'!$Z$6:$Z$860,0)),"") -> Events & Kultur | E32: =IFERROR(LARGE('MiT Strom Pipeline'!$Z$6:$Z$860,4),"") -> 150000 | F32: =IFERROR(INDEX('MiT Strom Pipeline'!$O$6:$O$860,MATCH(LARGE('MiT Strom Pipeline'!$Z$6:$Z$860,4),'MiT Strom Pipeline'!$Z$6:$Z$860,0)),"") -> 39500 | G32: =IFERROR(INDEX('MiT Strom Pipeline'!H6:H860,MATCH(LARGE('MiT Strom Pipeline'!Z6:Z860,4),'MiT Strom Pipeline'!Z6:Z860,0)),"") -> Juli | J32: SZ | K32: =SUMIF('MiT Strom Pipeline'!$C$6:$C$860,J32,'MiT Strom Pipeline'!$I$6:$I$860) -> 0 | L32: =K32+(26-ROW())*0.0001 -> -0.0006
A33: 5 | B33: =IFERROR(INDEX('MiT Strom Pipeline'!$B$6:$B$860,MATCH(LARGE('MiT Strom Pipeline'!$Z$6:$Z$860,5),'MiT Strom Pipeline'!$Z$6:$Z$860,0)),"") -> Murg Flums Energie | C33: =IFERROR(INDEX('MiT Strom Pipeline'!$C$6:$C$860,MATCH(LARGE('MiT Strom Pipeline'!$Z$6:$Z$860,5),'MiT Strom Pipeline'!$Z$6:$Z$860,0)),"") -> SG | D33: =IFERROR(INDEX('MiT Strom Pipeline'!$D$6:$D$860,MATCH(LARGE('MiT Strom Pipeline'!$Z$6:$Z$860,5),'MiT Strom Pipeline'!$Z$6:$Z$860,0)),"") -> EVU / Energie | E33: =IFERROR(LARGE('MiT Strom Pipeline'!$Z$6:$Z$860,5),"") -> 96658.69 | F33: =IFERROR(INDEX('MiT Strom Pipeline'!$O$6:$O$860,MATCH(LARGE('MiT Strom Pipeline'!$Z$6:$Z$860,5),'MiT Strom Pipeline'!$Z$6:$Z$860,0)),"") -> 7242.69 | G33: =IFERROR(INDEX('MiT Strom Pipeline'!H6:H860,MATCH(LARGE('MiT Strom Pipeline'!Z6:Z860,5),'MiT Strom Pipeline'!Z6:Z860,0)),"") -> Auf Abruf | J33: TG | K33: =SUMIF('MiT Strom Pipeline'!$C$6:$C$860,J33,'MiT Strom Pipeline'!$I$6:$I$860) -> 160817.26 | L33: =K33+(26-ROW())*0.0001 -> 160817.26
A34: 6 | B34: =IFERROR(INDEX('MiT Strom Pipeline'!$B$6:$B$860,MATCH(LARGE('MiT Strom Pipeline'!$Z$6:$Z$860,6),'MiT Strom Pipeline'!$Z$6:$Z$860,0)),"") -> Gampeln | C34: =IFERROR(INDEX('MiT Strom Pipeline'!$C$6:$C$860,MATCH(LARGE('MiT Strom Pipeline'!$Z$6:$Z$860,6),'MiT Strom Pipeline'!$Z$6:$Z$860,0)),"") -> VS | D34: =IFERROR(INDEX('MiT Strom Pipeline'!$D$6:$D$860,MATCH(LARGE('MiT Strom Pipeline'!$Z$6:$Z$860,6),'MiT Strom Pipeline'!$Z$6:$Z$860,0)),"") -> Event | E34: =IFERROR(LARGE('MiT Strom Pipeline'!$Z$6:$Z$860,6),"") -> 80621.21 | F34: =IFERROR(INDEX('MiT Strom Pipeline'!$O$6:$O$860,MATCH(LARGE('MiT Strom Pipeline'!$Z$6:$Z$860,6),'MiT Strom Pipeline'!$Z$6:$Z$860,0)),"") -> -10507.9 | G34: =IFERROR(INDEX('MiT Strom Pipeline'!H6:H860,MATCH(LARGE('MiT Strom Pipeline'!Z6:Z860,6),'MiT Strom Pipeline'!Z6:Z860,0)),"") -> Aug | J34: TI | K34: =SUMIF('MiT Strom Pipeline'!$C$6:$C$860,J34,'MiT Strom Pipeline'!$I$6:$I$860) -> 0 | L34: =K34+(26-ROW())*0.0001 -> -0.0008
A35: 7 | B35: =IFERROR(INDEX('MiT Strom Pipeline'!$B$6:$B$860,MATCH(LARGE('MiT Strom Pipeline'!$Z$6:$Z$860,7),'MiT Strom Pipeline'!$Z$6:$Z$860,0)),"") -> EIDG AMT Agroscope | C35: =IFERROR(INDEX('MiT Strom Pipeline'!$C$6:$C$860,MATCH(LARGE('MiT Strom Pipeline'!$Z$6:$Z$860,7),'MiT Strom Pipeline'!$Z$6:$Z$860,0)),"") -> ZH | D35: =IFERROR(INDEX('MiT Strom Pipeline'!$D$6:$D$860,MATCH(LARGE('MiT Strom Pipeline'!$Z$6:$Z$860,7),'MiT Strom Pipeline'!$Z$6:$Z$860,0)),"") -> Forschung | E35: =IFERROR(LARGE('MiT Strom Pipeline'!$Z$6:$Z$860,7),"") -> 13533 | F35: =IFERROR(INDEX('MiT Strom Pipeline'!$O$6:$O$860,MATCH(LARGE('MiT Strom Pipeline'!$Z$6:$Z$860,7),'MiT Strom Pipeline'!$Z$6:$Z$860,0)),"") -> 155.46 | G35: =IFERROR(INDEX('MiT Strom Pipeline'!H6:H860,MATCH(LARGE('MiT Strom Pipeline'!Z6:Z860,7),'MiT Strom Pipeline'!Z6:Z860,0)),"") -> Aug | J35: UR | K35: =SUMIF('MiT Strom Pipeline'!$C$6:$C$860,J35,'MiT Strom Pipeline'!$I$6:$I$860) -> 0 | L35: =K35+(26-ROW())*0.0001 -> -0.0009
A36: 8 | B36: =IFERROR(INDEX('MiT Strom Pipeline'!$B$6:$B$860,MATCH(LARGE('MiT Strom Pipeline'!$Z$6:$Z$860,8),'MiT Strom Pipeline'!$Z$6:$Z$860,0)),"") -> GETEC Park.Swiss AG | C36: =IFERROR(INDEX('MiT Strom Pipeline'!$C$6:$C$860,MATCH(LARGE('MiT Strom Pipeline'!$Z$6:$Z$860,8),'MiT Strom Pipeline'!$Z$6:$Z$860,0)),"") -> BL | D36: =IFERROR(INDEX('MiT Strom Pipeline'!$D$6:$D$860,MATCH(LARGE('MiT Strom Pipeline'!$Z$6:$Z$860,8),'MiT Strom Pipeline'!$Z$6:$Z$860,0)),"") -> Industrie | E36: =IFERROR(LARGE('MiT Strom Pipeline'!$Z$6:$Z$860,8),"") -> 13472.18 | F36: =IFERROR(INDEX('MiT Strom Pipeline'!$O$6:$O$860,MATCH(LARGE('MiT Strom Pipeline'!$Z$6:$Z$860,8),'MiT Strom Pipeline'!$Z$6:$Z$860,0)),"") -> 1.8189894e-12 | G36: =IFERROR(INDEX('MiT Strom Pipeline'!H6:H860,MATCH(LARGE('MiT Strom Pipeline'!Z6:Z860,8),'MiT Strom Pipeline'!Z6:Z860,0)),"") -> August | J36: VD | K36: =SUMIF('MiT Strom Pipeline'!$C$6:$C$860,J36,'MiT Strom Pipeline'!$I$6:$I$860) -> 0 | L36: =K36+(26-ROW())*0.0001 -> -0.001
A37: 9 | B37: =IFERROR(INDEX('MiT Strom Pipeline'!$B$6:$B$860,MATCH(LARGE('MiT Strom Pipeline'!$Z$6:$Z$860,9),'MiT Strom Pipeline'!$Z$6:$Z$860,0)),"") -> Oerlikon Metco Wohlen | C37: =IFERROR(INDEX('MiT Strom Pipeline'!$C$6:$C$860,MATCH(LARGE('MiT Strom Pipeline'!$Z$6:$Z$860,9),'MiT Strom Pipeline'!$Z$6:$Z$860,0)),"") -> AG | D37: =IFERROR(INDEX('MiT Strom Pipeline'!$D$6:$D$860,MATCH(LARGE('MiT Strom Pipeline'!$Z$6:$Z$860,9),'MiT Strom Pipeline'!$Z$6:$Z$860,0)),"") -> Industrie / Oberfläche | E37: =IFERROR(LARGE('MiT Strom Pipeline'!$Z$6:$Z$860,9),"") -> 13100 | F37: =IFERROR(INDEX('MiT Strom Pipeline'!$O$6:$O$860,MATCH(LARGE('MiT Strom Pipeline'!$Z$6:$Z$860,9),'MiT Strom Pipeline'!$Z$6:$Z$860,0)),"") -> 3000 | G37: =IFERROR(INDEX('MiT Strom Pipeline'!H6:H860,MATCH(LARGE('MiT Strom Pipeline'!Z6:Z860,9),'MiT Strom Pipeline'!Z6:Z860,0)),"") -> April | J37: VS | K37: =SUMIF('MiT Strom Pipeline'!$C$6:$C$860,J37,'MiT Strom Pipeline'!$I$6:$I$860) -> 303790.2 | L37: =K37+(26-ROW())*0.0001 -> 303790.2
A38: 10 | B38: =IFERROR(INDEX('MiT Strom Pipeline'!$B$6:$B$860,MATCH(LARGE('MiT Strom Pipeline'!$Z$6:$Z$860,10),'MiT Strom Pipeline'!$Z$6:$Z$860,0)),"") -> Siemens | C38: =IFERROR(INDEX('MiT Strom Pipeline'!$C$6:$C$860,MATCH(LARGE('MiT Strom Pipeline'!$Z$6:$Z$860,10),'MiT Strom Pipeline'!$Z$6:$Z$860,0)),"") -> ZH | D38: =IFERROR(INDEX('MiT Strom Pipeline'!$D$6:$D$860,MATCH(LARGE('MiT Strom Pipeline'!$Z$6:$Z$860,10),'MiT Strom Pipeline'!$Z$6:$Z$860,0)),"") -> Industrie / Elektro | E38: =IFERROR(LARGE('MiT Strom Pipeline'!$Z$6:$Z$860,10),"") -> 10000 | F38: =IFERROR(INDEX('MiT Strom Pipeline'!$O$6:$O$860,MATCH(LARGE('MiT Strom Pipeline'!$Z$6:$Z$860,10),'MiT Strom Pipeline'!$Z$6:$Z$860,0)),"") -> 10000 | G38: =IFERROR(INDEX('MiT Strom Pipeline'!H6:H860,MATCH(LARGE('MiT Strom Pipeline'!Z6:Z860,10),'MiT Strom Pipeline'!Z6:Z860,0)),"") -> tbd | J38: ZG | K38: =SUMIF('MiT Strom Pipeline'!$C$6:$C$860,J38,'MiT Strom Pipeline'!$I$6:$I$860) -> 40491.67 | L38: =K38+(26-ROW())*0.0001 -> 40491.669
J39: ZH | K39: =SUMIF('MiT Strom Pipeline'!$C$6:$C$860,J39,'MiT Strom Pipeline'!$I$6:$I$860) -> 2732239 | L39: =K39+(26-ROW())*0.0001 -> 2732239
A40: ↻ Auto-Update aus Pipeline · Sortiert nach Volumen ↓ · Nur WON mit numerischem Volumen
A41: 🖨 Strg+P → «Als PDF speichern» · Druckbereich A4 ist gesetzt

Sheet CEO Report
A1: ="⚡ MiT Strom Schweiz — CEO Sales Report · "&TEXT(TODAY(),"MMMM YYYY") -> ⚡ MiT Strom Schweiz — CEO Sales Report · August YYYY
A2: Mobil in Time AG · An Aggreko Company · Burak Ücöz · Neue Einträge in «MiT Strom Pipeline» erscheinen automatisch.
A5: ✅ AUFTRAGSEINGANG (WON) | E5: 📄 OFFERTE — Laufend | I5: 🎯 OPPORTUNITÄT
A6: =SUMIFS('MiT Strom Pipeline'!I$6:I$860,'MiT Strom Pipeline'!R$6:R$860,"WON") -> 1428553.1 | E6: =SUMIFS('MiT Strom Pipeline'!I$6:I$860,'MiT Strom Pipeline'!R$6:R$860,"offered")+SUMIFS('MiT Strom Pipeline'!I$6:I$860,'MiT Strom Pipeline'!R$6:R$860,"to be offered")+SUMIFS('MiT Strom Pipeline'!I$6:I$860,'MiT Strom Pipeline'!R$6:R$860,"on hold") -> 5433596.1 | I6: =SUMIFS('MiT Strom Pipeline'!I$6:I$860,'MiT Strom Pipeline'!R$6:R$860,"follow-up")+SUMIFS('MiT Strom Pipeline'!I$6:I$860,'MiT Strom Pipeline'!R$6:R$860,"Evaluation")+SUMIFS('MiT Strom Pipeline'!I$6:I$860,'MiT Strom Pipeline'!R$6:R$860,"tbd")+SUMIFS('MiT Strom Pipeline'!I$6:I$860,'MiT Strom Pipeline'!R$6:R$860,"In evaluation") -> 0
A7: =COUNTIF('MiT Strom Pipeline'!R$6:R$860,"WON") -> 12 | E7: =COUNTIF('MiT Strom Pipeline'!R$6:R$860,"offered")+COUNTIF('MiT Strom Pipeline'!R$6:R$860,"to be offered")+COUNTIF('MiT Strom Pipeline'!R$6:R$860,"on hold") -> 33 | I7: =COUNTIF('MiT Strom Pipeline'!R$6:R$860,"follow-up")+COUNTIF('MiT Strom Pipeline'!R$6:R$860,"Evaluation")+COUNTIF('MiT Strom Pipeline'!R$6:R$860,"tbd")+COUNTIF('MiT Strom Pipeline'!R$6:R$860,"In evaluation") -> 1
A9: ✅ 1. AUFTRAGSEINGANG (WON) — Bestätigte Aufträge
A10: # | B10: Kunde / Unternehmen | C10: Kt. | D10: Segment | E10: Start | F10: Leistung / Fleet | G10: Volumen CHF | H10: Gew.Wert CHF | I10: Marge CHF | J10: Status | K10: Wahr.% | L10: Nächster Schritt
A11: =IF($U11="","",IF(ISNUMBER(INDEX('MiT Strom Pipeline'!$A:$A,$U11)),INDEX('MiT Strom Pipeline'!$A:$A,$U11),"")) -> 1 | B11: =IF($U11="","",IF(INDEX('MiT Strom Pipeline'!$B:$B,$U11)="","",INDEX('MiT Strom Pipeline'!$B:$B,$U11))) -> Ice Hockey Championship | C11: =IF($U11="","",IF(INDEX('MiT Strom Pipeline'!$C:$C,$U11)="","",INDEX('MiT Strom Pipeline'!$C:$C,$U11))) -> ZH | D11: =IF($U11="","",IF(INDEX('MiT Strom Pipeline'!$D:$D,$U11)="","",INDEX('MiT Strom Pipeline'!$D:$D,$U11))) -> Events & Sport | E11: =IF($U11="","",IF(INDEX('MiT Strom Pipeline'!$H:$H,$U11)="","",INDEX('MiT Strom Pipeline'!$H:$H,$U11))) -> Mai | F11: =IF($U11="","",IF(INDEX('MiT Strom Pipeline'!$E:$E,$U11)="","",INDEX('MiT Strom Pipeline'!$E:$E,$U11))) -> 2×600+2×200 kVA | G11: =IF($U11="","",IF(ISNUMBER(INDEX('MiT Strom Pipeline'!$I:$I,$U11)),INDEX('MiT Strom Pipeline'!$I:$I,$U11),0)) -> 380000 | H11: =IF($U11="","",IF(ISNUMBER(INDEX('MiT Strom Pipeline'!$Q:$Q,$U11)),INDEX('MiT Strom Pipeline'!$Q:$Q,$U11),0)) -> 380000 | I11: =IF($U11="","",IF(ISNUMBER(INDEX('MiT Strom Pipeline'!$O:$O,$U11)),INDEX('MiT Strom Pipeline'!$O:$O,$U11),0)) -> 145000 | J11: =IF($U11="","",INDEX('MiT Strom Pipeline'!$R:$R,$U11)) -> WON | K11: =IF($U11="","",IF(ISNUMBER(INDEX('MiT Strom Pipeline'!$S:$S,$U11)),INDEX('MiT Strom Pipeline'!$S:$S,$U11),"")) -> 1 | L11: =IF($U11="","",IF(LEN(INDEX('MiT Strom Pipeline'!$V:$V,$U11))>0,LEFT(INDEX('MiT Strom Pipeline'!$V:$V,$U11),55),"")) -> Abgeschlossen | U11: =IFERROR(MATCH(1,'MiT Strom Pipeline'!$AB$6:$AB$860,0)+5,"") -> 9
A12: =IF($U12="","",IF(ISNUMBER(INDEX('MiT Strom Pipeline'!$A:$A,$U12)),INDEX('MiT Strom Pipeline'!$A:$A,$U12),"")) -> 2 | B12: =IF($U12="","",IF(INDEX('MiT Strom Pipeline'!$B:$B,$U12)="","",INDEX('MiT Strom Pipeline'!$B:$B,$U12))) -> Oerlikon Metco Wohlen | C12: =IF($U12="","",IF(INDEX('MiT Strom Pipeline'!$C:$C,$U12)="","",INDEX('MiT Strom Pipeline'!$C:$C,$U12))) -> AG | D12: =IF($U12="","",IF(INDEX('MiT Strom Pipeline'!$D:$D,$U12)="","",INDEX('MiT Strom Pipeline'!$D:$D,$U12))) -> Industrie / Oberfläche | E12: =IF($U12="","",IF(INDEX('MiT Strom Pipeline'!$H:$H,$U12)="","",INDEX('MiT Strom Pipeline'!$H:$H,$U12))) -> April | F12: =IF($U12="","",IF(INDEX('MiT Strom Pipeline'!$E:$E,$U12)="","",INDEX('MiT Strom Pipeline'!$E:$E,$U12))) -> 240 kVA Generator | G12: =IF($U12="","",IF(ISNUMBER(INDEX('MiT Strom Pipeline'!$I:$I,$U12)),INDEX('MiT Strom Pipeline'!$I:$I,$U12),0)) -> 13100 | H12: =IF($U12="","",IF(ISNUMBER(INDEX('MiT Strom Pipeline'!$Q:$Q,$U12)),INDEX('MiT Strom Pipeline'!$Q:$Q,$U12),0)) -> 13100 | I12: =IF($U12="","",IF(ISNUMBER(INDEX('MiT Strom Pipeline'!$O:$O,$U12)),INDEX('MiT Strom Pipeline'!$O:$O,$U12),0)) -> 3000 | J12: =IF($U12="","",INDEX('MiT Strom Pipeline'!$R:$R,$U12)) -> WON | K12: =IF($U12="","",IF(ISNUMBER(INDEX('MiT Strom Pipeline'!$S:$S,$U12)),INDEX('MiT Strom Pipeline'!$S:$S,$U12),"")) -> 1 | L12: =IF($U12="","",IF(LEN(INDEX('MiT Strom Pipeline'!$V:$V,$U12))>0,LEFT(INDEX('MiT Strom Pipeline'!$V:$V,$U12),55),"")) -> Abgeschlossen | U12: =IFERROR(MATCH(2,'MiT Strom Pipeline'!$AB$6:$AB$860,0)+5,"") -> 10
A13: =IF($U13="","",IF(ISNUMBER(INDEX('MiT Strom Pipeline'!$A:$A,$U13)),INDEX('MiT Strom Pipeline'!$A:$A,$U13),"")) -> 3 | B13: =IF($U13="","",IF(INDEX('MiT Strom Pipeline'!$B:$B,$U13)="","",INDEX('MiT Strom Pipeline'!$B:$B,$U13))) -> Siemens | C13: =IF($U13="","",IF(INDEX('MiT Strom Pipeline'!$C:$C,$U13)="","",INDEX('MiT Strom Pipeline'!$C:$C,$U13))) -> ZH | D13: =IF($U13="","",IF(INDEX('MiT Strom Pipeline'!$D:$D,$U13)="","",INDEX('MiT Strom Pipeline'!$D:$D,$U13))) -> Industrie / Elektro | E13: =IF($U13="","",IF(INDEX('MiT Strom Pipeline'!$H:$H,$U13)="","",INDEX('MiT Strom Pipeline'!$H:$H,$U13))) -> tbd | F13: =IF($U13="","",IF(INDEX('MiT Strom Pipeline'!$E:$E,$U13)="","",INDEX('MiT Strom Pipeline'!$E:$E,$U13))) -> 600 kVA Generator | G13: =IF($U13="","",IF(ISNUMBER(INDEX('MiT Strom Pipeline'!$I:$I,$U13)),INDEX('MiT Strom Pipeline'!$I:$I,$U13),0)) -> 10000 | H13: =IF($U13="","",IF(ISNUMBER(INDEX('MiT Strom Pipeline'!$Q:$Q,$U13)),INDEX('MiT Strom Pipeline'!$Q:$Q,$U13),0)) -> 10000 | I13: =IF($U13="","",IF(ISNUMBER(INDEX('MiT Strom Pipeline'!$O:$O,$U13)),INDEX('MiT Strom Pipeline'!$O:$O,$U13),0)) -> 10000 | J13: =IF($U13="","",INDEX('MiT Strom Pipeline'!$R:$R,$U13)) -> WON | K13: =IF($U13="","",IF(ISNUMBER(INDEX('MiT Strom Pipeline'!$S:$S,$U13)),INDEX('MiT Strom Pipeline'!$S:$S,$U13),"")) -> 1 | L13: =IF($U13="","",IF(LEN(INDEX('MiT Strom Pipeline'!$V:$V,$U13))>0,LEFT(INDEX('MiT Strom Pipeline'!$V:$V,$U13),55),"")) -> Abgeschlossen | U13: =IFERROR(MATCH(3,'MiT Strom Pipeline'!$AB$6:$AB$860,0)+5,"") -> 12
A14: =IF($U14="","",IF(ISNUMBER(INDEX('MiT Strom Pipeline'!$A:$A,$U14)),INDEX('MiT Strom Pipeline'!$A:$A,$U14),"")) -> 4 | B14: =IF($U14="","",IF(INDEX('MiT Strom Pipeline'!$B:$B,$U14)="","",INDEX('MiT Strom Pipeline'!$B:$B,$U14))) -> Stagelight – OpenAir Frauenfeld | C14: =IF($U14="","",IF(INDEX('MiT Strom Pipeline'!$C:$C,$U14)="","",INDEX('MiT Strom Pipeline'!$C:$C,$U14))) -> TG | D14: =IF($U14="","",IF(INDEX('MiT Strom Pipeline'!$D:$D,$U14)="","",INDEX('MiT Strom Pipeline'!$D:$D,$U14))) -> Events & Kultur | E14: =IF($U14="","",IF(INDEX('MiT Strom Pipeline'!$H:$H,$U14)="","",INDEX('MiT Strom Pipeline'!$H:$H,$U14))) -> Juli | F14: =IF($U14="","",IF(INDEX('MiT Strom Pipeline'!$E:$E,$U14)="","",INDEX('MiT Strom Pipeline'!$E:$E,$U14))) -> ~500 kVA Generator | G14: =IF($U14="","",IF(ISNUMBER(INDEX('MiT Strom Pipeline'!$I:$I,$U14)),INDEX('MiT Strom Pipeline'!$I:$I,$U14),0)) -> 150000 | H14: =IF($U14="","",IF(ISNUMBER(INDEX('MiT Strom Pipeline'!$Q:$Q,$U14)),INDEX('MiT Strom Pipeline'!$Q:$Q,$U14),0)) -> 0 | I14: =IF($U14="","",IF(ISNUMBER(INDEX('MiT Strom Pipeline'!$O:$O,$U14)),INDEX('MiT Strom Pipeline'!$O:$O,$U14),0)) -> 39500 | J14: =IF($U14="","",INDEX('MiT Strom Pipeline'!$R:$R,$U14)) -> WON | K14: =IF($U14="","",IF(ISNUMBER(INDEX('MiT Strom Pipeline'!$S:$S,$U14)),INDEX('MiT Strom Pipeline'!$S:$S,$U14),"")) -> 1 | L14: =IF($U14="","",IF(LEN(INDEX('MiT Strom Pipeline'!$V:$V,$U14))>0,LEFT(INDEX('MiT Strom Pipeline'!$V:$V,$U14),55),"")) -> Abgeschlossen | U14: =IFERROR(MATCH(4,'MiT Strom Pipeline'!$AB$6:$AB$860,0)+5,"") -> 13
A15: =IF($U15="","",IF(ISNUMBER(INDEX('MiT Strom Pipeline'!$A:$A,$U15)),INDEX('MiT Strom Pipeline'!$A:$A,$U15),"")) -> 10 | B15: =IF($U15="","",IF(INDEX('MiT Strom Pipeline'!$B:$B,$U15)="","",INDEX('MiT Strom Pipeline'!$B:$B,$U15))) -> Murg Flums Energie | C15: =IF($U15="","",IF(INDEX('MiT Strom Pipeline'!$C:$C,$U15)="","",INDEX('MiT Strom Pipeline'!$C:$C,$U15))) -> SG | D15: =IF($U15="","",IF(INDEX('MiT Strom Pipeline'!$D:$D,$U15)="","",INDEX('MiT Strom Pipeline'!$D:$D,$U15))) -> EVU / Energie | E15: =IF($U15="","",IF(INDEX('MiT Strom Pipeline'!$H:$H,$U15)="","",INDEX('MiT Strom Pipeline'!$H:$H,$U15))) -> Auf Abruf | F15: =IF($U15="","",IF(INDEX('MiT Strom Pipeline'!$E:$E,$U15)="","",INDEX('MiT Strom Pipeline'!$E:$E,$U15))) -> 250 kVA Generator | G15: =IF($U15="","",IF(ISNUMBER(INDEX('MiT Strom Pipeline'!$I:$I,$U15)),INDEX('MiT Strom Pipeline'!$I:$I,$U15),0)) -> 96658.69 | H15: =IF($U15="","",IF(ISNUMBER(INDEX('MiT Strom Pipeline'!$Q:$Q,$U15)),INDEX('MiT Strom Pipeline'!$Q:$Q,$U15),0)) -> 96658.69 | I15: =IF($U15="","",IF(ISNUMBER(INDEX('MiT Strom Pipeline'!$O:$O,$U15)),INDEX('MiT Strom Pipeline'!$O:$O,$U15),0)) -> 7242.69 | J15: =IF($U15="","",INDEX('MiT Strom Pipeline'!$R:$R,$U15)) -> WON | K15: =IF($U15="","",IF(ISNUMBER(INDEX('MiT Strom Pipeline'!$S:$S,$U15)),INDEX('MiT Strom Pipeline'!$S:$S,$U15),"")) -> 1 | L15: =IF($U15="","",IF(LEN(INDEX('MiT Strom Pipeline'!$V:$V,$U15))>0,LEFT(INDEX('MiT Strom Pipeline'!$V:$V,$U15),55),"")) -> Abrufbereitschaft | U15: =IFERROR(MATCH(5,'MiT Strom Pipeline'!$AB$6:$AB$860,0)+5,"") -> 14
A16: =IF($U16="","",IF(ISNUMBER(INDEX('MiT Strom Pipeline'!$A:$A,$U16)),INDEX('MiT Strom Pipeline'!$A:$A,$U16),"")) -> 21 | B16: =IF($U16="","",IF(INDEX('MiT Strom Pipeline'!$B:$B,$U16)="","",INDEX('MiT Strom Pipeline'!$B:$B,$U16))) -> X-Event | C16: =IF($U16="","",IF(INDEX('MiT Strom Pipeline'!$C:$C,$U16)="","",INDEX('MiT Strom Pipeline'!$C:$C,$U16))) -> SH | D16: =IF($U16="","",IF(INDEX('MiT Strom Pipeline'!$D:$D,$U16)="","",INDEX('MiT Strom Pipeline'!$D:$D,$U16))) -> Events / Medien | E16: =IF($U16="","",IF(INDEX('MiT Strom Pipeline'!$H:$H,$U16)="","",INDEX('MiT Strom Pipeline'!$H:$H,$U16))) -> Juni | F16: =IF($U16="","",IF(INDEX('MiT Strom Pipeline'!$E:$E,$U16)="","",INDEX('MiT Strom Pipeline'!$E:$E,$U16))) -> 100 kVA Generator | G16: =IF($U16="","",IF(ISNUMBER(INDEX('MiT Strom Pipeline'!$I:$I,$U16)),INDEX('MiT Strom Pipeline'!$I:$I,$U16),0)) -> 0 | H16: =IF($U16="","",IF(ISNUMBER(INDEX('MiT Strom Pipeline'!$Q:$Q,$U16)),INDEX('MiT Strom Pipeline'!$Q:$Q,$U16),0)) -> 0 | I16: =IF($U16="","",IF(ISNUMBER(INDEX('MiT Strom Pipeline'!$O:$O,$U16)),INDEX('MiT Strom Pipeline'!$O:$O,$U16),0)) -> 0 | J16: =IF($U16="","",INDEX('MiT Strom Pipeline'!$R:$R,$U16)) -> WON | K16: =IF($U16="","",IF(ISNUMBER(INDEX('MiT Strom Pipeline'!$S:$S,$U16)),INDEX('MiT Strom Pipeline'!$S:$S,$U16),"")) -> 1 | L16: =IF($U16="","",IF(LEN(INDEX('MiT Strom Pipeline'!$V:$V,$U16))>0,LEFT(INDEX('MiT Strom Pipeline'!$V:$V,$U16),55),"")) -> Abgeschlossen | U16: =IFERROR(MATCH(6,'MiT Strom Pipeline'!$AB$6:$AB$860,0)+5,"") -> 15
A17: =IF($U17="","",IF(ISNUMBER(INDEX('MiT Strom Pipeline'!$A:$A,$U17)),INDEX('MiT Strom Pipeline'!$A:$A,$U17),"")) -> 29 | B17: =IF($U17="","",IF(INDEX('MiT Strom Pipeline'!$B:$B,$U17)="","",INDEX('MiT Strom Pipeline'!$B:$B,$U17))) -> Gampeln | C17: =IF($U17="","",IF(INDEX('MiT Strom Pipeline'!$C:$C,$U17)="","",INDEX('MiT Strom Pipeline'!$C:$C,$U17))) -> VS | D17: =IF($U17="","",IF(INDEX('MiT Strom Pipeline'!$D:$D,$U17)="","",INDEX('MiT Strom Pipeline'!$D:$D,$U17))) -> Event | E17: =IF($U17="","",IF(INDEX('MiT Strom Pipeline'!$H:$H,$U17)="","",INDEX('MiT Strom Pipeline'!$H:$H,$U17))) -> Aug | F17: =IF($U17="","",IF(INDEX('MiT Strom Pipeline'!$E:$E,$U17)="","",INDEX('MiT Strom Pipeline'!$E:$E,$U17))) -> 6x300 kVA, 9x200 kVA Generator ,1x150 kWH BESS | G17: =IF($U17="","",IF(ISNUMBER(INDEX('MiT Strom Pipeline'!$I:$I,$U17)),INDEX('MiT Strom Pipeline'!$I:$I,$U17),0)) -> 80621.21 | H17: =IF($U17="","",IF(ISNUMBER(INDEX('MiT Strom Pipeline'!$Q:$Q,$U17)),INDEX('MiT Strom Pipeline'!$Q:$Q,$U17),0)) -> 80621.21 | I17: =IF($U17="","",IF(ISNUMBER(INDEX('MiT Strom Pipeline'!$O:$O,$U17)),INDEX('MiT Strom Pipeline'!$O:$O,$U17),0)) -> -10507.9 | J17: =IF($U17="","",INDEX('MiT Strom Pipeline'!$R:$R,$U17)) -> WON | K17: =IF($U17="","",IF(ISNUMBER(INDEX('MiT Strom Pipeline'!$S:$S,$U17)),INDEX('MiT Strom Pipeline'!$S:$S,$U17),"")) -> 1 | L17: =IF($U17="","",IF(LEN(INDEX('MiT Strom Pipeline'!$V:$V,$U17))>0,LEFT(INDEX('MiT Strom Pipeline'!$V:$V,$U17),55),"")) -> Abgeschlossen | U17: =IFERROR(MATCH(7,'MiT Strom Pipeline'!$AB$6:$AB$860,0)+5,"") -> 22
A18: =IF($U18="","",IF(ISNUMBER(INDEX('MiT Strom Pipeline'!$A:$A,$U18)),INDEX('MiT Strom Pipeline'!$A:$A,$U18),"")) -> 50 | B18: =IF($U18="","",IF(INDEX('MiT Strom Pipeline'!$B:$B,$U18)="","",INDEX('MiT Strom Pipeline'!$B:$B,$U18))) -> EIDG AMT Agroscope | C18: =IF($U18="","",IF(INDEX('MiT Strom Pipeline'!$C:$C,$U18)="","",INDEX('MiT Strom Pipeline'!$C:$C,$U18))) -> ZH | D18: =IF($U18="","",IF(INDEX('MiT Strom Pipeline'!$D:$D,$U18)="","",INDEX('MiT Strom Pipeline'!$D:$D,$U18))) -> Forschung | E18: =IF($U18="","",IF(INDEX('MiT Strom Pipeline'!$H:$H,$U18)="","",INDEX('MiT Strom Pipeline'!$H:$H,$U18))) -> Aug | F18: =IF($U18="","",IF(INDEX('MiT Strom Pipeline'!$E:$E,$U18)="","",INDEX('MiT Strom Pipeline'!$E:$E,$U18))) -> 450 kVA | G18: =IF($U18="","",IF(ISNUMBER(INDEX('MiT Strom Pipeline'!$I:$I,$U18)),INDEX('MiT Strom Pipeline'!$I:$I,$U18),0)) -> 13533 | H18: =IF($U18="","",IF(ISNUMBER(INDEX('MiT Strom Pipeline'!$Q:$Q,$U18)),INDEX('MiT Strom Pipeline'!$Q:$Q,$U18),0)) -> 13533 | I18: =IF($U18="","",IF(ISNUMBER(INDEX('MiT Strom Pipeline'!$O:$O,$U18)),INDEX('MiT Strom Pipeline'!$O:$O,$U18),0)) -> 155.46 | J18: =IF($U18="","",INDEX('MiT Strom Pipeline'!$R:$R,$U18)) -> WON | K18: =IF($U18="","",IF(ISNUMBER(INDEX('MiT Strom Pipeline'!$S:$S,$U18)),INDEX('MiT Strom Pipeline'!$S:$S,$U18),"")) -> 1 | L18: =IF($U18="","",IF(LEN(INDEX('MiT Strom Pipeline'!$V:$V,$U18))>0,LEFT(INDEX('MiT Strom Pipeline'!$V:$V,$U18),55),"")) -> Abgeschlossen | U18: =IFERROR(MATCH(8,'MiT Strom Pipeline'!$AB$6:$AB$860,0)+5,"") -> 60
A19: =IF($U19="","",IF(ISNUMBER(INDEX('MiT Strom Pipeline'!$A:$A,$U19)),INDEX('MiT Strom Pipeline'!$A:$A,$U19),"")) -> 51 | B19: =IF($U19="","",IF(INDEX('MiT Strom Pipeline'!$B:$B,$U19)="","",INDEX('MiT Strom Pipeline'!$B:$B,$U19))) -> (Megger) Power Diagnostix Service GmbH | C19: =IF($U19="","",IF(INDEX('MiT Strom Pipeline'!$C:$C,$U19)="","",INDEX('MiT Strom Pipeline'!$C:$C,$U19))) -> TG | D19: =IF($U19="","",IF(INDEX('MiT Strom Pipeline'!$D:$D,$U19)="","",INDEX('MiT Strom Pipeline'!$D:$D,$U19))) -> EVU | E19: =IF($U19="","",IF(INDEX('MiT Strom Pipeline'!$H:$H,$U19)="","",INDEX('MiT Strom Pipeline'!$H:$H,$U19))) -> Juli | F19: =IF($U19="","",IF(INDEX('MiT Strom Pipeline'!$E:$E,$U19)="","",INDEX('MiT Strom Pipeline'!$E:$E,$U19))) -> 600 kVA | G19: =IF($U19="","",IF(ISNUMBER(INDEX('MiT Strom Pipeline'!$I:$I,$U19)),INDEX('MiT Strom Pipeline'!$I:$I,$U19),0)) -> 5488.9 | H19: =IF($U19="","",IF(ISNUMBER(INDEX('MiT Strom Pipeline'!$Q:$Q,$U19)),INDEX('MiT Strom Pipeline'!$Q:$Q,$U19),0)) -> 5488.9 | I19: =IF($U19="","",IF(ISNUMBER(INDEX('MiT Strom Pipeline'!$O:$O,$U19)),INDEX('MiT Strom Pipeline'!$O:$O,$U19),0)) -> -411.29 | J19: =IF($U19="","",INDEX('MiT Strom Pipeline'!$R:$R,$U19)) -> WON | K19: =IF($U19="","",IF(ISNUMBER(INDEX('MiT Strom Pipeline'!$S:$S,$U19)),INDEX('MiT Strom Pipeline'!$S:$S,$U19),"")) -> 1 | L19: =IF($U19="","",IF(LEN(INDEX('MiT Strom Pipeline'!$V:$V,$U19))>0,LEFT(INDEX('MiT Strom Pipeline'!$V:$V,$U19),55),"")) -> Abgeschlossen | U19: =IFERROR(MATCH(9,'MiT Strom Pipeline'!$AB$6:$AB$860,0)+5,"") -> 61
A20: =IF($U20="","",IF(ISNUMBER(INDEX('MiT Strom Pipeline'!$A:$A,$U20)),INDEX('MiT Strom Pipeline'!$A:$A,$U20),"")) -> 52 | B20: =IF($U20="","",IF(INDEX('MiT Strom Pipeline'!$B:$B,$U20)="","",INDEX('MiT Strom Pipeline'!$B:$B,$U20))) -> DPR Heat Loadbank | C20: =IF($U20="","",IF(INDEX('MiT Strom Pipeline'!$C:$C,$U20)="","",INDEX('MiT Strom Pipeline'!$C:$C,$U20))) -> ZH | D20: =IF($U20="","",IF(INDEX('MiT Strom Pipeline'!$D:$D,$U20)="","",INDEX('MiT Strom Pipeline'!$D:$D,$U20))) -> Datacenter | E20: =IF($U20="","",IF(INDEX('MiT Strom Pipeline'!$H:$H,$U20)="","",INDEX('MiT Strom Pipeline'!$H:$H,$U20))) -> Aug | F20: =IF($U20="","",IF(INDEX('MiT Strom Pipeline'!$E:$E,$U20)="","",INDEX('MiT Strom Pipeline'!$E:$E,$U20))) -> 54x200 kVA Loadbank | G20: =IF($U20="","",IF(ISNUMBER(INDEX('MiT Strom Pipeline'!$I:$I,$U20)),INDEX('MiT Strom Pipeline'!$I:$I,$U20),0)) -> 333790 | H20: =IF($U20="","",IF(ISNUMBER(INDEX('MiT Strom Pipeline'!$Q:$Q,$U20)),INDEX('MiT Strom Pipeline'!$Q:$Q,$U20),0)) -> 333790 | I20: =IF($U20="","",IF(ISNUMBER(INDEX('MiT Strom Pipeline'!$O:$O,$U20)),INDEX('MiT Strom Pipeline'!$O:$O,$U20),0)) -> -25011.09 | J20: =IF($U20="","",INDEX('MiT Strom Pipeline'!$R:$R,$U20)) -> WON | K20: =IF($U20="","",IF(ISNUMBER(INDEX('MiT Strom Pipeline'!$S:$S,$U20)),INDEX('MiT Strom Pipeline'!$S:$S,$U20),"")) -> 1 | L20: =IF($U20="","",IF(LEN(INDEX('MiT Strom Pipeline'!$V:$V,$U20))>0,LEFT(INDEX('MiT Strom Pipeline'!$V:$V,$U20),55),"")) -> Kunde angeschrieben auf MiT seite mit aktueller CHF Pre | U20: =IFERROR(MATCH(10,'MiT Strom Pipeline'!$AB$6:$AB$860,0)+5,"") -> 62
A21: =IF($U21="","",IF(ISNUMBER(INDEX('MiT Strom Pipeline'!$A:$A,$U21)),INDEX('MiT Strom Pipeline'!$A:$A,$U21),"")) -> 53 | B21: =IF($U21="","",IF(INDEX('MiT Strom Pipeline'!$B:$B,$U21)="","",INDEX('MiT Strom Pipeline'!$B:$B,$U21))) -> DPR Generator Loadbank Test | C21: =IF($U21="","",IF(INDEX('MiT Strom Pipeline'!$C:$C,$U21)="","",INDEX('MiT Strom Pipeline'!$C:$C,$U21))) -> ZH | D21: =IF($U21="","",IF(INDEX('MiT Strom Pipeline'!$D:$D,$U21)="","",INDEX('MiT Strom Pipeline'!$D:$D,$U21))) -> Datacenter | E21: =IF($U21="","",IF(INDEX('MiT Strom Pipeline'!$H:$H,$U21)="","",INDEX('MiT Strom Pipeline'!$H:$H,$U21))) -> Aug | F21: =IF($U21="","",IF(INDEX('MiT Strom Pipeline'!$E:$E,$U21)="","",INDEX('MiT Strom Pipeline'!$E:$E,$U21))) -> 6000 kVA Loadbank | G21: =IF($U21="","",IF(ISNUMBER(INDEX('MiT Strom Pipeline'!$I:$I,$U21)),INDEX('MiT Strom Pipeline'!$I:$I,$U21),0)) -> 331889.15 | H21: =IF($U21="","",IF(ISNUMBER(INDEX('MiT Strom Pipeline'!$Q:$Q,$U21)),INDEX('MiT Strom Pipeline'!$Q:$Q,$U21),0)) -> 331889.15 | I21: =IF($U21="","",IF(ISNUMBER(INDEX('MiT Strom Pipeline'!$O:$O,$U21)),INDEX('MiT Strom Pipeline'!$O:$O,$U21),0)) -> -24868.66 | J21: =IF($U21="","",INDEX('MiT Strom Pipeline'!$R:$R,$U21)) -> WON | K21: =IF($U21="","",IF(ISNUMBER(INDEX('MiT Strom Pipeline'!$S:$S,$U21)),INDEX('MiT Strom Pipeline'!$S:$S,$U21),"")) -> 1 | L21: =IF($U21="","",IF(LEN(INDEX('MiT Strom Pipeline'!$V:$V,$U21))>0,LEFT(INDEX('MiT Strom Pipeline'!$V:$V,$U21),55),"")) -> Kunde angeschrieben auf MiT seite mit aktueller CHF Pre | U21: =IFERROR(MATCH(11,'MiT Strom Pipeline'!$AB$6:$AB$860,0)+5,"") -> 63
A22: =IF($U22="","",IF(ISNUMBER(INDEX('MiT Strom Pipeline'!$A:$A,$U22)),INDEX('MiT Strom Pipeline'!$A:$A,$U22),"")) -> 61 | B22: =IF($U22="","",IF(INDEX('MiT Strom Pipeline'!$B:$B,$U22)="","",INDEX('MiT Strom Pipeline'!$B:$B,$U22))) -> GETEC Park.Swiss AG | C22: =IF($U22="","",IF(INDEX('MiT Strom Pipeline'!$C:$C,$U22)="","",INDEX('MiT Strom Pipeline'!$C:$C,$U22))) -> BL | D22: =IF($U22="","",IF(INDEX('MiT Strom Pipeline'!$D:$D,$U22)="","",INDEX('MiT Strom Pipeline'!$D:$D,$U22))) -> Industrie | E22: =IF($U22="","",IF(INDEX('MiT Strom Pipeline'!$H:$H,$U22)="","",INDEX('MiT Strom Pipeline'!$H:$H,$U22))) -> August | F22: =IF($U22="","",IF(INDEX('MiT Strom Pipeline'!$E:$E,$U22)="","",INDEX('MiT Strom Pipeline'!$E:$E,$U22))) -> 600 kVA | G22: =IF($U22="","",IF(ISNUMBER(INDEX('MiT Strom Pipeline'!$I:$I,$U22)),INDEX('MiT Strom Pipeline'!$I:$I,$U22),0)) -> 13472.18 | H22: =IF($U22="","",IF(ISNUMBER(INDEX('MiT Strom Pipeline'!$Q:$Q,$U22)),INDEX('MiT Strom Pipeline'!$Q:$Q,$U22),0)) -> 13472.18 | I22: =IF($U22="","",IF(ISNUMBER(INDEX('MiT Strom Pipeline'!$O:$O,$U22)),INDEX('MiT Strom Pipeline'!$O:$O,$U22),0)) -> 1.8189894e-12 | J22: =IF($U22="","",INDEX('MiT Strom Pipeline'!$R:$R,$U22)) -> WON | K22: =IF($U22="","",IF(ISNUMBER(INDEX('MiT Strom Pipeline'!$S:$S,$U22)),INDEX('MiT Strom Pipeline'!$S:$S,$U22),"")) -> 1 | L22: =IF($U22="","",IF(LEN(INDEX('MiT Strom Pipeline'!$V:$V,$U22))>0,LEFT(INDEX('MiT Strom Pipeline'!$V:$V,$U22),55),"")) -> Kunde angeschrieben, Offerte erstellt, Kunde hat Offert | U22: =IFERROR(MATCH(12,'MiT Strom Pipeline'!$AB$6:$AB$860,0)+5,"") -> 71
A23: =IF($U23="","",IF(ISNUMBER(INDEX('MiT Strom Pipeline'!$A:$A,$U23)),INDEX('MiT Strom Pipeline'!$A:$A,$U23),"")) | B23: =IF($U23="","",IF(INDEX('MiT Strom Pipeline'!$B:$B,$U23)="","",INDEX('MiT Strom Pipeline'!$B:$B,$U23))) | C23: =IF($U23="","",IF(INDEX('MiT Strom Pipeline'!$C:$C,$U23)="","",INDEX('MiT Strom Pipeline'!$C:$C,$U23))) | D23: =IF($U23="","",IF(INDEX('MiT Strom Pipeline'!$D:$D,$U23)="","",INDEX('MiT Strom Pipeline'!$D:$D,$U23))) | E23: =IF($U23="","",IF(INDEX('MiT Strom Pipeline'!$H:$H,$U23)="","",INDEX('MiT Strom Pipeline'!$H:$H,$U23))) | F23: =IF($U23="","",IF(INDEX('MiT Strom Pipeline'!$E:$E,$U23)="","",INDEX('MiT Strom Pipeline'!$E:$E,$U23))) | G23: =IF($U23="","",IF(ISNUMBER(INDEX('MiT Strom Pipeline'!$I:$I,$U23)),INDEX('MiT Strom Pipeline'!$I:$I,$U23),0)) | H23: =IF($U23="","",IF(ISNUMBER(INDEX('MiT Strom Pipeline'!$Q:$Q,$U23)),INDEX('MiT Strom Pipeline'!$Q:$Q,$U23),0)) | I23: =IF($U23="","",IF(ISNUMBER(INDEX('MiT Strom Pipeline'!$O:$O,$U23)),INDEX('MiT Strom Pipeline'!$O:$O,$U23),0)) | J23: =IF($U23="","",INDEX('MiT Strom Pipeline'!$R:$R,$U23)) | K23: =IF($U23="","",IF(ISNUMBER(INDEX('MiT Strom Pipeline'!$S:$S,$U23)),INDEX('MiT Strom Pipeline'!$S:$S,$U23),"")) | L23: =IF($U23="","",IF(LEN(INDEX('MiT Strom Pipeline'!$V:$V,$U23))>0,LEFT(INDEX('MiT Strom Pipeline'!$V:$V,$U23),55),"")) | U23: =IFERROR(MATCH(13,'MiT Strom Pipeline'!$AB$6:$AB$860,0)+5,"")
A24: =IF($U24="","",IF(ISNUMBER(INDEX('MiT Strom Pipeline'!$A:$A,$U24)),INDEX('MiT Strom Pipeline'!$A:$A,$U24),"")) | B24: =IF($U24="","",IF(INDEX('MiT Strom Pipeline'!$B:$B,$U24)="","",INDEX('MiT Strom Pipeline'!$B:$B,$U24))) | C24: =IF($U24="","",IF(INDEX('MiT Strom Pipeline'!$C:$C,$U24)="","",INDEX('MiT Strom Pipeline'!$C:$C,$U24))) | D24: =IF($U24="","",IF(INDEX('MiT Strom Pipeline'!$D:$D,$U24)="","",INDEX('MiT Strom Pipeline'!$D:$D,$U24))) | E24: =IF($U24="","",IF(INDEX('MiT Strom Pipeline'!$H:$H,$U24)="","",INDEX('MiT Strom Pipeline'!$H:$H,$U24))) | F24: =IF($U24="","",IF(INDEX('MiT Strom Pipeline'!$E:$E,$U24)="","",INDEX('MiT Strom Pipeline'!$E:$E,$U24))) | G24: =IF($U24="","",IF(ISNUMBER(INDEX('MiT Strom Pipeline'!$I:$I,$U24)),INDEX('MiT Strom Pipeline'!$I:$I,$U24),0)) | H24: =IF($U24="","",IF(ISNUMBER(INDEX('MiT Strom Pipeline'!$Q:$Q,$U24)),INDEX('MiT Strom Pipeline'!$Q:$Q,$U24),0)) | I24: =IF($U24="","",IF(ISNUMBER(INDEX('MiT Strom Pipeline'!$O:$O,$U24)),INDEX('MiT Strom Pipeline'!$O:$O,$U24),0)) | J24: =IF($U24="","",INDEX('MiT Strom Pipeline'!$R:$R,$U24)) | K24: =IF($U24="","",IF(ISNUMBER(INDEX('MiT Strom Pipeline'!$S:$S,$U24)),INDEX('MiT Strom Pipeline'!$S:$S,$U24),"")) | L24: =IF($U24="","",IF(LEN(INDEX('MiT Strom Pipeline'!$V:$V,$U24))>0,LEFT(INDEX('MiT Strom Pipeline'!$V:$V,$U24),55),"")) | U24: =IFERROR(MATCH(14,'MiT Strom Pipeline'!$AB$6:$AB$860,0)+5,"")
A25: =IF($U25="","",IF(ISNUMBER(INDEX('MiT Strom Pipeline'!$A:$A,$U25)),INDEX('MiT Strom Pipeline'!$A:$A,$U25),"")) | B25: =IF($U25="","",IF(INDEX('MiT Strom Pipeline'!$B:$B,$U25)="","",INDEX('MiT Strom Pipeline'!$B:$B,$U25))) | C25: =IF($U25="","",IF(INDEX('MiT Strom Pipeline'!$C:$C,$U25)="","",INDEX('MiT Strom Pipeline'!$C:$C,$U25))) | D25: =IF($U25="","",IF(INDEX('MiT Strom Pipeline'!$D:$D,$U25)="","",INDEX('MiT Strom Pipeline'!$D:$D,$U25))) | E25: =IF($U25="","",IF(INDEX('MiT Strom Pipeline'!$H:$H,$U25)="","",INDEX('MiT Strom Pipeline'!$H:$H,$U25))) | F25: =IF($U25="","",IF(INDEX('MiT Strom Pipeline'!$E:$E,$U25)="","",INDEX('MiT Strom Pipeline'!$E:$E,$U25))) | G25: =IF($U25="","",IF(ISNUMBER(INDEX('MiT Strom Pipeline'!$I:$I,$U25)),INDEX('MiT Strom Pipeline'!$I:$I,$U25),0)) | H25: =IF($U25="","",IF(ISNUMBER(INDEX('MiT Strom Pipeline'!$Q:$Q,$U25)),INDEX('MiT Strom Pipeline'!$Q:$Q,$U25),0)) | I25: =IF($U25="","",IF(ISNUMBER(INDEX('MiT Strom Pipeline'!$O:$O,$U25)),INDEX('MiT Strom Pipeline'!$O:$O,$U25),0)) | J25: =IF($U25="","",INDEX('MiT Strom Pipeline'!$R:$R,$U25)) | K25: =IF($U25="","",IF(ISNUMBER(INDEX('MiT Strom Pipeline'!$S:$S,$U25)),INDEX('MiT Strom Pipeline'!$S:$S,$U25),"")) | L25: =IF($U25="","",IF(LEN(INDEX('MiT Strom Pipeline'!$V:$V,$U25))>0,LEFT(INDEX('MiT Strom Pipeline'!$V:$V,$U25),55),"")) | U25: =IFERROR(MATCH(15,'MiT Strom Pipeline'!$AB$6:$AB$860,0)+5,"")
A26: =IF($U26="","",IF(ISNUMBER(INDEX('MiT Strom Pipeline'!$A:$A,$U26)),INDEX('MiT Strom Pipeline'!$A:$A,$U26),"")) | B26: =IF($U26="","",IF(INDEX('MiT Strom Pipeline'!$B:$B,$U26)="","",INDEX('MiT Strom Pipeline'!$B:$B,$U26))) | C26: =IF($U26="","",IF(INDEX('MiT Strom Pipeline'!$C:$C,$U26)="","",INDEX('MiT Strom Pipeline'!$C:$C,$U26))) | D26: =IF($U26="","",IF(INDEX('MiT Strom Pipeline'!$D:$D,$U26)="","",INDEX('MiT Strom Pipeline'!$D:$D,$U26))) | E26: =IF($U26="","",IF(INDEX('MiT Strom Pipeline'!$H:$H,$U26)="","",INDEX('MiT Strom Pipeline'!$H:$H,$U26))) | F26: =IF($U26="","",IF(INDEX('MiT Strom Pipeline'!$E:$E,$U26)="","",INDEX('MiT Strom Pipeline'!$E:$E,$U26))) | G26: =IF($U26="","",IF(ISNUMBER(INDEX('MiT Strom Pipeline'!$I:$I,$U26)),INDEX('MiT Strom Pipeline'!$I:$I,$U26),0)) | H26: =IF($U26="","",IF(ISNUMBER(INDEX('MiT Strom Pipeline'!$Q:$Q,$U26)),INDEX('MiT Strom Pipeline'!$Q:$Q,$U26),0)) | I26: =IF($U26="","",IF(ISNUMBER(INDEX('MiT Strom Pipeline'!$O:$O,$U26)),INDEX('MiT Strom Pipeline'!$O:$O,$U26),0)) | J26: =IF($U26="","",INDEX('MiT Strom Pipeline'!$R:$R,$U26)) | K26: =IF($U26="","",IF(ISNUMBER(INDEX('MiT Strom Pipeline'!$S:$S,$U26)),INDEX('MiT Strom Pipeline'!$S:$S,$U26),"")) | L26: =IF($U26="","",IF(LEN(INDEX('MiT Strom Pipeline'!$V:$V,$U26))>0,LEFT(INDEX('MiT Strom Pipeline'!$V:$V,$U26),55),"")) | U26: =IFERROR(MATCH(16,'MiT Strom Pipeline'!$AB$6:$AB$860,0)+5,"")
A27: =IF($U27="","",IF(ISNUMBER(INDEX('MiT Strom Pipeline'!$A:$A,$U27)),INDEX('MiT Strom Pipeline'!$A:$A,$U27),"")) | B27: =IF($U27="","",IF(INDEX('MiT Strom Pipeline'!$B:$B,$U27)="","",INDEX('MiT Strom Pipeline'!$B:$B,$U27))) | C27: =IF($U27="","",IF(INDEX('MiT Strom Pipeline'!$C:$C,$U27)="","",INDEX('MiT Strom Pipeline'!$C:$C,$U27))) | D27: =IF($U27="","",IF(INDEX('MiT Strom Pipeline'!$D:$D,$U27)="","",INDEX('MiT Strom Pipeline'!$D:$D,$U27))) | E27: =IF($U27="","",IF(INDEX('MiT Strom Pipeline'!$H:$H,$U27)="","",INDEX('MiT Strom Pipeline'!$H:$H,$U27))) | F27: =IF($U27="","",IF(INDEX('MiT Strom Pipeline'!$E:$E,$U27)="","",INDEX('MiT Strom Pipeline'!$E:$E,$U27))) | G27: =IF($U27="","",IF(ISNUMBER(INDEX('MiT Strom Pipeline'!$I:$I,$U27)),INDEX('MiT Strom Pipeline'!$I:$I,$U27),0)) | H27: =IF($U27="","",IF(ISNUMBER(INDEX('MiT Strom Pipeline'!$Q:$Q,$U27)),INDEX('MiT Strom Pipeline'!$Q:$Q,$U27),0)) | I27: =IF($U27="","",IF(ISNUMBER(INDEX('MiT Strom Pipeline'!$O:$O,$U27)),INDEX('MiT Strom Pipeline'!$O:$O,$U27),0)) | J27: =IF($U27="","",INDEX('MiT Strom Pipeline'!$R:$R,$U27)) | K27: =IF($U27="","",IF(ISNUMBER(INDEX('MiT Strom Pipeline'!$S:$S,$U27)),INDEX('MiT Strom Pipeline'!$S:$S,$U27),"")) | L27: =IF($U27="","",IF(LEN(INDEX('MiT Strom Pipeline'!$V:$V,$U27))>0,LEFT(INDEX('MiT Strom Pipeline'!$V:$V,$U27),55),"")) | U27: =IFERROR(MATCH(17,'MiT Strom Pipeline'!$AB$6:$AB$860,0)+5,"")
A28: =IF($U28="","",IF(ISNUMBER(INDEX('MiT Strom Pipeline'!$A:$A,$U28)),INDEX('MiT Strom Pipeline'!$A:$A,$U28),"")) | B28: =IF($U28="","",IF(INDEX('MiT Strom Pipeline'!$B:$B,$U28)="","",INDEX('MiT Strom Pipeline'!$B:$B,$U28))) | C28: =IF($U28="","",IF(INDEX('MiT Strom Pipeline'!$C:$C,$U28)="","",INDEX('MiT Strom Pipeline'!$C:$C,$U28))) | D28: =IF($U28="","",IF(INDEX('MiT Strom Pipeline'!$D:$D,$U28)="","",INDEX('MiT Strom Pipeline'!$D:$D,$U28))) | E28: =IF($U28="","",IF(INDEX('MiT Strom Pipeline'!$H:$H,$U28)="","",INDEX('MiT Strom Pipeline'!$H:$H,$U28))) | F28: =IF($U28="","",IF(INDEX('MiT Strom Pipeline'!$E:$E,$U28)="","",INDEX('MiT Strom Pipeline'!$E:$E,$U28))) | G28: =IF($U28="","",IF(ISNUMBER(INDEX('MiT Strom Pipeline'!$I:$I,$U28)),INDEX('MiT Strom Pipeline'!$I:$I,$U28),0)) | H28: =IF($U28="","",IF(ISNUMBER(INDEX('MiT Strom Pipeline'!$Q:$Q,$U28)),INDEX('MiT Strom Pipeline'!$Q:$Q,$U28),0)) | I28: =IF($U28="","",IF(ISNUMBER(INDEX('MiT Strom Pipeline'!$O:$O,$U28)),INDEX('MiT Strom Pipeline'!$O:$O,$U28),0)) | J28: =IF($U28="","",INDEX('MiT Strom Pipeline'!$R:$R,$U28)) | K28: =IF($U28="","",IF(ISNUMBER(INDEX('MiT Strom Pipeline'!$S:$S,$U28)),INDEX('MiT Strom Pipeline'!$S:$S,$U28),"")) | L28: =IF($U28="","",IF(LEN(INDEX('MiT Strom Pipeline'!$V:$V,$U28))>0,LEFT(INDEX('MiT Strom Pipeline'!$V:$V,$U28),55),"")) | U28: =IFERROR(MATCH(18,'MiT Strom Pipeline'!$AB$6:$AB$860,0)+5,"")
A29: =IF($U29="","",IF(ISNUMBER(INDEX('MiT Strom Pipeline'!$A:$A,$U29)),INDEX('MiT Strom Pipeline'!$A:$A,$U29),"")) | B29: =IF($U29="","",IF(INDEX('MiT Strom Pipeline'!$B:$B,$U29)="","",INDEX('MiT Strom Pipeline'!$B:$B,$U29))) | C29: =IF($U29="","",IF(INDEX('MiT Strom Pipeline'!$C:$C,$U29)="","",INDEX('MiT Strom Pipeline'!$C:$C,$U29))) | D29: =IF($U29="","",IF(INDEX('MiT Strom Pipeline'!$D:$D,$U29)="","",INDEX('MiT Strom Pipeline'!$D:$D,$U29))) | E29: =IF($U29="","",IF(INDEX('MiT Strom Pipeline'!$H:$H,$U29)="","",INDEX('MiT Strom Pipeline'!$H:$H,$U29))) | F29: =IF($U29="","",IF(INDEX('MiT Strom Pipeline'!$E:$E,$U29)="","",INDEX('MiT Strom Pipeline'!$E:$E,$U29))) | G29: =IF($U29="","",IF(ISNUMBER(INDEX('MiT Strom Pipeline'!$I:$I,$U29)),INDEX('MiT Strom Pipeline'!$I:$I,$U29),0)) | H29: =IF($U29="","",IF(ISNUMBER(INDEX('MiT Strom Pipeline'!$Q:$Q,$U29)),INDEX('MiT Strom Pipeline'!$Q:$Q,$U29),0)) | I29: =IF($U29="","",IF(ISNUMBER(INDEX('MiT Strom Pipeline'!$O:$O,$U29)),INDEX('MiT Strom Pipeline'!$O:$O,$U29),0)) | J29: =IF($U29="","",INDEX('MiT Strom Pipeline'!$R:$R,$U29)) | K29: =IF($U29="","",IF(ISNUMBER(INDEX('MiT Strom Pipeline'!$S:$S,$U29)),INDEX('MiT Strom Pipeline'!$S:$S,$U29),"")) | L29: =IF($U29="","",IF(LEN(INDEX('MiT Strom Pipeline'!$V:$V,$U29))>0,LEFT(INDEX('MiT Strom Pipeline'!$V:$V,$U29),55),"")) | U29: =IFERROR(MATCH(19,'MiT Strom Pipeline'!$AB$6:$AB$860,0)+5,"")
A30: =IF($U30="","",IF(ISNUMBER(INDEX('MiT Strom Pipeline'!$A:$A,$U30)),INDEX('MiT Strom Pipeline'!$A:$A,$U30),"")) | B30: =IF($U30="","",IF(INDEX('MiT Strom Pipeline'!$B:$B,$U30)="","",INDEX('MiT Strom Pipeline'!$B:$B,$U30))) | C30: =IF($U30="","",IF(INDEX('MiT Strom Pipeline'!$C:$C,$U30)="","",INDEX('MiT Strom Pipeline'!$C:$C,$U30))) | D30: =IF($U30="","",IF(INDEX('MiT Strom Pipeline'!$D:$D,$U30)="","",INDEX('MiT Strom Pipeline'!$D:$D,$U30))) | E30: =IF($U30="","",IF(INDEX('MiT Strom Pipeline'!$H:$H,$U30)="","",INDEX('MiT Strom Pipeline'!$H:$H,$U30))) | F30: =IF($U30="","",IF(INDEX('MiT Strom Pipeline'!$E:$E,$U30)="","",INDEX('MiT Strom Pipeline'!$E:$E,$U30))) | G30: =IF($U30="","",IF(ISNUMBER(INDEX('MiT Strom Pipeline'!$I:$I,$U30)),INDEX('MiT Strom Pipeline'!$I:$I,$U30),0)) | H30: =IF($U30="","",IF(ISNUMBER(INDEX('MiT Strom Pipeline'!$Q:$Q,$U30)),INDEX('MiT Strom Pipeline'!$Q:$Q,$U30),0)) | I30: =IF($U30="","",IF(ISNUMBER(INDEX('MiT Strom Pipeline'!$O:$O,$U30)),INDEX('MiT Strom Pipeline'!$O:$O,$U30),0)) | J30: =IF($U30="","",INDEX('MiT Strom Pipeline'!$R:$R,$U30)) | K30: =IF($U30="","",IF(ISNUMBER(INDEX('MiT Strom Pipeline'!$S:$S,$U30)),INDEX('MiT Strom Pipeline'!$S:$S,$U30),"")) | L30: =IF($U30="","",IF(LEN(INDEX('MiT Strom Pipeline'!$V:$V,$U30))>0,LEFT(INDEX('MiT Strom Pipeline'!$V:$V,$U30),55),"")) | U30: =IFERROR(MATCH(20,'MiT Strom Pipeline'!$AB$6:$AB$860,0)+5,"")
A31: =IF($U31="","",IF(ISNUMBER(INDEX('MiT Strom Pipeline'!$A:$A,$U31)),INDEX('MiT Strom Pipeline'!$A:$A,$U31),"")) | B31: =IF($U31="","",IF(INDEX('MiT Strom Pipeline'!$B:$B,$U31)="","",INDEX('MiT Strom Pipeline'!$B:$B,$U31))) | C31: =IF($U31="","",IF(INDEX('MiT Strom Pipeline'!$C:$C,$U31)="","",INDEX('MiT Strom Pipeline'!$C:$C,$U31))) | D31: =IF($U31="","",IF(INDEX('MiT Strom Pipeline'!$D:$D,$U31)="","",INDEX('MiT Strom Pipeline'!$D:$D,$U31))) | E31: =IF($U31="","",IF(INDEX('MiT Strom Pipeline'!$H:$H,$U31)="","",INDEX('MiT Strom Pipeline'!$H:$H,$U31))) | F31: =IF($U31="","",IF(INDEX('MiT Strom Pipeline'!$E:$E,$U31)="","",INDEX('MiT Strom Pipeline'!$E:$E,$U31))) | G31: =IF($U31="","",IF(ISNUMBER(INDEX('MiT Strom Pipeline'!$I:$I,$U31)),INDEX('MiT Strom Pipeline'!$I:$I,$U31),0)) | H31: =IF($U31="","",IF(ISNUMBER(INDEX('MiT Strom Pipeline'!$Q:$Q,$U31)),INDEX('MiT Strom Pipeline'!$Q:$Q,$U31),0)) | I31: =IF($U31="","",IF(ISNUMBER(INDEX('MiT Strom Pipeline'!$O:$O,$U31)),INDEX('MiT Strom Pipeline'!$O:$O,$U31),0)) | J31: =IF($U31="","",INDEX('MiT Strom Pipeline'!$R:$R,$U31)) | K31: =IF($U31="","",IF(ISNUMBER(INDEX('MiT Strom Pipeline'!$S:$S,$U31)),INDEX('MiT Strom Pipeline'!$S:$S,$U31),"")) | L31: =IF($U31="","",IF(LEN(INDEX('MiT Strom Pipeline'!$V:$V,$U31))>0,LEFT(INDEX('MiT Strom Pipeline'!$V:$V,$U31),55),"")) | U31: =IFERROR(MATCH(21,'MiT Strom Pipeline'!$AB$6:$AB$860,0)+5,"")
A32: =IF($U32="","",IF(ISNUMBER(INDEX('MiT Strom Pipeline'!$A:$A,$U32)),INDEX('MiT Strom Pipeline'!$A:$A,$U32),"")) | B32: =IF($U32="","",IF(INDEX('MiT Strom Pipeline'!$B:$B,$U32)="","",INDEX('MiT Strom Pipeline'!$B:$B,$U32))) | C32: =IF($U32="","",IF(INDEX('MiT Strom Pipeline'!$C:$C,$U32)="","",INDEX('MiT Strom Pipeline'!$C:$C,$U32))) | D32: =IF($U32="","",IF(INDEX('MiT Strom Pipeline'!$D:$D,$U32)="","",INDEX('MiT Strom Pipeline'!$D:$D,$U32))) | E32: =IF($U32="","",IF(INDEX('MiT Strom Pipeline'!$H:$H,$U32)="","",INDEX('MiT Strom Pipeline'!$H:$H,$U32))) | F32: =IF($U32="","",IF(INDEX('MiT Strom Pipeline'!$E:$E,$U32)="","",INDEX('MiT Strom Pipeline'!$E:$E,$U32))) | G32: =IF($U32="","",IF(ISNUMBER(INDEX('MiT Strom Pipeline'!$I:$I,$U32)),INDEX('MiT Strom Pipeline'!$I:$I,$U32),0)) | H32: =IF($U32="","",IF(ISNUMBER(INDEX('MiT Strom Pipeline'!$Q:$Q,$U32)),INDEX('MiT Strom Pipeline'!$Q:$Q,$U32),0)) | I32: =IF($U32="","",IF(ISNUMBER(INDEX('MiT Strom Pipeline'!$O:$O,$U32)),INDEX('MiT Strom Pipeline'!$O:$O,$U32),0)) | J32: =IF($U32="","",INDEX('MiT Strom Pipeline'!$R:$R,$U32)) | K32: =IF($U32="","",IF(ISNUMBER(INDEX('MiT Strom Pipeline'!$S:$S,$U32)),INDEX('MiT Strom Pipeline'!$S:$S,$U32),"")) | L32: =IF($U32="","",IF(LEN(INDEX('MiT Strom Pipeline'!$V:$V,$U32))>0,LEFT(INDEX('MiT Strom Pipeline'!$V:$V,$U32),55),"")) | U32: =IFERROR(MATCH(22,'MiT Strom Pipeline'!$AB$6:$AB$860,0)+5,"")
