Workbook

Sheet Start
B1: GYM LOGBUCH | BEINTRAINING · FASSUNG VOR DER OP
B2: Gilt bis zur Operation am 30.09.2026. Danach auf die Reha-Fassung wechseln.
B4: Kurzübersicht
B5: Einheiten erfasst | C5: =COUNT(Einheiten!$I$4:$I$63) -> 17
B6: Sätze gesamt | C6: =COUNTA(Log!$E$4:$E$1203) -> 360
B7: Gesamtvolumen (t) | C7: =IFERROR(SUM(Log!$I$4:$I$1203)/1000,0) -> 271.227
B8: Schwerster Arbeitssatz (kg) | C8: =SUMPRODUCT(MAX((Log!$E$4:$E$1203="A")*(Log!$F$4:$F$1203<>"")*Log!$F$4:$F$1203)) -> 333
B10: Diese Fassung gilt bis zur Operation am 30.09.2026. Am OP-Tag auf die Reha-Fassung wechseln und die Zeilen aus 'Log' und 'Einheiten' hinüberkopieren - der Aufbau ist identisch, Auswertung und Rekorde rechnen dort sofort weiter. Die Blätter hier sind Planungshilfe, keine ärztliche Anweisung: was du vor der OP trainieren darfst, sagen Operateur und Physiotherapie.
B12: So arbeitest du damit
B13: Blatt 'Einheiten' | C13: Zuerst hier die Einheit anlegen: Nummer, Datum, Körpergewicht, Dauer, Schlaf, Gefühl. Das Datum zieht sich automatisch ins Log, du trägst es nur einmal ein.
B14: Blatt 'Log' | C14: Eine Zeile pro Satz. Nur die gelben Spalten ausfüllen: Einheit, Übung, Satztyp, Gewicht, Wdh, optional RPE und Notiz. Block, Volumen und e1RM rechnen sich selbst.
B15: Blatt 'Trainingsblatt' | C15: Ausdrucken und mitnehmen. Zeigt je Übung, was du zuletzt gemacht hast, dazu Zielvorschlag, Aufwärm-Rampe und leere Felder zum Eintragen mit Stift. Hinter jeder Übung steht, wie lange sie nach der OP ausfällt. Ein Ausdruck liefert vier Blätter je Block, also rund vier Trainingswochen am Stück - für spontane Zusatzübungen sind die Notizzeilen am Seitenende da.
B16: Blatt 'Auswertung' | C16: Volumen, Top-Gewicht und bester e1RM je Übung und Einheit. Drei Tabellen, jede auf einer eigenen Druckseite. Zeigt 16 Einheiten nebeneinander; mit der Zahl in B3 blätterst du weiter, die Gesamtspalte rechnet immer über alles.
B17: Blatt 'Progression' | C17: Erste gegen letzte Einheit: Veränderung in kg und Prozent, Abstand zum eigenen Bestwert, Trendbewertung.
B18: Blatt 'Rekorde' | C18: Bestwerte je Übung über alle Einheiten, inklusive der Einheit, in der der Rekord gefallen ist.
B19: Blatt 'Wochenplan' | C19: Wochenraster mit zwei Beineinheiten und den Regeln zur Regeneration: 72 Stunden Abstand, Satzpausen, Schlaf, was bei ausbleibendem Fortschritt zuerst zu prüfen ist. Dazu der Wiedereinstieg nach der Trainingspause: welche Übung diese Woche pausiert und welche mit welchem Prozentsatz zurückkommt.
B20: Blatt 'Dashboard' | C20: Kennzahlen und vier Diagramme auf einer Seite. Gut zum Aufhängen.
B21: Blatt 'Reha-Plan Beine' | C21: Der eigentliche Trainingsplan nach der OP. Je Phase steht dort, welche Übung läuft, mit wie vielen Sätzen und Wiederholungen und mit welchem konkreten Gewicht - gerechnet als Prozentsatz des letzten Arbeitsgewichts vor der OP und auf die Laststufe des Geräts abgerundet. Dieses Blatt ersetzt in der Reha das Trainingsblatt; ab Phase 4 wird wieder das Trainingsblatt genutzt.
B22: Blatt 'OP-Countdown' | C22: Tage und Wochen bis zum Termin, und vor allem: welche Übung nach der OP wie lange ausfällt und welcher Ersatz einspringt. Die Ersatzgeräte jetzt einarbeiten und das Arbeitsgewicht dort eintragen - dann steht der Startwert nach der OP schon fest.
B23: Blatt 'Vorbereitung' | C23: Checkliste bis zum OP-Tag: Fragen an Operateur und Physiotherapie, Organisation, Gym-Logistik. Die Antworten gehören in die Notizspalte, dann hast du sie später schwarz auf weiss.
B24: Blatt 'Baseline Schulter' | C24: Ausgangswerte beider Schultern vor der OP: Beweglichkeit in Grad, Schmerz, Curl-Testgewicht. Diese Zahlen sind nach der OP nicht mehr nachholbar, und der Reha-Fahrplan misst mehrere Meilensteine am Vergleich zur Gegenseite.
B25: Blatt 'Übungen' | C25: Stammdaten und Planvorgaben: Ziel-Wdh, Ziel-Sätze, Ziel-RPE und Startgewicht je Übung. Neue Übung hier ergänzen - sie erscheint automatisch in den Dropdowns und in allen Auswertungen. 'Aktiv' kennt drei Zustände: 'ja' läuft normal, 'pause' setzt eine Übung vorübergehend aus (sie bleibt in der Historie, das Trainingsblatt zeigt statt der Gewichte einen roten Pausenvermerk), 'nein' archiviert sie ganz. Die Spalte 'Anpassung %' drosselt das Zielgewicht einer Übung, ohne die Rechnung zu verfälschen: 100 ist normal, 80 heisst 80 Prozent des berechneten Ziels - gedacht für den Wiedereinstieg nach Pause oder Verletzung. Wichtig: die Anpassung wieder auf 100 setzen, sobald die Übung einmal auf dem reduzierten Gewicht gelaufen ist. Sonst rechnet der Plan die Prozente auf ein schon reduziertes Ergebnis, und das Zielgewicht sinkt Einheit für Einheit weiter statt zu steigen.
B27: Legende
B28: Gelbe Zellen | C28: Deine Eingabe. Nur hier tippen.
B29: Weisse / graue Zellen | C29: Formeln. Nicht überschreiben.
B30: Satztyp W | C30: Warmup. Zählt nicht ins Arbeitsvolumen.
B31: Satztyp A | C31: Arbeitssatz. Basis für Volumen, Top-Gewicht und e1RM.
B32: Satztyp R | C32: Reduktions- bzw. Dropsatz. Kette in der Spalte 'Drop-Kette' notieren, z.B. 110 / 72.5 / 35. Zählt nicht ins Arbeitsvolumen, weil die Wdh je Stufe fehlen.
B33: Volumen | C33: Gewicht × Wdh je Satz. Der ehrlichste Fortschrittswert an Maschinen.
B34: e1RM (Epley) | C34: Gewicht × (1 + Wdh / 30). An Maschinen kein echtes 1RM, aber ein sauberer Vergleich zwischen Einheiten mit unterschiedlichen Wiederholungszahlen.
B35: RPE | C35: Anstrengung 6 bis 10. 10 = keine Wiederholung mehr möglich. Optional, aber sehr hilfreich für die Steuerung. Die Zielwerte je Übung stehen im Blatt 'Übungen'.
B36: Zielbereich 5 bis 6 Wdh | C36: Alle Übungen laufen im selben Bereich: 5 bis 6 Wiederholungen je Arbeitssatz. Kraftlastig, dafür brauchen die Sätze längere Pausen - drei bis vier Minuten bei den schweren Übungen.
B37: Drei Sätze, absteigend | C37: Immer genau drei Arbeitssätze, keine Reduktionssätze mehr. Satz 1 ist der schwere Top-Satz und bestimmt allein die Progression. Satz 2 läuft mit 95 Prozent, Satz 3 mit 90 Prozent davon - beide dürfen eine beziehungsweise zwei Wiederholungen mehr, aber nie über 6. Auf dem Trainingsblatt steht je Satz das eigene Gewicht: Warmup 1 mit 40 und Warmup 2 mit 70 Prozent, dann Arbeitssatz 1 mit 100, Arbeitssatz 2 mit 95 und Arbeitssatz 3 mit 90 Prozent. Alle drei Arbeitssätze bleiben im Bereich 5 bis 6 Wiederholungen.
B38: Doppelte Progression | C38: So wird gesteigert, und zwar nach jedem Training neu: Solange der schwächste Arbeitssatz unter 6 Wdh liegt, bleibt das Gewicht stehen und es kommt eine Wiederholung dazu. Schaffen alle Sätze 6, kommt Gewicht drauf und die Wiederholungen fangen bei 5 wieder an. Bezug ist immer der schwächste Satz, nicht der beste. Sobald du die Einheit ins Log tippst, steht der nächste Schritt da.
B39: Wie viel Gewicht dazukommt | C39: Ein Prozent auf das letzte Top-Gewicht, aufgerundet auf die nächste Laststufe des Geräts. Das ist bewusst klein gehalten und über Monate tragfähig. An Maschinen mit groben Steckgewichten ist eine Stufe mehr als ein Prozent - der tatsächliche Zuwachs steht deshalb in Prozent neben dem Vorschlag. Wird ein Sprung zu gross, im Blatt 'Übungen' eine kleinere Laststufe eintragen.
... B41: Archiv | C41: Übung im Blatt 'Übungen' auf Aktiv = nein setzen. Sie verschwindet aus dem Trainingsblatt, bleibt in Log, Auswertung, Progression und Rekorden aber sichtbar - dort grau und kursiv.
B43: Offene Punkte aus der Originalquelle
B44: Kickback, Warmups | C44: Im Original stehen zwei Gewichte statt Gewicht plus Wdh (z.B. 35 kg / 49 kg). Als zwei Warmup-Sätze ohne Wdh erfasst.
B45: Adduktion, Einheit 4 | C45: Original 152.2 kg, überall sonst 152.5 kg. Als Tippfehler auf 152.5 korrigiert und im Log vermerkt. War es ein anderes Gerät, die beiden Zeilen im Log anpassen.
B46: Beinstrecker, Einheit 2 | C46: Zeile 'W 10 kg 20 kg 5-6 Wdh' als zwei Warmups ohne Wdh erfasst.
...

Sheet Wochenplan
B1: WOCHENPLAN | VOR DER OP
B2: Zwei Beineinheiten je Woche, dazwischen mindestens 72 Stunden. Regeneration ist Teil des Plans, nicht die Pause davon.
B4: Wochenraster
B5: Tag | C5: Einheit | D5: Inhalt | E5: Warum
B6: Montag | C6: Beine vorne | D6: Beinpresse eng · Split Squat · Beinstrecker · Adduktion | E6: Frischer Wochenstart für die schwerste Einheit.
B7: Dienstag | C7: frei | D7: Gehen, lockeres Radfahren, Mobilität | E7: Durchblutung fördert die Erholung, ohne neuen Reiz zu setzen.
B8: Mittwoch | C8: frei | D8: Oberkörper oder Ruhetag | E8: Beine bleiben unbelastet.
B9: Donnerstag | C9: Beine hinten | D9: Reverse V-Squat · RDL Kurzhantel · Beinpresse breit · Hip Thrust · Hip & Glute · Beinbeuger · Seitl. Kickbacks · Waden | E9: 72 Stunden nach Montag - die Vorderseite ist wieder erholt.
B10: Freitag | C10: frei | D10: Oberkörper oder Ruhetag | E10: Erholung.
B11: Samstag | C11: frei | D11: Gehen, Mobilität | E11: Lockere Bewegung, keine Beinlast.
B12: Sonntag | C12: frei | D12: Ruhetag | E12: Vollständige Pause vor dem nächsten Montag.
B14: Wiedereinstieg nach der Pause (Adduktoren links)
B15: Die Rückkehrwoche nach der Zerrung in der linken Oberschenkelinnenseite ist durch: Einheit 11 (Beine hinten) und Einheit 12 (Beine vorne) sind gelaufen, beide ohne gemeldete Beschwerden. Neun Übungen stehen deshalb wieder auf Anpassung 100 Prozent und drei Arbeitssätzen. Nur die zwei Übungen, die den verletzten Muskel direkt treffen, kommen gedrosselt zurück - Stand unten. Nach zwei beschwerdefreien Einheiten auch dort im Blatt 'Übungen' die Anpassung auf 100 und die Ziel-Sätze auf 3 setzen.
B16: Stufe | C16: Übungen | D16: Vorgabe | E16: Begründung
B17: erledigt | C17: Adduktion (Maschine) | D17: 3 Sätze, Anpassung 100 % | E17: In Einheit 17 mit 165 x 6 schmerzfrei gelaufen, das war die erste Einheit seit der Zerrung. Drosselung damit aufgehoben. Wichtig: die Anpassung muss weg, sobald eine Übung einmal auf dem reduzierten Gewicht gelaufen ist - sonst rechnet der Plan die Prozente auf ein schon reduziertes Ergebnis und die Last sinkt weiter.
B18: Eichung | C18: Beinpresse breiter Stand | D18: 3 Sätze, Start 220 kg | E18: Drosselung aufgehoben, aber bis heute nie ausgeführt. Das Startgewicht bleibt eine Schätzung und steht vorsichtig bei 220 kg statt 260 - die erste Einheit ist eine Eichung.
B19: 100 % | C19: alle übrigen zehn Übungen | D19: 3 Sätze, volle Progression | E19: Einheit 11, 12 und 13 nach der Pause ohne Beschwerden gelaufen. Die Drosselung hat ihren Zweck erfüllt und würde ab jetzt nur noch Fortschritt kosten.
B20: Abbruch | C20: alle Übungen | D20: bei Ziehen sofort beenden | E20: Ein Ziehen in der Leiste ist kein Muskelkater. Die Einheit endet, die Übung wird notiert, und es geht zur Ärztin oder zur Physiotherapie - nicht ins nächste Gewicht.
B22: Regeneration - die Regeln
B23: 72 Stunden zwischen zwei Beineinheiten | C23: Muskelprotein-Synthese läuft nach einer schweren Einheit rund zwei bis drei Tage. Wer früher wieder schwer belastet, sammelt Ermüdung statt Anpassung. Zwei Einheiten je Woche reichen bei drei Arbeitssätzen im Bereich 5 bis 6 vollkommen aus.
B24: Satzpausen: 3 bis 4 Minuten schwer, 2 Minuten Isolation | C24: Im Bereich 5 bis 6 Wiederholungen ist die Last hoch. Zu kurze Pausen kosten Wiederholungen im nächsten Satz und verfälschen damit die Progression - der schwächste Satz ist die Rechengrundlage.
B25: Schlaf 7 bis 9 Stunden | C25: Der grösste Wachstumshormon-Puls liegt im ersten Tiefschlafzyklus. Zwei kurze Nächte hintereinander sieht man in den Wiederholungen.
B26: Protein über den Tag verteilt | C26: 2.0 bis 2.5 g je kg Körpergewicht, auf vier bis fünf Mahlzeiten. Derselbe Wert, den der Reha-Fahrplan für die Sehnenheilung nennt.
B27: Muskelkater beim Aufwärmen | C27: Ist der Muskelkater der letzten Einheit beim zweiten Warmup noch deutlich spürbar, die Einheit mit zwei statt drei Arbeitssätzen fahren. Das Gewicht bleibt, das Volumen sinkt.
B28: Zwei Einheiten ohne Fortschritt | C28: Steht eine Übung zwei Einheiten auf demselben Gewicht und derselben Wiederholungszahl, ist meist die Erholung das Problem, nicht der Reiz. Erst Schlaf und Essen prüfen, dann das Programm.
B30: Drittes Trainingsblatt 'Auswärts Bülach': eigene Übungen für das zweite Gym. Die Maschinen dort haben andere Hebel, deshalb laufen sie mit eigener Historie und eigener Progression - sonst würden 200 kg am fremden Hip Thrust die 285 kg vom eigenen Gerät überschreiben. Ersetzt eine Auswärts-Einheit einen der beiden Tage oben, bleibt der 72-Stunden-Abstand trotzdem stehen.
B32: Zwei Beineinheiten an aufeinanderfolgenden Tagen sind möglich, aber nicht ideal: Kniebeuge-Muster und Hüftstreckung überschneiden sich stärker, als die Blocknamen vermuten lassen. Wenn es terminlich nicht anders geht, die zweite Einheit mit zwei statt drei Arbeitssätzen fahren.

Sheet Dashboard
A1: DASHBOARD | BEINTRAINING AUF EINEN BLICK
A2: Alle Werte rechnen sich aus dem Log.
B4: Einheiten | E4: Sätze gesamt | H4: Arbeitssätze
B5: =COUNT(Einheiten!$I$4:$I$63) -> 17 | E5: =COUNTA(Log!$E$4:$E$1203) -> 360 | H5: =COUNTIF(Log!$E$4:$E$1203,"A") -> 214
B7: Gesamtvolumen (t) | E7: Arbeitsvolumen (t) | H7: Volumen je Einheit (kg)
B8: =SUM(Log!$I$4:$I$1203)/1000 -> 271.227 | E8: =SUMIF(Log!$E$4:$E$1203,"A",Log!$I$4:$I$1203)/1000 -> 251.3395 | H8: =IFERROR(SUMIF(Log!$E$4:$E$1203,"A",Log!$I$4:$I$1203)/COUNT(Einheiten!$I$4:$I$63),"") -> 14784.676
B10: Schwerster Satz (kg) | E10: Bester e1RM (kg) | H10: Übungen im Plan
B11: =SUMPRODUCT(MAX((Log!$E$4:$E$1203="A")*(Log!$F$4:$F$1203<>"")*Log!$F$4:$F$1203)) -> 333 | E11: =MAX(Rekorde!$H$4:$H$23) -> 440 | H11: =COUNTIF(Übungen!$L$4:$L$23,"ja") -> 15
B13: Verlauf und Vergleich
B14: ='OP-Countdown'!$C$4 -> -8 | E14: ='OP-Countdown'!$D$4 -> -2 | H14: =SUMPRODUCT(('OP-Countdown'!$C$8:$C$27<>"")*(N('OP-Countdown'!$C$8:$C$27>0))*('OP-Countdown'!$F$8:$F$27<>"ja")) -> 16
B53: Noch nicht trainierte Einheiten und Übungen erscheinen in den Diagrammen ohne Balken.

Sheet OP-Countdown
A1: OP-COUNTDOWN | WAS BIS ZUM OP-TAG ZU TUN IST
A2: Diese Fassung gilt bis zur Operation. Danach die Reha-Fassung des Logbuchs verwenden und Log und Einheiten übernehmen.
C3: Tage bis OP | D3: Wochen bis OP
A4: OP-Datum | B4: 46295 | C4: =IF($B$4="","",$B$4-TODAY()) -> -8 | D4: =IF($B$4="","",ROUNDUP(($B$4-TODAY())/7,0)) -> -2 | E4: =IF($B$4="","",IF(TODAY()>$B$4,"OP-Termin liegt zurück - ab jetzt die Reha-Fassung des Logbuchs verwenden.",IF($B$4-TODAY()<=7,"Letzte Woche: Organisation abschliessen, Baseline messen, letzte schwere Einheit 2 bis 3 Tage vor der OP.",IF($B$4-TODAY()<=14,"Zwei Wochen: Baseline jetzt messen, Checkliste abarbeiten, Reha-Fassung ausdrucken.",IF($B$4-TODAY()<=28,"Letzte vier Wochen: Ersatzübungen einarbeiten und Baseline-Werte erfassen.","Normalbetrieb: regulär weitertrainieren, Werte sauber protokollieren."))))) -> OP-Termin liegt zurück - ab jetzt die Reha-Fassung des Logbuchs verwenden.
A6: Was nach der OP wegfällt - und was du dafür jetzt einüben solltest
A7: Übung | B7: gesperrt bis Woche nach OP | C7: Sperrdauer (Wochen) | D7: frei ab etwa | E7: Ersatz, der in der Sperrzeit einspringt | F7: schon getestet? | G7: Eingewöhntes Arbeitsgewicht / Notiz
A8: =IF(OR(Übungen!$A4="",Übungen!$L4="nein"),"",Übungen!$A4) -> Beinpresse eng | B8: =IF(OR(Übungen!$A4="",Übungen!$L4="nein"),"",Übungen!$M4) -> 6 | C8: =IF($B8="","",MAX(0,$B8-1)) -> 5 | D8: =IF(OR($B8="",$B$4=""),"",$B$4+($B8-1)*7) -> 46330 | E8: =IF($A8="","",IF($C8<=0,"kein Ausfall, läuft durch",Übungen!$O4)) -> Beinstrecker und Beinbeuger sitzend, beide ab Woche 2 frei
A9: =IF(OR(Übungen!$A5="",Übungen!$L5="nein"),"",Übungen!$A5) -> Split Squat | B9: =IF(OR(Übungen!$A5="",Übungen!$L5="nein"),"",Übungen!$M5) -> 12 | C9: =IF($B9="","",MAX(0,$B9-1)) -> 11 | D9: =IF(OR($B9="",$B$4=""),"",$B$4+($B9-1)*7) -> 46372 | E9: =IF($A9="","",IF($C9<=0,"kein Ausfall, läuft durch",Übungen!$O5)) -> Beinpresse einbeinig ab Woche 6, Multipresse ohne Zusatzlast ab Woche 12
A10: =IF(OR(Übungen!$A6="",Übungen!$L6="nein"),"",Übungen!$A6) -> Beinstrecker | B10: =IF(OR(Übungen!$A6="",Übungen!$L6="nein"),"",Übungen!$M6) -> 2 | C10: =IF($B10="","",MAX(0,$B10-1)) -> 1 | D10: =IF(OR($B10="",$B$4=""),"",$B$4+($B10-1)*7) -> 46302 | E10: =IF($A10="","",IF($C10<=0,"kein Ausfall, läuft durch",Übungen!$O6)) -> keiner, ab Freigabe der Wunde nutzbar
A11: =IF(OR(Übungen!$A7="",Übungen!$L7="nein"),"",Übungen!$A7) -> Adduktion | B11: =IF(OR(Übungen!$A7="",Übungen!$L7="nein"),"",Übungen!$M7) -> 2 | C11: =IF($B11="","",MAX(0,$B11-1)) -> 1 | D11: =IF(OR($B11="",$B$4=""),"",$B$4+($B11-1)*7) -> 46302 | E11: =IF($A11="","",IF($C11<=0,"kein Ausfall, läuft durch",Übungen!$O7)) -> keiner, ab Freigabe der Wunde nutzbar
A12: =IF(OR(Übungen!$A8="",Übungen!$L8="nein"),"",Übungen!$A8) -> Reverse V-Squat | B12: =IF(OR(Übungen!$A8="",Übungen!$L8="nein"),"",Übungen!$M8) -> 12 | C12: =IF($B12="","",MAX(0,$B12-1)) -> 11 | D12: =IF(OR($B12="",$B$4=""),"",$B$4+($B12-1)*7) -> 46372 | E12: =IF($A12="","",IF($C12<=0,"kein Ausfall, läuft durch",Übungen!$O8)) -> Beinpresse enger Stand ab Woche 6
A13: =IF(OR(Übungen!$A9="",Übungen!$L9="nein"),"",Übungen!$A9) -> Rumänisches Kreuzheben | B13: =IF(OR(Übungen!$A9="",Übungen!$L9="nein"),"",Übungen!$M9) -> 16 | C13: =IF($B13="","",MAX(0,$B13-1)) -> 15 | D13: =IF(OR($B13="",$B$4=""),"",$B$4+($B13-1)*7) -> 46400 | E13: =IF($A13="","",IF($C13<=0,"kein Ausfall, läuft durch",Übungen!$O9)) -> Beinbeuger sitzend, Rückenstrecker mit vor der Brust gekreuzten Armen, Kabel-RDL mit Hüftgurt
A14: =IF(OR(Übungen!$A10="",Übungen!$L10="nein"),"",Übungen!$A10) -> Rumänisches Kreuzheben KH | B14: =IF(OR(Übungen!$A10="",Übungen!$L10="nein"),"",Übungen!$M10) -> 16 | C14: =IF($B14="","",MAX(0,$B14-1)) -> 15 | D14: =IF(OR($B14="",$B$4=""),"",$B$4+($B14-1)*7) -> 46400 | E14: =IF($A14="","",IF($C14<=0,"kein Ausfall, läuft durch",Übungen!$O10)) -> Beinbeuger sitzend, Rückenstrecker mit vor der Brust gekreuzten Armen, Kabel-RDL mit Hüftgurt
A15: =IF(OR(Übungen!$A11="",Übungen!$L11="nein"),"",Übungen!$A11) -> Beinpresse breit | B15: =IF(OR(Übungen!$A11="",Übungen!$L11="nein"),"",Übungen!$M11) -> 6 | C15: =IF($B15="","",MAX(0,$B15-1)) -> 5 | D15: =IF(OR($B15="",$B$4=""),"",$B$4+($B15-1)*7) -> 46330 | E15: =IF($A15="","",IF($C15<=0,"kein Ausfall, läuft durch",Übungen!$O11)) -> Beinstrecker und Beinbeuger sitzend, beide ab Woche 2 frei
A16: =IF(OR(Übungen!$A12="",Übungen!$L12="nein"),"",Übungen!$A12) -> Hip Thrust | B16: =IF(OR(Übungen!$A12="",Übungen!$L12="nein"),"",Übungen!$M12) -> 12 | C16: =IF($B16="","",MAX(0,$B16-1)) -> 11 | D16: =IF(OR($B16="",$B$4=""),"",$B$4+($B16-1)*7) -> 46372 | E16: =IF($A16="","",IF($C16<=0,"kein Ausfall, läuft durch",Übungen!$O12)) -> Hip & Glute Maschine ab Woche 6
A17: =IF(OR(Übungen!$A13="",Übungen!$L13="nein"),"",Übungen!$A13) -> Hip & Glute | B17: =IF(OR(Übungen!$A13="",Übungen!$L13="nein"),"",Übungen!$M13) -> 6 | C17: =IF($B17="","",MAX(0,$B17-1)) -> 5 | D17: =IF(OR($B17="",$B$4=""),"",$B$4+($B17-1)*7) -> 46330 | E17: =IF($A17="","",IF($C17<=0,"kein Ausfall, läuft durch",Übungen!$O13)) -> Beinbeuger sitzend, ab Woche 2 frei
A18: =IF(OR(Übungen!$A14="",Übungen!$L14="nein"),"",Übungen!$A14) -> Beinbeuger | B18: =IF(OR(Übungen!$A14="",Übungen!$L14="nein"),"",Übungen!$M14) -> 2 | C18: =IF($B18="","",MAX(0,$B18-1)) -> 1 | D18: =IF(OR($B18="",$B$4=""),"",$B$4+($B18-1)*7) -> 46302 | E18: =IF($A18="","",IF($C18<=0,"kein Ausfall, läuft durch",Übungen!$O14)) -> keiner, ab Freigabe der Wunde nutzbar
A19: =IF(OR(Übungen!$A15="",Übungen!$L15="nein"),"",Übungen!$A15) -> Seitliche Kickbacks | B19: =IF(OR(Übungen!$A15="",Übungen!$L15="nein"),"",Übungen!$M15) -> 6 | C19: =IF($B19="","",MAX(0,$B19-1)) -> 5 | D19: =IF(OR($B19="",$B$4=""),"",$B$4+($B19-1)*7) -> 46330 | E19: =IF($A19="","",IF($C19<=0,"kein Ausfall, läuft durch",Übungen!$O15)) -> Abduktion an der Maschine im Sitzen
... A27: =IF(OR(Übungen!$A23="",Übungen!$L23="nein"),"",Übungen!$A23) | B27: =IF(OR(Übungen!$A23="",Übungen!$L23="nein"),"",Übungen!$M23) | C27: =IF($B27="","",MAX(0,$B27-1)) | D27: =IF(OR($B27="",$B$4=""),"",$B$4+($B27-1)*7) | E27: =IF($A27="","",IF($C27<=0,"kein Ausfall, läuft durch",Übungen!$O23))
A29: Lesehilfe: Die Sperrdauer kommt aus der Spalte 'Reha frei ab Woche' im Blatt 'Übungen'. Rot markiert sind die Übungen, die einen Monat oder länger ausfallen - genau Übungen, die einen Monat oder länger ausfallen - genau für die lohnt es sich, den Ersatz jetzt einzuarbeiten, statt ihn nach der OP zum ersten Mal auszuprobieren. Trag rechts das Gewicht ein, mit dem der Ersatz sauber läuft, dann steht der Startwert nach der OP schon fest.
A31: Zeitfenster bis zum OP-Tag
A32: bis 4 Wochen vorher | B32: Normalbetrieb. Regulär trainieren und sauber protokollieren - je vollständiger die Historie, desto belastbarer sind die Zielwerte, auf die du nach der Pause zurückkommst.
A33: 4 bis 1 Woche vorher | B33: Ersatzübungen einarbeiten: die Geräte, die nach der OP einspringen müssen, einmal mit Arbeitsgewicht durchspielen und den Wert oben eintragen. Baseline-Werte im Blatt 'Baseline Schulter' erfassen, beide Seiten.
A34: letzte Woche | B34: Organisation abschliessen (Blatt 'Vorbereitung'), Baseline-Messung wiederholen, damit zwei Messpunkte vorliegen. Wie stark du das Training zurückfährst, besprichst du mit Operateur und Physiotherapie.
A35: OP-Tag | B35: Auf die Reha-Fassung des Logbuchs umsteigen. Zeilen aus 'Log' und 'Einheiten' einfach hinüberkopieren - der Aufbau ist identisch, Auswertung und Rekorde rechnen dort sofort weiter.
A37: Die Zeitfenster sind Planungshilfe für Training und Organisation, keine medizinische Vorgabe. Was du in den Tagen vor der OP trainieren darfst und was nicht, sagen Operateur und Physiotherapie.

Sheet Vorbereitung
B1: VORBEREITUNG | CHECKLISTE BIS ZUM OP-TAG
B2: Abhaken, was erledigt ist. Die Punkte unter 'Fragen an Operateur und Physiotherapie' sind Fragen, keine Antworten - die Antworten gehören in die Notizspalte.
B4: Fragen an Operateur und Physiotherapie
B5: Aufgabe | C5: erledigt | D5: bis wann | E5: Antwort / Notiz
B6: Das schriftliche Nachbehandlungsschema mitgeben lassen - alle Wochenangaben im Logbuch sind bis dahin nur abgeleitet.
B7: Wie gross ist die Subscapularis-Läsion, und wie wird genäht? Davon hängt ab, wie streng die ersten 6 Wochen laufen.
B8: Wie lange Gilchrist, Tag und Nacht? Ab wann abbauen?
B9: Bis zu welchem Winkel darf passiv bewegt werden - Flexion, Abduktion, und vor allem Aussenrotation?
B10: Ab wann aktive Innenrotation ohne Widerstand, ab wann gegen Widerstand?
B11: Ab wann Ellenbogenbeugung und Supination gegen Widerstand? (Tenodese-Protokoll, läuft parallel zum Naht-Protokoll.)
B12: Ab wann ist Beintraining im Sitzen wieder erlaubt? Im Logbuch steht Tag 10 bis 14 als abgeleiteter Wert.
B13: Ab wann ist die Beinpresse erlaubt? Im Logbuch steht Woche 6 als abgeleiteter Wert, nicht als ärztliche Freigabe.
B14: Ab wann darf eine Langhantel wieder gehalten werden? Davon hängen Hip Thrust und Rumänisches Kreuzheben ab.
B15: Ab wann darf der Arm wieder Hebelast tragen, und wie viel?
B16: Wann ist der erste Physiotermin, und ist die Verordnung da?
B17: Welche Schmerzmedikation, und wie lange? (Der Fahrplan vermerkt, dass dauerhaft hochdosierte NSAR die Heilung bremsen - Rückfrage lohnt.)
... B20: Organisation
B21: Aufgabe | C21: erledigt | D21: bis wann | E21: Antwort / Notiz
B22: OP-Termin, Anreise und Begleitung für den Heimweg geklärt
B23: Arbeitsausfall angemeldet, Krankschreibung besprochen
B24: Schlinge, Kühlpackungen und Verbandsmaterial zu Hause
B25: Kleidung zum Knöpfen bereitgelegt - über den Kopf ziehen fällt weg. Weite Ärmel rechts, damit der Arm nicht verdreht werden muss
B26: Alltag rechts durchgespielt: Haare, BH, Gürtel, Gesässtasche, Anschnallen. Was nur hinter dem Rücken geht, fällt wochenlang aus - jetzt Alternativen festlegen
B27: Hilfe für die erste Woche organisiert, nicht nur für den OP-Tag
B28: Schlafplatz halbsitzend vorbereitet, Kissen besorgt
B29: Einkäufe und Haushalt für die erste Woche vorbereitet
B30: Wichtige Telefonnummern notiert: Klinik, Operateur, Physio
B32: Training und Gym
B33: Aufgabe | C33: erledigt | D33: bis wann | E33: Antwort / Notiz
B34: Ersatzübungen im Blatt 'OP-Countdown' durchgespielt und Arbeitsgewichte eingetragen
B35: Baseline Schulter gemessen, beide Seiten, mindestens zwei Messpunkte - inklusive Innenrotationskraft, die misst der Fahrplan in Phase 4 und 5
B36: Letzte schwere Beineinheit spätestens 2 bis 3 Tage vor der OP, danach nur noch Gehen
B37: Gym-Mitgliedschaft: Pausierung geklärt, falls längere Unterbrechung
B38: Trainingsblätter der Reha-Fassung einmal ausgedruckt und bereitgelegt
B39: Fotos der Ausgangssituation gemacht, falls du den Verlauf auch optisch festhalten willst
B41: Aus dem Reha-Fahrplan vorziehen
B42: Aufgabe | C42: erledigt | D42: bis wann | E42: Antwort / Notiz
B43: Proteinversorgung geplant - der Fahrplan nennt 2.0 bis 2.5 g pro kg täglich als heilungsfördernd
B44: Schlafroutine eingerichtet, solange das Schlafen noch bequem ist
B45: Nikotin: der Fahrplan führt es als starke Bremse für die Sehnen-Knochen-Heilung
...

Sheet Baseline Schulter
A1: BASELINE SCHULTER | AUSGANGSWERTE VOR DER OP
A2: Beide Seiten messen, mindestens an zwei Terminen. Diese Werte sind nach der OP nicht mehr nachholbar - der Reha-Fahrplan misst mehrere Meilensteine am Vergleich zur Gegenseite.
A3: Vergleich operierte Seite gegen Gegenseite
A4: Messwert | C4: operierte Seite | D4: Gegenseite | E4: Anteil
A5: Flexion (Grad) | C5: =IF(SUMPRODUCT(MAX(($B$16:$B$39="operiert")*($E$16:$E$39<>"")*$E$16:$E$39))=0,"",SUMPRODUCT(MAX(($B$16:$B$39="operiert")*($E$16:$E$39<>"")*$E$16:$E$39))) | D5: =IF(SUMPRODUCT(MAX(($B$16:$B$39="gesund")*($E$16:$E$39<>"")*$E$16:$E$39))=0,"",SUMPRODUCT(MAX(($B$16:$B$39="gesund")*($E$16:$E$39<>"")*$E$16:$E$39))) | E5: =IF(OR($C5="",$D5="",$D5=0),"",$C5/$D5) | F5: Der Reha-Fahrplan misst Phase 4 an etwa 70 bis 80 Prozent und Phase 5 an mindestens 90 Prozent der Gegenseite - und zwar für Innenrotation UND Ellenbogenbeugung. Beides hier vorher messen, sonst sind die Prozentwerte später nicht überprüfbar. Innenrotation im Sitzen am Kabel mit angelegtem Ellenbogen testen, Curl am immer gleichen Gerät. Gleiche Wiederholungszahl, gleiche Tageszeit.
A6: Abduktion (Grad) | C6: =IF(SUMPRODUCT(MAX(($B$16:$B$39="operiert")*($F$16:$F$39<>"")*$F$16:$F$39))=0,"",SUMPRODUCT(MAX(($B$16:$B$39="operiert")*($F$16:$F$39<>"")*$F$16:$F$39))) | D6: =IF(SUMPRODUCT(MAX(($B$16:$B$39="gesund")*($F$16:$F$39<>"")*$F$16:$F$39))=0,"",SUMPRODUCT(MAX(($B$16:$B$39="gesund")*($F$16:$F$39<>"")*$F$16:$F$39))) | E6: =IF(OR($C6="",$D6="",$D6=0),"",$C6/$D6)
A7: Aussenrotation (Grad) | C7: =IF(SUMPRODUCT(MAX(($B$16:$B$39="operiert")*($G$16:$G$39<>"")*$G$16:$G$39))=0,"",SUMPRODUCT(MAX(($B$16:$B$39="operiert")*($G$16:$G$39<>"")*$G$16:$G$39))) | D7: =IF(SUMPRODUCT(MAX(($B$16:$B$39="gesund")*($G$16:$G$39<>"")*$G$16:$G$39))=0,"",SUMPRODUCT(MAX(($B$16:$B$39="gesund")*($G$16:$G$39<>"")*$G$16:$G$39))) | E7: =IF(OR($C7="",$D7="",$D7=0),"",$C7/$D7)
A8: Curl-Testgewicht (kg) | C8: =IF(SUMPRODUCT(MAX(($B$16:$B$39="operiert")*($H$16:$H$39<>"")*$H$16:$H$39))=0,"",SUMPRODUCT(MAX(($B$16:$B$39="operiert")*($H$16:$H$39<>"")*$H$16:$H$39))) | D8: =IF(SUMPRODUCT(MAX(($B$16:$B$39="gesund")*($H$16:$H$39<>"")*$H$16:$H$39))=0,"",SUMPRODUCT(MAX(($B$16:$B$39="gesund")*($H$16:$H$39<>"")*$H$16:$H$39))) | E8: =IF(OR($C8="",$D8="",$D8=0),"",$C8/$D8)
A10: Hinweise zur Messung
A11: · Immer dieselbe Position, dieselbe Tageszeit und dieselbe Messmethode - sonst vergleichst du später Rauschen statt Fortschritt.
A12: · Beide Seiten an jedem Messtermin, sonst fehlt der Bezugswert.
A13: · Mindestens zwei Termine vor der OP, damit ein Ausreisser auffällt.
A14: · Curl-Testgewicht: das Gewicht, mit dem eine feste Wiederholungszahl sauber gelingt - nicht das Maximum.
A15: Datum | B15: Seite | C15: Schmerz Ruhe 0-10 | D15: Schmerz Belastung 0-10 | E15: Flexion Grad | F15: Abduktion Grad | G15: Aussen- rotation Grad | H15: Curl-Testgewicht (kg) | I15: Wdh dazu | J15: Notiz

Sheet Reha-Fahrplan
A1: REHA-FAHRPLAN | SUBSCAPULARIS-NAHT MIT BIZEPSTENODESE, RECHTS
A2: Konservative Richtwerte für die Naht einer Subscapularis-Sehne mit gleichzeitiger Bizepstenodese. Deutlich strenger und länger als bei einer isolierten Tenodese, weil eine genähte Sehne am Knochen einheilen muss. Das schriftliche Nachbehandlungsschema des Operateurs hat in jedem einzelnen Punkt Vorrang vor dieser Tabelle.
A4: Der geplante Eingriff
A5: Eingriff | B5: Arthroskopie mit Sehnennaht und Bizepstenodese
A6: Diagnose | B6: Läsion am Oberrand des Subscapularis mit Bizepssehnen-Instabilität
A7: Seite | B7: rechts
A8: Termin | B8: 30.09.2026
A9: Ruhigstellung | B9: Gilchrist-Bandage
A10: Dringlichkeit laut Aufklärung | B10: keine - Termin frei wählbar
A11: Verbesserungswahrscheinlichkeit laut Aufklärung | B11: gut
A12: Quelle: Operationsaufklärung. Die Freigabewochen in diesem Blatt und im Blatt 'Übungen' sind daraus abgeleitet und konservativ gesetzt - sie sind KEINE ärztliche Vorgabe. Sobald das schriftliche Nachbehandlungsschema des Operateurs vorliegt, gilt ausschliesslich dieses; Abweichungen im Blatt 'Übungen' in der Spalte 'Reha frei ab Woche' eintragen.
A14: Grundregeln über die gesamte Zeit
A15: Warum dieser Plan strenger ist als der alte | B15: Der Subscapularis gehört zur Rotatorenmanschette. Bei einer isolierten Bizepstenodese ist nur eine Sehne umgesetzt, hier wird zusätzlich eine gerissene Sehne an den Knochen genäht. Sehne heilt am Knochen langsam und ist in den ersten Wochen schwächer als die Naht selbst. Alle Freigaben liegen deshalb rund doppelt so spät wie im vorherigen Plan.
A16: Die vier Verbote | B16: Keine aktive Innenrotation gegen Widerstand - das ist die Arbeit des genähten Muskels. Keine passive Aussenrotation über die Freigabegrenze - das zieht die Naht auseinander. Keine aktive Ellenbogenbeugung und keine Supination gegen Widerstand - das belastet die Tenodese. Kein Stützen, Hängen oder Ziehen über den rechten Arm.
A17: Hand hinter den Rücken ist tabu | B17: Die Bewegung kombiniert maximale Innenrotation mit Streckung und ist die klassische Position, in der eine frische Subscapularis-Naht versagt. Gilt für Alltag genauso wie fürs Gym: BH schliessen, Gürtel, Gesässtasche, Rückwärtsgreifen beim Aufsetzen an der Maschine.
A18: Gilchrist konsequent tragen | B18: Nach Vorgabe des Operateurs, üblicherweise 4 bis 6 Wochen Tag und Nacht. Abgelegt wird sie nur für die freigegebenen Übungen und für die Körperpflege, und dabei hängt der Arm entspannt am Körper.
A19: Die gefährliche Phase | B19: Woche 3 bis 8. Der Schmerz ist weg, die Schlinge fällt, und die Sehnen-Knochen-Heilung ist zugleich am schwächsten. Die meisten Re-Rupturen passieren hier, nicht in den ersten Tagen.
A20: Schmerz als Grenze | B20: Bewegung bis zum Schmerz, nie darüber hinaus. Schmerz, der nach der Einheit länger als 2 Stunden anhält, heisst: zu viel gemacht.
A21: Wenn zwei Vorgaben sich widersprechen | B21: Immer die strengere nehmen. Das Naht-Protokoll ist bei Bewegung und Innenrotation führend, das Tenodese-Protokoll bei Ellenbogenbeugung und Supination. Beide laufen parallel, keines hebt das andere auf.
A22: Rechte Seite heisst Alltag mitplanen | B22: Anziehen, Haare, Autofahren, Einkaufstasche, Tür aufhalten. Was mit der rechten Hand nur unter Zug oder Verdrehung geht, wird in den ersten Wochen von jemand anderem gemacht oder anders gelöst. Das vorher besprechen, nicht am ersten Tag improvisieren.
A24: Phasenplan
A25: Phase | B25: Woche nach OP | C25: Ziel der Phase | D25: Schulter: erlaubt | E25: Schulter: verboten | F25: Beintraining | G25: Meilenstein zum Weitergehen
A26: Phase 1 Schutz | B26: 0 - 6 | C26: Die Naht ungestört einheilen lassen. Wunde zu, Schmerz und Schwellung runter, Gelenk nicht einsteifen lassen. | D26: Gilchrist Tag und Nacht nach Vorgabe. Passive Bewegung nur im freigegebenen Bereich, typischerweise Flexion bis etwa 90 Grad, Abduktion bis etwa 60 Grad, Aussenrotation nur bis zur Neutralstellung 0 Grad. Pendelübungen. Hand, Handgelenk, Ellenbogen und Nacken aktiv bewegen. Eis mehrmals täglich. | E26: Jede aktive Innenrotation. Jede Aussenrotation über 0 Grad. Aktive Ellenbogenbeugung und Supination gegen Widerstand. Hand hinter den Rücken. Heben, Tragen, Stützen, Abstossen aus dem Bett über den rechten Arm. | F26: Ab Freigabe der Wunde, frühestens Tag 10 bis 14: Beinstrecker, Adduktion, Beinbeuger sitzend, Waden sitzend. Alles im Sitzen, Arm bleibt in der Schlinge, Ein- und Aussteigen nur über die linke Seite. Gehen ab Tag 1. | G26: Wunde trocken und reizlos. Ruheschmerz unter 3 von 10. Passive Flexion etwa 90 Grad, Aussenrotation bis 0 Grad schmerzfrei. Ärztliche Freigabe zum Ablegen der Schlinge.
A27: Phase 2 Beweglichkeit | B27: 6 - 12 | C27: Schlinge abtrainieren, Beweglichkeit vollständig zurückholen, Schulterblatt ansteuern. | D27: Schlinge weg. Aktiv-assistive Bewegung zu aktiver Bewegung ohne Widerstand. Aussenrotation schrittweise über 0 Grad hinaus freigeben. Schulterblatt-Ansteuerung. Ab Woche 8 bis 10 sanfte submaximale Isometrie für die Innenrotation, etwa 20 bis 30 Prozent, kurz halten. | E27: Weiterhin keine Innenrotation gegen nennenswerten Widerstand. Keine Beugung und keine Supination gegen Widerstand. Hebelast maximal 1 kg. Kein Zug, kein Hängen, keine Stütz-Position. Hand hinter den Rücken weiterhin nicht. | F27: Zusätzlich ab Woche 6: Beinpresse enger und breiter Stand, Hip & Glute Maschine, seitliche Kickbacks im Sitzen, Waden stehend ohne Schulterpolster. Fahrrad ohne Belastung über den Lenker ab Woche 3. | G27: Aktive Flexion mindestens 140 Grad, Abduktion 130 Grad, Aussenrotation 45 Grad. Bauchpress-Test und Lift-off-Test ohne Widerstand schmerzfrei möglich.
A28: Phase 3 erste Last | B28: 12 - 16 | C28: Innenrotation und Bizeps erstmals wieder unter Last bringen. | D28: Ab Woche 12 leichte Innenrotation gegen Widerstand, Start mit Band in der kleinsten Stufe. Ab Woche 12 leichte Ellenbogenbeugung und Supination gegen Widerstand, Start bei 1 bis 2 kg, Steigerung in 0.5 kg-Schritten. Progressive Manschetten- und Schulterblattarbeit. Leichte geschlossene Kette. | E28: Kein Bankdrücken mit Langhantel, keine Dips, keine Klimmzüge, kein schweres Rudern. Keine explosiven oder ruckartigen Bewegungen. Keine maximale Dehnung in Aussenrotation oder am Bizeps. | F28: Ab Woche 12: Hip Thrust mit Stange mit vor der Brust gekreuzten Armen, Reverse V-Squat mit lockerem Griff, Split Squat in der Multipresse ohne Zusatzhantel. Beintraining sonst wieder vollständig. | G28: Beweglichkeit seitengleich. Innenrotationskraft etwa 50 Prozent der Gegenseite, schmerzfrei. Beugung gegen Widerstand schmerzfrei.
A29: Phase 4 Aufbau | B29: Monat 4 - 6 | C29: Kraft für Innenrotation, Beugung und Druckmuster zurückholen. | D29: Innenrotation progressiv mit Band und Kabel. Bizeps-Curls progressiv, Start leicht und hohe Wiederholungen. Drücken zuerst an der Maschine, dann Kurzhantel. Latzug im neutralen Griff. Rudern gestützt. | E29: Weiterhin keine Maximallast. Kein schweres Langhantel-Bankdrücken. Keine Klimmzüge mit Zusatzgewicht. Kein Reissen der Last aus der Dehnung. | F29: Ab Monat 4: Rumänisches Kreuzheben mit Langhantel leicht wieder aufnehmen, Technik vor Last. Split Squat mit Kurzhantel ab Monat 4. | G29: Innenrotations- und Beugekraft etwa 70 bis 80 Prozent der Gegenseite. Kein Schmerz im Sulcus und vorne am Gelenk unter Belastung.
A30: Phase 5 Rückkehr | B30: Monat 6 - 9 | C30: Zurück zur vollen Trainingslast, seitengleiche Kraft. | D30: Progressiver Aufbau aller Muster. Langhantel-Bankdrücken, schweres Rudern und Klimmzüge frühestens ab Monat 6 bis 7. Maximallast nach ärztlicher Freigabe. | E30: Nichts pauschal verboten, aber jede neue Belastung mit reduzierter Last einführen und über 2 bis 3 Wochen steigern. | F30: Beintraining vollständig ohne Einschränkung, alle Übungen wie im Normalmodus. | G30: Innenrotations- und Beugekraft mindestens 90 Prozent der Gegenseite. Volle Beweglichkeit. Schmerzfrei über 4 Wochen.
A32: SOFORT ZUM ARZT
A33: Plötzlicher Kraftverlust bei der Innenrotation: die Hand lässt sich nicht mehr gegen den Bauch drücken, oder sie rutscht beim Versuch weg. Plötzlicher stechender Schmerz mit hörbarem Knall in Schulter oder Oberarm. Sichtbare Verformung des Bizepsbauchs nach unten (Popeye). Plötzlicher Kraftverlust bei der Ellenbogenbeugung. Rötung, Überwärmung, Wundsekret oder Fieber. Zunehmender statt abnehmender Schmerz über mehrere Tage. Taubheit oder Kribbeln in Hand oder Fingern. Ein Ereignis, bei dem der Arm ruckartig nach hinten gerissen wurde - auch ohne sofortigen Schmerz melden.
A35: WAS DIE HEILUNG MESSBAR BREMST ODER FÖRDERT
A36: Energieverfügbarkeit | B36: bremst stark | C36: Kollagensynthese und Wundheilung brauchen Energie. Bei sehr niedrigem Körperfett und Defizit heilt Sehne und Knochen langsamer. In der Heilungsphase Erhaltungskalorien oder leichter Überschuss, kein Defizit.
A37: Protein | B37: fördert | C37: 2.0 bis 2.5 g pro kg Körpergewicht täglich, gleichmässig auf 4 bis 5 Mahlzeiten. Kollagen entsteht nicht aus dem Nichts.
A38: Vitamin C und Vitamin D | B38: fördert | C38: Vitamin C ist Kofaktor der Kollagen-Hydroxylierung. Vitamin D für die knöcherne Einheilung, Zielwert im oberen Normbereich. Beides über Blutbild prüfen, nicht raten.
A39: Schlaf | B39: fördert stark | C39: Der grösste Wachstumshormon-Puls des Tages liegt im ersten Tiefschlafzyklus. 7 bis 9 Stunden sind in der Heilungsphase keine Empfehlung, sondern Teil der Behandlung. Mit Gilchrist schläft es sich schlecht - halb sitzend mit Kissen unter dem Ellenbogen hilft.
A40: NSAR wie Ibuprofen und Diclofenac | B40: bremst | C40: Dauerhaft hochdosiert hemmen sie genau die Entzündungsphase, die für die Sehnen-Knochen-Heilung nötig ist. Kurzfristig zur Schmerzkontrolle nach Rücksprache, nicht als Wochenprogramm.
A41: Nikotin | B41: bremst stark | C41: Verschlechtert Durchblutung und Sehnen-Knochen-Heilung deutlich. Bei einer genähten Manschettensehne ist das der grösste einzelne vermeidbare Risikofaktor für eine Re-Ruptur.
A42: Hochdosierte Androgene | B42: Risiko | C42: Erhöhen Sehnensteifigkeit und senken Elastizität, Kollagen-Crosslinks werden ungünstig verändert. Sehnenrupturen unter Anwendung sind dokumentiert. Gehört vollständig und ungeschönt zum Operateur, weil es die Nachbehandlung verändert.
A44: Diese Seite ist eine Gedächtnisstütze, keine ärztliche Anweisung. Bei jedem Widerspruch zum Nachbehandlungsschema des Operateurs oder zur Ansage der Physiotherapie gilt deren Vorgabe.

Sheet Reha-Plan Beine
A1: REHA-PLAN BEINE | GEWICHTE FÜR JEDE PHASE
A2: Startgewichte als Prozentsatz des letzten Arbeitsgewichts vor der OP, automatisch auf die Laststufe des Geräts abgerundet. Dieses Blatt ersetzt in der Reha das Trainingsblatt.
A4: Die Wochenangaben sind konservativ abgeleitet und NICHT ärztlich bestätigt. Das schriftliche Nachbehandlungsschema des Operateurs hat Vorrang - weicht es ab, die Wochen im Blatt 'Übungen' anpassen, dann stimmt auch die Ampel im Blatt 'Reha-Modus'.
A6: Wo wir heute stehen
A7: OP-Datum | B7: =DATE(2026,9,30) -> 46295 | C7: ="Aktive Phase: "&IF(MAX(1,ROUNDDOWN((TODAY()-DATE(2026,9,30))/7,0)+1)<=6,"1 - Schutz",IF(MAX(1,ROUNDDOWN((TODAY()-DATE(2026,9,30))/7,0)+1)<=12,"2 - Beweglichkeit",IF(MAX(1,ROUNDDOWN((TODAY()-DATE(2026,9,30))/7,0)+1)<=16,"3 - erste Last","4 - zurück zum normalen Plan"))) -> Aktive Phase: 1 - Schutz
A8: Tage nach OP | B8: =(TODAY()-DATE(2026,9,30)) -> 8 | C8: =IF((TODAY()-DATE(2026,9,30))<8,"Noch kein Beintraining. Gehen ab Tag 1, Gilchrist durchgehend, Wunde heilen lassen.",IF((TODAY()-DATE(2026,9,30))<10,"Erste Einheit steht an, sobald die Wunde freigegeben ist - dann Phase 1.",IF(MAX(1,ROUNDDOWN((TODAY()-DATE(2026,9,30))/7,0)+1)<=6,"Phase 1 läuft: zwei Einheiten je Woche, die vier sitzenden Maschinen unten.",IF(MAX(1,ROUNDDOWN((TODAY()-DATE(2026,9,30))/7,0)+1)<=12,"Phase 2: Beinpresse und Hip & Glute sind dazugekommen.",IF(MAX(1,ROUNDDOWN((TODAY()-DATE(2026,9,30))/7,0)+1)<=16,"Phase 3: freie Gewichte sind zurück.","Phase 4: ab jetzt wieder mit dem Blatt 'Trainingsblatt' arbeiten."))))) -> Erste Einheit steht an, sobald die Wunde freigegeben ist - dann Phase 1.
A9: Woche nach OP | B9: =MAX(1,ROUNDDOWN((TODAY()-DATE(2026,9,30))/7,0)+1) -> 2 | C9: ="Nächster Schritt: "&IF(MAX(1,ROUNDDOWN((TODAY()-DATE(2026,9,30))/7,0)+1)<=6,"ab Woche 7 kommen Beinpresse eng und breit, Hip & Glute und seitliche Kickbacks dazu - erst nach ärztlicher Freigabe zum Ablegen der Schlinge.",IF(MAX(1,ROUNDDOWN((TODAY()-DATE(2026,9,30))/7,0)+1)<=12,"ab Woche 13 kommen Reverse V-Squat, Hip Thrust und Split Squat zurück.",IF(MAX(1,ROUNDDOWN((TODAY()-DATE(2026,9,30))/7,0)+1)<=16,"ab Monat 4 kommt das Rumänische Kreuzheben zurück, danach wieder Zielbereich 5-6.","keiner mehr - der Reha-Teil ist durch."))) -> Nächster Schritt: ab Woche 7 kommen Beinpresse eng und breit, Hip & Glute und seitliche Kickbacks dazu - erst nach ärztlicher Freigabe zum Ablegen der Schlinge.
A11: Phase 1 · Woche 2 bis 6 · alles im Sitzen, Arm in der Schlinge
A12: Frühester Start Tag 10 bis 14 und erst nach Freigabe der Wunde. Zwei Einheiten je Woche. Ziel ist Erhalt, nicht Aufbau - die Last ist bewusst niedrig, weil der Kreislauf und der Schlaf in diesen Wochen nicht mitspielen. Ein- und Aussteigen immer über die linke Seite.
A13: Übung | B13: Gerät / Ausführung | C13: Sätze × Wdh | D13: Start (kg) | E13: Anteil | F13: Hinweis
A14: Beinstrecker | B14: Maschine sitzend, Hände im Schoss | C14: 2 × 12-15 | D14: =IF(IF(Rekorde!$L$6="",Übungen!$H$6,Rekorde!$L$6)="","offen",IF(Übungen!$J$6="",ROUND(IF(Rekorde!$L$6="",Übungen!$H$6,Rekorde!$L$6)*60/100*2,0)/2,FLOOR(IF(Rekorde!$L$6="",Übungen!$H$6,Rekorde!$L$6)*60/100/Übungen!$J$6,1)*Übungen!$J$6)) -> 55 | E14: 60 % | F14: Erste Einheit bewusst eine Stufe darunter.
A15: Beinbeuger | B15: Maschine sitzend, Griffe loslassen | C15: 2 × 12-15 | D15: =IF(IF(Rekorde!$L$14="",Übungen!$H$14,Rekorde!$L$14)="","offen",IF(Übungen!$J$14="",ROUND(IF(Rekorde!$L$14="",Übungen!$H$14,Rekorde!$L$14)*60/100*2,0)/2,FLOOR(IF(Rekorde!$L$14="",Übungen!$H$14,Rekorde!$L$14)*60/100/Übungen!$J$14,1)*Übungen!$J$14)) -> 25 | E15: 60 % | F15: Das Polster hält das Bein, nicht die Hand.
A16: Adduktion | B16: Maschine, Arm in der Schlinge | C16: 2 × 12-15 | D16: =IF(IF(Rekorde!$L$7="",Übungen!$H$7,Rekorde!$L$7)="","offen",IF(Übungen!$J$7="",ROUND(IF(Rekorde!$L$7="",Übungen!$H$7,Rekorde!$L$7)*60/100*2,0)/2,FLOOR(IF(Rekorde!$L$7="",Übungen!$H$7,Rekorde!$L$7)*60/100/Übungen!$J$7,1)*Übungen!$J$7)) -> 97.5 | E16: 60 % | F16: Links war im September die Zerrung - hier besonders langsam einsteigen.
A17: Waden | B17: Maschine sitzend | C17: 2 × 15 | D17: =IF(IF(Rekorde!$L$16="",Übungen!$H$16,Rekorde!$L$16)="","offen",IF(Übungen!$J$16="",ROUND(IF(Rekorde!$L$16="",Übungen!$H$16,Rekorde!$L$16)*60/100*2,0)/2,FLOOR(IF(Rekorde!$L$16="",Übungen!$H$16,Rekorde!$L$16)*60/100/Übungen!$J$16,1)*Übungen!$J$16)) -> 110 | E17: 60 % | F17: Nur die sitzende Variante, kein Schulterpolster.
A19: Phase 2 · Woche 6 bis 12 · Schlinge weg, Beinpresse zurück
A20: Erst nach ärztlicher Freigabe zum Ablegen der Schlinge. Jetzt sind zwei volle Beineinheiten je Woche möglich, weiter mit 72 Stunden Abstand. Bauchpresse dosieren: bei RPE 8 stoppen, nicht bei 9.
A21: Übung | B21: Gerät / Ausführung | C21: Sätze × Wdh | D21: Start (kg) | E21: Anteil | F21: Hinweis
A22: Beinpresse eng | B22: tiefe Fussposition, Hände seitlich ablegen | C22: 3 × 10-12 | D22: =IF(IF(Rekorde!$L$4="",Übungen!$H$4,Rekorde!$L$4)="","offen",IF(Übungen!$J$4="",ROUND(IF(Rekorde!$L$4="",Übungen!$H$4,Rekorde!$L$4)*55/100*2,0)/2,FLOOR(IF(Rekorde!$L$4="",Übungen!$H$4,Rekorde!$L$4)*55/100/Übungen!$J$4,1)*Übungen!$J$4)) -> 165 | E22: 55 % | F22: Neu in dieser Phase. Nicht an den Griffen ziehen.
A23: Beinpresse breit | B23: breiter Stand, Füsse hoch | C23: 3 × 10-12 | D23: =IF(IF(Rekorde!$L$11="",Übungen!$H$11,Rekorde!$L$11)="","offen",IF(Übungen!$J$11="",ROUND(IF(Rekorde!$L$11="",Übungen!$H$11,Rekorde!$L$11)*55/100*2,0)/2,FLOOR(IF(Rekorde!$L$11="",Übungen!$H$11,Rekorde!$L$11)*55/100/Übungen!$J$11,1)*Übungen!$J$11)) -> 120 | E23: 55 % | F23: Neu in dieser Phase. Zieht die Adduktoren in die Dehnung - links vorsichtig.
A24: Hip & Glute | B24: Maschine, Arme vor der Brust gekreuzt | C24: 3 × 10-12 | D24: =IF(IF(Rekorde!$L$13="",Übungen!$H$13,Rekorde!$L$13)="","offen",IF(Übungen!$J$13="",ROUND(IF(Rekorde!$L$13="",Übungen!$H$13,Rekorde!$L$13)*55/100*2,0)/2,FLOOR(IF(Rekorde!$L$13="",Übungen!$H$13,Rekorde!$L$13)*55/100/Übungen!$J$13,1)*Übungen!$J$13)) -> 90 | E24: 55 % | F24: Neu in dieser Phase. Ersetzt den Hip Thrust mit der Stange.
A25: Seitliche Kickbacks | B25: Kabel, nur links abstützen | C25: 2 × 12-15 | D25: =IF(IF(Rekorde!$L$15="",Übungen!$H$15,Rekorde!$L$15)="","offen",IF(Übungen!$J$15="",ROUND(IF(Rekorde!$L$15="",Übungen!$H$15,Rekorde!$L$15)*55/100*2,0)/2,FLOOR(IF(Rekorde!$L$15="",Übungen!$H$15,Rekorde!$L$15)*55/100/Übungen!$J$15,1)*Übungen!$J$15)) -> 18 | E25: 55 % | F25: Neu in dieser Phase.
A26: Beinstrecker | B26: wie Phase 1 | C26: 3 × 10-12 | D26: =IF(IF(Rekorde!$L$6="",Übungen!$H$6,Rekorde!$L$6)="","offen",IF(Übungen!$J$6="",ROUND(IF(Rekorde!$L$6="",Übungen!$H$6,Rekorde!$L$6)*75/100*2,0)/2,FLOOR(IF(Rekorde!$L$6="",Übungen!$H$6,Rekorde!$L$6)*75/100/Übungen!$J$6,1)*Übungen!$J$6)) -> 70 | E26: 75 % | F26: läuft weiter
A27: Beinbeuger | B27: wie Phase 1 | C27: 3 × 10-12 | D27: =IF(IF(Rekorde!$L$14="",Übungen!$H$14,Rekorde!$L$14)="","offen",IF(Übungen!$J$14="",ROUND(IF(Rekorde!$L$14="",Übungen!$H$14,Rekorde!$L$14)*75/100*2,0)/2,FLOOR(IF(Rekorde!$L$14="",Übungen!$H$14,Rekorde!$L$14)*75/100/Übungen!$J$14,1)*Übungen!$J$14)) -> 32.5 | E27: 75 % | F27: läuft weiter
A28: Adduktion | B28: wie Phase 1 | C28: 3 × 10-12 | D28: =IF(IF(Rekorde!$L$7="",Übungen!$H$7,Rekorde!$L$7)="","offen",IF(Übungen!$J$7="",ROUND(IF(Rekorde!$L$7="",Übungen!$H$7,Rekorde!$L$7)*75/100*2,0)/2,FLOOR(IF(Rekorde!$L$7="",Übungen!$H$7,Rekorde!$L$7)*75/100/Übungen!$J$7,1)*Übungen!$J$7)) -> 122.5 | E28: 75 % | F28: läuft weiter
A29: Waden | B29: jetzt auch stehend ohne Schulterpolster | C29: 3 × 12-15 | D29: =IF(IF(Rekorde!$L$16="",Übungen!$H$16,Rekorde!$L$16)="","offen",IF(Übungen!$J$16="",ROUND(IF(Rekorde!$L$16="",Übungen!$H$16,Rekorde!$L$16)*75/100*2,0)/2,FLOOR(IF(Rekorde!$L$16="",Übungen!$H$16,Rekorde!$L$16)*75/100/Übungen!$J$16,1)*Übungen!$J$16)) -> 140 | E29: 75 % | F29: läuft weiter
A31: Phase 3 · Woche 12 bis 16 · freie Gewichte kommen zurück
A32: Ab hier darf der Arm wieder halten und stützen. Die drei neuen Übungen starten bewusst bei der Hälfte: die Bewegung ist seit drei Monaten weg, nicht nur die Kraft.
A33: Übung | B33: Gerät / Ausführung | C33: Sätze × Wdh | D33: Start (kg) | E33: Anteil | F33: Hinweis
A34: Reverse V-Squat | B34: Maschine, lockerer Griff | C34: 3 × 8-10 | D34: =IF(IF(Rekorde!$L$8="",Übungen!$H$8,Rekorde!$L$8)="","offen",IF(Übungen!$J$8="",ROUND(IF(Rekorde!$L$8="",Übungen!$H$8,Rekorde!$L$8)*50/100*2,0)/2,FLOOR(IF(Rekorde!$L$8="",Übungen!$H$8,Rekorde!$L$8)*50/100/Übungen!$J$8,1)*Übungen!$J$8)) -> 105 | E34: 50 % | F34: Neu in dieser Phase. Polster auf Schulter und Nacken - erste Einheit nur Technik.
A35: Hip Thrust | B35: Langhantel, Stange auflegen lassen | C35: 3 × 8-10 | D35: =IF(IF(Rekorde!$L$12="",Übungen!$H$12,Rekorde!$L$12)="","offen",IF(Übungen!$J$12="",ROUND(IF(Rekorde!$L$12="",Übungen!$H$12,Rekorde!$L$12)*50/100*2,0)/2,FLOOR(IF(Rekorde!$L$12="",Übungen!$H$12,Rekorde!$L$12)*50/100/Übungen!$J$12,1)*Übungen!$J$12)) -> 140 | E35: 50 % | F35: Neu in dieser Phase. Arme vor der Brust kreuzen.
A36: Split Squat | B36: Multipresse ohne Zusatzhantel | C36: 3 × 8-10 | D36: =IF(IF(Rekorde!$L$5="",Übungen!$H$5,Rekorde!$L$5)="","offen",IF(Übungen!$J$5="",ROUND(IF(Rekorde!$L$5="",Übungen!$H$5,Rekorde!$L$5)*50/100*2,0)/2,FLOOR(IF(Rekorde!$L$5="",Übungen!$H$5,Rekorde!$L$5)*50/100/Übungen!$J$5,1)*Übungen!$J$5)) -> 60 | E36: 50 % | F36: Neu in dieser Phase. Kurzhanteln erst ab Monat 4.
A37: Beinpresse eng | B37: wie Phase 2 | C37: 3 × 8-10 | D37: =IF(IF(Rekorde!$L$4="",Übungen!$H$4,Rekorde!$L$4)="","offen",IF(Übungen!$J$4="",ROUND(IF(Rekorde!$L$4="",Übungen!$H$4,Rekorde!$L$4)*85/100*2,0)/2,FLOOR(IF(Rekorde!$L$4="",Übungen!$H$4,Rekorde!$L$4)*85/100/Übungen!$J$4,1)*Übungen!$J$4)) -> 255 | E37: 85 % | F37: läuft weiter
A38: Beinpresse breit | B38: wie Phase 2 | C38: 3 × 8-10 | D38: =IF(IF(Rekorde!$L$11="",Übungen!$H$11,Rekorde!$L$11)="","offen",IF(Übungen!$J$11="",ROUND(IF(Rekorde!$L$11="",Übungen!$H$11,Rekorde!$L$11)*85/100*2,0)/2,FLOOR(IF(Rekorde!$L$11="",Übungen!$H$11,Rekorde!$L$11)*85/100/Übungen!$J$11,1)*Übungen!$J$11)) -> 185 | E38: 85 % | F38: läuft weiter
A39: Hip & Glute | B39: wie Phase 2 | C39: 3 × 8-10 | D39: =IF(IF(Rekorde!$L$13="",Übungen!$H$13,Rekorde!$L$13)="","offen",IF(Übungen!$J$13="",ROUND(IF(Rekorde!$L$13="",Übungen!$H$13,Rekorde!$L$13)*85/100*2,0)/2,FLOOR(IF(Rekorde!$L$13="",Übungen!$H$13,Rekorde!$L$13)*85/100/Übungen!$J$13,1)*Übungen!$J$13)) -> 140 | E39: 85 % | F39: läuft weiter
A40: Seitliche Kickbacks | B40: wie Phase 2 | C40: 3 × 10-12 | D40: =IF(IF(Rekorde!$L$15="",Übungen!$H$15,Rekorde!$L$15)="","offen",IF(Übungen!$J$15="",ROUND(IF(Rekorde!$L$15="",Übungen!$H$15,Rekorde!$L$15)*85/100*2,0)/2,FLOOR(IF(Rekorde!$L$15="",Übungen!$H$15,Rekorde!$L$15)*85/100/Übungen!$J$15,1)*Übungen!$J$15)) -> 30 | E40: 85 % | F40: läuft weiter
A41: Beinstrecker | B41: wie Phase 1 | C41: 3 × 8-10 | D41: =IF(IF(Rekorde!$L$6="",Übungen!$H$6,Rekorde!$L$6)="","offen",IF(Übungen!$J$6="",ROUND(IF(Rekorde!$L$6="",Übungen!$H$6,Rekorde!$L$6)*95/100*2,0)/2,FLOOR(IF(Rekorde!$L$6="",Übungen!$H$6,Rekorde!$L$6)*95/100/Übungen!$J$6,1)*Übungen!$J$6)) -> 90 | E41: 95 % | F41: läuft weiter
A42: Beinbeuger | B42: wie Phase 1 | C42: 3 × 8-10 | D42: =IF(IF(Rekorde!$L$14="",Übungen!$H$14,Rekorde!$L$14)="","offen",IF(Übungen!$J$14="",ROUND(IF(Rekorde!$L$14="",Übungen!$H$14,Rekorde!$L$14)*95/100*2,0)/2,FLOOR(IF(Rekorde!$L$14="",Übungen!$H$14,Rekorde!$L$14)*95/100/Übungen!$J$14,1)*Übungen!$J$14)) -> 42.5 | E42: 95 % | F42: läuft weiter
A43: Adduktion | B43: wie Phase 1 | C43: 3 × 8-10 | D43: =IF(IF(Rekorde!$L$7="",Übungen!$H$7,Rekorde!$L$7)="","offen",IF(Übungen!$J$7="",ROUND(IF(Rekorde!$L$7="",Übungen!$H$7,Rekorde!$L$7)*95/100*2,0)/2,FLOOR(IF(Rekorde!$L$7="",Übungen!$H$7,Rekorde!$L$7)*95/100/Übungen!$J$7,1)*Übungen!$J$7)) -> 155 | E43: 95 % | F43: läuft weiter
A44: Waden | B44: sitzend oder stehend | C44: 3 × 10-12 | D44: =IF(IF(Rekorde!$L$16="",Übungen!$H$16,Rekorde!$L$16)="","offen",IF(Übungen!$J$16="",ROUND(IF(Rekorde!$L$16="",Übungen!$H$16,Rekorde!$L$16)*95/100*2,0)/2,FLOOR(IF(Rekorde!$L$16="",Übungen!$H$16,Rekorde!$L$16)*95/100/Übungen!$J$16,1)*Übungen!$J$16)) -> 180 | E44: 95 % | F44: läuft weiter
A46: Phase 4 · ab Monat 4 · zurück zum normalen Plan
...

Sheet Einheiten
A1: EINHEITEN | KOPFDATEN JE TRAINING
A2: Gelb ausfüllen. Das Datum wandert automatisch ins Log; Sätze, Volumen und Tonnage rechnen sich aus dem Log.
A3: Einheit | B3: Datum | C3: Fokus | D3: Körper- gewicht (kg) | E3: Dauer (min) | F3: Schlaf (h) | G3: Gefühl 1-5 | H3: Arbeits- sätze | I3: Arbeits- volumen (kg) | J3: Tonnage gesamt (kg) | K3: Tage seit letzter Einheit | L3: Notiz
A4: 1 | H4: =IF(COUNTIFS(Log!$B$4:$B$1203,$A4,Log!$E$4:$E$1203,"A")=0,"",COUNTIFS(Log!$B$4:$B$1203,$A4,Log!$E$4:$E$1203,"A")) -> 18 | I4: =IF($H4="","",SUMIFS(Log!$I$4:$I$1203,Log!$B$4:$B$1203,$A4,Log!$E$4:$E$1203,"A")) -> 19139.5 | J4: =IF($H4="","",SUMIFS(Log!$I$4:$I$1203,Log!$B$4:$B$1203,$A4)) -> 23617
A5: 2 | H5: =IF(COUNTIFS(Log!$B$4:$B$1203,$A5,Log!$E$4:$E$1203,"A")=0,"",COUNTIFS(Log!$B$4:$B$1203,$A5,Log!$E$4:$E$1203,"A")) -> 18 | I5: =IF($H5="","",SUMIFS(Log!$I$4:$I$1203,Log!$B$4:$B$1203,$A5,Log!$E$4:$E$1203,"A")) -> 19654 | J5: =IF($H5="","",SUMIFS(Log!$I$4:$I$1203,Log!$B$4:$B$1203,$A5)) -> 23569
A6: 3 | H6: =IF(COUNTIFS(Log!$B$4:$B$1203,$A6,Log!$E$4:$E$1203,"A")=0,"",COUNTIFS(Log!$B$4:$B$1203,$A6,Log!$E$4:$E$1203,"A")) -> 14 | I6: =IF($H6="","",SUMIFS(Log!$I$4:$I$1203,Log!$B$4:$B$1203,$A6,Log!$E$4:$E$1203,"A")) -> 17343.5 | J6: =IF($H6="","",SUMIFS(Log!$I$4:$I$1203,Log!$B$4:$B$1203,$A6)) -> 20558.5
A7: 4 | H7: =IF(COUNTIFS(Log!$B$4:$B$1203,$A7,Log!$E$4:$E$1203,"A")=0,"",COUNTIFS(Log!$B$4:$B$1203,$A7,Log!$E$4:$E$1203,"A")) -> 12 | I7: =IF($H7="","",SUMIFS(Log!$I$4:$I$1203,Log!$B$4:$B$1203,$A7,Log!$E$4:$E$1203,"A")) -> 18367.5 | J7: =IF($H7="","",SUMIFS(Log!$I$4:$I$1203,Log!$B$4:$B$1203,$A7)) -> 21427.5
A8: 5 | H8: =IF(COUNTIFS(Log!$B$4:$B$1203,$A8,Log!$E$4:$E$1203,"A")=0,"",COUNTIFS(Log!$B$4:$B$1203,$A8,Log!$E$4:$E$1203,"A")) -> 20 | I8: =IF($H8="","",SUMIFS(Log!$I$4:$I$1203,Log!$B$4:$B$1203,$A8,Log!$E$4:$E$1203,"A")) -> 25361 | J8: =IF($H8="","",SUMIFS(Log!$I$4:$I$1203,Log!$B$4:$B$1203,$A8)) -> 30581
A9: 6 | H9: =IF(COUNTIFS(Log!$B$4:$B$1203,$A9,Log!$E$4:$E$1203,"A")=0,"",COUNTIFS(Log!$B$4:$B$1203,$A9,Log!$E$4:$E$1203,"A")) -> 11 | I9: =IF($H9="","",SUMIFS(Log!$I$4:$I$1203,Log!$B$4:$B$1203,$A9,Log!$E$4:$E$1203,"A")) -> 14572 | J9: =IF($H9="","",SUMIFS(Log!$I$4:$I$1203,Log!$B$4:$B$1203,$A9)) -> 14572
A10: 7 | H10: =IF(COUNTIFS(Log!$B$4:$B$1203,$A10,Log!$E$4:$E$1203,"A")=0,"",COUNTIFS(Log!$B$4:$B$1203,$A10,Log!$E$4:$E$1203,"A")) -> 12 | I10: =IF($H10="","",SUMIFS(Log!$I$4:$I$1203,Log!$B$4:$B$1203,$A10,Log!$E$4:$E$1203,"A")) -> 18167 | J10: =IF($H10="","",SUMIFS(Log!$I$4:$I$1203,Log!$B$4:$B$1203,$A10)) -> 18167
A11: 8 | H11: =IF(COUNTIFS(Log!$B$4:$B$1203,$A11,Log!$E$4:$E$1203,"A")=0,"",COUNTIFS(Log!$B$4:$B$1203,$A11,Log!$E$4:$E$1203,"A")) -> 12 | I11: =IF($H11="","",SUMIFS(Log!$I$4:$I$1203,Log!$B$4:$B$1203,$A11,Log!$E$4:$E$1203,"A")) -> 14853.5 | J11: =IF($H11="","",SUMIFS(Log!$I$4:$I$1203,Log!$B$4:$B$1203,$A11)) -> 14853.5
A12: 9 | H12: =IF(COUNTIFS(Log!$B$4:$B$1203,$A12,Log!$E$4:$E$1203,"A")=0,"",COUNTIFS(Log!$B$4:$B$1203,$A12,Log!$E$4:$E$1203,"A")) -> 10 | I12: =IF($H12="","",SUMIFS(Log!$I$4:$I$1203,Log!$B$4:$B$1203,$A12,Log!$E$4:$E$1203,"A")) -> 10515 | J12: =IF($H12="","",SUMIFS(Log!$I$4:$I$1203,Log!$B$4:$B$1203,$A12)) -> 10515
A13: 10 | H13: =IF(COUNTIFS(Log!$B$4:$B$1203,$A13,Log!$E$4:$E$1203,"A")=0,"",COUNTIFS(Log!$B$4:$B$1203,$A13,Log!$E$4:$E$1203,"A")) -> 9 | I13: =IF($H13="","",SUMIFS(Log!$I$4:$I$1203,Log!$B$4:$B$1203,$A13,Log!$E$4:$E$1203,"A")) -> 12680 | J13: =IF($H13="","",SUMIFS(Log!$I$4:$I$1203,Log!$B$4:$B$1203,$A13)) -> 12680
A14: 11 | H14: =IF(COUNTIFS(Log!$B$4:$B$1203,$A14,Log!$E$4:$E$1203,"A")=0,"",COUNTIFS(Log!$B$4:$B$1203,$A14,Log!$E$4:$E$1203,"A")) -> 12 | I14: =IF($H14="","",SUMIFS(Log!$I$4:$I$1203,Log!$B$4:$B$1203,$A14,Log!$E$4:$E$1203,"A")) -> 15102 | J14: =IF($H14="","",SUMIFS(Log!$I$4:$I$1203,Log!$B$4:$B$1203,$A14)) -> 15102
A15: 12 | H15: =IF(COUNTIFS(Log!$B$4:$B$1203,$A15,Log!$E$4:$E$1203,"A")=0,"",COUNTIFS(Log!$B$4:$B$1203,$A15,Log!$E$4:$E$1203,"A")) -> 9 | I15: =IF($H15="","",SUMIFS(Log!$I$4:$I$1203,Log!$B$4:$B$1203,$A15,Log!$E$4:$E$1203,"A")) -> 9070 | J15: =IF($H15="","",SUMIFS(Log!$I$4:$I$1203,Log!$B$4:$B$1203,$A15)) -> 9070
... A63: 60 | H63: =IF(COUNTIFS(Log!$B$4:$B$1203,$A63,Log!$E$4:$E$1203,"A")=0,"",COUNTIFS(Log!$B$4:$B$1203,$A63,Log!$E$4:$E$1203,"A")) | I63: =IF($H63="","",SUMIFS(Log!$I$4:$I$1203,Log!$B$4:$B$1203,$A63,Log!$E$4:$E$1203,"A")) | J63: =IF($H63="","",SUMIFS(Log!$I$4:$I$1203,Log!$B$4:$B$1203,$A63))
A64: Summe | H64: =SUM(H4:H63) -> 214 | I64: =SUM(I4:I63) -> 251339.5 | J64: =SUM(J4:J63) -> 271227
A66: Ohne Datum funktioniert alles weiter, aber nur mit Datum rechnet die Spalte 'Tage seit letzter Einheit'. Unter zwei Tagen wird sie gelb - zwischen zwei Beineinheiten sollten 72 Stunden liegen, siehe Blatt 'Wochenplan'.

Sheet Log
A1: TRAININGSLOG | EIN SATZ PRO ZEILE
A2: Gelbe Spalten ausfüllen. Datum, Block, Volumen und e1RM rechnen automatisch.
A3: Datum | B3: Einheit | C3: Block | D3: Übung | E3: Satz | F3: Gewicht (kg) | G3: Wdh | H3: RPE | I3: Volumen (kg) | J3: e1RM (kg) | K3: Drop-Kette | L3: Notiz
A4: =IFERROR(IF($B4="","",IF(INDEX(Einheiten!$B$4:$B$63,MATCH($B4,Einheiten!$A$4:$A$63,0))=0,"",INDEX(Einheiten!$B$4:$B$63,MATCH($B4,Einheiten!$A$4:$A$63,0)))),"") | B4: 1 | C4: =IFERROR(IF($D4="","",INDEX(Übungen!$B$4:$B$23,MATCH($D4,Übungen!$A$4:$A$23,0))),"") -> Beine vorne | D4: Adduktion | E4: W | F4: 77.5 | G4: 17 | I4: =IF(AND(ISNUMBER($F4),ISNUMBER($G4),$E4<>"R"),$F4*$G4,"") -> 1317.5 | J4: =IF(AND($E4="A",ISNUMBER($F4),ISNUMBER($G4)),$F4*(1+$G4/30),"")
A5: =IFERROR(IF($B5="","",IF(INDEX(Einheiten!$B$4:$B$63,MATCH($B5,Einheiten!$A$4:$A$63,0))=0,"",INDEX(Einheiten!$B$4:$B$63,MATCH($B5,Einheiten!$A$4:$A$63,0)))),"") | B5: 1 | C5: =IFERROR(IF($D5="","",INDEX(Übungen!$B$4:$B$23,MATCH($D5,Übungen!$A$4:$A$23,0))),"") -> Beine vorne | D5: Adduktion | E5: A | F5: 152.5 | G5: 17 | I5: =IF(AND(ISNUMBER($F5),ISNUMBER($G5),$E5<>"R"),$F5*$G5,"") -> 2592.5 | J5: =IF(AND($E5="A",ISNUMBER($F5),ISNUMBER($G5)),$F5*(1+$G5/30),"") -> 238.91667
A6: =IFERROR(IF($B6="","",IF(INDEX(Einheiten!$B$4:$B$63,MATCH($B6,Einheiten!$A$4:$A$63,0))=0,"",INDEX(Einheiten!$B$4:$B$63,MATCH($B6,Einheiten!$A$4:$A$63,0)))),"") | B6: 1 | C6: =IFERROR(IF($D6="","",INDEX(Übungen!$B$4:$B$23,MATCH($D6,Übungen!$A$4:$A$23,0))),"") -> Beine vorne | D6: Adduktion | E6: A | F6: 152.5 | G6: 10 | I6: =IF(AND(ISNUMBER($F6),ISNUMBER($G6),$E6<>"R"),$F6*$G6,"") -> 1525 | J6: =IF(AND($E6="A",ISNUMBER($F6),ISNUMBER($G6)),$F6*(1+$G6/30),"") -> 203.33333
A7: =IFERROR(IF($B7="","",IF(INDEX(Einheiten!$B$4:$B$63,MATCH($B7,Einheiten!$A$4:$A$63,0))=0,"",INDEX(Einheiten!$B$4:$B$63,MATCH($B7,Einheiten!$A$4:$A$63,0)))),"") | B7: 1 | C7: =IFERROR(IF($D7="","",INDEX(Übungen!$B$4:$B$23,MATCH($D7,Übungen!$A$4:$A$23,0))),"") -> Beine vorne | D7: Adduktion | E7: R | F7: 110 | G7: 10 | I7: =IF(AND(ISNUMBER($F7),ISNUMBER($G7),$E7<>"R"),$F7*$G7,"") | J7: =IF(AND($E7="A",ISNUMBER($F7),ISNUMBER($G7)),$F7*(1+$G7/30),"") | K7: 110 / 72.5
A8: =IFERROR(IF($B8="","",IF(INDEX(Einheiten!$B$4:$B$63,MATCH($B8,Einheiten!$A$4:$A$63,0))=0,"",INDEX(Einheiten!$B$4:$B$63,MATCH($B8,Einheiten!$A$4:$A$63,0)))),"") | B8: 2 | C8: =IFERROR(IF($D8="","",INDEX(Übungen!$B$4:$B$23,MATCH($D8,Übungen!$A$4:$A$23,0))),"") -> Beine vorne | D8: Adduktion | E8: W | F8: 85 | G8: 10 | I8: =IF(AND(ISNUMBER($F8),ISNUMBER($G8),$E8<>"R"),$F8*$G8,"") -> 850 | J8: =IF(AND($E8="A",ISNUMBER($F8),ISNUMBER($G8)),$F8*(1+$G8/30),"")
A9: =IFERROR(IF($B9="","",IF(INDEX(Einheiten!$B$4:$B$63,MATCH($B9,Einheiten!$A$4:$A$63,0))=0,"",INDEX(Einheiten!$B$4:$B$63,MATCH($B9,Einheiten!$A$4:$A$63,0)))),"") | B9: 2 | C9: =IFERROR(IF($D9="","",INDEX(Übungen!$B$4:$B$23,MATCH($D9,Übungen!$A$4:$A$23,0))),"") -> Beine vorne | D9: Adduktion | E9: A | F9: 152.5 | G9: 20 | I9: =IF(AND(ISNUMBER($F9),ISNUMBER($G9),$E9<>"R"),$F9*$G9,"") -> 3050 | J9: =IF(AND($E9="A",ISNUMBER($F9),ISNUMBER($G9)),$F9*(1+$G9/30),"") -> 254.16667
A10: =IFERROR(IF($B10="","",IF(INDEX(Einheiten!$B$4:$B$63,MATCH($B10,Einheiten!$A$4:$A$63,0))=0,"",INDEX(Einheiten!$B$4:$B$63,MATCH($B10,Einheiten!$A$4:$A$63,0)))),"") | B10: 2 | C10: =IFERROR(IF($D10="","",INDEX(Übungen!$B$4:$B$23,MATCH($D10,Übungen!$A$4:$A$23,0))),"") -> Beine vorne | D10: Adduktion | E10: A | F10: 152.5 | G10: 16 | I10: =IF(AND(ISNUMBER($F10),ISNUMBER($G10),$E10<>"R"),$F10*$G10,"") -> 2440 | J10: =IF(AND($E10="A",ISNUMBER($F10),ISNUMBER($G10)),$F10*(1+$G10/30),"") -> 233.83333
A11: =IFERROR(IF($B11="","",IF(INDEX(Einheiten!$B$4:$B$63,MATCH($B11,Einheiten!$A$4:$A$63,0))=0,"",INDEX(Einheiten!$B$4:$B$63,MATCH($B11,Einheiten!$A$4:$A$63,0)))),"") | B11: 2 | C11: =IFERROR(IF($D11="","",INDEX(Übungen!$B$4:$B$23,MATCH($D11,Übungen!$A$4:$A$23,0))),"") -> Beine vorne | D11: Adduktion | E11: R | F11: 110 | G11: 10 | I11: =IF(AND(ISNUMBER($F11),ISNUMBER($G11),$E11<>"R"),$F11*$G11,"") | J11: =IF(AND($E11="A",ISNUMBER($F11),ISNUMBER($G11)),$F11*(1+$G11/30),"") | K11: 110 / 72.5 / 35
A12: =IFERROR(IF($B12="","",IF(INDEX(Einheiten!$B$4:$B$63,MATCH($B12,Einheiten!$A$4:$A$63,0))=0,"",INDEX(Einheiten!$B$4:$B$63,MATCH($B12,Einheiten!$A$4:$A$63,0)))),"") | B12: 3 | C12: =IFERROR(IF($D12="","",INDEX(Übungen!$B$4:$B$23,MATCH($D12,Übungen!$A$4:$A$23,0))),"") -> Beine vorne | D12: Adduktion | E12: W | F12: 65 | G12: 10 | I12: =IF(AND(ISNUMBER($F12),ISNUMBER($G12),$E12<>"R"),$F12*$G12,"") -> 650 | J12: =IF(AND($E12="A",ISNUMBER($F12),ISNUMBER($G12)),$F12*(1+$G12/30),"")
