Workbook

Sheet Übersicht
A1: Übersicht Zielkunden Schweiz
A2: Stand 27.09.2026 | alle Zahlen per Formel aus «Kundenliste» | VERTRAULICH
A4: Firmen gesamt | B4: Kernliste | C4: Prio A | D4: Prio B | E4: Prio C | F4: Status offen (CRM)
A5: =COUNTA(Kundenliste!$E$5:$E$129) -> 125 | B5: =COUNTIF(Kundenliste!$B$5:$B$129,"Ja") -> 70 | C5: =COUNTIF(Kundenliste!$X$5:$X$129,"A") -> 36 | D5: =COUNTIF(Kundenliste!$X$5:$X$129,"B") -> 69 | E5: =COUNTIF(Kundenliste!$X$5:$X$129,"C") -> 20 | F5: =COUNTIF(Kundenliste!$Y$5:$Y$129,"Offen: CRM prüfen") -> 125
A7: Segmentmix gemäss Vorgabe 60/20/20
A8: Segment | B8: Firmen gesamt | C8: Kernliste | D8: Soll-Anteil | E8: Ist-Anteil Kernliste | F8: Abweichung | G8: Prio A | H8: Prio B | I8: Prio C
A9: Installateure (60 %) | B9: =COUNTIF(Kundenliste!$C$5:$C$129,$A9) -> 42 | C9: =COUNTIFS(Kundenliste!$C$5:$C$129,$A9,Kundenliste!$B$5:$B$129,"Ja") -> 42 | D9: 0.6 | E9: =IF($C$12=0,0,C9/$C$12) -> 0.6 | F9: =E9-D9 -> 0 | G9: =COUNTIFS(Kundenliste!$C$5:$C$129,$A9,Kundenliste!$X$5:$X$129,"A") -> 11 | H9: =COUNTIFS(Kundenliste!$C$5:$C$129,$A9,Kundenliste!$X$5:$X$129,"B") -> 20 | I9: =COUNTIFS(Kundenliste!$C$5:$C$129,$A9,Kundenliste!$X$5:$X$129,"C") -> 11
A10: FM / EVU / Planer (20 %) | B10: =COUNTIF(Kundenliste!$C$5:$C$129,$A10) -> 35 | C10: =COUNTIFS(Kundenliste!$C$5:$C$129,$A10,Kundenliste!$B$5:$B$129,"Ja") -> 14 | D10: 0.2 | E10: =IF($C$12=0,0,C10/$C$12) -> 0.2 | F10: =E10-D10 -> 0 | G10: =COUNTIFS(Kundenliste!$C$5:$C$129,$A10,Kundenliste!$X$5:$X$129,"A") -> 7 | H10: =COUNTIFS(Kundenliste!$C$5:$C$129,$A10,Kundenliste!$X$5:$X$129,"B") -> 25 | I10: =COUNTIFS(Kundenliste!$C$5:$C$129,$A10,Kundenliste!$X$5:$X$129,"C") -> 3
A11: GU/TU + Industrie (20 %) | B11: =COUNTIF(Kundenliste!$C$5:$C$129,$A11) -> 48 | C11: =COUNTIFS(Kundenliste!$C$5:$C$129,$A11,Kundenliste!$B$5:$B$129,"Ja") -> 14 | D11: 0.2 | E11: =IF($C$12=0,0,C11/$C$12) -> 0.2 | F11: =E11-D11 -> 0 | G11: =COUNTIFS(Kundenliste!$C$5:$C$129,$A11,Kundenliste!$X$5:$X$129,"A") -> 18 | H11: =COUNTIFS(Kundenliste!$C$5:$C$129,$A11,Kundenliste!$X$5:$X$129,"B") -> 24 | I11: =COUNTIFS(Kundenliste!$C$5:$C$129,$A11,Kundenliste!$X$5:$X$129,"C") -> 6
A12: Total | B12: =SUM(B9:B11) -> 125 | C12: =SUM(C9:C11) -> 70 | D12: =SUM(D9:D11) -> 1 | E12: =SUM(E9:E11) -> 1 | G12: =SUM(G9:G11) -> 36 | H12: =SUM(H9:H11) -> 69 | I12: =SUM(I9:I11) -> 20
A14: Regionen x Prio
A15: Region | B15: Prio A | C15: Prio B | D15: Prio C | E15: Total | F15: davon Kernliste | G15: Installateure | H15: FM/EVU/Planer | I15: GU/TU+Industrie
A16: West (Romandie) | B16: =COUNTIFS(Kundenliste!$I$5:$I$129,$A16,Kundenliste!$X$5:$X$129,"A") -> 4 | C16: =COUNTIFS(Kundenliste!$I$5:$I$129,$A16,Kundenliste!$X$5:$X$129,"B") -> 17 | D16: =COUNTIFS(Kundenliste!$I$5:$I$129,$A16,Kundenliste!$X$5:$X$129,"C") -> 6 | E16: =SUM(B16:D16) -> 27 | F16: =COUNTIFS(Kundenliste!$I$5:$I$129,$A16,Kundenliste!$B$5:$B$129,"Ja") -> 13 | G16: =COUNTIFS(Kundenliste!$I$5:$I$129,$A16,Kundenliste!$C$5:$C$129,"Installateure (60 %)") -> 9 | H16: =COUNTIFS(Kundenliste!$I$5:$I$129,$A16,Kundenliste!$C$5:$C$129,"FM / EVU / Planer (20 %)") -> 7 | I16: =COUNTIFS(Kundenliste!$I$5:$I$129,$A16,Kundenliste!$C$5:$C$129,"GU/TU + Industrie (20 %)") -> 11
A17: Mittelland/Bern | B17: =COUNTIFS(Kundenliste!$I$5:$I$129,$A17,Kundenliste!$X$5:$X$129,"A") -> 4 | C17: =COUNTIFS(Kundenliste!$I$5:$I$129,$A17,Kundenliste!$X$5:$X$129,"B") -> 9 | D17: =COUNTIFS(Kundenliste!$I$5:$I$129,$A17,Kundenliste!$X$5:$X$129,"C") -> 3 | E17: =SUM(B17:D17) -> 16 | F17: =COUNTIFS(Kundenliste!$I$5:$I$129,$A17,Kundenliste!$B$5:$B$129,"Ja") -> 9 | G17: =COUNTIFS(Kundenliste!$I$5:$I$129,$A17,Kundenliste!$C$5:$C$129,"Installateure (60 %)") -> 8 | H17: =COUNTIFS(Kundenliste!$I$5:$I$129,$A17,Kundenliste!$C$5:$C$129,"FM / EVU / Planer (20 %)") -> 2 | I17: =COUNTIFS(Kundenliste!$I$5:$I$129,$A17,Kundenliste!$C$5:$C$129,"GU/TU + Industrie (20 %)") -> 6
A18: Nordwestschweiz | B18: =COUNTIFS(Kundenliste!$I$5:$I$129,$A18,Kundenliste!$X$5:$X$129,"A") -> 11 | C18: =COUNTIFS(Kundenliste!$I$5:$I$129,$A18,Kundenliste!$X$5:$X$129,"B") -> 10 | D18: =COUNTIFS(Kundenliste!$I$5:$I$129,$A18,Kundenliste!$X$5:$X$129,"C") -> 1 | E18: =SUM(B18:D18) -> 22 | F18: =COUNTIFS(Kundenliste!$I$5:$I$129,$A18,Kundenliste!$B$5:$B$129,"Ja") -> 16 | G18: =COUNTIFS(Kundenliste!$I$5:$I$129,$A18,Kundenliste!$C$5:$C$129,"Installateure (60 %)") -> 6 | H18: =COUNTIFS(Kundenliste!$I$5:$I$129,$A18,Kundenliste!$C$5:$C$129,"FM / EVU / Planer (20 %)") -> 6 | I18: =COUNTIFS(Kundenliste!$I$5:$I$129,$A18,Kundenliste!$C$5:$C$129,"GU/TU + Industrie (20 %)") -> 10
A19: Zürich | B19: =COUNTIFS(Kundenliste!$I$5:$I$129,$A19,Kundenliste!$X$5:$X$129,"A") -> 11 | C19: =COUNTIFS(Kundenliste!$I$5:$I$129,$A19,Kundenliste!$X$5:$X$129,"B") -> 15 | D19: =COUNTIFS(Kundenliste!$I$5:$I$129,$A19,Kundenliste!$X$5:$X$129,"C") -> 0 | E19: =SUM(B19:D19) -> 26 | F19: =COUNTIFS(Kundenliste!$I$5:$I$129,$A19,Kundenliste!$B$5:$B$129,"Ja") -> 15 | G19: =COUNTIFS(Kundenliste!$I$5:$I$129,$A19,Kundenliste!$C$5:$C$129,"Installateure (60 %)") -> 8 | H19: =COUNTIFS(Kundenliste!$I$5:$I$129,$A19,Kundenliste!$C$5:$C$129,"FM / EVU / Planer (20 %)") -> 8 | I19: =COUNTIFS(Kundenliste!$I$5:$I$129,$A19,Kundenliste!$C$5:$C$129,"GU/TU + Industrie (20 %)") -> 10
A20: Ostschweiz | B20: =COUNTIFS(Kundenliste!$I$5:$I$129,$A20,Kundenliste!$X$5:$X$129,"A") -> 2 | C20: =COUNTIFS(Kundenliste!$I$5:$I$129,$A20,Kundenliste!$X$5:$X$129,"B") -> 8 | D20: =COUNTIFS(Kundenliste!$I$5:$I$129,$A20,Kundenliste!$X$5:$X$129,"C") -> 1 | E20: =SUM(B20:D20) -> 11 | F20: =COUNTIFS(Kundenliste!$I$5:$I$129,$A20,Kundenliste!$B$5:$B$129,"Ja") -> 5 | G20: =COUNTIFS(Kundenliste!$I$5:$I$129,$A20,Kundenliste!$C$5:$C$129,"Installateure (60 %)") -> 4 | H20: =COUNTIFS(Kundenliste!$I$5:$I$129,$A20,Kundenliste!$C$5:$C$129,"FM / EVU / Planer (20 %)") -> 4 | I20: =COUNTIFS(Kundenliste!$I$5:$I$129,$A20,Kundenliste!$C$5:$C$129,"GU/TU + Industrie (20 %)") -> 3
A21: Zentralschweiz | B21: =COUNTIFS(Kundenliste!$I$5:$I$129,$A21,Kundenliste!$X$5:$X$129,"A") -> 3 | C21: =COUNTIFS(Kundenliste!$I$5:$I$129,$A21,Kundenliste!$X$5:$X$129,"B") -> 4 | D21: =COUNTIFS(Kundenliste!$I$5:$I$129,$A21,Kundenliste!$X$5:$X$129,"C") -> 3 | E21: =SUM(B21:D21) -> 10 | F21: =COUNTIFS(Kundenliste!$I$5:$I$129,$A21,Kundenliste!$B$5:$B$129,"Ja") -> 7 | G21: =COUNTIFS(Kundenliste!$I$5:$I$129,$A21,Kundenliste!$C$5:$C$129,"Installateure (60 %)") -> 4 | H21: =COUNTIFS(Kundenliste!$I$5:$I$129,$A21,Kundenliste!$C$5:$C$129,"FM / EVU / Planer (20 %)") -> 4 | I21: =COUNTIFS(Kundenliste!$I$5:$I$129,$A21,Kundenliste!$C$5:$C$129,"GU/TU + Industrie (20 %)") -> 2
A22: Tessin | B22: =COUNTIFS(Kundenliste!$I$5:$I$129,$A22,Kundenliste!$X$5:$X$129,"A") -> 1 | C22: =COUNTIFS(Kundenliste!$I$5:$I$129,$A22,Kundenliste!$X$5:$X$129,"B") -> 6 | D22: =COUNTIFS(Kundenliste!$I$5:$I$129,$A22,Kundenliste!$X$5:$X$129,"C") -> 6 | E22: =SUM(B22:D22) -> 13 | F22: =COUNTIFS(Kundenliste!$I$5:$I$129,$A22,Kundenliste!$B$5:$B$129,"Ja") -> 5 | G22: =COUNTIFS(Kundenliste!$I$5:$I$129,$A22,Kundenliste!$C$5:$C$129,"Installateure (60 %)") -> 3 | H22: =COUNTIFS(Kundenliste!$I$5:$I$129,$A22,Kundenliste!$C$5:$C$129,"FM / EVU / Planer (20 %)") -> 4 | I22: =COUNTIFS(Kundenliste!$I$5:$I$129,$A22,Kundenliste!$C$5:$C$129,"GU/TU + Industrie (20 %)") -> 6
A23: Total | B23: =SUM(B16:B22) -> 36 | C23: =SUM(C16:C22) -> 69 | D23: =SUM(D16:D22) -> 20 | E23: =SUM(E16:E22) -> 125 | F23: =SUM(F16:F22) -> 70 | G23: =SUM(G16:G22) -> 42 | H23: =SUM(H16:H22) -> 35 | I23: =SUM(I16:I22) -> 48
A25: Verkaufsgebiet
A26: Gebiet | B26: Prio A | C26: Prio B | D26: Prio C | E26: Total
A27: West | B27: =COUNTIFS(Kundenliste!$J$5:$J$129,$A27,Kundenliste!$X$5:$X$129,"A") -> 4 | C27: =COUNTIFS(Kundenliste!$J$5:$J$129,$A27,Kundenliste!$X$5:$X$129,"B") -> 17 | D27: =COUNTIFS(Kundenliste!$J$5:$J$129,$A27,Kundenliste!$X$5:$X$129,"C") -> 6 | E27: =SUM(B27:D27) -> 27
A28: Deutschschweiz | B28: =COUNTIFS(Kundenliste!$J$5:$J$129,$A28,Kundenliste!$X$5:$X$129,"A") -> 31 | C28: =COUNTIFS(Kundenliste!$J$5:$J$129,$A28,Kundenliste!$X$5:$X$129,"B") -> 46 | D28: =COUNTIFS(Kundenliste!$J$5:$J$129,$A28,Kundenliste!$X$5:$X$129,"C") -> 8 | E28: =SUM(B28:D28) -> 85
A29: Tessin | B29: =COUNTIFS(Kundenliste!$J$5:$J$129,$A29,Kundenliste!$X$5:$X$129,"A") -> 1 | C29: =COUNTIFS(Kundenliste!$J$5:$J$129,$A29,Kundenliste!$X$5:$X$129,"B") -> 6 | D29: =COUNTIFS(Kundenliste!$J$5:$J$129,$A29,Kundenliste!$X$5:$X$129,"C") -> 6 | E29: =SUM(B29:D29) -> 13
A31: Kategorien
A32: Kategorie | B32: Prio A | C32: Prio B | D32: Prio C | E32: Total | F32: Ø Score
A33: Installateur | B33: =COUNTIFS(Kundenliste!$D$5:$D$129,$A33,Kundenliste!$X$5:$X$129,"A") -> 11 | C33: =COUNTIFS(Kundenliste!$D$5:$D$129,$A33,Kundenliste!$X$5:$X$129,"B") -> 20 | D33: =COUNTIFS(Kundenliste!$D$5:$D$129,$A33,Kundenliste!$X$5:$X$129,"C") -> 11 | E33: =SUM(B33:D33) -> 42 | F33: =IFERROR(AVERAGEIF(Kundenliste!$D$5:$D$129,$A33,Kundenliste!$U$5:$U$129),0) -> 3.497619
A34: Facility Manager | B34: =COUNTIFS(Kundenliste!$D$5:$D$129,$A34,Kundenliste!$X$5:$X$129,"A") -> 2 | C34: =COUNTIFS(Kundenliste!$D$5:$D$129,$A34,Kundenliste!$X$5:$X$129,"B") -> 5 | D34: =COUNTIFS(Kundenliste!$D$5:$D$129,$A34,Kundenliste!$X$5:$X$129,"C") -> 0 | E34: =SUM(B34:D34) -> 7 | F34: =IFERROR(AVERAGEIF(Kundenliste!$D$5:$D$129,$A34,Kundenliste!$U$5:$U$129),0) -> 3.6357143
A35: Stadtwerk/EVU | B35: =COUNTIFS(Kundenliste!$D$5:$D$129,$A35,Kundenliste!$X$5:$X$129,"A") -> 4 | C35: =COUNTIFS(Kundenliste!$D$5:$D$129,$A35,Kundenliste!$X$5:$X$129,"B") -> 12 | D35: =COUNTIFS(Kundenliste!$D$5:$D$129,$A35,Kundenliste!$X$5:$X$129,"C") -> 0 | E35: =SUM(B35:D35) -> 16 | F35: =IFERROR(AVERAGEIF(Kundenliste!$D$5:$D$129,$A35,Kundenliste!$U$5:$U$129),0) -> 3.675
A36: Elektroplaner | B36: =COUNTIFS(Kundenliste!$D$5:$D$129,$A36,Kundenliste!$X$5:$X$129,"A") -> 1 | C36: =COUNTIFS(Kundenliste!$D$5:$D$129,$A36,Kundenliste!$X$5:$X$129,"B") -> 8 | D36: =COUNTIFS(Kundenliste!$D$5:$D$129,$A36,Kundenliste!$X$5:$X$129,"C") -> 3 | E36: =SUM(B36:D36) -> 12 | F36: =IFERROR(AVERAGEIF(Kundenliste!$D$5:$D$129,$A36,Kundenliste!$U$5:$U$129),0) -> 3.3
A37: GU/TU | B37: =COUNTIFS(Kundenliste!$D$5:$D$129,$A37,Kundenliste!$X$5:$X$129,"A") -> 5 | C37: =COUNTIFS(Kundenliste!$D$5:$D$129,$A37,Kundenliste!$X$5:$X$129,"B") -> 5 | D37: =COUNTIFS(Kundenliste!$D$5:$D$129,$A37,Kundenliste!$X$5:$X$129,"C") -> 1 | E37: =SUM(B37:D37) -> 11 | F37: =IFERROR(AVERAGEIF(Kundenliste!$D$5:$D$129,$A37,Kundenliste!$U$5:$U$129),0) -> 3.8045455
A38: Rechenzentrum | B38: =COUNTIFS(Kundenliste!$D$5:$D$129,$A38,Kundenliste!$X$5:$X$129,"A") -> 6 | C38: =COUNTIFS(Kundenliste!$D$5:$D$129,$A38,Kundenliste!$X$5:$X$129,"B") -> 5 | D38: =COUNTIFS(Kundenliste!$D$5:$D$129,$A38,Kundenliste!$X$5:$X$129,"C") -> 1 | E38: =SUM(B38:D38) -> 12 | F38: =IFERROR(AVERAGEIF(Kundenliste!$D$5:$D$129,$A38,Kundenliste!$U$5:$U$129),0) -> 3.9083333
A39: Industrie | B39: =COUNTIFS(Kundenliste!$D$5:$D$129,$A39,Kundenliste!$X$5:$X$129,"A") -> 3 | C39: =COUNTIFS(Kundenliste!$D$5:$D$129,$A39,Kundenliste!$X$5:$X$129,"B") -> 3 | D39: =COUNTIFS(Kundenliste!$D$5:$D$129,$A39,Kundenliste!$X$5:$X$129,"C") -> 4 | E39: =SUM(B39:D39) -> 10 | F39: =IFERROR(AVERAGEIF(Kundenliste!$D$5:$D$129,$A39,Kundenliste!$U$5:$U$129),0) -> 3.23
A40: Spital | B40: =COUNTIFS(Kundenliste!$D$5:$D$129,$A40,Kundenliste!$X$5:$X$129,"A") -> 1 | C40: =COUNTIFS(Kundenliste!$D$5:$D$129,$A40,Kundenliste!$X$5:$X$129,"B") -> 4 | D40: =COUNTIFS(Kundenliste!$D$5:$D$129,$A40,Kundenliste!$X$5:$X$129,"C") -> 0 | E40: =SUM(B40:D40) -> 5 | F40: =IFERROR(AVERAGEIF(Kundenliste!$D$5:$D$129,$A40,Kundenliste!$U$5:$U$129),0) -> 3.5
A41: Infrastruktur | B41: =COUNTIFS(Kundenliste!$D$5:$D$129,$A41,Kundenliste!$X$5:$X$129,"A") -> 2 | C41: =COUNTIFS(Kundenliste!$D$5:$D$129,$A41,Kundenliste!$X$5:$X$129,"B") -> 1 | D41: =COUNTIFS(Kundenliste!$D$5:$D$129,$A41,Kundenliste!$X$5:$X$129,"C") -> 0 | E41: =SUM(B41:D41) -> 3 | F41: =IFERROR(AVERAGEIF(Kundenliste!$D$5:$D$129,$A41,Kundenliste!$U$5:$U$129),0) -> 3.8166667
A42: Event | B42: =COUNTIFS(Kundenliste!$D$5:$D$129,$A42,Kundenliste!$X$5:$X$129,"A") -> 1 | C42: =COUNTIFS(Kundenliste!$D$5:$D$129,$A42,Kundenliste!$X$5:$X$129,"B") -> 6 | D42: =COUNTIFS(Kundenliste!$D$5:$D$129,$A42,Kundenliste!$X$5:$X$129,"C") -> 0 | E42: =SUM(B42:D42) -> 7 | F42: =IFERROR(AVERAGEIF(Kundenliste!$D$5:$D$129,$A42,Kundenliste!$U$5:$U$129),0) -> 3.7
A44: Kundenstatus MiT (aus CRM zu befüllen)
A45: Status | B45: Anzahl | C45: davon Prio A
A46: Offen: CRM prüfen | B46: =COUNTIF(Kundenliste!$Y$5:$Y$129,$A46) -> 125 | C46: =COUNTIFS(Kundenliste!$Y$5:$Y$129,$A46,Kundenliste!$X$5:$X$129,"A") -> 36
...

Sheet Kundenliste
A1: Zielkundenliste Schweiz: Mobile Energie (Generator, BESS, USV, Trafo, NEA, PQ, Baustrom, Event)
A2: Stand 27.09.2026 | 125 Firmen | Kernliste 70 (60/20/20) | Score und Prio rechnen aus Blatt «Methodik» | VERTRAULICH
A3: Blaue Spalten Q-T (Fit/Volumen/Timing/Zugang) sowie Prio final, Kundenstatus, Ansprechperson, Verantwortlich, nächster Schritt und Datum sind Eingabefelder.
A4: ID | B4: Kernliste Top 70 | C4: Segment | D4: Kategorie | E4: Firma | F4: Gruppe / Mutter | G4: Ort | H4: Kt. | I4: Region | J4: Gebiet | K4: Sprache | L4: Website | M4: Grösse | N4: Anlass / Projekt 2025-2027 | O4: MiT-Leistungen | P4: Warum (Begründung) | Q4: Fit | R4: Volumen | S4: Timing | T4: Zugang | U4: Score | V4: Prio Vorschlag | W4: Prio final | X4: Prio | Y4: Kundenstatus MiT | Z4: Verloren seit | AA4: Zielrolle Ansprechperson | AB4: Ansprechperson (Name) | AC4: GL öffentlich (Quelle) | AD4: LinkedIn Firma | AE4: LinkedIn Personen | AF4: Quelle | AG4: Validierung / Hinweis | AH4: Verantwortlich | AI4: Nächster Schritt | AJ4: Datum nächster Schritt | AK4: Letzter Kontakt
A5: CH-001 | B5: Ja | C5: Installateure (60 %) | D5: Installateur | E5: Burkhalter Gruppe (Holding) | F5: börsenkotiert | G5: Zürich | H5: ZH | I5: Zürich | J5: Deutschschweiz | K5: DE | L5: burkhalter.ch | M5: 5'356 FTE, 83 Gesellschaften, 169 Standorte (31.12.2025) | N5: Kein spezifischer Anlass recherchiert | O5: Baustrom, Generator, USV, NEA-Test | P5: Grösster Elektroinstallateur CH. Ein Rahmenvertrag öffnet Dutzende Töchter (u.a. Sedelec, Mérinat, EAGB, Hufschmid, Celio, Grichting & Valterio). | Q5: 5 | R5: 5 | S5: 4 | T5: 3 | U5: =ROUND(Q5*Methodik!$B$5+R5*Methodik!$B$6+S5*Methodik!$B$7+T5*Methodik!$B$8,2) -> 4.45 | V5: =IF(U5>=Methodik!$B$11,"A",IF(U5>=Methodik!$B$12,"B","C")) -> A | X5: =IF(W5="",V5,W5) -> A | Y5: Offen: CRM prüfen | AA5: Leiter Grossprojekte / Bereichsleiter Baustrom / Einkauf | AC5: CEO Zeno Böhm (Moneycab) | AD5: Suche öffnen | AE5: Suche öffnen | AF5: Link
A6: CH-002 | B6: Ja | C6: Installateure (60 %) | D6: Installateur | E6: ETAVIS AG | F6: VINCI Energies | G6: Zürich | H6: ZH | I6: Zürich | J6: Deutschschweiz | K6: DE | L6: etavis.ch | M6: >2'400 MA | N6: Kein spezifischer Anlass recherchiert | O6: Baustrom, Generator, USV, NEA-Test | P6: Landesweit in Infrastruktur (Flughafen, Tunnel, Bahn) und Rechenzentren. Zugang zu VINCI-Schwestern (Actemium, Gfeller). | Q6: 5 | R6: 5 | S6: 4 | T6: 3 | U6: =ROUND(Q6*Methodik!$B$5+R6*Methodik!$B$6+S6*Methodik!$B$7+T6*Methodik!$B$8,2) -> 4.45 | V6: =IF(U6>=Methodik!$B$11,"A",IF(U6>=Methodik!$B$12,"B","C")) -> A | X6: =IF(W6="",V6,W6) -> A | Y6: Offen: CRM prüfen | AA6: Leiter Grossprojekte / Bereichsleiter Baustrom / Einkauf | AD6: Suche öffnen | AE6: Suche öffnen | AF6: Link
A7: CH-003 | B7: Ja | C7: Installateure (60 %) | D7: Installateur | E7: Equans Switzerland AG | F7: Bouygues (ex Bouygues E&S InTec / Alpiq InTec) | G7: Zürich | H7: ZH | I7: Zürich | J7: Deutschschweiz | K7: DE | L7: equans.ch | M7: >1'600 MA, >20 Standorte (Broschüre 2025, Zahl prüfen) | N7: Kein spezifischer Anlass recherchiert | O7: Generator, Trafo, NEA-Test, USV, Baustrom | P7: Energie, Verkehr, Industrie und FM unter einem Dach: NEA-Tests, Service-Unterbrüche, temporäre Einspeisung. | Q7: 5 | R7: 5 | S7: 4 | T7: 3 | U7: =ROUND(Q7*Methodik!$B$5+R7*Methodik!$B$6+S7*Methodik!$B$7+T7*Methodik!$B$8,2) -> 4.45 | V7: =IF(U7>=Methodik!$B$11,"A",IF(U7>=Methodik!$B$12,"B","C")) -> A | X7: =IF(W7="",V7,W7) -> A | Y7: Offen: CRM prüfen | AA7: Leiter Grossprojekte / Bereichsleiter Baustrom / Einkauf | AD7: Suche öffnen | AE7: Suche öffnen | AF7: Link | AG7: Seit 07/2024 unter diesem Namen. MA-Zahl wirkt tief, prüfen.
A8: CH-004 | B8: Ja | C8: Installateure (60 %) | D8: Installateur | E8: BKW Building Solutions AG | F8: BKW | G8: Ostermundigen | H8: BE | I8: Mittelland/Bern | J8: Deutschschweiz | K8: DE/FR | L8: bkw.ch | M8: ca. 4'000 MA in ca. 50 Firmen | N8: Kein spezifischer Anlass recherchiert | O8: Baustrom, BESS, Generator | P8: Dach von AEK, ISP, swisspro, Arnold, inelectro. Zentraler Einkaufsrahmen für Baustrom und BESS. | Q8: 5 | R8: 5 | S8: 3 | T8: 3 | U8: =ROUND(Q8*Methodik!$B$5+R8*Methodik!$B$6+S8*Methodik!$B$7+T8*Methodik!$B$8,2) -> 4.2 | V8: =IF(U8>=Methodik!$B$11,"A",IF(U8>=Methodik!$B$12,"B","C")) -> A | X8: =IF(W8="",V8,W8) -> A | Y8: Offen: CRM prüfen | AA8: Leiter Grossprojekte / Bereichsleiter Baustrom / Einkauf | AD8: Suche öffnen | AE8: Suche öffnen | AF8: Link | AG8: BKW ist Lauberhorn-Sponsor: Nähe zu Energiethemen, evtl. Eigenlösungen.
A9: CH-005 | B9: Ja | C9: Installateure (60 %) | D9: Installateur | E9: Actemium Schweiz AG | F9: VINCI Energies (ex Cegelec) | G9: Ittigen | H9: BE | I9: Mittelland/Bern | J9: Deutschschweiz | K9: DE/FR | L9: actemium.ch | M9: ca. 930 MA (prüfen) | N9: Kein spezifischer Anlass recherchiert | O9: Generator, Lastbank/NEA-Test, Trafo, USV | P9: Industrieautomation und Prozessanlagen: Shutdowns, Inbetriebnahmen, Lastbanktests. | Q9: 5 | R9: 4 | S9: 4 | T9: 3 | U9: =ROUND(Q9*Methodik!$B$5+R9*Methodik!$B$6+S9*Methodik!$B$7+T9*Methodik!$B$8,2) -> 4.15 | V9: =IF(U9>=Methodik!$B$11,"A",IF(U9>=Methodik!$B$12,"B","C")) -> A | X9: =IF(W9="",V9,W9) -> A | Y9: Offen: CRM prüfen | AA9: Leiter Grossprojekte / Bereichsleiter Baustrom / Einkauf | AD9: Suche öffnen | AE9: Suche öffnen | AF9: Link
A10: CH-006 | B10: Ja | C10: Installateure (60 %) | D10: Installateur | E10: Arnold AG | F10: BKW (Infra Services) | G10: Wangen an der Aare | H10: BE | I10: Mittelland/Bern | J10: Deutschschweiz | K10: DE | L10: arnold.ch | M10: ca. 1'000 MA Infra-Services-Gruppe | N10: Kein spezifischer Anlass recherchiert | O10: Trafo, Generator, Netzersatz | P10: Hochspannungs- und Kabelnetzbau: Ersatzversorgung bei Netzumbauten, Trafo-Miete. | Q10: 5 | R10: 4 | S10: 4 | T10: 3 | U10: =ROUND(Q10*Methodik!$B$5+R10*Methodik!$B$6+S10*Methodik!$B$7+T10*Methodik!$B$8,2) -> 4.15 | V10: =IF(U10>=Methodik!$B$11,"A",IF(U10>=Methodik!$B$12,"B","C")) -> A | X10: =IF(W10="",V10,W10) -> A | Y10: Offen: CRM prüfen | AA10: Leiter Grossprojekte / Bereichsleiter Baustrom / Einkauf | AD10: Suche öffnen | AE10: Suche öffnen | AF10: Link
A11: CH-007 | B11: Ja | C11: Installateure (60 %) | D11: Installateur | E11: CKW Gebäudetechnik AG | F11: CKW / Axpo | G11: Luzern | H11: LU | I11: Zentralschweiz | J11: Deutschschweiz | K11: DE | L11: ckw.ch | M11: ca. 1'400 MA, 60 Standorte | N11: Kein spezifischer Anlass recherchiert | O11: Baustrom, Generator, BESS | P11: Grösster Installateur Zentralschweiz mit eigenen Grossbaustellen-Teams. | Q11: 5 | R11: 4 | S11: 4 | T11: 3 | U11: =ROUND(Q11*Methodik!$B$5+R11*Methodik!$B$6+S11*Methodik!$B$7+T11*Methodik!$B$8,2) -> 4.15 | V11: =IF(U11>=Methodik!$B$11,"A",IF(U11>=Methodik!$B$12,"B","C")) -> A | X11: =IF(W11="",V11,W11) -> A | Y11: Offen: CRM prüfen | AA11: Leiter Grossprojekte / Bereichsleiter Baustrom / Einkauf | AD11: Suche öffnen | AE11: Suche öffnen | AF11: Link | AG11: Firmenname (ex CKW Conex) prüfen.
A12: CH-008 | B12: Ja | C12: Installateure (60 %) | D12: Installateur | E12: EKZ Eltop AG | F12: EKZ | G12: Fahrweid (Weiningen) | H12: ZH | I12: Zürich | J12: Deutschschweiz | K12: DE | L12: ekzeltop.ch | M12: ca. 550 MA, ca. 40 Standorte | N12: Kein spezifischer Anlass recherchiert | O12: Baustrom, BESS, Generator | P12: Flächendeckend im Kanton ZH, PV und Speicher im Portfolio. | Q12: 5 | R12: 4 | S12: 4 | T12: 3 | U12: =ROUND(Q12*Methodik!$B$5+R12*Methodik!$B$6+S12*Methodik!$B$7+T12*Methodik!$B$8,2) -> 4.15 | V12: =IF(U12>=Methodik!$B$11,"A",IF(U12>=Methodik!$B$12,"B","C")) -> A | X12: =IF(W12="",V12,W12) -> A | Y12: Offen: CRM prüfen | AA12: Leiter Grossprojekte / Bereichsleiter Baustrom / Einkauf | AC12: CEO Claudio Gallo (EKZ-MM 2023, Aktualität prüfen) | AD12: Suche öffnen | AE12: Suche öffnen | AF12: Link
A13: CH-009 | B13: Ja | C13: Installateure (60 %) | D13: Installateur | E13: ETAVIS Kriegel+Schaffner AG | F13: VINCI Energies / ETAVIS | G13: Basel | H13: BS | I13: Nordwestschweiz | J13: Deutschschweiz | K13: DE | L13: etavis.ch | M13: ca. 700 MA Region NWCH (prüfen) | N13: Pharma-Grossprojekte Basel (Roche Bau 12, Bachem) | O13: USV, Generator, NEA-Test, Trafo | P13: Pharma und Chemie Basel: Shutdowns, Umbauten unter GMP, hohe Ausfallkosten beim Endkunden. | Q13: 5 | R13: 4 | S13: 4 | T13: 3 | U13: =ROUND(Q13*Methodik!$B$5+R13*Methodik!$B$6+S13*Methodik!$B$7+T13*Methodik!$B$8,2) -> 4.15 | V13: =IF(U13>=Methodik!$B$11,"A",IF(U13>=Methodik!$B$12,"B","C")) -> A | X13: =IF(W13="",V13,W13) -> A | Y13: Offen: CRM prüfen | AA13: Leiter Grossprojekte / Bereichsleiter Baustrom / Einkauf | AD13: Suche öffnen | AE13: Suche öffnen | AF13: Link
A14: CH-010 | B14: Ja | C14: Installateure (60 %) | D14: Installateur | E14: Egg-Telsa SA | F14: unabhängig (prüfen) | G14: Genève | H14: GE | I14: West (Romandie) | J14: West | K14: FR | L14: eggtelsa.com | M14: 300 bis knapp 500 MA | N14: Cap2030 Genève Aéroport (2026-2032) | O14: Baustrom, Event, Generator, USV | P14: Grösster unabhängiger Installateur in Genf: Baustrom, Events, internationale Organisationen. | Q14: 5 | R14: 4 | S14: 4 | T14: 3 | U14: =ROUND(Q14*Methodik!$B$5+R14*Methodik!$B$6+S14*Methodik!$B$7+T14*Methodik!$B$8,2) -> 4.15 | V14: =IF(U14>=Methodik!$B$11,"A",IF(U14>=Methodik!$B$12,"B","C")) -> A | X14: =IF(W14="",V14,W14) -> A | Y14: Offen: CRM prüfen | AA14: Leiter Grossprojekte / Bereichsleiter Baustrom / Einkauf | AD14: Suche öffnen | AE14: Suche öffnen | AF14: Link
A15: CH-011 | B15: Ja | C15: Installateure (60 %) | D15: Installateur | E15: Selmoni Gruppe | F15: unabhängig (prüfen) | G15: Münchenstein | H15: BL | I15: Nordwestschweiz | J15: Deutschschweiz | K15: DE | L15: selmoni.ch | M15: ca. 600 MA | N15: Life-Sciences-Projekte Basel | O15: USV, NEA-Test, Generator | P15: Life Sciences Basel, Verteilbau: USV, NEA, Shutdowns. | Q15: 5 | R15: 4 | S15: 4 | T15: 3 | U15: =ROUND(Q15*Methodik!$B$5+R15*Methodik!$B$6+S15*Methodik!$B$7+T15*Methodik!$B$8,2) -> 4.15 | V15: =IF(U15>=Methodik!$B$11,"A",IF(U15>=Methodik!$B$12,"B","C")) -> A | X15: =IF(W15="",V15,W15) -> A | Y15: Offen: CRM prüfen | AA15: Leiter Grossprojekte / Bereichsleiter Baustrom / Einkauf | AD15: Suche öffnen | AE15: Suche öffnen | AF15: Link | AG15: CEO-Name nur aus Suche, nicht verifiziert.
A16: CH-012 | B16: Ja | C16: Installateure (60 %) | D16: Installateur | E16: cablex AG | F16: Swisscom | G16: Gümligen | H16: BE | I16: Mittelland/Bern | J16: Deutschschweiz | K16: DE/FR/IT | L16: cablex.ch | M16: ca. 2'300 MA | N16: Kein spezifischer Anlass recherchiert | O16: BESS, Generator, USV | P16: Netzinfrastruktur und Mobilfunk landesweit: Notstrom für Antennen und Knoten, BESS für Umbauten. | Q16: 5 | R16: 4 | S16: 3 | T16: 3 | U16: =ROUND(Q16*Methodik!$B$5+R16*Methodik!$B$6+S16*Methodik!$B$7+T16*Methodik!$B$8,2) -> 3.9 | V16: =IF(U16>=Methodik!$B$11,"A",IF(U16>=Methodik!$B$12,"B","C")) -> B | X16: =IF(W16="",V16,W16) -> B | Y16: Offen: CRM prüfen | AA16: Leiter Grossprojekte / Bereichsleiter Baustrom / Einkauf | AC16: CEO Roger Keller (seit 01.01.2025, cablex.ch) | AD16: Suche öffnen | AE16: Suche öffnen | AF16: Link
A17: CH-013 | B17: Ja | C17: Installateure (60 %) | D17: Installateur | E17: Alpine-Energie Schweiz AG | F17: ALPINE-ENERGIE Gruppe (DE/AT) | G17: Oftringen | H17: AG | I17: Nordwestschweiz | J17: Deutschschweiz | K17: DE | L17: prüfen | M17: k.A. | N17: Kein spezifischer Anlass recherchiert | O17: Generator, Trafo | P17: Freileitung, Fahrleitung, Tunnel: mobile Energie auf Linienbaustellen. | Q17: 5 | R17: 3 | S17: 4 | T17: 3 | U17: =ROUND(Q17*Methodik!$B$5+R17*Methodik!$B$6+S17*Methodik!$B$7+T17*Methodik!$B$8,2) -> 3.85 | V17: =IF(U17>=Methodik!$B$11,"A",IF(U17>=Methodik!$B$12,"B","C")) -> B | X17: =IF(W17="",V17,W17) -> B | Y17: Offen: CRM prüfen | AA17: Leiter Grossprojekte / Bereichsleiter Baustrom / Einkauf | AD17: Suche öffnen | AE17: Suche öffnen | AF17: Link | AG17: Website prüfen.
A18: CH-014 | B18: Ja | C18: Installateure (60 %) | D18: Installateur | E18: Baumann Koelliker Gruppe | F18: unabhängig (Familie) | G18: Zürich | H18: ZH | I18: Zürich | J18: Deutschschweiz | K18: DE | L18: baumann-koelliker-gruppe.ch | M18: 1'250 MA, 16-17 Firmen | N18: Kein spezifischer Anlass recherchiert | O18: Baustrom, Generator | P18: Viele Grossbaustellen in ZH: Baustrom-Rahmenvertrag. | Q18: 4 | R18: 4 | S18: 4 | T18: 3 | U18: =ROUND(Q18*Methodik!$B$5+R18*Methodik!$B$6+S18*Methodik!$B$7+T18*Methodik!$B$8,2) -> 3.85 | V18: =IF(U18>=Methodik!$B$11,"A",IF(U18>=Methodik!$B$12,"B","C")) -> B | X18: =IF(W18="",V18,W18) -> B | Y18: Offen: CRM prüfen | AA18: Leiter Grossprojekte / Bereichsleiter Baustrom / Einkauf | AD18: Suche öffnen | AE18: Suche öffnen | AF18: Link
A19: CH-015 | B19: Ja | C19: Installateure (60 %) | D19: Installateur | E19: Grichting & Valterio Electro SA | F19: Burkhalter (seit 2009) | G19: Sion | H19: VS | I19: West (Romandie) | J19: West | K19: FR/DE | L19: grichting-valterio.ch | M19: 104-170 MA (uneinheitlich) | N19: Lonza Visp Ramp-up 2026 | O19: Baustrom, NEA-Test, Generator | P19: Walliser Industrie (Lonza-Umfeld) und Infrastruktur. | Q19: 5 | R19: 3 | S19: 4 | T19: 3 | U19: =ROUND(Q19*Methodik!$B$5+R19*Methodik!$B$6+S19*Methodik!$B$7+T19*Methodik!$B$8,2) -> 3.85 | V19: =IF(U19>=Methodik!$B$11,"A",IF(U19>=Methodik!$B$12,"B","C")) -> B | X19: =IF(W19="",V19,W19) -> B | Y19: Offen: CRM prüfen | AA19: Leiter Grossprojekte / Bereichsleiter Baustrom / Einkauf | AD19: Suche öffnen | AE19: Suche öffnen | AF19: Link
A20: CH-016 | B20: Ja | C20: Installateure (60 %) | D20: Installateur | E20: Sedelec SA | F20: Burkhalter | G20: Carouge | H20: GE | I20: West (Romandie) | J20: West | K20: FR | L20: sedelec-geneve.ch | M20: >200 MA | N20: Kein spezifischer Anlass recherchiert | O20: Baustrom, USV | P20: Genfer Grossbaustellen, dazu Sedelec Lausanne. | Q20: 4 | R20: 4 | S20: 4 | T20: 3 | U20: =ROUND(Q20*Methodik!$B$5+R20*Methodik!$B$6+S20*Methodik!$B$7+T20*Methodik!$B$8,2) -> 3.85 | V20: =IF(U20>=Methodik!$B$11,"A",IF(U20>=Methodik!$B$12,"B","C")) -> B | X20: =IF(W20="",V20,W20) -> B | Y20: Offen: CRM prüfen | AA20: Leiter Grossprojekte / Bereichsleiter Baustrom / Einkauf | AD20: Suche öffnen | AE20: Suche öffnen | AF20: Link
A21: CH-017 | B21: Ja | C21: Installateure (60 %) | D21: Installateur | E21: Elektro Compagnoni AG | F21: unabhängig (Familie, 2. Generation) | G21: Zürich | H21: ZH | I21: Zürich | J21: Deutschschweiz | K21: DE | L21: elektro-compagnoni.ch | M21: ca. 140 MA | N21: Kein spezifischer Anlass recherchiert | O21: Trafo, NEA-Test, Generator | P21: Hochspannung, Schaltanlagen, Telecom: direkter Bedarf an Trafo-Miete und NEA. | Q21: 5 | R21: 3 | S21: 3 | T21: 4 | U21: =ROUND(Q21*Methodik!$B$5+R21*Methodik!$B$6+S21*Methodik!$B$7+T21*Methodik!$B$8,2) -> 3.75 | V21: =IF(U21>=Methodik!$B$11,"A",IF(U21>=Methodik!$B$12,"B","C")) -> B | X21: =IF(W21="",V21,W21) -> B | Y21: Offen: CRM prüfen | AA21: Leiter Grossprojekte / Bereichsleiter Baustrom / Einkauf | AD21: Suche öffnen | AE21: Suche öffnen | AF21: Link | AG21: Keine Burkhalter-Tochter.
A22: CH-018 | B22: Ja | C22: Installateure (60 %) | D22: Installateur | E22: ETAVIS Grossenbacher AG | F22: VINCI Energies / ETAVIS | G22: St. Gallen | H22: SG | I22: Ostschweiz | J22: Deutschschweiz | K22: DE | L22: etavis.ch | M22: k.A. | N22: Kein spezifischer Anlass recherchiert | O22: Baustrom, Generator | P22: Ostschweizer Grossbaustellen und Industrie, Einstieg über ETAVIS-Rahmen. | Q22: 4 | R22: 4 | S22: 3 | T22: 3 | U22: =ROUND(Q22*Methodik!$B$5+R22*Methodik!$B$6+S22*Methodik!$B$7+T22*Methodik!$B$8,2) -> 3.6 | V22: =IF(U22>=Methodik!$B$11,"A",IF(U22>=Methodik!$B$12,"B","C")) -> B | X22: =IF(W22="",V22,W22) -> B | Y22: Offen: CRM prüfen | AA22: Leiter Grossprojekte / Bereichsleiter Baustrom / Einkauf | AD22: Suche öffnen | AE22: Suche öffnen | AF22: Link
A23: CH-019 | B23: Ja | C23: Installateure (60 %) | D23: Installateur | E23: Groupe E Connect SA | F23: Groupe E | G23: Granges-Paccot / Matran | H23: FR | I23: West (Romandie) | J23: West | K23: FR/DE | L23: groupe-e.ch | M23: 880 MA, 12 Filialen FR/VD/VS/GE | N23: Groupe E baut 2025 rund 188 Stellen ab | O23: Baustrom, Generator | P23: Grossbaustellen Romandie: Baustrom, Tableaux. | Q23: 4 | R23: 4 | S23: 3 | T23: 3 | U23: =ROUND(Q23*Methodik!$B$5+R23*Methodik!$B$6+S23*Methodik!$B$7+T23*Methodik!$B$8,2) -> 3.6 | V23: =IF(U23>=Methodik!$B$11,"A",IF(U23>=Methodik!$B$12,"B","C")) -> B | X23: =IF(W23="",V23,W23) -> B | Y23: Offen: CRM prüfen | AA23: Leiter Grossprojekte / Bereichsleiter Baustrom / Einkauf | AC23: CEO Mutter Groupe E: Alain Sapin | AD23: Suche öffnen | AE23: Suche öffnen | AF23: Link | AG23: Restrukturierung: Kostendruck.
A24: CH-020 | B24: Ja | C24: Installateure (60 %) | D24: Installateur | E24: Kummler+Matter EVT AG | F24: Equans Switzerland (inkl. Mauerhofer & Zuber) | G24: Zürich | H24: ZH | I24: Zürich | J24: Deutschschweiz | K24: DE/FR | L24: kuma-evt.ch | M24: k.A. | N24: Kein spezifischer Anlass recherchiert | O24: Generator, BESS, Trafo | P24: Netz- und Freileitungsbau, Bahnstrom. Hat eigene mobile Trafostationen: Partner bei Spitzen, zugleich Wettbewerber. | Q24: 4 | R24: 4 | S24: 3 | T24: 3 | U24: =ROUND(Q24*Methodik!$B$5+R24*Methodik!$B$6+S24*Methodik!$B$7+T24*Methodik!$B$8,2) -> 3.6 | V24: =IF(U24>=Methodik!$B$11,"A",IF(U24>=Methodik!$B$12,"B","C")) -> B | X24: =IF(W24="",V24,W24) -> B | Y24: Offen: CRM prüfen | AA24: Leiter Grossprojekte / Bereichsleiter Baustrom / Einkauf | AD24: Suche öffnen | AE24: Suche öffnen | AF24: Link | AG24: Partner- oder Wettbewerberrolle intern klären.
A25: CH-021 | B25: Ja | C25: Installateure (60 %) | D25: Installateur | E25: Maréchaux Elektro AG / Gruppe | F25: unabhängig (Familie) | G25: Luzern | H25: LU | I25: Zentralschweiz | J25: Deutschschweiz | K25: DE | L25: marechaux.ch | M25: ca. 1'000 MA Gruppe, davon 750 Elektro | N25: Kein spezifischer Anlass recherchiert | O25: Baustrom, Generator | P25: Grösster unabhängiger Anbieter Zentralschweiz, Grossprojekte. | Q25: 4 | R25: 4 | S25: 3 | T25: 3 | U25: =ROUND(Q25*Methodik!$B$5+R25*Methodik!$B$6+S25*Methodik!$B$7+T25*Methodik!$B$8,2) -> 3.6 | V25: =IF(U25>=Methodik!$B$11,"A",IF(U25>=Methodik!$B$12,"B","C")) -> B | X25: =IF(W25="",V25,W25) -> B | Y25: Offen: CRM prüfen | AA25: Leiter Grossprojekte / Bereichsleiter Baustrom / Einkauf | AD25: Suche öffnen | AE25: Suche öffnen | AF25: Link
A26: CH-022 | B26: Ja | C26: Installateure (60 %) | D26: Installateur | E26: ETAVIS Elettro-Impianti SA | F26: VINCI Energies / ETAVIS | G26: Pregassona-Lugano | H26: TI | I26: Tessin | J26: Tessin | K26: IT | L26: etavis.ch/it | M26: k.A. | N26: 2. Gotthardröhre Süd (Airolo) im Umfeld | O26: Baustrom, Generator, Trafo | P26: Tessiner Grossprojekte und Tunnel. Einer der wenigen grösseren Installateure im Tessin. | Q26: 4 | R26: 3 | S26: 4 | T26: 3 | U26: =ROUND(Q26*Methodik!$B$5+R26*Methodik!$B$6+S26*Methodik!$B$7+T26*Methodik!$B$8,2) -> 3.55 | V26: =IF(U26>=Methodik!$B$11,"A",IF(U26>=Methodik!$B$12,"B","C")) -> B | X26: =IF(W26="",V26,W26) -> B | Y26: Offen: CRM prüfen | AA26: Leiter Grossprojekte / Bereichsleiter Baustrom / Einkauf | AD26: Suche öffnen | AE26: Suche öffnen | AF26: Link | AG26: Tunnelbezug unbestätigt.
A27: CH-023 | B27: Ja | C27: Installateure (60 %) | D27: Installateur | E27: AEK AG | F27: BKW (seit 2022) | G27: Solothurn | H27: SO | I27: Mittelland/Bern | J27: Deutschschweiz | K27: DE | L27: aek.ch | M27: ca. 250 MA | N27: Kein spezifischer Anlass recherchiert | O27: NEA-Test, Baustrom, Generator | P27: Industrie Solothurn (z.B. Grossauftrag Bell). | Q27: 4 | R27: 3 | S27: 3 | T27: 3 | U27: =ROUND(Q27*Methodik!$B$5+R27*Methodik!$B$6+S27*Methodik!$B$7+T27*Methodik!$B$8,2) -> 3.3 | V27: =IF(U27>=Methodik!$B$11,"A",IF(U27>=Methodik!$B$12,"B","C")) -> B | X27: =IF(W27="",V27,W27) -> B | Y27: Offen: CRM prüfen | AA27: Leiter Grossprojekte / Bereichsleiter Baustrom / Einkauf | AD27: Suche öffnen | AE27: Suche öffnen | AF27: Link
A28: CH-024 | B28: Ja | C28: Installateure (60 %) | D28: Installateur | E28: Elektrotechnik AG EAGB | F28: Burkhalter (seit 2020) | G28: Basel | H28: BS | I28: Nordwestschweiz | J28: Deutschschweiz | K28: DE | L28: eagb.ch | M28: ca. 175 MA | N28: Kein spezifischer Anlass recherchiert | O28: Generator, USV | P28: Basler Industrie und Spitäler: Notstrom und Überbrückung. | Q28: 4 | R28: 3 | S28: 3 | T28: 3 | U28: =ROUND(Q28*Methodik!$B$5+R28*Methodik!$B$6+S28*Methodik!$B$7+T28*Methodik!$B$8,2) -> 3.3 | V28: =IF(U28>=Methodik!$B$11,"A",IF(U28>=Methodik!$B$12,"B","C")) -> B | X28: =IF(W28="",V28,W28) -> B | Y28: Offen: CRM prüfen | AA28: Leiter Grossprojekte / Bereichsleiter Baustrom / Einkauf | AD28: Suche öffnen | AE28: Suche öffnen | AF28: Link
A29: CH-025 | B29: Ja | C29: Installateure (60 %) | D29: Installateur | E29: Ellenbroek Hugentobler AG | F29: unabhängig (prüfen) | G29: Frauenfeld | H29: TG | I29: Ostschweiz | J29: Deutschschweiz | K29: DE | L29: elhag.ch | M29: >160 MA | N29: Kein spezifischer Anlass recherchiert | O29: Netzersatz, Generator | P29: Leader im Thurgau inkl. Netzbau NS/MS: Netzersatz bei Kabelzug. | Q29: 4 | R29: 3 | S29: 3 | T29: 3 | U29: =ROUND(Q29*Methodik!$B$5+R29*Methodik!$B$6+S29*Methodik!$B$7+T29*Methodik!$B$8,2) -> 3.3 | V29: =IF(U29>=Methodik!$B$11,"A",IF(U29>=Methodik!$B$12,"B","C")) -> B | X29: =IF(W29="",V29,W29) -> B | Y29: Offen: CRM prüfen | AA29: Leiter Grossprojekte / Bereichsleiter Baustrom / Einkauf | AD29: Suche öffnen | AE29: Suche öffnen | AF29: Link
A30: CH-026 | B30: Ja | C30: Installateure (60 %) | D30: Installateur | E30: Jost Elektro AG Brugg | F30: unabhängig (Familie Bürgi) | G30: Brugg | H30: AG | I30: Nordwestschweiz | J30: Deutschschweiz | K30: DE | L30: jostelektro.ch | M30: ca. 200 MA | N30: Kein spezifischer Anlass recherchiert | O30: Baustrom, NEA-Test | P30: Aargauer Industrie und Kraftwerksumfeld. | Q30: 4 | R30: 3 | S30: 3 | T30: 3 | U30: =ROUND(Q30*Methodik!$B$5+R30*Methodik!$B$6+S30*Methodik!$B$7+T30*Methodik!$B$8,2) -> 3.3 | V30: =IF(U30>=Methodik!$B$11,"A",IF(U30>=Methodik!$B$12,"B","C")) -> B | X30: =IF(W30="",V30,W30) -> B | Y30: Offen: CRM prüfen | AA30: Leiter Grossprojekte / Bereichsleiter Baustrom / Einkauf | AD30: Suche öffnen | AE30: Suche öffnen | AF30: Link | AG30: Firma wurde laut AZ aufgeteilt: aktuelle Struktur prüfen.
A31: CH-027 | B31: Ja | C31: Installateure (60 %) | D31: Installateur | E31: Romande Energie Services SA | F31: Romande Energie | G31: Morges (prüfen) | H31: VD | I31: West (Romandie) | J31: West | K31: FR | L31: romande-energie.ch | M31: >200 MA | N31: Kein spezifischer Anlass recherchiert | O31: BESS, Generator, USV | P31: Industrie und Tertiär VD/FR/GE/VS/NE, PV und Speicher im Portfolio. | Q31: 4 | R31: 3 | S31: 3 | T31: 3 | U31: =ROUND(Q31*Methodik!$B$5+R31*Methodik!$B$6+S31*Methodik!$B$7+T31*Methodik!$B$8,2) -> 3.3 | V31: =IF(U31>=Methodik!$B$11,"A",IF(U31>=Methodik!$B$12,"B","C")) -> B | X31: =IF(W31="",V31,W31) -> B | Y31: Offen: CRM prüfen | AA31: Leiter Grossprojekte / Bereichsleiter Baustrom / Einkauf | AD31: Suche öffnen | AE31: Suche öffnen | AF31: Link
A32: CH-028 | B32: Ja | C32: Installateure (60 %) | D32: Installateur | E32: swisspro AG | F32: BKW (seit 2019) | G32: Urdorf | H32: ZH | I32: Zürich | J32: Deutschschweiz | K32: DE | L32: swisspro.ch | M32: ca. 430 MA (prüfen) | N32: Kein spezifischer Anlass recherchiert | O32: USV, BESS | P32: ICT und Gebäudeautomation: USV bei Rechenzentrums- und Netzumbauten. | Q32: 4 | R32: 3 | S32: 3 | T32: 3 | U32: =ROUND(Q32*Methodik!$B$5+R32*Methodik!$B$6+S32*Methodik!$B$7+T32*Methodik!$B$8,2) -> 3.3 | V32: =IF(U32>=Methodik!$B$11,"A",IF(U32>=Methodik!$B$12,"B","C")) -> B | X32: =IF(W32="",V32,W32) -> B | Y32: Offen: CRM prüfen | AA32: Leiter Grossprojekte / Bereichsleiter Baustrom / Einkauf | AD32: Suche öffnen | AE32: Suche öffnen | AF32: Link
A33: CH-029 | B33: Ja | C33: Installateure (60 %) | D33: Installateur | E33: Wenger + Wirz AG | F33: unabhängig | G33: Schaffhausen | H33: SH | I33: Ostschweiz | J33: Deutschschweiz | K33: DE | L33: wenger-wirz.ch | M33: ca. 130 MA (prüfen) | N33: STACK-Rechenzentrum Beringen SH (36 MW, Eröffnung 2026) | O33: PQ-Audit, Baustrom, Generator | P33: Nr. 1 in SH, macht Netzanalysen. Nähe zum RZ-Campus Beringen. | Q33: 4 | R33: 2 | S33: 4 | T33: 3 | U33: =ROUND(Q33*Methodik!$B$5+R33*Methodik!$B$6+S33*Methodik!$B$7+T33*Methodik!$B$8,2) -> 3.25 | V33: =IF(U33>=Methodik!$B$11,"A",IF(U33>=Methodik!$B$12,"B","C")) -> B | X33: =IF(W33="",V33,W33) -> B | Y33: Offen: CRM prüfen | AA33: Leiter Grossprojekte / Bereichsleiter Baustrom / Einkauf | AD33: Suche öffnen | AE33: Suche öffnen | AF33: Link | AG33: Beteiligung an STACK Beringen nicht belegt.
A34: CH-030 | B34: Ja | C34: Installateure (60 %) | D34: Installateur | E34: BKW ISP AG | F34: BKW | G34: Oberhofen am Thunersee (prüfen) | H34: BE | I34: Mittelland/Bern | J34: Deutschschweiz | K34: DE | L34: bkw.ch | M34: 200-499 MA (uneinheitlich) | N34: Kein spezifischer Anlass recherchiert | O34: Baustrom, Generator | P34: Elektroinstallation und PV im Raum Bern. | Q34: 3 | R34: 3 | S34: 3 | T34: 3 | U34: =ROUND(Q34*Methodik!$B$5+R34*Methodik!$B$6+S34*Methodik!$B$7+T34*Methodik!$B$8,2) -> 3 | V34: =IF(U34>=Methodik!$B$11,"A",IF(U34>=Methodik!$B$12,"B","C")) -> B | X34: =IF(W34="",V34,W34) -> B | Y34: Offen: CRM prüfen | AA34: Leiter Grossprojekte / Bereichsleiter Baustrom / Einkauf | AD34: Suche öffnen | AE34: Suche öffnen | AF34: Link | AG34: Sitz prüfen.
A35: CH-031 | B35: Ja | C35: Installateure (60 %) | D35: Installateur | E35: Elektro-Bau AG Rothrist | F35: k.A. | G35: Rothrist | H35: AG | I35: Nordwestschweiz | J35: Deutschschweiz | K35: DE | L35: elektro-bau.ch | M35: ca. 130 MA | N35: Kein spezifischer Anlass recherchiert | O35: Baustrom, Generator | P35: Logistik- und Industriebauten an der Mittelland-Achse. | Q35: 3 | R35: 3 | S35: 3 | T35: 3 | U35: =ROUND(Q35*Methodik!$B$5+R35*Methodik!$B$6+S35*Methodik!$B$7+T35*Methodik!$B$8,2) -> 3 | V35: =IF(U35>=Methodik!$B$11,"A",IF(U35>=Methodik!$B$12,"B","C")) -> B | X35: =IF(W35="",V35,W35) -> B | Y35: Offen: CRM prüfen | AA35: Leiter Grossprojekte / Bereichsleiter Baustrom / Einkauf | AD35: Suche öffnen | AE35: Suche öffnen | AF35: Link
A36: CH-032 | B36: Ja | C36: Installateure (60 %) | D36: Installateur | E36: Elettro-Celio SA | F36: Burkhalter | G36: Giubiasco | H36: TI | I36: Tessin | J36: Tessin | K36: IT | L36: celio.ch | M36: ca. 30 MA | N36: SBB-Frequenzumformer Giubiasco in Modernisierung | O36: Baustrom, Generator | P36: Sopraceneri und Mesolcina. | Q36: 3 | R36: 2 | S36: 4 | T36: 3 | U36: =ROUND(Q36*Methodik!$B$5+R36*Methodik!$B$6+S36*Methodik!$B$7+T36*Methodik!$B$8,2) -> 2.95 | V36: =IF(U36>=Methodik!$B$11,"A",IF(U36>=Methodik!$B$12,"B","C")) -> C | X36: =IF(W36="",V36,W36) -> C | Y36: Offen: CRM prüfen | AA36: Leiter Grossprojekte / Bereichsleiter Baustrom / Einkauf | AD36: Suche öffnen | AE36: Suche öffnen | AF36: Link
A37: CH-033 | B37: Ja | C37: Installateure (60 %) | D37: Installateur | E37: Mérinat SA | F37: Burkhalter (seit 2021) | G37: Vevey | H37: VD | I37: West (Romandie) | J37: West | K37: FR | L37: merinat.ch | M37: ca. 80 MA | N37: Montreux Jazz Festival in der Region | O37: Generator, Event | P37: Riviera, Hotellerie und Kliniken: Notstrom. | Q37: 3 | R37: 2 | S37: 4 | T37: 3 | U37: =ROUND(Q37*Methodik!$B$5+R37*Methodik!$B$6+S37*Methodik!$B$7+T37*Methodik!$B$8,2) -> 2.95 | V37: =IF(U37>=Methodik!$B$11,"A",IF(U37>=Methodik!$B$12,"B","C")) -> C | X37: =IF(W37="",V37,W37) -> C | Y37: Offen: CRM prüfen | AA37: Leiter Grossprojekte / Bereichsleiter Baustrom / Einkauf | AD37: Suche öffnen | AE37: Suche öffnen | AF37: Link
A38: CH-034 | B38: Ja | C38: Installateure (60 %) | D38: Installateur | E38: Gfeller Elektro AG | F38: VINCI Energies / ETAVIS (seit 2022) | G38: Bern | H38: BE | I38: Mittelland/Bern | J38: Deutschschweiz | K38: DE | L38: prüfen | M38: ca. 90-100 MA | N38: Kein spezifischer Anlass recherchiert | O38: Baustrom, Generator | P38: Gewerbe- und Verwaltungsbauten Bern. Kleinere Volumen, guter Zugang. | Q38: 3 | R38: 2 | S38: 3 | T38: 4 | U38: =ROUND(Q38*Methodik!$B$5+R38*Methodik!$B$6+S38*Methodik!$B$7+T38*Methodik!$B$8,2) -> 2.85 | V38: =IF(U38>=Methodik!$B$11,"A",IF(U38>=Methodik!$B$12,"B","C")) -> C | X38: =IF(W38="",V38,W38) -> C | Y38: Offen: CRM prüfen | AA38: Leiter Grossprojekte / Bereichsleiter Baustrom / Einkauf | AD38: Suche öffnen | AE38: Suche öffnen | AF38: Link
A39: CH-035 | B39: Ja | C39: Installateure (60 %) | D39: Installateur | E39: Scherler AG, Elektro und Telematik | F39: unabhängig (Familie) | G39: Bern | H39: BE | I39: Mittelland/Bern | J39: Deutschschweiz | K39: DE | L39: scherler-ag.ch | M39: k.A. | N39: Kein spezifischer Anlass recherchiert | O39: Baustrom, Generator | P39: Schaltanlagenbau und Installation Bern. | Q39: 3 | R39: 2 | S39: 3 | T39: 4 | U39: =ROUND(Q39*Methodik!$B$5+R39*Methodik!$B$6+S39*Methodik!$B$7+T39*Methodik!$B$8,2) -> 2.85 | V39: =IF(U39>=Methodik!$B$11,"A",IF(U39>=Methodik!$B$12,"B","C")) -> C | X39: =IF(W39="",V39,W39) -> C | Y39: Offen: CRM prüfen | AA39: Leiter Grossprojekte / Bereichsleiter Baustrom / Einkauf | AD39: Suche öffnen | AE39: Suche öffnen | AF39: Link | AG39: Nicht verwechseln mit SCHERLER AG Luzern (Planer).
A40: CH-036 | B40: Ja | C40: Installateure (60 %) | D40: Installateur | E40: Cauderay SA | F40: unabhängig | G40: Lausanne | H40: VD | I40: West (Romandie) | J40: West | K40: FR | L40: cauderay.com | M40: ca. 85 MA | N40: Kein spezifischer Anlass recherchiert | O40: Baustrom, Generator | P40: Gewerbe und Tertiär Lausanne. | Q40: 3 | R40: 2 | S40: 3 | T40: 3 | U40: =ROUND(Q40*Methodik!$B$5+R40*Methodik!$B$6+S40*Methodik!$B$7+T40*Methodik!$B$8,2) -> 2.7 | V40: =IF(U40>=Methodik!$B$11,"A",IF(U40>=Methodik!$B$12,"B","C")) -> C | X40: =IF(W40="",V40,W40) -> C | Y40: Offen: CRM prüfen | AA40: Leiter Grossprojekte / Bereichsleiter Baustrom / Einkauf | AD40: Suche öffnen | AE40: Suche öffnen | AF40: Link
...

Sheet Methodik
A1: Methodik, Legende und Grenzen der Recherche
A2: Stand 27.09.2026
A4: Gewichtung Score | B4: Wert | C4: Bedeutung (Skala je Kriterium 1 = schwach bis 5 = stark)
A5: Fit | B5: 0.3 | C5: Passt der Bedarf zum MiT-Portfolio (Generator, BESS, USV, Trafo, NEA-Test, PQ, Baustrom, Event)?
A6: Volumen | B6: 0.3 | C6: Erwartbares Mietvolumen pro Jahr bzw. Hebel über Töchter/Rahmenvertrag.
A7: Timing | B7: 0.25 | C7: Konkreter Anlass 2025-2027 (Bau, UW-Umbau, Commissioning, Ramp-up, Event-Saison).
A8: Zugang | B8: 0.15 | C8: Erreichbarkeit: regionale Nähe, Entscheid lokal vs. Konzern/EMEA, öffentliche Beschaffung.
A9: Summe Gewichte | B9: =SUM(B5:B8) -> 1
A11: Schwelle Prio A | B11: 4 | C11: Score >= Schwelle A: jetzt aktiv angehen (Termin in den nächsten 6 Wochen).
A12: Schwelle Prio B | B12: 3 | C12: Score >= Schwelle B: im Quartal angehen, Anlass beobachten.
A13: Prio C | C13: Darunter: Beobachten, opportunistisch bedienen, über Partner/Töchter abdecken.
A15: Bedienung
A16: Gelbe Zellen | C16: Eingaben. Gewichte und Schwellen hier ändern, Score und Prio in der Kundenliste rechnen neu.
A17: Prio final | C17: Leer lassen = Vorschlag gilt. A/B/C eintragen = übersteuert den Vorschlag. Spalte «Prio» ist die gültige.
A18: Kundenstatus MiT | C18: Alle Zeilen stehen auf «Offen: CRM prüfen». Bestands-, A- und verlorene Kunden sind öffentlich nicht
C19: recherchierbar und müssen aus dem MiT-CRM bzw. von Mauro, Jörg und Roberto eingetragen werden (Dropdown).
A20: Verloren seit | C20: Nur bei Status «Verlorener Kunde» ausfüllen (Datum). Grund in «Validierung / Hinweis».
A21: Kernliste Top 70 | C21: 70 Firmen im Verhältnis 60/20/20 (42/14/14) nach Vorgabe. Alle übrigen Zeilen sind Reserve bzw. Ergänzung.
A23: Grenzen der Recherche
A24: Quellen | C24: Websuche vom 27.09.2026: Firmenwebsites, Handelsregister-Aggregatoren, Medienmitteilungen, Fachpresse.
C25: Einige Seiten (u.a. NZZ, SRF, einzelne .ch-Domains) waren nicht direkt abrufbar: Werte teils nur aus Suchergebnissen.
A26: Mitarbeiterzahlen | C26: Teils aus Vorjahren oder Sekundärquellen. «(prüfen)» bzw. «uneinheitlich» = vor externer Verwendung verifizieren.
A27: Ansprechpersonen | C27: Keine Namen erfunden. Nur öffentlich genannte GL-Mitglieder mit Quelle. Die LinkedIn-Links öffnen eine
C28: Suche (Firma bzw. Firma + Zielfunktion), keine verifizierten Profile. Namen nach Prüfung in «Ansprechperson» eintragen.
A29: Relevanz / Warum | C29: Einschätzung aus Sicht mobiler Energie. Belegt sind nur die Fakten in «Anlass / Projekt» und «Grösse».
A30: Nicht aufgenommen | C30: Steiner AG (Nachlassstundung), Deltalis (RZ-Betrieb eingestellt). Ohne belastbare Quelle weggelassen:
C31: Dussmann, Kaufmann, Perenzia, Nine, Swiss Fort Knox, atNorth, Colt. BKW (Konzern), Axpo Grid, Swissgrid, AEW, EKT, EWL,
C32: St.Galler Stadtwerke sind reale Zielkunden, aber noch ohne geprüfte Kennzahlen: als nächste Ergänzung vorgesehen.
A33: Wettbewerb/Partner | C33: Kummler+Matter EVT vermietet eigene mobile Trafostationen: Partner und Wettbewerber zugleich.
A34: Vertraulich | C34: Interne Arbeitsliste. Nicht an Kunden weitergeben.

Sheet Listen
A1: Segment | B1: Kategorie | C1: Region | D1: Prio | E1: Kundenstatus | F1: Team | G1: Kernliste | H1: Skala | I1: Gebiet
A2: Installateure (60 %) | B2: Installateur | C2: West (Romandie) | D2: A | E2: Offen: CRM prüfen | F2: Burak | G2: Ja | H2: 1 | I2: West
A3: FM / EVU / Planer (20 %) | B3: Facility Manager | C3: Mittelland/Bern | D3: B | E3: A-Kunde | F3: Mauro | G3: Nein | H3: 2 | I3: Deutschschweiz
A4: GU/TU + Industrie (20 %) | B4: Stadtwerk/EVU | C4: Nordwestschweiz | D4: C | E4: Bestandskunde mit Potenzial | F4: Jörg | H4: 3 | I4: Tessin
B5: Elektroplaner | C5: Zürich | E5: Verlorener Kunde | F5: Roberto | H5: 4
B6: GU/TU | C6: Ostschweiz | E6: Potenzial / Aufbau | H6: 5
B7: Rechenzentrum | C7: Zentralschweiz
B8: Industrie | C8: Tessin
B9: Spital
B10: Infrastruktur
B11: Event
