Workbook

Sheet Start
A1: Top-Player Power Schweiz 2027
A2: Mobil in Time AG · Strom Schweiz | Stand 27.09.2026 | VERTRAULICH, intern
A4: So liest du die Liste
A5: 1. Nur Projekte, bei denen Power-Mieten über CHF 50'000 möglich sind. Schwerpunkt Rechenzentren, dazu Tunnel, Netz, Spitäler, Industrie, Events.
A6: 2. Potenzial = was das Projekt an Generator-, Lastbank- und BESS-Miete bringen kann (Szenario, blau, änderbar).
A7: 3. Erwartung 2027 = Potenzial × Anteil, der 2027 anfällt × Wahrscheinlichkeit, dass MiT gewinnt. Das ist die realistische Zahl.
A8: 4. Sätze sind Markt-Richtwerte (US, umgerechnet), keine MiT-Preise. Im Blatt «Annahmen» Spalte E eure Sätze eintragen: alles rechnet neu.
A9: 5. Trafo-Miete, Transport, Service und Treibstoff sind nicht eingerechnet: das Potenzial ist konservativ.
A11: Top-Player | C11: Potenzial brutto CHF | E11: Erwartung 2027 CHF | G11: davon Rechenzentren | I11: Prio A
A12: =COUNTA('Top-Player'!$D$5:$D$42) -> 38 | C12: =SUM('Top-Player'!$R$5:$R$42) -> 5280200 | E12: =SUM('Top-Player'!$U$5:$U$42) -> 735100 | G12: =SUMIF('Top-Player'!$C$5:$C$42,"Rechenzentrum",'Top-Player'!$U$5:$U$42) -> 171300 | I12: =COUNTIF('Top-Player'!$B$5:$B$42,"A") -> 9
A14: Nach Segment
A15: Segment | B15: Anzahl | C15: Potenzial brutto CHF | D15: Erwartung 2027 CHF | E15: Anteil an Erwartung
A16: Rechenzentrum | B16: =COUNTIF('Top-Player'!$C$5:$C$42,A16) -> 8 | C16: =SUMIF('Top-Player'!$C$5:$C$42,A16,'Top-Player'!$R$5:$R$42) -> 1761400 | D16: =SUMIF('Top-Player'!$C$5:$C$42,A16,'Top-Player'!$U$5:$U$42) -> 171300 | E16: =IF(SUM($D$16:$D$22)=0,0,D16/SUM($D$16:$D$22)) -> 0.23302952
A17: Infrastruktur | B17: =COUNTIF('Top-Player'!$C$5:$C$42,A17) -> 10 | C17: =SUMIF('Top-Player'!$C$5:$C$42,A17,'Top-Player'!$R$5:$R$42) -> 1702100 | D17: =SUMIF('Top-Player'!$C$5:$C$42,A17,'Top-Player'!$U$5:$U$42) -> 248100 | E17: =IF(SUM($D$16:$D$22)=0,0,D17/SUM($D$16:$D$22)) -> 0.3375051
A18: Netz / Unterwerk | B18: =COUNTIF('Top-Player'!$C$5:$C$42,A18) -> 5 | C18: =SUMIF('Top-Player'!$C$5:$C$42,A18,'Top-Player'!$R$5:$R$42) -> 313700 | D18: =SUMIF('Top-Player'!$C$5:$C$42,A18,'Top-Player'!$U$5:$U$42) -> 55400 | E18: =IF(SUM($D$16:$D$22)=0,0,D18/SUM($D$16:$D$22)) -> 0.075363896
A19: Spital | B19: =COUNTIF('Top-Player'!$C$5:$C$42,A19) -> 3 | C19: =SUMIF('Top-Player'!$C$5:$C$42,A19,'Top-Player'!$R$5:$R$42) -> 332400 | D19: =SUMIF('Top-Player'!$C$5:$C$42,A19,'Top-Player'!$U$5:$U$42) -> 65100 | E19: =IF(SUM($D$16:$D$22)=0,0,D19/SUM($D$16:$D$22)) -> 0.08855938
A20: Industrie | B20: =COUNTIF('Top-Player'!$C$5:$C$42,A20) -> 4 | C20: =SUMIF('Top-Player'!$C$5:$C$42,A20,'Top-Player'!$R$5:$R$42) -> 389400 | D20: =SUMIF('Top-Player'!$C$5:$C$42,A20,'Top-Player'!$U$5:$U$42) -> 69700 | E20: =IF(SUM($D$16:$D$22)=0,0,D20/SUM($D$16:$D$22)) -> 0.094817032
A21: Event | B21: =COUNTIF('Top-Player'!$C$5:$C$42,A21) -> 3 | C21: =SUMIF('Top-Player'!$C$5:$C$42,A21,'Top-Player'!$R$5:$R$42) -> 231700 | D21: =SUMIF('Top-Player'!$C$5:$C$42,A21,'Top-Player'!$U$5:$U$42) -> 24100 | E21: =IF(SUM($D$16:$D$22)=0,0,D21/SUM($D$16:$D$22)) -> 0.032784655
A22: Kanal-Partner | B22: =COUNTIF('Top-Player'!$C$5:$C$42,A22) -> 5 | C22: =SUMIF('Top-Player'!$C$5:$C$42,A22,'Top-Player'!$R$5:$R$42) -> 549500 | D22: =SUMIF('Top-Player'!$C$5:$C$42,A22,'Top-Player'!$U$5:$U$42) -> 101400 | E22: =IF(SUM($D$16:$D$22)=0,0,D22/SUM($D$16:$D$22)) -> 0.13794042
A23: Total | B23: =SUM(B16:B22) -> 38 | C23: =SUM(C16:C22) -> 5280200 | D23: =SUM(D16:D22) -> 735100
A25: Top 10 nach Erwartung 2027
A26: Rang | B26: Projekt / Kunde | C26: Segment | D26: Erwartung 2027 CHF | E26: Potenzial CHF | F26: Prio
A27: 1 | B27: =INDEX('Top-Player'!$D$5:$D$42,MATCH(1,'Top-Player'!$A$5:$A$42,0)) -> 2. Gotthardröhre | C27: =INDEX('Top-Player'!$C$5:$C$42,MATCH(1,'Top-Player'!$A$5:$A$42,0)) -> Infrastruktur | D27: =INDEX('Top-Player'!$U$5:$U$42,MATCH(1,'Top-Player'!$A$5:$A$42,0)) -> 66100 | E27: =INDEX('Top-Player'!$R$5:$R$42,MATCH(1,'Top-Player'!$A$5:$A$42,0)) -> 440900 | F27: =INDEX('Top-Player'!$B$5:$B$42,MATCH(1,'Top-Player'!$A$5:$A$42,0)) -> A
A28: 2 | B28: =INDEX('Top-Player'!$D$5:$D$42,MATCH(2,'Top-Player'!$A$5:$A$42,0)) -> Sisikoner Tunnel (Neue Axenstrasse) | C28: =INDEX('Top-Player'!$C$5:$C$42,MATCH(2,'Top-Player'!$A$5:$A$42,0)) -> Infrastruktur | D28: =INDEX('Top-Player'!$U$5:$U$42,MATCH(2,'Top-Player'!$A$5:$A$42,0)) -> 66100 | E28: =INDEX('Top-Player'!$R$5:$R$42,MATCH(2,'Top-Player'!$A$5:$A$42,0)) -> 330700 | F28: =INDEX('Top-Player'!$B$5:$B$42,MATCH(2,'Top-Player'!$A$5:$A$42,0)) -> A
A29: 3 | B29: =INDEX('Top-Player'!$D$5:$D$42,MATCH(3,'Top-Player'!$A$5:$A$42,0)) -> Kantonsspital Aarau «Dreiklang» | C29: =INDEX('Top-Player'!$C$5:$C$42,MATCH(3,'Top-Player'!$A$5:$A$42,0)) -> Spital | D29: =INDEX('Top-Player'!$U$5:$U$42,MATCH(3,'Top-Player'!$A$5:$A$42,0)) -> 38000 | E29: =INDEX('Top-Player'!$R$5:$R$42,MATCH(3,'Top-Player'!$A$5:$A$42,0)) -> 151900 | F29: =INDEX('Top-Player'!$B$5:$B$42,MATCH(3,'Top-Player'!$A$5:$A$42,0)) -> A
A30: 4 | B30: =INDEX('Top-Player'!$D$5:$D$42,MATCH(4,'Top-Player'!$A$5:$A$42,0)) -> STACK ZUR02 Beringen | C30: =INDEX('Top-Player'!$C$5:$C$42,MATCH(4,'Top-Player'!$A$5:$A$42,0)) -> Rechenzentrum | D30: =INDEX('Top-Player'!$U$5:$U$42,MATCH(4,'Top-Player'!$A$5:$A$42,0)) -> 37000 | E30: =INDEX('Top-Player'!$R$5:$R$42,MATCH(4,'Top-Player'!$A$5:$A$42,0)) -> 205700 | F30: =INDEX('Top-Player'!$B$5:$B$42,MATCH(4,'Top-Player'!$A$5:$A$42,0)) -> A
A31: 5 | B31: =INDEX('Top-Player'!$D$5:$D$42,MATCH(5,'Top-Player'!$A$5:$A$42,0)) -> Bachem Werk Sisslerfeld | C31: =INDEX('Top-Player'!$C$5:$C$42,MATCH(5,'Top-Player'!$A$5:$A$42,0)) -> Industrie | D31: =INDEX('Top-Player'!$U$5:$U$42,MATCH(5,'Top-Player'!$A$5:$A$42,0)) -> 33900 | E31: =INDEX('Top-Player'!$R$5:$R$42,MATCH(5,'Top-Player'!$A$5:$A$42,0)) -> 169600 | F31: =INDEX('Top-Player'!$B$5:$B$42,MATCH(5,'Top-Player'!$A$5:$A$42,0)) -> A
A32: 6 | B32: =INDEX('Top-Player'!$D$5:$D$42,MATCH(6,'Top-Player'!$A$5:$A$42,0)) -> Pumpspeicherwerk Grimsel 4 | C32: =INDEX('Top-Player'!$C$5:$C$42,MATCH(6,'Top-Player'!$A$5:$A$42,0)) -> Infrastruktur | D32: =INDEX('Top-Player'!$U$5:$U$42,MATCH(6,'Top-Player'!$A$5:$A$42,0)) -> 33100 | E32: =INDEX('Top-Player'!$R$5:$R$42,MATCH(6,'Top-Player'!$A$5:$A$42,0)) -> 220400 | F32: =INDEX('Top-Player'!$B$5:$B$42,MATCH(6,'Top-Player'!$A$5:$A$42,0)) -> A
A33: 7 | B33: =INDEX('Top-Player'!$D$5:$D$42,MATCH(7,'Top-Player'!$A$5:$A$42,0)) -> Vantage ZRH3 Volketswil | C33: =INDEX('Top-Player'!$C$5:$C$42,MATCH(7,'Top-Player'!$A$5:$A$42,0)) -> Rechenzentrum | D33: =INDEX('Top-Player'!$U$5:$U$42,MATCH(7,'Top-Player'!$A$5:$A$42,0)) -> 28000 | E33: =INDEX('Top-Player'!$R$5:$R$42,MATCH(7,'Top-Player'!$A$5:$A$42,0)) -> 700200 | F33: =INDEX('Top-Player'!$B$5:$B$42,MATCH(7,'Top-Player'!$A$5:$A$42,0)) -> A
A34: 8 | B34: =INDEX('Top-Player'!$D$5:$D$42,MATCH(8,'Top-Player'!$A$5:$A$42,0)) -> ETAVIS / VINCI Energies (Rahmen) | C34: =INDEX('Top-Player'!$C$5:$C$42,MATCH(8,'Top-Player'!$A$5:$A$42,0)) -> Kanal-Partner | D34: =INDEX('Top-Player'!$U$5:$U$42,MATCH(8,'Top-Player'!$A$5:$A$42,0)) -> 27800 | E34: =INDEX('Top-Player'!$R$5:$R$42,MATCH(8,'Top-Player'!$A$5:$A$42,0)) -> 138900 | F34: =INDEX('Top-Player'!$B$5:$B$42,MATCH(8,'Top-Player'!$A$5:$A$42,0)) -> A
A35: 9 | B35: =INDEX('Top-Player'!$D$5:$D$42,MATCH(9,'Top-Player'!$A$5:$A$42,0)) -> Burkhalter Gruppe (Rahmen) | C35: =INDEX('Top-Player'!$C$5:$C$42,MATCH(9,'Top-Player'!$A$5:$A$42,0)) -> Kanal-Partner | D35: =INDEX('Top-Player'!$U$5:$U$42,MATCH(9,'Top-Player'!$A$5:$A$42,0)) -> 25400 | E35: =INDEX('Top-Player'!$R$5:$R$42,MATCH(9,'Top-Player'!$A$5:$A$42,0)) -> 127200 | F35: =INDEX('Top-Player'!$B$5:$B$42,MATCH(9,'Top-Player'!$A$5:$A$42,0)) -> A
A36: 10 | B36: =INDEX('Top-Player'!$D$5:$D$42,MATCH(10,'Top-Player'!$A$5:$A$42,0)) -> Green Metro-Campus Dielsdorf (nächstes RZ) | C36: =INDEX('Top-Player'!$C$5:$C$42,MATCH(10,'Top-Player'!$A$5:$A$42,0)) -> Rechenzentrum | D36: =INDEX('Top-Player'!$U$5:$U$42,MATCH(10,'Top-Player'!$A$5:$A$42,0)) -> 23500 | E36: =INDEX('Top-Player'!$R$5:$R$42,MATCH(10,'Top-Player'!$A$5:$A$42,0)) -> 156900 | F36: =INDEX('Top-Player'!$B$5:$B$42,MATCH(10,'Top-Player'!$A$5:$A$42,0)) -> B
A39: Blätter in dieser Datei
A40: Top-Player | B40: Die 38 Projekte mit Potenzial, Szenario, Kontakt und nächstem Schritt
A41: 90-Tage-Plan | B41: Aufgaben Okt. 2026 bis Jan. 2027 mit Status zum Abhaken
A42: Rechenzentren | B42: Alle RZ-Projekte 2026-2028 mit MW, Zeitplan, GU, Netzanschluss
A43: Produktbedarf | B43: Welches Segment welches Power-Produkt braucht
A44: Portfolio | B44: Was wir vermieten, Kennwerte, Cross-Sell
A45: Annahmen | B45: Mietsätze, Kurs, Schwellen: hier MiT-Sätze eintragen
A46: Beobachten | B46: Unter CHF 50'000 oder noch zu unsicher
...

Sheet Top-Player
A1: Top-Player Power Schweiz 2027
A2: Stand 27.09.2026 | 38 Projekte mit Potenzial über CHF 50'000 | sortiert nach Erwartung 2027 | VERTRAULICH
A3: Blaue Zahlen = Szenario-Annahmen, änderbar. Potenzial = Generator (MVA × Wochen × Satz) + Lastbank (MW × Wochen × Satz) + BESS (MW × Monate × Satz). Sätze im Blatt «Annahmen».
A4: Rang | B4: Prio | C4: Segment | D4: Projekt / Kunde | E4: Einstieg über | F4: Ort | G4: Kt. | H4: Region | I4: Sprache | J4: Anlass und Zeitfenster | K4: Power-Bedarf | L4: Generator MVA | M4: Generator Wochen | N4: Lastbank MW | O4: Lastbank Wochen | P4: BESS MW | Q4: BESS Monate | R4: Potenzial Power CHF | S4: Anteil 2027 | T4: Wahrschein-lichkeit | U4: Erwartung 2027 CHF | V4: Cross-Sell Wärme / Kälte | W4: Nächster Schritt | X4: Verantwortlich | Y4: Status MiT (CRM) | Z4: Zielrolle | AA4: Ansprechperson (Name) | AB4: Kontakt (Tel. / E-Mail) | AC4: Letzter Kontakt | AD4: Nächster Termin | AE4: Quelle | AF4: Hinweis / Annahme
A5: =RANK(U5,$U$5:$U$42)+COUNTIF($U$5:U5,U5)-1 -> 1 | B5: =IF(U5>=Annahmen!$B$24,"A",IF(U5>=Annahmen!$B$25,"B","C")) -> A | C5: Infrastruktur | D5: 2. Gotthardröhre | E5: ASTRA; Marti-Gruppe (Hauptlos Süd) | F5: Göschenen / Airolo | G5: UR/TI | H5: Tessin | I5: DE/IT | J5: CHF 2,14 Mrd., Vortrieb bis ca. 2029/30 | K5: Backup-Generatoren für Vortrieb und Lüftung, Lastspitzen | L5: 2 | M5: 52 | N5: 0 | O5: 0 | P5: 0 | Q5: 0 | R5: =ROUND(L5*M5*Annahmen!$F$9+N5*O5*Annahmen!$F$12+P5*Q5*Annahmen!$F$15,-2) -> 440900 | S5: 1 | T5: 0.15 | U5: =ROUND(R5*S5*T5,-2) -> 66100 | V5: Bauheizung Portalinstallationen | W5: Marti Baustellenleitung Airolo: Backup-Konzept und Wartungsfenster | Y5: Offen: CRM prüfen | Z5: Bauleitung ARGE, Baustelleneinrichtung, Einkauf | AE5: Link
A6: =RANK(U6,$U$5:$U$42)+COUNTIF($U$5:U6,U6)-1 -> 2 | B6: =IF(U6>=Annahmen!$B$24,"A",IF(U6>=Annahmen!$B$25,"B","C")) -> A | C6: Infrastruktur | D6: Sisikoner Tunnel (Neue Axenstrasse) | E6: ARGE Implenia/Frutiger; Bauherr ASTRA | F6: Sisikon | G6: UR | H6: Zentralschweiz | I6: DE | J6: über CHF 430 Mio., Bau Okt. 2025 bis 2034 | K6: Baustrom und Netzersatz für Lüftung | L6: 1.5 | M6: 52 | N6: 0 | O6: 0 | P6: 0 | Q6: 0 | R6: =ROUND(L6*M6*Annahmen!$F$9+N6*O6*Annahmen!$F$12+P6*Q6*Annahmen!$F$15,-2) -> 330700 | S6: 1 | T6: 0.2 | U6: =ROUND(R6*S6*T6,-2) -> 66100 | V6: Bauheizung, Entfeuchtung im Tunnel | W6: ARGE-Bauleitung: Rahmen für Baustrom-Backup | Y6: Offen: CRM prüfen | Z6: Bauleitung ARGE, Baustelleneinrichtung, Einkauf | AE6: Link
A7: =RANK(U7,$U$5:$U$42)+COUNTIF($U$5:U7,U7)-1 -> 3 | B7: =IF(U7>=Annahmen!$B$24,"A",IF(U7>=Annahmen!$B$25,"B","C")) -> A | C7: Spital | D7: Kantonsspital Aarau «Dreiklang» | E7: KSA; TU Implenia | F7: Aarau | G7: AG | H7: Nordwestschweiz | I7: DE | J7: ca. CHF 750 Mio., Übergabe 15.09.2026, Umzug Jan. 2027, danach Rückbau | K7: NEA-Lasttest mit Lastbank, Netzersatz beim Umzug, Baustrom Rückbau | L7: 1 | M7: 34 | N7: 2 | O7: 2 | P7: 0 | Q7: 0 | R7: =ROUND(L7*M7*Annahmen!$F$9+N7*O7*Annahmen!$F$12+P7*Q7*Annahmen!$F$15,-2) -> 151900 | S7: 1 | T7: 0.25 | U7: =ROUND(R7*S7*T7,-2) -> 38000 | V7: Klima/Kühlung während Umzug | W7: KSA Technik und Implenia: NEA-Test und Rückbau-Baustrom jetzt anbieten | Y7: Offen: CRM prüfen | Z7: Leiter Technik und Betrieb, TU-Projektleitung | AE7: Link
A8: =RANK(U8,$U$5:$U$42)+COUNTIF($U$5:U8,U8)-1 -> 4 | B8: =IF(U8>=Annahmen!$B$24,"A",IF(U8>=Annahmen!$B$25,"B","C")) -> A | C8: Rechenzentrum | D8: STACK ZUR02 Beringen | E8: STACK Infrastructure; PM MBA Projektmanagement | F8: Beringen | G8: SH | H8: Ostschweiz | I8: EN/DE | J8: 36 MW IT, Betriebsstart Herbst 2026, neues Unterwerk vom Betreiber finanziert | K8: Lastbank für IST je Data Hall, Generator-Überbrückung falls Unterwerk verzögert, Tankcontainer | L8: 4 | M8: 8 | N8: 12 | O8: 3 | P8: 0 | Q8: 0 | R8: =ROUND(L8*M8*Annahmen!$F$9+N8*O8*Annahmen!$F$12+P8*Q8*Annahmen!$F$15,-2) -> 205700 | S8: 0.6 | T8: 0.3 | U8: =ROUND(R8*S8*T8,-2) -> 37000 | V8: Temporäre Kühlung beim IST, falls Kälte nicht fertig | W8: Commissioning-Manager STACK und MBA sofort anfragen: IST-Plan der nächsten Phasen | Y8: Offen: CRM prüfen | Z8: Commissioning-Manager, Construction Manager, Critical Facility Ops | AE8: Link | AF8: Hot Lead. Phase 1 läuft evtl. schon, Ziel sind Folgephasen 2027.
A9: =RANK(U9,$U$5:$U$42)+COUNTIF($U$5:U9,U9)-1 -> 5 | B9: =IF(U9>=Annahmen!$B$24,"A",IF(U9>=Annahmen!$B$25,"B","C")) -> A | C9: Industrie | D9: Bachem Werk Sisslerfeld | E9: Bachem | F9: Eiken | G9: AG | H9: Nordwestschweiz | I9: DE | J9: über CHF 500 Mio., Greenfield, Bau bis ca. 2030 | K9: Baustrom bis Netzanschluss, später Qualifizierung | L9: 1 | M9: 40 | N9: 0 | O9: 0 | P9: 0 | Q9: 0 | R9: =ROUND(L9*M9*Annahmen!$F$9+N9*O9*Annahmen!$F$12+P9*Q9*Annahmen!$F$15,-2) -> 169600 | S9: 1 | T9: 0.2 | U9: =ROUND(R9*S9*T9,-2) -> 33900 | V9: Bauheizung, Bautrocknung | W9: Bachem Engineering und GU: Baustromkonzept | Y9: Offen: CRM prüfen | Z9: Engineering / Utilities, Technischer Einkauf | AE9: Link
A10: =RANK(U10,$U$5:$U$42)+COUNTIF($U$5:U10,U10)-1 -> 6 | B10: =IF(U10>=Annahmen!$B$24,"A",IF(U10>=Annahmen!$B$25,"B","C")) -> A | C10: Infrastruktur | D10: Pumpspeicherwerk Grimsel 4 | E10: KWO (BKW-Beteiligung) | F10: Grimsel | G10: BE | H10: Mittelland/Bern | I10: DE | J10: CHF 300 Mio., 2 × 84 MW, Bau Juni 2026 bis 2032 | K10: Baustrom und Backup für hochalpine Untertagebaustelle | L10: 1 | M10: 52 | N10: 0 | O10: 0 | P10: 0 | Q10: 0 | R10: =ROUND(L10*M10*Annahmen!$F$9+N10*O10*Annahmen!$F$12+P10*Q10*Annahmen!$F$15,-2) -> 220400 | S10: 1 | T10: 0.15 | U10: =ROUND(R10*S10*T10,-2) -> 33100 | V10: Bauheizung, Entfeuchtung | W10: KWO Projektleitung: Backup-Konzept Kaverne | Y10: Offen: CRM prüfen | Z10: Bauleitung ARGE, Baustelleneinrichtung, Einkauf | AE10: Link | AF10: BKW-Nähe: Konkurrenzlage prüfen.
A11: =RANK(U11,$U$5:$U$42)+COUNTIF($U$5:U11,U11)-1 -> 7 | B11: =IF(U11>=Annahmen!$B$24,"A",IF(U11>=Annahmen!$B$25,"B","C")) -> A | C11: Rechenzentrum | D11: Vantage ZRH3 Volketswil | E11: Vantage Data Centers | F11: Volketswil | G11: ZH | H11: Zürich | I11: EN | J11: 100 bis 150 MW Campus, Phase 1 live 2028, neue Unterwerke nötig, Engpass im Vornetz | K11: Generator/BESS-Überbrückung bis Netzanschluss, später Lastbank-IST | L11: 5 | M11: 26 | N11: 0 | O11: 0 | P11: 1 | Q11: 6 | R11: =ROUND(L11*M11*Annahmen!$F$9+N11*O11*Annahmen!$F$12+P11*Q11*Annahmen!$F$15,-2) -> 700200 | S11: 0.4 | T11: 0.1 | U11: =ROUND(R11*S11*T11,-2) -> 28000 | V11: Temporäre Kühlung, Abwärme-Thema mit Energie 360° | W11: Beziehung jetzt aufbauen, Beschaffung oft EMEA-zentral | Y11: Offen: CRM prüfen | Z11: Commissioning-Manager, Construction Manager, Critical Facility Ops | AE11: Link | AF11: Grösstes Einzelpotenzial, tiefe Wahrscheinlichkeit. Quellen: EKZ blue (2025), DCD, Energie 360°; genauen Artikel-Link ergänzen.
A12: =RANK(U12,$U$5:$U$42)+COUNTIF($U$5:U12,U12)-1 -> 8 | B12: =IF(U12>=Annahmen!$B$24,"A",IF(U12>=Annahmen!$B$25,"B","C")) -> A | C12: Kanal-Partner | D12: ETAVIS / VINCI Energies (Rahmen) | E12: VINCI Energies: ETAVIS, Actemium, Gfeller | F12: Zürich | G12: ZH | H12: Zürich | I12: DE/FR/IT | J12: >2'400 MA ETAVIS; Infrastruktur, RZ, Industrie | K12: Baustrom, Lastbank bei Inbetriebnahmen | L12: 1 | M12: 30 | N12: 1 | O12: 6 | P12: 0 | Q12: 0 | R12: =ROUND(L12*M12*Annahmen!$F$9+N12*O12*Annahmen!$F$12+P12*Q12*Annahmen!$F$15,-2) -> 138900 | S12: 1 | T12: 0.2 | U12: =ROUND(R12*S12*T12,-2) -> 27800 | V12: Bauheizung | W12: VINCI Einkauf CH: Rahmen für Power | Y12: Offen: CRM prüfen | Z12: Einkauf Gruppe, Bereichsleiter Grossprojekte | AE12: Link | AF12: Rahmenvolumen ist Annahme.
A13: =RANK(U13,$U$5:$U$42)+COUNTIF($U$5:U13,U13)-1 -> 9 | B13: =IF(U13>=Annahmen!$B$24,"A",IF(U13>=Annahmen!$B$25,"B","C")) -> A | C13: Kanal-Partner | D13: Burkhalter Gruppe (Rahmen) | E13: Burkhalter Holding, 83 Gesellschaften | F13: Zürich | G13: ZH | H13: Zürich | I13: DE/FR/IT | J13: 5'356 FTE, 169 Standorte (31.12.2025) | K13: Baustrom und NEA-Tests über viele Töchter | L13: 1 | M13: 30 | N13: 0 | O13: 0 | P13: 0 | Q13: 0 | R13: =ROUND(L13*M13*Annahmen!$F$9+N13*O13*Annahmen!$F$12+P13*Q13*Annahmen!$F$15,-2) -> 127200 | S13: 1 | T13: 0.2 | U13: =ROUND(R13*S13*T13,-2) -> 25400 | V13: Bauheizung, Trocknung über dieselben Baustellen | W13: Zentraler Einkauf: Rahmenvertrag, dann Töchter regional | Y13: Offen: CRM prüfen | Z13: Einkauf Gruppe, Bereichsleiter Grossprojekte | AE13: Link | AF13: Rahmenvolumen (MVA-Wochen) ist Annahme.
A14: =RANK(U14,$U$5:$U$42)+COUNTIF($U$5:U14,U14)-1 -> 10 | B14: =IF(U14>=Annahmen!$B$24,"A",IF(U14>=Annahmen!$B$25,"B","C")) -> B | C14: Rechenzentrum | D14: Green Metro-Campus Dielsdorf (nächstes RZ) | E14: Green; PM MBA Projektmanagement | F14: Dielsdorf | G14: ZH | H14: Zürich | I14: DE | J14: Baustart weiteres RZ 2026, Campus-Anschluss 50 MW über neues EKZ-UW | K14: Baustrom-Generator, später Lastbank für IST (2028) | L14: 1 | M14: 26 | N14: 6 | O14: 4 | P14: 0 | Q14: 0 | R14: =ROUND(L14*M14*Annahmen!$F$9+N14*O14*Annahmen!$F$12+P14*Q14*Annahmen!$F$15,-2) -> 156900 | S14: 0.6 | T14: 0.25 | U14: =ROUND(R14*S14*T14,-2) -> 23500 | V14: Bauheizung und Bautrocknung im Winter | W14: Mit dem Lupfig-Kontakt bei Green gleich mitverhandeln | Y14: Offen: CRM prüfen | Z14: Commissioning-Manager, Construction Manager, Critical Facility Ops | AE14: Link
A15: =RANK(U15,$U$5:$U$42)+COUNTIF($U$5:U15,U15)-1 -> 11 | B15: =IF(U15>=Annahmen!$B$24,"A",IF(U15>=Annahmen!$B$25,"B","C")) -> B | C15: Rechenzentrum | D15: NorthC Arlesheim (uptownBasel) | E15: NorthC Datacenters | F15: Arlesheim | G15: BL | H15: Nordwestschweiz | I15: DE/EN | J15: 4,5 MW IT (Ausbau 7,5), Betrieb ab Mitte 2027, NEA mit HVO | K15: Lastbank für IST, Generator für Tests | L15: 1 | M15: 12 | N15: 4.5 | O15: 3 | P15: 0 | Q15: 0 | R15: =ROUND(L15*M15*Annahmen!$F$9+N15*O15*Annahmen!$F$12+P15*Q15*Annahmen!$F$15,-2) -> 77100 | S15: 1 | T15: 0.3 | U15: =ROUND(R15*S15*T15,-2) -> 23100 | V15: HVO-Generatoren passen zum Nachhaltigkeitskonzept | W15: NorthC Projektleitung CH: IST-Termin 2027 und Lastbank-Bedarf klären | Y15: Offen: CRM prüfen | Z15: Commissioning-Manager, Construction Manager, Critical Facility Ops | AE15: Link
A16: =RANK(U16,$U$5:$U$42)+COUNTIF($U$5:U16,U16)-1 -> 12 | B16: =IF(U16>=Annahmen!$B$24,"A",IF(U16>=Annahmen!$B$25,"B","C")) -> B | C16: Kanal-Partner | D16: Equans Switzerland (Rahmen) | E16: Bouygues / Equans | F16: Zürich | G16: ZH | H16: Zürich | I16: DE/FR | J16: >1'600 MA, Energie, Verkehr, Industrie, FM | K16: Netzersatz, NEA-Tests, Baustrom | L16: 1 | M16: 25 | N16: 1 | O16: 4 | P16: 0 | Q16: 0 | R16: =ROUND(L16*M16*Annahmen!$F$9+N16*O16*Annahmen!$F$12+P16*Q16*Annahmen!$F$15,-2) -> 113800 | S16: 1 | T16: 0.2 | U16: =ROUND(R16*S16*T16,-2) -> 22800 | V16: Heizung/Kühlung im FM-Geschäft | W16: Equans Einkauf und FM-Leitung gemeinsam | Y16: Offen: CRM prüfen | Z16: Einkauf Gruppe, Bereichsleiter Grossprojekte | AE16: Link | AF16: Rahmenvolumen ist Annahme.
A17: =RANK(U17,$U$5:$U$42)+COUNTIF($U$5:U17,U17)-1 -> 13 | B17: =IF(U17>=Annahmen!$B$24,"A",IF(U17>=Annahmen!$B$25,"B","C")) -> B | C17: Rechenzentrum | D17: Digital Realty ZUR4 Glattbrugg | E17: Digital Realty (GU noch unbekannt) | F17: Opfikon-Glattbrugg | G17: ZH | H17: Zürich | I17: EN | J17: 15 MW IT, Spatenstich 27.08.2026, Fertigstellung 2028, High-Density/KI | K17: Baustrom 2027, Lastbank für IST 2028 (≈ IT-Last) | L17: 1 | M17: 26 | N17: 15 | O17: 4 | P17: 0 | Q17: 0 | R17: =ROUND(L17*M17*Annahmen!$F$9+N17*O17*Annahmen!$F$12+P17*Q17*Annahmen!$F$15,-2) -> 227000 | S17: 0.45 | T17: 0.2 | U17: =ROUND(R17*S17*T17,-2) -> 20400 | V17: Bauheizung Winter 2026/27, Kühlung beim IST | W17: GU/Elektro über Baugesuch und simap ermitteln, dann Baustrom offerieren | Y17: Offen: CRM prüfen | Z17: Commissioning-Manager, Construction Manager, Critical Facility Ops | AE17: Link | AF17: Deck auf Englisch klären.
A18: =RANK(U18,$U$5:$U$42)+COUNTIF($U$5:U18,U18)-1 -> 14 | B18: =IF(U18>=Annahmen!$B$24,"A",IF(U18>=Annahmen!$B$25,"B","C")) -> B | C18: Infrastruktur | D18: Bahnhof Zürich Stadelhofen (4. Gleis) | E18: SBB | F18: Zürich | G18: ZH | H18: Zürich | I18: DE | J18: CHF 1,1 Mrd., Baustart 2027, ca. 10 Jahre | K18: Leise BESS für Nachtarbeit, Netzersatz | L18: 0.5 | M18: 26 | N18: 0 | O18: 0 | P18: 0.5 | Q18: 6 | R18: =ROUND(L18*M18*Annahmen!$F$9+N18*O18*Annahmen!$F$12+P18*Q18*Annahmen!$F$15,-2) -> 129600 | S18: 1 | T18: 0.15 | U18: =ROUND(R18*S18*T18,-2) -> 19400 | V18: Bautrocknung | W18: BESS-Hybrid als leise Lösung für Innenstadt positionieren | Y18: Offen: CRM prüfen | Z18: Bauleitung ARGE, Baustelleneinrichtung, Einkauf | AE18: Link | AF18: Öffentliche Beschaffung.
A19: =RANK(U19,$U$5:$U$42)+COUNTIF($U$5:U19,U19)-1 -> 15 | B19: =IF(U19>=Annahmen!$B$24,"A",IF(U19>=Annahmen!$B$25,"B","C")) -> B | C19: Netz / Unterwerk | D19: CKW: UW Sursee und Trafostations-Erneuerung | E19: CKW | F19: Sursee / Zentralschweiz | G19: LU | H19: Zentralschweiz | I19: DE | J19: UW Sursee IBN Frühling 2027 (CHF 11 Mio.), ca. 2'500 Trafostationen im Netz | K19: Netzersatz bei Umschaltungen, Generatoren für Trafostations-Tausch | L19: 1 | M19: 18 | N19: 0 | O19: 0 | P19: 0 | Q19: 0 | R19: =ROUND(L19*M19*Annahmen!$F$9+N19*O19*Annahmen!$F$12+P19*Q19*Annahmen!$F$15,-2) -> 76300 | S19: 1 | T19: 0.25 | U19: =ROUND(R19*S19*T19,-2) -> 19100 | W19: CKW Netzbau: Rahmen für Netzersatz beim Stationstausch | Y19: Offen: CRM prüfen | Z19: Leiter Netzbau / Unterwerke, Projektleiter UW | AE19: Link | AF19: Szenario: UW Sursee 2 MVA × 4 Wo plus Stationstausch 0,5 MVA × 20 Wo = ca. 18 MVA-Wochen.
A20: =RANK(U20,$U$5:$U$42)+COUNTIF($U$5:U20,U20)-1 -> 16 | B20: =IF(U20>=Annahmen!$B$24,"A",IF(U20>=Annahmen!$B$25,"B","C")) -> B | C20: Spital | D20: USZ Campus MITTE1|2 | E20: USZ; b+p baurealisation | F20: Zürich | G20: ZH | H20: Zürich | I20: DE | J20: CHF 950 Mio., Bau laufend, Betrieb 2031 | K20: Netzersatz und BESS bei Umschaltungen im Vollbetrieb | L20: 1 | M20: 12 | N20: 0 | O20: 0 | P20: 0.5 | Q20: 6 | R20: =ROUND(L20*M20*Annahmen!$F$9+N20*O20*Annahmen!$F$12+P20*Q20*Annahmen!$F$15,-2) -> 125400 | S20: 1 | T20: 0.15 | U20: =ROUND(R20*S20*T20,-2) -> 18800 | V20: Klima/Kühlung Provisorien | W20: USZ Technik: Umschaltkonzept 2027 | Y20: Offen: CRM prüfen | Z20: Leiter Technik und Betrieb, TU-Projektleitung | AE20: Link | AF20: Öffentliche Beschaffung.
A21: =RANK(U21,$U$5:$U$42)+COUNTIF($U$5:U21,U21)-1 -> 17 | B21: =IF(U21>=Annahmen!$B$24,"A",IF(U21>=Annahmen!$B$25,"B","C")) -> B | C21: Netz / Unterwerk | D21: Axpo UW Niederurnen (Gesamterneuerung) | E21: Axpo Grid | F21: Niederurnen | G21: GL | H21: Ostschweiz | I21: DE | J21: 110/16 kV, ab Frühling 2026 ca. 3 Jahre, etappenweise | K21: Netzersatz und Eigenbedarf bei Umschaltungen, mobiler Trafo (Wert fehlt) | L21: 2 | M21: 8 | N21: 0 | O21: 0 | P21: 0 | Q21: 0 | R21: =ROUND(L21*M21*Annahmen!$F$9+N21*O21*Annahmen!$F$12+P21*Q21*Annahmen!$F$15,-2) -> 67800 | S21: 1 | T21: 0.25 | U21: =ROUND(R21*S21*T21,-2) -> 17000 | W21: Axpo Grid Projektleitung: Etappenplan 2027 | Y21: Offen: CRM prüfen | Z21: Leiter Netzbau / Unterwerke, Projektleiter UW | AE21: Link | AF21: Trafo-Miete nicht eingerechnet.
A22: =RANK(U22,$U$5:$U$42)+COUNTIF($U$5:U22,U22)-1 -> 18 | B22: =IF(U22>=Annahmen!$B$24,"A",IF(U22>=Annahmen!$B$25,"B","C")) -> B | C22: Infrastruktur | D22: Genève Aéroport Cap2030 / Plateforme multimodale | E22: Genève Aéroport; Losinger Marazzi (LMB) | F22: Genf | G22: GE | H22: West (Romandie) | I22: FR | J22: ca. CHF 560 bis 640 Mio., Multimodal 2026-2029, Terminal ab 2027 | K22: Baustrom und USV/BESS im laufenden Terminalbetrieb | L22: 1 | M22: 26 | N22: 0 | O22: 0 | P22: 0.5 | Q22: 6 | R22: =ROUND(L22*M22*Annahmen!$F$9+N22*O22*Annahmen!$F$12+P22*Q22*Annahmen!$F$15,-2) -> 184700 | S22: 0.6 | T22: 0.15 | U22: =ROUND(R22*S22*T22,-2) -> 16600 | V22: Bauheizung, Klima Provisorien | W22: Losinger Marazzi Bauleitung GVA, Französisch | Y22: Offen: CRM prüfen | Z22: Bauleitung ARGE, Baustelleneinrichtung, Einkauf | AE22: Link
A23: =RANK(U23,$U$5:$U$42)+COUNTIF($U$5:U23,U23)-1 -> 19 | B23: =IF(U23>=Annahmen!$B$24,"A",IF(U23>=Annahmen!$B$25,"B","C")) -> B | C23: Infrastruktur | D23: Brüttener Tunnel (MehrSpur Zürich-Winterthur) | E23: SBB | F23: Bassersdorf / Dietlikon | G23: ZH | H23: Zürich | I23: DE | J23: Hauptarbeiten ab 2027, TBM ab 2029 | K23: Installationsplätze vor Netzanschluss: Baustrom | L23: 1 | M23: 26 | N23: 0 | O23: 0 | P23: 0 | Q23: 0 | R23: =ROUND(L23*M23*Annahmen!$F$9+N23*O23*Annahmen!$F$12+P23*Q23*Annahmen!$F$15,-2) -> 110200 | S23: 1 | T23: 0.15 | U23: =ROUND(R23*S23*T23,-2) -> 16500 | V23: Bauheizung | W23: SBB Infrastruktur Projekte: Baustrom-Ausschreibung verfolgen (simap) | Y23: Offen: CRM prüfen | Z23: Bauleitung ARGE, Baustelleneinrichtung, Einkauf | AE23: Link | AF23: Öffentliche Beschaffung.
A24: =RANK(U24,$U$5:$U$42)+COUNTIF($U$5:U24,U24)-1 -> 20 | B24: =IF(U24>=Annahmen!$B$24,"A",IF(U24>=Annahmen!$B$25,"B","C")) -> B | C24: Industrie | D24: Roche Basel Bau 51 und laufende Bauten | E24: Roche | F24: Basel / Kaiseraugst | G24: BS | H24: Nordwestschweiz | I24: DE/EN | J24: Bau 51 CHF 790 Mio. (Grundstein 21.09.2026), ca. CHF 1,4 Mrd. laufende Bauten | K24: Baustrom, später Lastbank/USV bei Qualifizierung | L24: 1 | M24: 26 | N24: 0 | O24: 0 | P24: 0 | Q24: 0 | R24: =ROUND(L24*M24*Annahmen!$F$9+N24*O24*Annahmen!$F$12+P24*Q24*Annahmen!$F$15,-2) -> 110200 | S24: 1 | T24: 0.15 | U24: =ROUND(R24*S24*T24,-2) -> 16500 | V24: Klima/Reinraum-Provisorien | W24: Zugang über Installateur/FM vor Ort (ETAVIS K+S, Selmoni, CBRE) | Y24: Offen: CRM prüfen | Z24: Engineering / Utilities, Technischer Einkauf | AE24: Link
A25: =RANK(U25,$U$5:$U$42)+COUNTIF($U$5:U25,U25)-1 -> 21 | B25: =IF(U25>=Annahmen!$B$24,"A",IF(U25>=Annahmen!$B$25,"B","C")) -> B | C25: Rechenzentrum | D25: NorthC Genf «The Hive» | E25: NorthC Datacenters | F25: Kanton Genf | G25: GE | H25: West (Romandie) | I25: FR/EN | J25: 4,5 MW IT (3 × 1,5 MW), Baustart Q1 2026, fertig Q2 2028 | K25: Baustrom, Lastbank je 1,5-MW-Stufe | L25: 0.5 | M25: 40 | N25: 1.5 | O25: 3 | P25: 0 | Q25: 0 | R25: =ROUND(L25*M25*Annahmen!$F$9+N25*O25*Annahmen!$F$12+P25*Q25*Annahmen!$F$15,-2) -> 93500 | S25: 0.6 | T25: 0.25 | U25: =ROUND(R25*S25*T25,-2) -> 14000 | V25: Bauheizung, später Kühlung beim IST | W25: Zusammen mit Arlesheim als Paket anbieten | Y25: Offen: CRM prüfen | Z25: Commissioning-Manager, Construction Manager, Critical Facility Ops | AE25: Link
A26: =RANK(U26,$U$5:$U$42)+COUNTIF($U$5:U26,U26)-1 -> 22 | B26: =IF(U26>=Annahmen!$B$24,"A",IF(U26>=Annahmen!$B$25,"B","C")) -> B | C26: Rechenzentrum | D26: FlexBase Technologiezentrum Laufenburg | E26: FlexBase; Bau ERNE Gruppe | F26: Laufenburg | G26: AG | H26: Nordwestschweiz | I26: DE/EN | J26: KI-RZ plus Redox-Flow-Speicher >800 MW, Vollbetrieb Sommer 2028 (Zeitplan umstritten) | K26: Baustrom über Jahre, später Commissioning | L26: 2 | M26: 26 | N26: 0 | O26: 0 | P26: 0 | Q26: 0 | R26: =ROUND(L26*M26*Annahmen!$F$9+N26*O26*Annahmen!$F$12+P26*Q26*Annahmen!$F$15,-2) -> 220400 | S26: 0.6 | T26: 0.1 | U26: =ROUND(R26*S26*T26,-2) -> 13200 | V26: Bauheizung, Bautrocknung | W26: Über ERNE einsteigen, Finanzierung beobachten | Y26: Offen: CRM prüfen | Z26: Commissioning-Manager, Construction Manager, Critical Facility Ops | AE26: Link | AF26: Bewilligt ist nur die Gebäudehülle.
A27: =RANK(U27,$U$5:$U$42)+COUNTIF($U$5:U27,U27)-1 -> 23 | B27: =IF(U27>=Annahmen!$B$24,"A",IF(U27>=Annahmen!$B$25,"B","C")) -> B | C27: Kanal-Partner | D27: BKW Building Solutions (Rahmen) | E27: BKW: AEK, ISP, swisspro, Arnold, inelectro | F27: Ostermundigen | G27: BE | H27: Mittelland/Bern | I27: DE/FR | J27: ca. 4'000 MA in ca. 50 Firmen | K27: Baustrom, Netzersatz (Arnold: Kabelnetzbau) | L27: 1 | M27: 20 | N27: 0 | O27: 0 | P27: 0 | Q27: 0 | R27: =ROUND(L27*M27*Annahmen!$F$9+N27*O27*Annahmen!$F$12+P27*Q27*Annahmen!$F$15,-2) -> 84800 | S27: 1 | T27: 0.15 | U27: =ROUND(R27*S27*T27,-2) -> 12700 | V27: Bauheizung | W27: BKW BS Einkauf; BKW ist auch Energie-Anbieter | Y27: Offen: CRM prüfen | Z27: Einkauf Gruppe, Bereichsleiter Grossprojekte | AE27: Link | AF27: Rahmenvolumen ist Annahme.
A28: =RANK(U28,$U$5:$U$42)+COUNTIF($U$5:U28,U28)-1 -> 24 | B28: =IF(U28>=Annahmen!$B$24,"A",IF(U28>=Annahmen!$B$25,"B","C")) -> B | C28: Kanal-Partner | D28: CKW Gebäudetechnik und EKZ Eltop (Rahmen) | E28: Axpo-Gruppe (CKW) / EKZ | F28: Luzern / Zürich | G28: LU/ZH | H28: Zentralschweiz | I28: DE | J28: ca. 1'400 MA CKW GT, ca. 550 MA EKZ Eltop | K28: Baustrom, BESS | L28: 1 | M28: 20 | N28: 0 | O28: 0 | P28: 0 | Q28: 0 | R28: =ROUND(L28*M28*Annahmen!$F$9+N28*O28*Annahmen!$F$12+P28*Q28*Annahmen!$F$15,-2) -> 84800 | S28: 1 | T28: 0.15 | U28: =ROUND(R28*S28*T28,-2) -> 12700 | V28: Bauheizung | W28: Getrennt ansprechen, gemeinsam auswerten | Y28: Offen: CRM prüfen | Z28: Einkauf Gruppe, Bereichsleiter Grossprojekte | AE28: Link | AF28: Rahmenvolumen ist Annahme.
A29: =RANK(U29,$U$5:$U$42)+COUNTIF($U$5:U29,U29)-1 -> 25 | B29: =IF(U29>=Annahmen!$B$24,"A",IF(U29>=Annahmen!$B$25,"B","C")) -> B | C29: Event | D29: FIS Ski-WM Crans-Montana 2027 | E29: Swiss-Ski / OK Crans-Montana 2027 | F29: Crans-Montana | G29: VS | H29: West (Romandie) | I29: FR | J29: 01.-14.02.2027, zwei Wochen Broadcast, Fan-Zonen, Hospitality | K29: Redundante Generatoren (n+1), BESS für Hospitality | L29: 3 | M29: 4 | N29: 0 | O29: 0 | P29: 0.5 | Q29: 1 | R29: =ROUND(L29*M29*Annahmen!$F$9+N29*O29*Annahmen!$F$12+P29*Q29*Annahmen!$F$15,-2) -> 63300 | S29: 1 | T29: 0.2 | U29: =ROUND(R29*S29*T29,-2) -> 12700 | V29: Zeltheizung, Heizzentralen | W29: OK Crans-Montana 2027 sofort kontaktieren, Französisch | Y29: Offen: CRM prüfen | Z29: Produktionsleitung, Technische Leitung OK | AE29: Link | AF29: Szenario-Grösse ist Annahme.
A30: =RANK(U30,$U$5:$U$42)+COUNTIF($U$5:U30,U30)-1 -> 26 | B30: =IF(U30>=Annahmen!$B$24,"A",IF(U30>=Annahmen!$B$25,"B","C")) -> B | C30: Rechenzentrum | D30: Green Zürich West 4 Lupfig | E30: Green; GU Implenia | F30: Lupfig | G30: AG | H30: Nordwestschweiz | I30: DE | J30: 12 MW IT, Inbetriebnahme 2026 geplant (eine Quelle nennt 2027) | K30: Lastbank für IST, Generator für Tests und Überbrückung | L30: 2 | M30: 4 | N30: 6 | O30: 4 | P30: 0 | Q30: 0 | R30: =ROUND(L30*M30*Annahmen!$F$9+N30*O30*Annahmen!$F$12+P30*Q30*Annahmen!$F$15,-2) -> 80600 | S30: 0.5 | T30: 0.3 | U30: =ROUND(R30*S30*T30,-2) -> 12100 | V30: Temporäre Kühlung beim IST | W30: Green Facility/Commissioning und Implenia-Projektleitung kontaktieren | Y30: Offen: CRM prüfen | Z30: Commissioning-Manager, Construction Manager, Critical Facility Ops | AE30: Link | AF30: Commissioning läuft vermutlich jetzt. Tempo zählt.
A31: =RANK(U31,$U$5:$U$42)+COUNTIF($U$5:U31,U31)-1 -> 27 | B31: =IF(U31>=Annahmen!$B$24,"A",IF(U31>=Annahmen!$B$25,"B","C")) -> B | C31: Industrie | D31: Lonza Stein Fill & Finish (plus Visp) | E31: Lonza | F31: Stein / Visp | G31: AG/VS | H31: Nordwestschweiz | I31: DE/EN | J31: CHF 500 Mio. Anlage Stein operativ ab H1 2027, Ibex Visp im Ramp-up | K31: NEA-Lasttests, temporäre USV, Netzersatz bei Validierung | L31: 1 | M31: 12 | N31: 2 | O31: 2 | P31: 0 | Q31: 0 | R31: =ROUND(L31*M31*Annahmen!$F$9+N31*O31*Annahmen!$F$12+P31*Q31*Annahmen!$F$15,-2) -> 58700 | S31: 1 | T31: 0.2 | U31: =ROUND(R31*S31*T31,-2) -> 11700 | V31: Kühlung bei Validierung | W31: Lonza Engineering Stein: Inbetriebnahme H1 2027 | Y31: Offen: CRM prüfen | Z31: Engineering / Utilities, Technischer Einkauf | AE31: Link
A32: =RANK(U32,$U$5:$U$42)+COUNTIF($U$5:U32,U32)-1 -> 28 | B32: =IF(U32>=Annahmen!$B$24,"A",IF(U32>=Annahmen!$B$25,"B","C")) -> B | C32: Event | D32: WEF Annual Meeting 2027 | E32: World Economic Forum | F32: Davos | G32: GR | H32: Ostschweiz | I32: EN/DE | J32: 18.-22.01.2027, Pavillons und Sicherheit bei knappem Ortsnetz | K32: Generatoren redundant, BESS-Hybrid für leise Zonen | L32: 4 | M32: 3 | N32: 0 | O32: 0 | P32: 1 | Q32: 1 | R32: =ROUND(L32*M32*Annahmen!$F$9+N32*O32*Annahmen!$F$12+P32*Q32*Annahmen!$F$15,-2) -> 75700 | S32: 1 | T32: 0.15 | U32: =ROUND(R32*S32*T32,-2) -> 11400 | V32: Zeltheizung, Heizzentralen (MiT-Kern) | W32: Offerte für 2027 jetzt, Aufbau startet im Dezember | Y32: Offen: CRM prüfen | Z32: Produktionsleitung, Technische Leitung OK | AE32: Link | AF32: Szenario-Grösse ist Annahme.
A33: =RANK(U33,$U$5:$U$42)+COUNTIF($U$5:U33,U33)-1 -> 29 | B33: =IF(U33>=Annahmen!$B$24,"A",IF(U33>=Annahmen!$B$25,"B","C")) -> B | C33: Infrastruktur | D33: Stadtautobahn St.Gallen (BSA-Umstellung) | E33: ASTRA | F33: St. Gallen | G33: SG | H33: Ostschweiz | I33: DE | J33: ca. CHF 524 Mio., Schlussarbeiten 2027 bis Sommer 2028 | K33: Netzersatz für Lüftung und Beleuchtung bei Umstellung | L33: 1 | M33: 12 | N33: 0 | O33: 0 | P33: 0 | Q33: 0 | R33: =ROUND(L33*M33*Annahmen!$F$9+N33*O33*Annahmen!$F$12+P33*Q33*Annahmen!$F$15,-2) -> 50900 | S33: 1 | T33: 0.2 | U33: =ROUND(R33*S33*T33,-2) -> 10200 | W33: ASTRA Filiale Winterthur / BSA-Unternehmer: Umschaltplan | Y33: Offen: CRM prüfen | Z33: Bauleitung ARGE, Baustelleneinrichtung, Einkauf | AE33: Link
A34: =RANK(U34,$U$5:$U$42)+COUNTIF($U$5:U34,U34)-1 -> 30 | B34: =IF(U34>=Annahmen!$B$24,"A",IF(U34>=Annahmen!$B$25,"B","C")) -> B | C34: Netz / Unterwerk | D34: Romande Energie: UW-Modernisierung HS/MS | E34: Romande Energie | F34: Kanton Waadt | G34: VD | H34: West (Romandie) | I34: FR | J34: Mehrere Unterwerk-Umbauten 2024-2027 | K34: Netzersatz, mobiler Trafo (Wert fehlt) | L34: 1 | M34: 12 | N34: 0 | O34: 0 | P34: 0 | Q34: 0 | R34: =ROUND(L34*M34*Annahmen!$F$9+N34*O34*Annahmen!$F$12+P34*Q34*Annahmen!$F$15,-2) -> 50900 | S34: 1 | T34: 0.2 | U34: =ROUND(R34*S34*T34,-2) -> 10200 | W34: Romande Energie Netzbau, Französisch | Y34: Offen: CRM prüfen | Z34: Leiter Netzbau / Unterwerke, Projektleiter UW | AE34: Link
A35: =RANK(U35,$U$5:$U$42)+COUNTIF($U$5:U35,U35)-1 -> 31 | B35: =IF(U35>=Annahmen!$B$24,"A",IF(U35>=Annahmen!$B$25,"B","C")) -> C | C35: Infrastruktur | D35: Flughafen Zürich: neuer Tower | E35: Flughafen Zürich AG | F35: Kloten | G35: ZH | H35: Zürich | I35: DE | J35: Tower-Bau ab 2027 (ca. 2 Jahre), Dock A ab 2030 (> CHF 1 Mrd.) | K35: Netzersatz und BESS bei Umschaltungen im 24/7-Betrieb | L35: 1 | M35: 12 | N35: 0 | O35: 0 | P35: 0.5 | Q35: 6 | R35: =ROUND(L35*M35*Annahmen!$F$9+N35*O35*Annahmen!$F$12+P35*Q35*Annahmen!$F$15,-2) -> 125400 | S35: 0.5 | T35: 0.15 | U35: =ROUND(R35*S35*T35,-2) -> 9400 | V35: Klima/Kühlung für Provisorien | W35: Flughafen Energie/Technik: Rahmen für Umschaltungen anbieten | Y35: Offen: CRM prüfen | Z35: Bauleitung ARGE, Baustelleneinrichtung, Einkauf | AE35: Link
A36: =RANK(U36,$U$5:$U$42)+COUNTIF($U$5:U36,U36)-1 -> 32 | B36: =IF(U36>=Annahmen!$B$24,"A",IF(U36>=Annahmen!$B$25,"B","C")) -> C | C36: Infrastruktur | D36: A1 Wankdorf-Schönbühl (8-Spur-Ausbau) | E36: ASTRA | F36: Bern / Schönbühl | G36: BE | H36: Mittelland/Bern | I36: DE | J36: CHF 474 Mio., ab 2027, ca. 6 Jahre | K36: Generatoren für Lichtsignale, Beleuchtung, Installationsplätze | L36: 0.5 | M36: 26 | N36: 0 | O36: 0 | P36: 0 | Q36: 0 | R36: =ROUND(L36*M36*Annahmen!$F$9+N36*O36*Annahmen!$F$12+P36*Q36*Annahmen!$F$15,-2) -> 55100 | S36: 1 | T36: 0.15 | U36: =ROUND(R36*S36*T36,-2) -> 8300 | W36: Zuschlag an Bau-ARGE abwarten, dann ARGE ansprechen | Y36: Offen: CRM prüfen | Z36: Bauleitung ARGE, Baustelleneinrichtung, Einkauf | AE36: Link
A37: =RANK(U37,$U$5:$U$42)+COUNTIF($U$5:U37,U37)-1 -> 33 | B37: =IF(U37>=Annahmen!$B$24,"A",IF(U37>=Annahmen!$B$25,"B","C")) -> C | C37: Spital | D37: Kantonsspital St.Gallen Haus 07B | E37: HOCH Health Ostschweiz | F37: St. Gallen | G37: SG | H37: Ostschweiz | I37: DE | J37: Rohbau 2026, Ausbau 2027/28, Übergabe 2029 | K37: Baustrom Ausbau, später NEA-Test | L37: 0.5 | M37: 26 | N37: 0 | O37: 0 | P37: 0 | Q37: 0 | R37: =ROUND(L37*M37*Annahmen!$F$9+N37*O37*Annahmen!$F$12+P37*Q37*Annahmen!$F$15,-2) -> 55100 | S37: 1 | T37: 0.15 | U37: =ROUND(R37*S37*T37,-2) -> 8300 | V37: Bauheizung, Trocknung | W37: HOCH Bau und Technik: Ausbauphase 2027 | Y37: Offen: CRM prüfen | Z37: Leiter Technik und Betrieb, TU-Projektleitung | AE37: Link
A38: =RANK(U38,$U$5:$U$42)+COUNTIF($U$5:U38,U38)-1 -> 34 | B38: =IF(U38>=Annahmen!$B$24,"A",IF(U38>=Annahmen!$B$25,"B","C")) -> C | C38: Industrie | D38: Novartis Schweizerhalle und Stein | E38: Novartis | F38: Pratteln / Stein | G38: BL/AG | H38: Nordwestschweiz | I38: DE/EN | J38: USD 80 Mio. siRNA Schweizerhalle, USD 26 Mio. Sterile Stein, bis ca. 2028 | K38: Netzersatz bei Umbauten im GMP-Betrieb | L38: 1 | M38: 12 | N38: 0 | O38: 0 | P38: 0 | Q38: 0 | R38: =ROUND(L38*M38*Annahmen!$F$9+N38*O38*Annahmen!$F$12+P38*Q38*Annahmen!$F$15,-2) -> 50900 | S38: 1 | T38: 0.15 | U38: =ROUND(R38*S38*T38,-2) -> 7600 | V38: Klima | W38: Novartis Engineering: Umschaltfenster | Y38: Offen: CRM prüfen | Z38: Engineering / Utilities, Technischer Einkauf | AE38: Link
A39: =RANK(U39,$U$5:$U$42)+COUNTIF($U$5:U39,U39)-1 -> 35 | B39: =IF(U39>=Annahmen!$B$24,"A",IF(U39>=Annahmen!$B$25,"B","C")) -> C | C39: Netz / Unterwerk | D39: ewz UW Sihlfeld (Erneuerung) | E39: ewz | F39: Zürich | G39: ZH | H39: Zürich | I39: DE | J39: Innerstädtisches Unterwerk, 2027-2029 | K39: Provisorien: Generator-Netzersatz, mobiler Trafo (Wert fehlt) | L39: 2 | M39: 8 | N39: 0 | O39: 0 | P39: 0 | Q39: 0 | R39: =ROUND(L39*M39*Annahmen!$F$9+N39*O39*Annahmen!$F$12+P39*Q39*Annahmen!$F$15,-2) -> 67800 | S39: 0.5 | T39: 0.2 | U39: =ROUND(R39*S39*T39,-2) -> 6800 | W39: ewz Netzbau: Provisoriumskonzept, IVöB-Verfahren beachten | Y39: Offen: CRM prüfen | Z39: Leiter Netzbau / Unterwerke, Projektleiter UW | AE39: Link | AF39: Öffentliche Beschaffung.
A40: =RANK(U40,$U$5:$U$42)+COUNTIF($U$5:U40,U40)-1 -> 36 | B40: =IF(U40>=Annahmen!$B$24,"A",IF(U40>=Annahmen!$B$25,"B","C")) -> C | C40: Infrastruktur | D40: Gare de Lausanne (Léman 2030) | E40: SBB/CFF | F40: Lausanne | G40: VD | H40: West (Romandie) | I40: FR | J40: Hauptarbeiten ab Ende 2027, viele Nachtschichten | K40: BESS und Generator für Nachtbaustellen | L40: 0.5 | M40: 8 | N40: 0 | O40: 0 | P40: 0.5 | Q40: 3 | R40: =ROUND(L40*M40*Annahmen!$F$9+N40*O40*Annahmen!$F$12+P40*Q40*Annahmen!$F$15,-2) -> 54200 | S40: 0.3 | T40: 0.15 | U40: =ROUND(R40*S40*T40,-2) -> 2400 | V40: Bautrocknung | W40: CFF Projektleitung Lausanne, Dokumente auf Französisch | Y40: Offen: CRM prüfen | Z40: Bauleitung ARGE, Baustelleneinrichtung, Einkauf | AE40: Link
...

Sheet 90-Tage-Plan
A1: 90-Tage-Plan Oktober 2026 bis Januar 2027
A2: Vorschlag, im Team bestätigen. Status per Dropdown, überfällige Termine werden rot.
A4: Nr. | B4: Monat | C4: Termin | D4: Aufgabe | E4: Projekt / Kunde | F4: Erwartung 2027 CHF | G4: Verantwortlich | H4: Status | I4: Ergebnis / Notiz
A5: 1 | B5: Oktober | C5: 46311 | D5: Commissioning-Manager kontaktieren, IST-Plan der Folgephasen klären | E5: STACK ZUR02 Beringen | F5: =IFERROR(INDEX('Top-Player'!$U$5:$U$42,MATCH("STACK ZUR02 Beringen",'Top-Player'!$D$5:$D$42,0)),0) -> 37000 | H5: offen
A6: 2 | B6: Oktober | C6: 46311 | D6: IST-Termin und Lastbank-Bedarf mit Green und Implenia klären | E6: Green Zürich West 4 Lupfig | F6: =IFERROR(INDEX('Top-Player'!$U$5:$U$42,MATCH("Green Zürich West 4 Lupfig",'Top-Player'!$D$5:$D$42,0)),0) -> 12100 | H6: offen
A7: 3 | B7: Oktober | C7: 46318 | D7: NEA-Lasttest Umzug Jan. 2027 und Rückbau-Baustrom offerieren | E7: Kantonsspital Aarau «Dreiklang» | F7: =IFERROR(INDEX('Top-Player'!$U$5:$U$42,MATCH("Kantonsspital Aarau «Dreiklang»",'Top-Player'!$D$5:$D$42,0)),0) -> 38000 | H7: offen
A8: 4 | B8: Oktober | C8: 46318 | D8: OK kontaktieren, Bedarf abfragen (Unterlagen Französisch) | E8: FIS Ski-WM Crans-Montana 2027 | F8: =IFERROR(INDEX('Top-Player'!$U$5:$U$42,MATCH("FIS Ski-WM Crans-Montana 2027",'Top-Player'!$D$5:$D$42,0)),0) -> 12700 | H8: offen
A9: 5 | B9: Oktober | C9: 46325 | D9: Arlesheim und Genf als Paket anbieten | E9: NorthC Arlesheim (uptownBasel) / NorthC Genf «The Hive» | F9: =IFERROR(INDEX('Top-Player'!$U$5:$U$42,MATCH("NorthC Arlesheim (uptownBasel)",'Top-Player'!$D$5:$D$42,0)),0)+IFERROR(INDEX('Top-Player'!$U$5:$U$42,MATCH("NorthC Genf «The Hive»",'Top-Player'!$D$5:$D$42,0)),0) -> 37100 | H9: offen
A10: 6 | B10: November | C10: 46339 | D10: Rahmengespräch Einkauf Gruppe | E10: Burkhalter Gruppe (Rahmen) | F10: =IFERROR(INDEX('Top-Player'!$U$5:$U$42,MATCH("Burkhalter Gruppe (Rahmen)",'Top-Player'!$D$5:$D$42,0)),0) -> 25400 | H10: offen
A11: 7 | B11: November | C11: 46339 | D11: Rahmengespräch Einkauf VINCI Energies CH | E11: ETAVIS / VINCI Energies (Rahmen) | F11: =IFERROR(INDEX('Top-Player'!$U$5:$U$42,MATCH("ETAVIS",'Top-Player'!$D$5:$D$42,0)),0)+IFERROR(INDEX('Top-Player'!$U$5:$U$42,MATCH("VINCI Energies (Rahmen)",'Top-Player'!$D$5:$D$42,0)),0) -> 0 | H11: offen
A12: 8 | B12: November | C12: 46346 | D12: Rahmengespräch Einkauf und FM-Leitung | E12: Equans Switzerland (Rahmen) | F12: =IFERROR(INDEX('Top-Player'!$U$5:$U$42,MATCH("Equans Switzerland (Rahmen)",'Top-Player'!$D$5:$D$42,0)),0) -> 22800 | H12: offen
A13: 9 | B13: November | C13: 46346 | D13: Offerte abgeben, Aufbau startet im Dezember | E13: WEF Annual Meeting 2027 | F13: =IFERROR(INDEX('Top-Player'!$U$5:$U$42,MATCH("WEF Annual Meeting 2027",'Top-Player'!$D$5:$D$42,0)),0) -> 11400 | H13: offen
A14: 10 | B14: November | C14: 46353 | D14: GU/Elektro über simap und Baugesuch ermitteln, Baustrom offerieren | E14: Digital Realty ZUR4 Glattbrugg | F14: =IFERROR(INDEX('Top-Player'!$U$5:$U$42,MATCH("Digital Realty ZUR4 Glattbrugg",'Top-Player'!$D$5:$D$42,0)),0) -> 20400 | H14: offen
A15: 11 | B15: Dezember | C15: 46360 | D15: MiT-Mietsätze im Blatt «Annahmen» Spalte E eintragen | E15: alle | H15: offen
A16: 12 | B16: Dezember | C16: 46367 | D16: Kundenstatus aus CRM für alle Top-Player eintragen | E16: alle | H16: offen
A17: 13 | B17: Dezember | C17: 46374 | D17: Backup-Rahmen mit Baustellenleitung besprechen | E17: 2. Gotthardröhre / Sisikoner Tunnel (Neue Axenstrasse) | F17: =IFERROR(INDEX('Top-Player'!$U$5:$U$42,MATCH("2. Gotthardröhre",'Top-Player'!$D$5:$D$42,0)),0)+IFERROR(INDEX('Top-Player'!$U$5:$U$42,MATCH("Sisikoner Tunnel (Neue Axenstrasse)",'Top-Player'!$D$5:$D$42,0)),0) -> 132200 | H17: offen
A18: 14 | B18: Januar | C18: 46402 | D18: Review im Team, Pipeline neu rechnen, Prio anpassen | E18: alle | H18: offen
A19: 15 | B19: Januar | C19: 46409 | D19: Beziehung aufbauen, RZ 2028 aufgleisen | E19: Vantage ZRH3 Volketswil | F19: =IFERROR(INDEX('Top-Player'!$U$5:$U$42,MATCH("Vantage ZRH3 Volketswil",'Top-Player'!$D$5:$D$42,0)),0) -> 28000 | H19: offen

Sheet Rechenzentren
A1: Rechenzentren Schweiz 2026-2028
A2: Fakten aus öffentlichen Quellen, Stand 27.09.2026. (?) = unsicher. Potenzial nur für Top-Player (Blatt «Top-Player»).
A4: Betreiber / Projekt | B4: Standort | C4: IT-Leistung MW | D4: Zeitplan | E4: GU / PM | F4: Netzanschluss | G4: Für uns | H4: Quelle
A5: STACK ZUR02 | B5: Beringen SH | C5: 36 | D5: Aufrichte 2025, Betriebsstart Herbst 2026 | E5: PM MBA Projektmanagement | F5: neues Unterwerk vom Betreiber finanziert, ca. 350 GWh/a | G5: Hot Lead: Folgephasen-IST 2027 | H5: stackinfra.com; shn.ch 12.02.2026
A6: Green Zürich West 4 | B6: Lupfig AG | C6: 12 | D6: Baustart 01/2025, IBN 2026 (eine Quelle: 2027) | E6: GU Implenia (> CHF 150 Mio.) | F6: Abwärme ins Netz IBB | G6: Hot Lead: Commissioning läuft | H6: implenia.com 27.03.2025
A7: Green Metro-Campus | B7: Dielsdorf ZH | C7: Campus-Anschluss 50 MW | D7: RZ2/RZ3 im Bau, weiteres RZ Baustart 2026 | E7: PM MBA Projektmanagement | F7: EKZ-UW Dielsdorf (CHF 14 Mio., 50 MW) seit 09/2025 | G7: Baustrom 2027, IST 2028 | H7: baublatt.ch; ekz.ch
A8: Digital Realty ZUR4 | B8: Opfikon-Glattbrugg ZH | C8: 15 | D8: Spatenstich 27.08.2026, fertig 2028 | E8: unbekannt: simap / Baugesuch prüfen | F8: unbekannt | G8: Baustrom 2027, IST 2028 | H8: investor.digitalrealty.com 27.08.2026
A9: Vantage ZRH3 | B9: Volketswil ZH | C9: 100 bis 150 | D9: Phase 1 live 2028 | E9: unbekannt | F9: neue Unterwerke nötig, Engpass Vornetz Axpo/Swissgrid | G9: Beziehung aufbauen, EMEA-Beschaffung | H9: ekz.ch/blue 2025; datacenterdynamics.com
A10: NorthC Arlesheim | B10: Arlesheim BL | C10: 4,5 (Ausbau 7,5) | D10: Betrieb ab Mitte 2027 | E10: unbekannt | F10: 6 MVA, NEA mit HVO | G10: IST 2027 | H10: northcdatacenters.com 11.09.2025
A11: NorthC «The Hive» | B11: Kanton Genf | C11: 4,5 (3 × 1,5) | D11: Baustart Q1 2026, fertig Q2 2028 | E11: unbekannt | F11: NEA mit HVO, Direct-to-Chip | G11: Baustrom 2027, IST 2028 | H11: northcdatacenters.com
A12: FlexBase TZL | B12: Laufenburg AG | C12: bis ca. 500 (technisch, ?) | D12: Spatenstich 05.05.2025, Vollbetrieb Sommer 2028 (umstritten) | E12: ERNE Gruppe | F12: Swissgrid Phase 1 bewilligt, 800 MW | G12: Beobachten, über ERNE | H12: flexbase.ch; srf.ch
A13: Equinix ZH4 Phase 6 | B13: Zürich | C13: ? | D13: CHF 40 Mio., fertig 2027 | E13: ? | F13: ? | G13: Beobachten (unter CHF 50'000) | H13: inside-it.ch 12.11.2024
A14: NTT Zurich 1 | B14: Rümlang ZH | C14: 20 | D14: in Betrieb, keine Erweiterung gefunden | E14: – | F14: – | G14: NEA-Tests wiederkehrend | H14: datacentermap.com
A15: ENKA Beringerfeld | B15: Beringen SH | C15: ? | D15: Baugesuch in Vorprüfung, Widerstand | E15: ENKA İnşaat | F15: unklar | G15: Beobachten | H15: shaz.ch 10.08.2026
A17: Commissioning (IST) in Kürze
A18: IST Level 5: Strom, Kälte und Notstrom laufen gemeinsam auf Design-Last, Netz wird getrennt, Fehler werden simuliert.
A19: Lastbank-Leistung ≈ Design-IT-Last der getesteten Data Hall, dazu Heizlastbänke im White Space.
A20: Laststufen 25 / 50 / 75 / 100 %, danach mehrere Stunden Volllast.
A21: IST-Fenster typisch 4 bis 6 Wochen; 8 bis 16 Wochen von erster Energisierung bis IST-Abschluss je Data Hall.
A22: Mängel im IST erzwingen Re-Tests und damit erneute Lastbank-Miete.
A23: Quellen: anvilfield.com (IST Field Guide), sunbeltsolomon.com, hillstone.co.uk (US/UK-Fachquellen).

Sheet Produktbedarf
A1: Produktbedarf je Segment
A2: 3 = Kernbedarf, 2 = häufig, 1 = gelegentlich, 0 = kaum. Einschätzung aus den Szenarien, änderbar.
A4: Segment | B4: Generator | C4: Lastbank | D4: BESS | E4: Mobiler Trafo | F4: NEA-Test / USV | G4: Tank / HVO | H4: Top-Player | I4: Erwartung 2027 CHF
A5: Rechenzentrum | B5: 3 | C5: 3 | D5: 2 | E5: 1 | F5: 3 | G5: 2 | H5: =COUNTIF('Top-Player'!$C$5:$C$42,A5) -> 8 | I5: =SUMIF('Top-Player'!$C$5:$C$42,A5,'Top-Player'!$U$5:$U$42) -> 171300
A6: Infrastruktur | B6: 3 | C6: 0 | D6: 2 | E6: 1 | F6: 0 | G6: 3 | H6: =COUNTIF('Top-Player'!$C$5:$C$42,A6) -> 10 | I6: =SUMIF('Top-Player'!$C$5:$C$42,A6,'Top-Player'!$U$5:$U$42) -> 248100
A7: Netz / Unterwerk | B7: 3 | C7: 0 | D7: 1 | E7: 3 | F7: 1 | G7: 1 | H7: =COUNTIF('Top-Player'!$C$5:$C$42,A7) -> 5 | I7: =SUMIF('Top-Player'!$C$5:$C$42,A7,'Top-Player'!$U$5:$U$42) -> 55400
A8: Spital | B8: 2 | C8: 2 | D8: 2 | E8: 1 | F8: 3 | G8: 1 | H8: =COUNTIF('Top-Player'!$C$5:$C$42,A8) -> 3 | I8: =SUMIF('Top-Player'!$C$5:$C$42,A8,'Top-Player'!$U$5:$U$42) -> 65100
A9: Industrie | B9: 3 | C9: 1 | D9: 1 | E9: 1 | F9: 2 | G9: 1 | H9: =COUNTIF('Top-Player'!$C$5:$C$42,A9) -> 4 | I9: =SUMIF('Top-Player'!$C$5:$C$42,A9,'Top-Player'!$U$5:$U$42) -> 69700
A10: Event | B10: 3 | C10: 0 | D10: 3 | E10: 0 | F10: 0 | G10: 2 | H10: =COUNTIF('Top-Player'!$C$5:$C$42,A10) -> 3 | I10: =SUMIF('Top-Player'!$C$5:$C$42,A10,'Top-Player'!$U$5:$U$42) -> 24100
A11: Kanal-Partner | B11: 3 | C11: 1 | D11: 1 | E11: 1 | F11: 2 | G11: 1 | H11: =COUNTIF('Top-Player'!$C$5:$C$42,A11) -> 5 | I11: =SUMIF('Top-Player'!$C$5:$C$42,A11,'Top-Player'!$U$5:$U$42) -> 101400
A13: Lesart: Generator ist überall Türöffner, Lastbank im RZ, Trafo im Netz, BESS bei Events und Nachtbaustellen.

Sheet Portfolio
A1: Portfolio Power und Cross-Sell
A2: Was wir vermieten, wofür, an wen. Kennwerte laut Quelle; fehlende Werte als Lücke markiert.
A4: Produkt | B4: Wofür | C4: Typische Kunden | D4: Kennwerte / Hinweis | E4: Quelle
A5: Generator | B5: Baustrom, Netzersatz, Events, Überbrückung bis Netzanschluss | C5: GU/TU, Tunnel, RZ im Bau, Events, Netzbetreiber | D5: Aggreko CH: 30 bis 2'100 kVA, Diesel, Gas, HVO, Stage V. Immer klären: Prime (Dauer) oder Standby (Notstrom). | E5: aggreko.com/de-ch/products/generators
A6: Lastbank | B6: Künstliche Last für NEA-Tests und RZ-Commissioning (IST) | C6: RZ, Spitäler, Pharma, Facility Manager | D6: Aggreko: 100 bis 6'250 kW, Commissioning Level L1 bis L5, flüssigkeitsgekühlte Varianten für KI-RZ. | E6: aggreko.com (Data Centre Commissioning, Load Banks)
A7: BESS | B7: Leise, emissionsfreie Versorgung, Lastspitzen kappen, Hybrid mit Generator | C7: Events, Nachtbaustellen, Innenstadt, Spitäler | D7: Beispiel Aggreko: 1 MW / 1,2 MWh. Immer nutzbare Kapazität (kWh) und C-Rate angeben, nicht Nennkapazität. | E7: aggreko.com
A8: Mobiler Trafo | B8: Provisorische Einspeisung MS/NS bei Unterwerk- und Stationsumbau | C8: Netzbetreiber, Industrie, Grossbaustellen | D8: Bei MiT nicht belegt, über Aggreko prüfen. Mietsatz: Wert fehlt, aus Preisliste ergänzen. | E8: aggreko.com
A9: NEA-Test und Messung | B9: Netzersatzanlage unter Last prüfen, Netzqualität vor und nach Umschaltung messen | C9: Spitäler, Industrie, RZ, Facility Manager | D9: Messung nach EN 50160 (Spannungsmerkmale) mit Geräten nach IEC 61000-4-30 Klasse A. | E9: eigene Fachkompetenz
A10: Tankcontainer / HVO | B10: Treibstoff-Logistik für Dauerbetrieb, erneuerbarer Diesel | C10: Tunnel, RZ-Überbrückung, Events | D10: 1 MVA bei 75 % Last: ca. 139 bis 154 l/h (Cummins C1000 D5), rund CHF 350 pro Stunde bei 2,41 CHF/l. | E10: Cummins-Datenblatt; TCS 18.09.2026
A11: Cross-Sell Wärme / Kälte | B11: Bauheizung, Trocknung, temporäre Kühlung, Zeltheizung, Entfeuchtung | C11: Winterbaustellen, RZ-IST, Spital-Umzug, WEF, Ski-WM | D11: MiT-Kerngeschäft. Kühlung Richtwert ca. CHF 16'400 pro MW (therm.) und Monat (US-Lease, umgerechnet). | E11: mobilintime.com; kwipped.com

Sheet Annahmen
A1: Annahmen: Mietsätze und Schwellen
A2: Stand 27.09.2026 | gelbe Zellen = Eingaben | Spalte E «MiT-Satz» überschreibt den Richtwert
A4: Parameter | B4: Richtwert | C4: Einheit | D4: Quelle / Herleitung | E4: MiT-Satz (eintragen) | F4: gilt
A5: Wechselkurs USD/CHF | B5: 0.828 | C5: CHF je USD | D5: Stichdatum 24.09.2026: 1 USD = 0,828 CHF (exchangerates.org.uk / Wise)
A6: cos phi (Generator-Nennleistung) | B6: 0.8 | D6: Standard 0,8: 1 MVA ≈ 0,8 MW Wirkleistung
A7: Generator Miete, tief | B7: 5000 | C7: USD pro MW und Woche | D7: US-Richtwert 500 kW: 2'500-3'900 USD/Woche, hochgerechnet auf 1 MW (dieselfuelhq.com, 2026)
A8: Generator Miete, hoch | B8: 7800 | C8: USD pro MW und Woche | D8: wie oben
A9: Generator Miete (Modell) | B9: =AVERAGE(B7:B8)*B6*B5 -> 4239.36 | C9: CHF pro MVA und Woche | D9: Mittelwert × cos phi × Kurs. Nur Grössenordnung, durch MiT-Preisliste ersetzen | F9: =IF(E9<>"",E9,B9) -> 4239.36
A10: Lastbank Miete, tief | B10: 1600 | C10: USD pro MW und Woche | D10: US-Richtwert 1-MW-Lastbank: 1'600-3'100 USD/Woche (countbricks.com, 2026)
A11: Lastbank Miete, hoch | B11: 3100 | C11: USD pro MW und Woche | D11: wie oben
A12: Lastbank Miete (Modell) | B12: =AVERAGE(B10:B11)*B5 -> 1945.8 | C12: CHF pro MW und Woche | D12: Mittelwert × Kurs. Ohne Personal/Engineering für IST | F12: =IF(E12<>"",E12,B12) -> 1945.8
A13: BESS Miete, tief | B13: 10000 | C13: USD pro MW und Monat | D13: Bandbreite 10'000-50'000 USD/MW/Monat (ritarpower.com, Herstellerblog, nicht belastbar)
A14: BESS Miete, hoch | B14: 50000 | C14: USD pro MW und Monat | D14: wie oben
A15: BESS Miete (Modell) | B15: =AVERAGE(B13:B14)*B5 -> 24840 | C15: CHF pro MW und Monat | D15: Mittelwert × Kurs. Nutzbare Kapazität und C-Rate je Projekt klären | F15: =IF(E15<>"",E15,B15) -> 24840
A16: Mobiler Trafo Miete | B16: Wert fehlt | C16: CHF pro Woche | D16: Öffentlich nicht gefunden: aus MiT-Preisliste ergänzen. Nicht im Potenzial enthalten
A17: Transport, Montage, Service | B17: Wert fehlt | C17: CHF | D17: Nicht im Potenzial enthalten: aus MiT-Preisliste ergänzen
A19: Dieselverbrauch 1 MVA bei 75 % Last | B19: 145 | C19: l/h | D19: Cummins C1000 D5: 139 l/h Prime, 154 l/h Standby (Datenblatt)
A20: Dieselpreis Schweiz | B20: 2.41 | C20: CHF/l | D20: TCS 18.09.2026: 2,41 CHF/l (Tankstelle, Gewerbepreis tiefer)
A21: Treibstoffkosten 1 MVA bei 75 % Last | B21: =B19*B20 -> 349.45 | C21: CHF pro Stunde | D21: Argument für BESS-Hybrid: jede Stunde Generator-Leerlauf kostet
A22: Temporäre Kühlung (Cross-Sell) | B22: =34666/1.75*B5 -> 16401.97 | C22: CHF pro MW (therm.) und Monat | D22: US-Lease 500 t Chiller (ca. 1,75 MW) 34'666 USD/Monat (kwipped.com). Nur Info
A24: Prio A ab Erwartung 2027 | B24: 25000 | C24: CHF | D24: Erwartung = Potenzial × Anteil 2027 × Wahrscheinlichkeit
A25: Prio B ab Erwartung 2027 | B25: 10000 | C25: CHF | D25: darunter Prio C
A26: Schwelle Top-Player (Potenzial) | B26: 50000 | C26: CHF | D26: Vorgabe: Projekte mit mehr als CHF 50'000 Potenzial

Sheet Beobachten
A1: Beobachten
A2: Unter CHF 50'000, zu früh oder zu unsicher. Quartalsweise prüfen, bei neuem Anlass in «Top-Player» übernehmen.
A4: Segment | B4: Projekt / Kunde | C4: Ort | D4: Warum (noch) nicht Top | E4: Quelle
A5: Rechenzentrum | B5: Equinix ZH4 Phase 6 | C5: Zürich | D5: CHF 40 Mio. Ausbau, fertig 2027. Kleiner Commissioning-Umfang. | E5: Link
A6: Rechenzentrum | B6: ENKA Rechenzentrum Beringerfeld | C6: Beringen SH | D6: Baugesuch in Vorprüfung, starker Widerstand. | E6: Link
A7: Rechenzentrum | B7: Microsoft / AWS / Google Cloud-Regionen | C7: Zürich / Genf | D7: Standorte nicht öffentlich, meist Colocation: Zugang über Green, Vantage, STACK. | E7: Link
A8: Rechenzentrum | B8: Swiss Government Cloud (BIT) | C8: Bund | D8: CHF 319 Mio. 2025-2032, Private Cloud in eigenen RZ. | E8: Link
A9: Netz / Unterwerk | B9: Alpiq BESS Niedergösgen 300 MW / 1,2 GWh | C9: Niedergösgen SO | D9: Bau 2027, IBN 2029: Baustrom klein, Partner-Thema BESS. | E9: Link
A10: Netz / Unterwerk | B10: BESS Bonaduz 60 MW / 120 MWh | C10: Bonaduz GR | D10: COD H1 2027, Commissioning-Support prüfen. | E10: Link
A11: Spital | B11: Spital Sion Erweiterung | C11: Sion VS | D11: OP-Bündelung bis Ende 2027, Umfang eher unter CHF 50'000. | E11: Link
A12: Industrie | B12: Swiss Chip FabLab Dübendorf | C12: Dübendorf ZH | D12: Finanzierung offen, Betrieb ab 2028 geplant. | E12: Link
A13: Event | B13: Weltcup Adelboden und Lauberhorn | C13: Adelboden / Wengen BE | D13: Je unter CHF 50'000 Miete, zusammen interessant. BKW Sponsor Lauberhorn. | E13: Link
A14: Event | B14: Sommer-Openairs (St.Gallen, Frauenfeld, Gurten, Paléo, Montreux) | C14: diverse | D14: Einzeln meist unter CHF 50'000, als Saisonpaket prüfen. | E14: Link
A15: Event | B15: Art Basel 2027 | C15: Basel | D15: Satelliten-Pavillons, Umfang unklar. | E15: Link
... A19: Elektroplaner | B19: Amstein + Walthert, HHM, Scherler | C19: national | D19: Kaufen nicht selbst, schreiben aber Notstrom und Lastbank-Tests aus. | E19: Link

Sheet Wettbewerb
A1: Wettbewerb mobiler Strom Schweiz
A2: Aus Websuche, Angaben auf der verlinkten Seite prüfen.
A4: Anbieter | B4: Angebot | C4: Quelle
A5: Avesco Rent (Cat) | B5: Cat-Generatoren, z.B. XQP500 (550 kVA) | C5: Link
A6: Bimex | B6: Aggregate bis 2'000 kVA, netzparallel | C6: Link
A7: GENGA AG | B7: bis 670 kVA, auf Anfrage bis 2'500 kVA | C7: Link
A8: Kummler+Matter EVT | B8: Mobile Trafostationen MS/NS (Partner und Wettbewerber) | C8: Link
A9: Arag Bau | B9: Generatoren 20 bis 608 kVA | C9: Link
A10: Loxam CH / Boels CH | B10: Generatoren bis ca. 150 kVA | C10: Link
A11: Energyst (Cat Rental Power) | B11: Generatoren, Trafos, Lastbänke; CH vermutlich über Avesco | C11: Link

Sheet Glossar
A1: Glossar: Abkürzungen
A2: Gleiche Liste wie im Anhang der Präsentation.
A4: Kürzel | B4: Bedeutung
A5: BESS | B5: Battery Energy Storage System, Batteriespeicher
A6: NEA | B6: Netzersatzanlage (Notstromaggregat)
A7: USV | B7: Unterbrechungsfreie Stromversorgung
A8: IST / L1-L5 | B8: Integrated Systems Test, RZ-Gesamttest = Level 5
A9: kVA / MVA | B9: Scheinleistung (Nennleistung Generator)
A10: kW / MW | B10: Wirkleistung; bei cos phi 0,8: 1 MVA ≈ 0,8 MW
A11: IT-MW | B11: Elektrische Leistung der Server im RZ
A12: UW / GIS | B12: Unterwerk / gasisolierte Schaltanlage
A13: HS / MS / NS | B13: Hoch-, Mittel-, Niederspannung
A14: HVO | B14: Hydriertes Pflanzenöl, erneuerbarer Diesel
A15: TBM / BSA | B15: Tunnelbohrmaschine / Tunnel-Sicherheitstechnik
... A26: CRM / FX | B26: Kundendatenbank / Wechselkurs

Sheet Methode & Quellen
A1: Methode und Quellen
A2: Stand 27.09.2026
A4: Auswahl | B4: Websuche 27.09.2026 zu Rechenzentren, Grossbaustellen, Unterwerken, Spitälern, Pharma und Events 2026-2028 in der Schweiz.
B5: Aufgenommen, wenn das Power-Szenario mehr als CHF 50'000 Miete ergibt. Alles andere steht in «Beobachten».
A6: Szenario | B6: Je Projekt: Generator MVA × Wochen, Lastbank MW × Wochen, BESS MW × Monate. Grössen sind eigene Annahmen aus den öffentlichen Fakten
B7: (z.B. Lastbank für IST ≈ IT-Last einer Data Hall, 3-4 Wochen; Tunnel-Backup 52 Wochen). Blaue Zellen anpassen, sobald ihr mehr wisst.
A8: Sätze | B8: Öffentliche Listenpreise ab 100 kVA gibt es in CH/DE/AT nicht (nur auf Anfrage). Genutzt werden US-Richtwerte, umgerechnet 0,828 CHF/USD (24.09.2026).
B9: Diese Werte sind Grössenordnung, keine Offertenbasis. MiT-Sätze in «Annahmen» Spalte E eintragen.
A10: Anteil 2027 | B10: Welcher Teil des Volumens ins Kalenderjahr 2027 fällt (Bau- bzw. Eventtermine aus den Quellen).
A11: Wahrscheinlichkeit | B11: Chance, dass MiT den Auftrag gewinnt: 10 % (EMEA-Beschaffung, unsicherer Zeitplan) bis 30 % (konkreter Anlass, Region nah).
A12: Commissioning | B12: Integrated Systems Test (Level 5): Last ≈ Design-IT-Last, Stufen 25/50/75/100 %, IST-Fenster 4-6 Wochen (anvilfield.com, sunbeltsolomon.com).
A13: Netzengpass | B13: EKZ: über 100 Anschlussanfragen von RZ, 6 von 9 neuen Unterwerken entstehen für RZ, Engpass im Vornetz Axpo/Swissgrid (ekz.ch, 2025).
A14: Nicht enthalten | B14: Trafo-Miete, Transport, Montage, Service, Treibstoff: Potenzial ist bewusst konservativ.
A15: Kundenstatus | B15: MiT-Status (Bestand, verloren, Aufbau) ist nicht öffentlich: Spalte «Status MiT (CRM)» aus dem CRM füllen.
A16: Vertraulich | B16: Interne Arbeitsliste. Keine Weitergabe an Kunden.

Sheet Listen
A1: Segment | B1: Team | C1: Status
A2: Rechenzentrum | B2: Burak | C2: Offen: CRM prüfen
A3: Infrastruktur | B3: Mauro | C3: A-Kunde
A4: Netz / Unterwerk | B4: Jörg | C4: Bestandskunde mit Potenzial
A5: Spital | B5: Roberto | C5: Verlorener Kunde
A6: Industrie | C6: Potenzial / Aufbau
A7: Event
A8: Kanal-Partner
