Workbook

Sheet Offerte
A1: MOBIL IN TIME | F1: IHR KONTAKT
A2: =Stammdaten!$B$2 | F2: =Stammdaten!$B$12
A3: =Stammdaten!$B$3&" · "&Stammdaten!$B$4 | F3: ="Tel. "&Stammdaten!$B$13
A4: ="Tel. "&Stammdaten!$B$5&" · "&Stammdaten!$B$6&" · "&Stammdaten!$B$7 | F4: =Stammdaten!$B$14
A7: KUNDE | F7: OFFERTE
A8: Herr Reto Gloor | F8: Offerte-Nr. | G8: Q663790202605072109
A9: EK AG | F9: Datum | G9: 46191
A10: Tel. +41 62 767 80 62 | F10: Mietbeginn | G10: 46427
A11: reto.gloor@ekag.ch | F11: Mietende | G11: 46447
F12: Mietzeitraum | G12: =G11-G10+1&" Tage"
F13: Mindestmiete | G13: 7 Tage
A14: ="Sehr geehrter "&LEFT(A8,FIND(" ",A8)-1)&" "&MID(A8,FIND(" ",A8,FIND(" ",A8)+1)+1,99)
A15: =SUBSTITUTE(Stammdaten!$B$22,"{AGB}",Stammdaten!$B$9)
A19: Preisaufstellung – Preise reflektieren Mengen
A21: Pos | B21: Anz | C21: Beschreibung | D21: Einh. | E21: Preis/Wo. | F21: Wochen | G21: Position
A22: =IF(C22="","",COUNTA($C$22:C22)) | B22: 1 | C22: 6MVA Trafo 16,5kV YNyn0 | D22: Stk | E22: 5409.82 | F22: 1 | G22: =IF($C22="","",N($B22)*N($E22)*N($F22)) | I22: =IFERROR(VLOOKUP(C22,Artikel!$A$2:$C$16,3,FALSE),"")
A23: =IF(C23="","",COUNTA($C$22:C23)) | B23: 1 | C23: 3MVA Trafo 16,5kV YNyn0 | D23: Stk | E23: 1588.15 | F23: 1 | G23: =IF($C23="","",N($B23)*N($E23)*N($F23)) | I23: =IFERROR(VLOOKUP(C23,Artikel!$A$2:$C$16,3,FALSE),"")
A24: =IF(C24="","",COUNTA($C$22:C24)) | B24: 2 | C24: 25 Meter x Kabel 32A | D24: Stk | E24: 6.85 | F24: 1 | G24: =IF($C24="","",N($B24)*N($E24)*N($F24)) | I24: =IFERROR(VLOOKUP(C24,Artikel!$A$2:$C$16,3,FALSE),"")
A25: =IF(C25="","",COUNTA($C$22:C25)) | B25: 1 | C25: Load Bank 6000 kVA Resistive and Reactive : 400V 3-ph @ 50 Hz | D25: Stk | E25: 4960.73 | F25: 1 | G25: =IF($C25="","",N($B25)*N($E25)*N($F25)) | I25: =IFERROR(VLOOKUP(C25,Artikel!$A$2:$C$16,3,FALSE),"")
A26: =IF(C26="","",COUNTA($C$22:C26)) | B26: 1 | C26: Load Bank 3300 kVA Resistive and Reactive : 400V 3-ph @ 50 Hz | D26: Stk | E26: 3087.82 | F26: 1 | G26: =IF($C26="","",N($B26)*N($E26)*N($F26)) | I26: =IFERROR(VLOOKUP(C26,Artikel!$A$2:$C$16,3,FALSE),"")
A27: =IF(C27="","",COUNTA($C$22:C27)) | B27: 63 | C27: 10 Meter x Einzeladerkabel 240mm² (Set A) | D27: Stk | E27: 4.483651 | F27: 1 | G27: =IF($C27="","",N($B27)*N($E27)*N($F27)) | I27: =IFERROR(VLOOKUP(C27,Artikel!$A$2:$C$16,3,FALSE),"")
A28: =IF(C28="","",COUNTA($C$22:C28)) | B28: 32 | C28: 10 Meter x Einzeladerkabel 240mm² (Set B) | D28: Stk | E28: 4.483437 | F28: 1 | G28: =IF($C28="","",N($B28)*N($E28)*N($F28)) | I28: =IFERROR(VLOOKUP(C28,Artikel!$A$2:$C$16,3,FALSE),"")
A29: =IF(C29="","",COUNTA($C$22:C29)) | B29: 1 | C29: 25 Meter x Kabel 125A | D29: Stk | E29: 12.57 | F29: 1 | G29: =IF($C29="","",N($B29)*N($E29)*N($F29)) | I29: =IFERROR(VLOOKUP(C29,Artikel!$A$2:$C$16,3,FALSE),"")
A30: =IF(C30="","",COUNTA($C$22:C30)) | B30: 1 | C30: 25 Meter x Kabel 63A | D30: Stk | E30: 9.46 | F30: 1 | G30: =IF($C30="","",N($B30)*N($E30)*N($F30)) | I30: =IFERROR(VLOOKUP(C30,Artikel!$A$2:$C$16,3,FALSE),"")
A31: =IF(C31="","",COUNTA($C$22:C31)) | B31: 1 | C31: Umweltschutzpauschale | D31: Psch | E31: 1085.57 | F31: 1 | G31: =IF($C31="","",N($B31)*N($E31)*N($F31)) | I31: =IFERROR(VLOOKUP(C31,Artikel!$A$2:$C$16,3,FALSE),"")
A32: =IF(C32="","",COUNTA($C$22:C32)) | B32: 1 | C32: Befreiung von der Versicherungspflicht | D32: Psch | E32: 1860.98 | F32: 1 | G32: =IF($C32="","",N($B32)*N($E32)*N($F32)) | I32: =IFERROR(VLOOKUP(C32,Artikel!$A$2:$C$16,3,FALSE),"")
A33: =IF(C33="","",COUNTA($C$22:C33)) | D33: =IFERROR(VLOOKUP(C33,Artikel!$A$2:$C$16,2,FALSE),"") | E33: =IFERROR(VLOOKUP(C33,Artikel!$A$2:$C$16,3,FALSE),"") | F33: =IF(C33="","",1) | G33: =IF($C33="","",N($B33)*N($E33)*N($F33)) | I33: =IFERROR(VLOOKUP(C33,Artikel!$A$2:$C$16,3,FALSE),"")
A34: =IF(C34="","",COUNTA($C$22:C34)) | D34: =IFERROR(VLOOKUP(C34,Artikel!$A$2:$C$16,2,FALSE),"") | E34: =IFERROR(VLOOKUP(C34,Artikel!$A$2:$C$16,3,FALSE),"") | F34: =IF(C34="","",1) | G34: =IF($C34="","",N($B34)*N($E34)*N($F34)) | I34: =IFERROR(VLOOKUP(C34,Artikel!$A$2:$C$16,3,FALSE),"")
A35: =IF(C35="","",COUNTA($C$22:C35)) | D35: =IFERROR(VLOOKUP(C35,Artikel!$A$2:$C$16,2,FALSE),"") | E35: =IFERROR(VLOOKUP(C35,Artikel!$A$2:$C$16,3,FALSE),"") | F35: =IF(C35="","",1) | G35: =IF($C35="","",N($B35)*N($E35)*N($F35)) | I35: =IFERROR(VLOOKUP(C35,Artikel!$A$2:$C$16,3,FALSE),"")
A36: =IF(C36="","",COUNTA($C$22:C36)) | D36: =IFERROR(VLOOKUP(C36,Artikel!$A$2:$C$16,2,FALSE),"") | E36: =IFERROR(VLOOKUP(C36,Artikel!$A$2:$C$16,3,FALSE),"") | F36: =IF(C36="","",1) | G36: =IF($C36="","",N($B36)*N($E36)*N($F36)) | I36: =IFERROR(VLOOKUP(C36,Artikel!$A$2:$C$16,3,FALSE),"")
A37: =IF(C37="","",COUNTA($C$22:C37)) | D37: =IFERROR(VLOOKUP(C37,Artikel!$A$2:$C$16,2,FALSE),"") | E37: =IFERROR(VLOOKUP(C37,Artikel!$A$2:$C$16,3,FALSE),"") | F37: =IF(C37="","",1) | G37: =IF($C37="","",N($B37)*N($E37)*N($F37)) | I37: =IFERROR(VLOOKUP(C37,Artikel!$A$2:$C$16,3,FALSE),"")
A38: =IF(C38="","",COUNTA($C$22:C38)) | D38: =IFERROR(VLOOKUP(C38,Artikel!$A$2:$C$16,2,FALSE),"") | E38: =IFERROR(VLOOKUP(C38,Artikel!$A$2:$C$16,3,FALSE),"") | F38: =IF(C38="","",1) | G38: =IF($C38="","",N($B38)*N($E38)*N($F38)) | I38: =IFERROR(VLOOKUP(C38,Artikel!$A$2:$C$16,3,FALSE),"")
A39: =IF(C39="","",COUNTA($C$22:C39)) | D39: =IFERROR(VLOOKUP(C39,Artikel!$A$2:$C$16,2,FALSE),"") | E39: =IFERROR(VLOOKUP(C39,Artikel!$A$2:$C$16,3,FALSE),"") | F39: =IF(C39="","",1) | G39: =IF($C39="","",N($B39)*N($E39)*N($F39)) | I39: =IFERROR(VLOOKUP(C39,Artikel!$A$2:$C$16,3,FALSE),"")
A40: =IF(C40="","",COUNTA($C$22:C40)) | D40: =IFERROR(VLOOKUP(C40,Artikel!$A$2:$C$16,2,FALSE),"") | E40: =IFERROR(VLOOKUP(C40,Artikel!$A$2:$C$16,3,FALSE),"") | F40: =IF(C40="","",1) | G40: =IF($C40="","",N($B40)*N($E40)*N($F40)) | I40: =IFERROR(VLOOKUP(C40,Artikel!$A$2:$C$16,3,FALSE),"")
A41: Zwischentotal (GESAMT) | G41: =SUM(G22:G40)
A42: ="Rabatt "&TEXT(Stammdaten!$B$17,"0.0%") | G42: =-ROUND(G41*Stammdaten!$B$17,2)
A43: Total nach Rabatt | G43: =G41+G42
A44: ="MwSt "&TEXT(Stammdaten!$B$18,"0.0%") | G44: =ROUND(G43*Stammdaten!$B$18,2)
A45: Endbetrag (CHF) | G45: =G43+G44
A47: ="Anmerkung: "&Stammdaten!$B$24
...

Sheet Stammdaten
A1: FIRMA (Absender)
A2: Firmenname | B2: Mobil in Time AG
A3: Strasse | B3: Mattenstrasse 3
A4: PLZ / Ort | B4: 8253 Diessenhofen
A5: Telefon | B5: +41 44 806 13 00
A6: E-Mail | B6: info@mobilintime.com
A7: Web | B7: www.mobilintime.com
A8: Zusatz | B8: Ein Unternehmen der Mobil in Time Gruppe
A9: AGB-Hinweis (URL) | B9: www.mobilintime.com
A11: SACHBEARBEITER
A12: Name | B12: Burak Ücöz
A13: Telefon | B13: +41 76 202 01 70
A14: E-Mail | B14: uecoez@mobilintime.com
A16: STANDARDWERTE
A17: Rabatt (%) | B17: 0.1
A18: MwSt (%) | B18: 0
A19: Währung | B19: CHF
A21: TEXTBAUSTEINE
A22: Einleitung | B22: Wir bedanken uns für Ihr Interesse an einer Zusammenarbeit mit uns. Aufgrund der von Ihnen gemachten Angaben und gemäss unseren Allgemeinen Geschäftsbedingungen, einsehbar auf {AGB}, bieten wir Ihnen folgende Leistungen freibleibend an.
A23: Grussformel | B23: Mit freundlichen Grüssen
A24: Anmerkung | B24: Dieses Budgetangebot ist für beide Parteien unverbindlich. Alle Anmietungen erfolgen vorbehaltlich der Verfügbarkeit bei Aufgabe der Bestellung und zu den Preisen, die im offiziellen Angebot aufgeführt sind, sobald die zusätzlichen Detailinformationen vorliegen, die sich auf Ihr Equipment und Ihren Servicebedarf beziehen.

Sheet Artikel
A1: Beschreibung | B1: Einheit | C1: Einzelpreis/Woche (CHF)
A2: 6MVA Trafo 16,5kV YNyn0 | B2: Stk | C2: 5409.82
A3: 3MVA Trafo 16,5kV YNyn0 | B3: Stk | C3: 1588.15
A4: 1MVA Trafo 16,5kV YNyn0 | B4: Stk | C4: 850
A5: Load Bank 6000 kVA Resistive and Reactive : 400V 3-ph @ 50 Hz | B5: Stk | C5: 4960.73
A6: Load Bank 3300 kVA Resistive and Reactive : 400V 3-ph @ 50 Hz | B6: Stk | C6: 3087.82
A7: 25 Meter x Kabel 32A | B7: Stk | C7: 6.85
A8: 25 Meter x Kabel 63A | B8: Stk | C8: 9.46
A9: 25 Meter x Kabel 125A | B9: Stk | C9: 12.57
A10: 10 Meter x Einzeladerkabel 240mm² (Set A) | B10: Stk | C10: 4.483651
A11: 10 Meter x Einzeladerkabel 240mm² (Set B) | B11: Stk | C11: 4.483438
A12: 10 Meter x Einzeladerkabel 240mm² | B12: Stk | C12: 4.48
A13: Umweltschutzpauschale | B13: Psch | C13: 1085.57
... A16: Montage / Inbetriebnahme (pro Std.) | B16: Std | C16: 135
